[24/Nov/2023 18:22:34] WARNING [django.request:241] Unauthorized: /api/company/check-in/0
[24/Nov/2023 18:22:34] WARNING [django.request:241] Unauthorized: /api/company/check-in/0
[24/Nov/2023 18:22:34] WARNING [django.server:212] "GET /api/company/check-in/0 HTTP/1.1" 401 58
[24/Nov/2023 18:22:34] WARNING [django.server:212] "GET /api/company/check-in/0 HTTP/1.1" 401 58
[01/Jan/2024 15:25:46] ERROR [django.request:241] Internal Server Error: /api/chatRecommendation/get/
Traceback (most recent call last):
  File "/usr/local/lib/python3.10/site-packages/django/core/handlers/exception.py", line 55, in inner
    response = get_response(request)
  File "/usr/local/lib/python3.10/site-packages/django/core/handlers/base.py", line 197, in _get_response
    response = wrapped_callback(request, *callback_args, **callback_kwargs)
  File "/usr/local/lib/python3.10/site-packages/django/views/decorators/csrf.py", line 56, in wrapper_view
    return view_func(*args, **kwargs)
  File "/usr/local/lib/python3.10/site-packages/django/views/generic/base.py", line 104, in view
    return self.dispatch(request, *args, **kwargs)
  File "/usr/local/lib/python3.10/site-packages/rest_framework/views.py", line 509, in dispatch
    response = self.handle_exception(exc)
  File "/usr/local/lib/python3.10/site-packages/rest_framework/views.py", line 469, in handle_exception
    self.raise_uncaught_exception(exc)
  File "/usr/local/lib/python3.10/site-packages/rest_framework/views.py", line 480, in raise_uncaught_exception
    raise exc
  File "/usr/local/lib/python3.10/site-packages/rest_framework/views.py", line 506, in dispatch
    response = handler(request, *args, **kwargs)
  File "/usr/local/lib/python3.10/site-packages/rest_framework/decorators.py", line 50, in handler
    return func(*args, **kwargs)
  File "/app/backend/api/chatbot/replyBot.py", line 40, in predict_job_title
    user_data_std = scaler.transform(user_data)
  File "/usr/local/lib/python3.10/site-packages/sklearn/utils/_set_output.py", line 140, in wrapped
    data_to_wrap = f(self, X, *args, **kwargs)
  File "/usr/local/lib/python3.10/site-packages/sklearn/preprocessing/_data.py", line 992, in transform
    X = self._validate_data(
  File "/usr/local/lib/python3.10/site-packages/sklearn/base.py", line 548, in _validate_data
    self._check_feature_names(X, reset=reset)
  File "/usr/local/lib/python3.10/site-packages/sklearn/base.py", line 481, in _check_feature_names
    raise ValueError(message)
ValueError: The feature names should match those that were passed during fit.
Feature names unseen at fit time:
- biochemistry
·
- immunochemistry
immunocytochemistry
Feature names seen at fit time, yet now missing:
- biochemistry
·
- immunochemistry
immunocytochemistry

[01/Jan/2024 15:25:46] ERROR [django.request:241] Internal Server Error: /api/chatRecommendation/get/
Traceback (most recent call last):
  File "/usr/local/lib/python3.10/site-packages/django/core/handlers/exception.py", line 55, in inner
    response = get_response(request)
  File "/usr/local/lib/python3.10/site-packages/django/core/handlers/base.py", line 197, in _get_response
    response = wrapped_callback(request, *callback_args, **callback_kwargs)
  File "/usr/local/lib/python3.10/site-packages/django/views/decorators/csrf.py", line 56, in wrapper_view
    return view_func(*args, **kwargs)
  File "/usr/local/lib/python3.10/site-packages/django/views/generic/base.py", line 104, in view
    return self.dispatch(request, *args, **kwargs)
  File "/usr/local/lib/python3.10/site-packages/rest_framework/views.py", line 509, in dispatch
    response = self.handle_exception(exc)
  File "/usr/local/lib/python3.10/site-packages/rest_framework/views.py", line 469, in handle_exception
    self.raise_uncaught_exception(exc)
  File "/usr/local/lib/python3.10/site-packages/rest_framework/views.py", line 480, in raise_uncaught_exception
    raise exc
  File "/usr/local/lib/python3.10/site-packages/rest_framework/views.py", line 506, in dispatch
    response = handler(request, *args, **kwargs)
  File "/usr/local/lib/python3.10/site-packages/rest_framework/decorators.py", line 50, in handler
    return func(*args, **kwargs)
  File "/app/backend/api/chatbot/replyBot.py", line 40, in predict_job_title
    user_data_std = scaler.transform(user_data)
  File "/usr/local/lib/python3.10/site-packages/sklearn/utils/_set_output.py", line 140, in wrapped
    data_to_wrap = f(self, X, *args, **kwargs)
  File "/usr/local/lib/python3.10/site-packages/sklearn/preprocessing/_data.py", line 992, in transform
    X = self._validate_data(
  File "/usr/local/lib/python3.10/site-packages/sklearn/base.py", line 548, in _validate_data
    self._check_feature_names(X, reset=reset)
  File "/usr/local/lib/python3.10/site-packages/sklearn/base.py", line 481, in _check_feature_names
    raise ValueError(message)
ValueError: The feature names should match those that were passed during fit.
Feature names unseen at fit time:
- biochemistry
·
- immunochemistry
immunocytochemistry
Feature names seen at fit time, yet now missing:
- biochemistry
·
- immunochemistry
immunocytochemistry

[01/Jan/2024 15:25:46] ERROR [django.server:212] "POST /api/chatRecommendation/get/ HTTP/1.1" 500 139303
[01/Jan/2024 15:25:46] ERROR [django.server:212] "POST /api/chatRecommendation/get/ HTTP/1.1" 500 139303
[01/Jan/2024 15:26:06] ERROR [django.request:241] Internal Server Error: /api/chatRecommendation/get/
Traceback (most recent call last):
  File "/usr/local/lib/python3.10/site-packages/django/core/handlers/exception.py", line 55, in inner
    response = get_response(request)
  File "/usr/local/lib/python3.10/site-packages/django/core/handlers/base.py", line 197, in _get_response
    response = wrapped_callback(request, *callback_args, **callback_kwargs)
  File "/usr/local/lib/python3.10/site-packages/django/views/decorators/csrf.py", line 56, in wrapper_view
    return view_func(*args, **kwargs)
  File "/usr/local/lib/python3.10/site-packages/django/views/generic/base.py", line 104, in view
    return self.dispatch(request, *args, **kwargs)
  File "/usr/local/lib/python3.10/site-packages/rest_framework/views.py", line 509, in dispatch
    response = self.handle_exception(exc)
  File "/usr/local/lib/python3.10/site-packages/rest_framework/views.py", line 469, in handle_exception
    self.raise_uncaught_exception(exc)
  File "/usr/local/lib/python3.10/site-packages/rest_framework/views.py", line 480, in raise_uncaught_exception
    raise exc
  File "/usr/local/lib/python3.10/site-packages/rest_framework/views.py", line 506, in dispatch
    response = handler(request, *args, **kwargs)
  File "/usr/local/lib/python3.10/site-packages/rest_framework/decorators.py", line 50, in handler
    return func(*args, **kwargs)
  File "/app/backend/api/chatbot/replyBot.py", line 40, in predict_job_title
    user_data_std = scaler.transform(user_data)
  File "/usr/local/lib/python3.10/site-packages/sklearn/utils/_set_output.py", line 140, in wrapped
    data_to_wrap = f(self, X, *args, **kwargs)
  File "/usr/local/lib/python3.10/site-packages/sklearn/preprocessing/_data.py", line 992, in transform
    X = self._validate_data(
  File "/usr/local/lib/python3.10/site-packages/sklearn/base.py", line 548, in _validate_data
    self._check_feature_names(X, reset=reset)
  File "/usr/local/lib/python3.10/site-packages/sklearn/base.py", line 481, in _check_feature_names
    raise ValueError(message)
ValueError: The feature names should match those that were passed during fit.
Feature names unseen at fit time:
- biochemistry
·
- immunochemistry
immunocytochemistry
Feature names seen at fit time, yet now missing:
- biochemistry
·
- immunochemistry
immunocytochemistry

[01/Jan/2024 15:26:06] ERROR [django.request:241] Internal Server Error: /api/chatRecommendation/get/
Traceback (most recent call last):
  File "/usr/local/lib/python3.10/site-packages/django/core/handlers/exception.py", line 55, in inner
    response = get_response(request)
  File "/usr/local/lib/python3.10/site-packages/django/core/handlers/base.py", line 197, in _get_response
    response = wrapped_callback(request, *callback_args, **callback_kwargs)
  File "/usr/local/lib/python3.10/site-packages/django/views/decorators/csrf.py", line 56, in wrapper_view
    return view_func(*args, **kwargs)
  File "/usr/local/lib/python3.10/site-packages/django/views/generic/base.py", line 104, in view
    return self.dispatch(request, *args, **kwargs)
  File "/usr/local/lib/python3.10/site-packages/rest_framework/views.py", line 509, in dispatch
    response = self.handle_exception(exc)
  File "/usr/local/lib/python3.10/site-packages/rest_framework/views.py", line 469, in handle_exception
    self.raise_uncaught_exception(exc)
  File "/usr/local/lib/python3.10/site-packages/rest_framework/views.py", line 480, in raise_uncaught_exception
    raise exc
  File "/usr/local/lib/python3.10/site-packages/rest_framework/views.py", line 506, in dispatch
    response = handler(request, *args, **kwargs)
  File "/usr/local/lib/python3.10/site-packages/rest_framework/decorators.py", line 50, in handler
    return func(*args, **kwargs)
  File "/app/backend/api/chatbot/replyBot.py", line 40, in predict_job_title
    user_data_std = scaler.transform(user_data)
  File "/usr/local/lib/python3.10/site-packages/sklearn/utils/_set_output.py", line 140, in wrapped
    data_to_wrap = f(self, X, *args, **kwargs)
  File "/usr/local/lib/python3.10/site-packages/sklearn/preprocessing/_data.py", line 992, in transform
    X = self._validate_data(
  File "/usr/local/lib/python3.10/site-packages/sklearn/base.py", line 548, in _validate_data
    self._check_feature_names(X, reset=reset)
  File "/usr/local/lib/python3.10/site-packages/sklearn/base.py", line 481, in _check_feature_names
    raise ValueError(message)
ValueError: The feature names should match those that were passed during fit.
Feature names unseen at fit time:
- biochemistry
·
- immunochemistry
immunocytochemistry
Feature names seen at fit time, yet now missing:
- biochemistry
·
- immunochemistry
immunocytochemistry

[01/Jan/2024 15:26:06] ERROR [django.server:212] "POST /api/chatRecommendation/get/ HTTP/1.1" 500 139303
[01/Jan/2024 15:26:06] ERROR [django.server:212] "POST /api/chatRecommendation/get/ HTTP/1.1" 500 139303
[01/Jan/2024 15:53:53] ERROR [django.request:241] Internal Server Error: /api/chatRecommendation/get/
Traceback (most recent call last):
  File "/usr/local/lib/python3.10/site-packages/django/core/handlers/exception.py", line 55, in inner
    response = get_response(request)
  File "/usr/local/lib/python3.10/site-packages/django/core/handlers/base.py", line 197, in _get_response
    response = wrapped_callback(request, *callback_args, **callback_kwargs)
  File "/usr/local/lib/python3.10/site-packages/django/views/decorators/csrf.py", line 56, in wrapper_view
    return view_func(*args, **kwargs)
  File "/usr/local/lib/python3.10/site-packages/django/views/generic/base.py", line 104, in view
    return self.dispatch(request, *args, **kwargs)
  File "/usr/local/lib/python3.10/site-packages/rest_framework/views.py", line 509, in dispatch
    response = self.handle_exception(exc)
  File "/usr/local/lib/python3.10/site-packages/rest_framework/views.py", line 469, in handle_exception
    self.raise_uncaught_exception(exc)
  File "/usr/local/lib/python3.10/site-packages/rest_framework/views.py", line 480, in raise_uncaught_exception
    raise exc
  File "/usr/local/lib/python3.10/site-packages/rest_framework/views.py", line 506, in dispatch
    response = handler(request, *args, **kwargs)
  File "/usr/local/lib/python3.10/site-packages/rest_framework/decorators.py", line 50, in handler
    return func(*args, **kwargs)
  File "/app/backend/api/chatbot/replyBot.py", line 56, in predict_job_title
    return JsonResponse({'predicted_job_title': answer})
  File "/usr/local/lib/python3.10/site-packages/django/http/response.py", line 748, in __init__
    data = json.dumps(data, cls=encoder, **json_dumps_params)
  File "/usr/local/lib/python3.10/json/__init__.py", line 238, in dumps
    **kw).encode(obj)
  File "/usr/local/lib/python3.10/json/encoder.py", line 199, in encode
    chunks = self.iterencode(o, _one_shot=True)
  File "/usr/local/lib/python3.10/json/encoder.py", line 257, in iterencode
    return _iterencode(o, 0)
  File "/usr/local/lib/python3.10/site-packages/django/core/serializers/json.py", line 106, in default
    return super().default(o)
  File "/usr/local/lib/python3.10/json/encoder.py", line 179, in default
    raise TypeError(f'Object of type {o.__class__.__name__} '
TypeError: Object of type ndarray is not JSON serializable
[01/Jan/2024 15:53:53] ERROR [django.request:241] Internal Server Error: /api/chatRecommendation/get/
Traceback (most recent call last):
  File "/usr/local/lib/python3.10/site-packages/django/core/handlers/exception.py", line 55, in inner
    response = get_response(request)
  File "/usr/local/lib/python3.10/site-packages/django/core/handlers/base.py", line 197, in _get_response
    response = wrapped_callback(request, *callback_args, **callback_kwargs)
  File "/usr/local/lib/python3.10/site-packages/django/views/decorators/csrf.py", line 56, in wrapper_view
    return view_func(*args, **kwargs)
  File "/usr/local/lib/python3.10/site-packages/django/views/generic/base.py", line 104, in view
    return self.dispatch(request, *args, **kwargs)
  File "/usr/local/lib/python3.10/site-packages/rest_framework/views.py", line 509, in dispatch
    response = self.handle_exception(exc)
  File "/usr/local/lib/python3.10/site-packages/rest_framework/views.py", line 469, in handle_exception
    self.raise_uncaught_exception(exc)
  File "/usr/local/lib/python3.10/site-packages/rest_framework/views.py", line 480, in raise_uncaught_exception
    raise exc
  File "/usr/local/lib/python3.10/site-packages/rest_framework/views.py", line 506, in dispatch
    response = handler(request, *args, **kwargs)
  File "/usr/local/lib/python3.10/site-packages/rest_framework/decorators.py", line 50, in handler
    return func(*args, **kwargs)
  File "/app/backend/api/chatbot/replyBot.py", line 56, in predict_job_title
    return JsonResponse({'predicted_job_title': answer})
  File "/usr/local/lib/python3.10/site-packages/django/http/response.py", line 748, in __init__
    data = json.dumps(data, cls=encoder, **json_dumps_params)
  File "/usr/local/lib/python3.10/json/__init__.py", line 238, in dumps
    **kw).encode(obj)
  File "/usr/local/lib/python3.10/json/encoder.py", line 199, in encode
    chunks = self.iterencode(o, _one_shot=True)
  File "/usr/local/lib/python3.10/json/encoder.py", line 257, in iterencode
    return _iterencode(o, 0)
  File "/usr/local/lib/python3.10/site-packages/django/core/serializers/json.py", line 106, in default
    return super().default(o)
  File "/usr/local/lib/python3.10/json/encoder.py", line 179, in default
    raise TypeError(f'Object of type {o.__class__.__name__} '
TypeError: Object of type ndarray is not JSON serializable
[01/Jan/2024 15:53:53] ERROR [django.server:212] "POST /api/chatRecommendation/get/ HTTP/1.1" 500 125702
[01/Jan/2024 15:53:53] ERROR [django.server:212] "POST /api/chatRecommendation/get/ HTTP/1.1" 500 125702
[01/Jan/2024 15:57:27] ERROR [django.request:241] Internal Server Error: /api/chatRecommendation/get/
Traceback (most recent call last):
  File "/usr/local/lib/python3.10/site-packages/django/core/handlers/exception.py", line 55, in inner
    response = get_response(request)
  File "/usr/local/lib/python3.10/site-packages/django/core/handlers/base.py", line 197, in _get_response
    response = wrapped_callback(request, *callback_args, **callback_kwargs)
  File "/usr/local/lib/python3.10/site-packages/django/views/decorators/csrf.py", line 56, in wrapper_view
    return view_func(*args, **kwargs)
  File "/usr/local/lib/python3.10/site-packages/django/views/generic/base.py", line 104, in view
    return self.dispatch(request, *args, **kwargs)
  File "/usr/local/lib/python3.10/site-packages/rest_framework/views.py", line 509, in dispatch
    response = self.handle_exception(exc)
  File "/usr/local/lib/python3.10/site-packages/rest_framework/views.py", line 469, in handle_exception
    self.raise_uncaught_exception(exc)
  File "/usr/local/lib/python3.10/site-packages/rest_framework/views.py", line 480, in raise_uncaught_exception
    raise exc
  File "/usr/local/lib/python3.10/site-packages/rest_framework/views.py", line 506, in dispatch
    response = handler(request, *args, **kwargs)
  File "/usr/local/lib/python3.10/site-packages/rest_framework/decorators.py", line 50, in handler
    return func(*args, **kwargs)
  File "/app/backend/api/chatbot/replyBot.py", line 56, in predict_job_title
    return JsonResponse({'predicted_job_title': answer})
  File "/usr/local/lib/python3.10/site-packages/django/http/response.py", line 748, in __init__
    data = json.dumps(data, cls=encoder, **json_dumps_params)
  File "/usr/local/lib/python3.10/json/__init__.py", line 238, in dumps
    **kw).encode(obj)
  File "/usr/local/lib/python3.10/json/encoder.py", line 199, in encode
    chunks = self.iterencode(o, _one_shot=True)
  File "/usr/local/lib/python3.10/json/encoder.py", line 257, in iterencode
    return _iterencode(o, 0)
  File "/usr/local/lib/python3.10/site-packages/django/core/serializers/json.py", line 106, in default
    return super().default(o)
  File "/usr/local/lib/python3.10/json/encoder.py", line 179, in default
    raise TypeError(f'Object of type {o.__class__.__name__} '
TypeError: Object of type ndarray is not JSON serializable
[01/Jan/2024 15:57:27] ERROR [django.request:241] Internal Server Error: /api/chatRecommendation/get/
Traceback (most recent call last):
  File "/usr/local/lib/python3.10/site-packages/django/core/handlers/exception.py", line 55, in inner
    response = get_response(request)
  File "/usr/local/lib/python3.10/site-packages/django/core/handlers/base.py", line 197, in _get_response
    response = wrapped_callback(request, *callback_args, **callback_kwargs)
  File "/usr/local/lib/python3.10/site-packages/django/views/decorators/csrf.py", line 56, in wrapper_view
    return view_func(*args, **kwargs)
  File "/usr/local/lib/python3.10/site-packages/django/views/generic/base.py", line 104, in view
    return self.dispatch(request, *args, **kwargs)
  File "/usr/local/lib/python3.10/site-packages/rest_framework/views.py", line 509, in dispatch
    response = self.handle_exception(exc)
  File "/usr/local/lib/python3.10/site-packages/rest_framework/views.py", line 469, in handle_exception
    self.raise_uncaught_exception(exc)
  File "/usr/local/lib/python3.10/site-packages/rest_framework/views.py", line 480, in raise_uncaught_exception
    raise exc
  File "/usr/local/lib/python3.10/site-packages/rest_framework/views.py", line 506, in dispatch
    response = handler(request, *args, **kwargs)
  File "/usr/local/lib/python3.10/site-packages/rest_framework/decorators.py", line 50, in handler
    return func(*args, **kwargs)
  File "/app/backend/api/chatbot/replyBot.py", line 56, in predict_job_title
    return JsonResponse({'predicted_job_title': answer})
  File "/usr/local/lib/python3.10/site-packages/django/http/response.py", line 748, in __init__
    data = json.dumps(data, cls=encoder, **json_dumps_params)
  File "/usr/local/lib/python3.10/json/__init__.py", line 238, in dumps
    **kw).encode(obj)
  File "/usr/local/lib/python3.10/json/encoder.py", line 199, in encode
    chunks = self.iterencode(o, _one_shot=True)
  File "/usr/local/lib/python3.10/json/encoder.py", line 257, in iterencode
    return _iterencode(o, 0)
  File "/usr/local/lib/python3.10/site-packages/django/core/serializers/json.py", line 106, in default
    return super().default(o)
  File "/usr/local/lib/python3.10/json/encoder.py", line 179, in default
    raise TypeError(f'Object of type {o.__class__.__name__} '
TypeError: Object of type ndarray is not JSON serializable
[01/Jan/2024 15:57:27] ERROR [django.server:212] "POST /api/chatRecommendation/get/ HTTP/1.1" 500 125795
[01/Jan/2024 15:57:27] ERROR [django.server:212] "POST /api/chatRecommendation/get/ HTTP/1.1" 500 125795
[01/Jan/2024 16:00:46] ERROR [django.request:241] Internal Server Error: /api/chatRecommendation/get/
Traceback (most recent call last):
  File "/usr/local/lib/python3.10/site-packages/django/core/handlers/exception.py", line 55, in inner
    response = get_response(request)
  File "/usr/local/lib/python3.10/site-packages/django/core/handlers/base.py", line 197, in _get_response
    response = wrapped_callback(request, *callback_args, **callback_kwargs)
  File "/usr/local/lib/python3.10/site-packages/django/views/decorators/csrf.py", line 56, in wrapper_view
    return view_func(*args, **kwargs)
  File "/usr/local/lib/python3.10/site-packages/django/views/generic/base.py", line 104, in view
    return self.dispatch(request, *args, **kwargs)
  File "/usr/local/lib/python3.10/site-packages/rest_framework/views.py", line 509, in dispatch
    response = self.handle_exception(exc)
  File "/usr/local/lib/python3.10/site-packages/rest_framework/views.py", line 469, in handle_exception
    self.raise_uncaught_exception(exc)
  File "/usr/local/lib/python3.10/site-packages/rest_framework/views.py", line 480, in raise_uncaught_exception
    raise exc
  File "/usr/local/lib/python3.10/site-packages/rest_framework/views.py", line 506, in dispatch
    response = handler(request, *args, **kwargs)
  File "/usr/local/lib/python3.10/site-packages/rest_framework/decorators.py", line 50, in handler
    return func(*args, **kwargs)
  File "/app/backend/api/chatbot/replyBot.py", line 57, in predict_job_title
    return JsonResponse({'predicted_job_title': answer})
  File "/usr/local/lib/python3.10/site-packages/django/http/response.py", line 748, in __init__
    data = json.dumps(data, cls=encoder, **json_dumps_params)
  File "/usr/local/lib/python3.10/json/__init__.py", line 238, in dumps
    **kw).encode(obj)
  File "/usr/local/lib/python3.10/json/encoder.py", line 199, in encode
    chunks = self.iterencode(o, _one_shot=True)
  File "/usr/local/lib/python3.10/json/encoder.py", line 257, in iterencode
    return _iterencode(o, 0)
  File "/usr/local/lib/python3.10/site-packages/django/core/serializers/json.py", line 106, in default
    return super().default(o)
  File "/usr/local/lib/python3.10/json/encoder.py", line 179, in default
    raise TypeError(f'Object of type {o.__class__.__name__} '
TypeError: Object of type ndarray is not JSON serializable
[01/Jan/2024 16:00:46] ERROR [django.request:241] Internal Server Error: /api/chatRecommendation/get/
Traceback (most recent call last):
  File "/usr/local/lib/python3.10/site-packages/django/core/handlers/exception.py", line 55, in inner
    response = get_response(request)
  File "/usr/local/lib/python3.10/site-packages/django/core/handlers/base.py", line 197, in _get_response
    response = wrapped_callback(request, *callback_args, **callback_kwargs)
  File "/usr/local/lib/python3.10/site-packages/django/views/decorators/csrf.py", line 56, in wrapper_view
    return view_func(*args, **kwargs)
  File "/usr/local/lib/python3.10/site-packages/django/views/generic/base.py", line 104, in view
    return self.dispatch(request, *args, **kwargs)
  File "/usr/local/lib/python3.10/site-packages/rest_framework/views.py", line 509, in dispatch
    response = self.handle_exception(exc)
  File "/usr/local/lib/python3.10/site-packages/rest_framework/views.py", line 469, in handle_exception
    self.raise_uncaught_exception(exc)
  File "/usr/local/lib/python3.10/site-packages/rest_framework/views.py", line 480, in raise_uncaught_exception
    raise exc
  File "/usr/local/lib/python3.10/site-packages/rest_framework/views.py", line 506, in dispatch
    response = handler(request, *args, **kwargs)
  File "/usr/local/lib/python3.10/site-packages/rest_framework/decorators.py", line 50, in handler
    return func(*args, **kwargs)
  File "/app/backend/api/chatbot/replyBot.py", line 57, in predict_job_title
    return JsonResponse({'predicted_job_title': answer})
  File "/usr/local/lib/python3.10/site-packages/django/http/response.py", line 748, in __init__
    data = json.dumps(data, cls=encoder, **json_dumps_params)
  File "/usr/local/lib/python3.10/json/__init__.py", line 238, in dumps
    **kw).encode(obj)
  File "/usr/local/lib/python3.10/json/encoder.py", line 199, in encode
    chunks = self.iterencode(o, _one_shot=True)
  File "/usr/local/lib/python3.10/json/encoder.py", line 257, in iterencode
    return _iterencode(o, 0)
  File "/usr/local/lib/python3.10/site-packages/django/core/serializers/json.py", line 106, in default
    return super().default(o)
  File "/usr/local/lib/python3.10/json/encoder.py", line 179, in default
    raise TypeError(f'Object of type {o.__class__.__name__} '
TypeError: Object of type ndarray is not JSON serializable
[01/Jan/2024 16:00:46] ERROR [django.server:212] "POST /api/chatRecommendation/get/ HTTP/1.1" 500 125678
[01/Jan/2024 16:00:46] ERROR [django.server:212] "POST /api/chatRecommendation/get/ HTTP/1.1" 500 125678
[01/Jan/2024 16:06:06] ERROR [django.request:241] Internal Server Error: /api/chatRecommendation/get/
Traceback (most recent call last):
  File "/usr/local/lib/python3.10/site-packages/django/core/handlers/exception.py", line 55, in inner
    response = get_response(request)
  File "/usr/local/lib/python3.10/site-packages/django/core/handlers/base.py", line 197, in _get_response
    response = wrapped_callback(request, *callback_args, **callback_kwargs)
  File "/usr/local/lib/python3.10/site-packages/django/views/decorators/csrf.py", line 56, in wrapper_view
    return view_func(*args, **kwargs)
  File "/usr/local/lib/python3.10/site-packages/django/views/generic/base.py", line 104, in view
    return self.dispatch(request, *args, **kwargs)
  File "/usr/local/lib/python3.10/site-packages/rest_framework/views.py", line 509, in dispatch
    response = self.handle_exception(exc)
  File "/usr/local/lib/python3.10/site-packages/rest_framework/views.py", line 469, in handle_exception
    self.raise_uncaught_exception(exc)
  File "/usr/local/lib/python3.10/site-packages/rest_framework/views.py", line 480, in raise_uncaught_exception
    raise exc
  File "/usr/local/lib/python3.10/site-packages/rest_framework/views.py", line 506, in dispatch
    response = handler(request, *args, **kwargs)
  File "/usr/local/lib/python3.10/site-packages/rest_framework/decorators.py", line 50, in handler
    return func(*args, **kwargs)
  File "/app/backend/api/chatbot/replyBot.py", line 55, in predict_job_title
    answer = '推薦職位：' + predicted_job_title.tolist()
TypeError: can only concatenate str (not "list") to str
[01/Jan/2024 16:06:06] ERROR [django.request:241] Internal Server Error: /api/chatRecommendation/get/
Traceback (most recent call last):
  File "/usr/local/lib/python3.10/site-packages/django/core/handlers/exception.py", line 55, in inner
    response = get_response(request)
  File "/usr/local/lib/python3.10/site-packages/django/core/handlers/base.py", line 197, in _get_response
    response = wrapped_callback(request, *callback_args, **callback_kwargs)
  File "/usr/local/lib/python3.10/site-packages/django/views/decorators/csrf.py", line 56, in wrapper_view
    return view_func(*args, **kwargs)
  File "/usr/local/lib/python3.10/site-packages/django/views/generic/base.py", line 104, in view
    return self.dispatch(request, *args, **kwargs)
  File "/usr/local/lib/python3.10/site-packages/rest_framework/views.py", line 509, in dispatch
    response = self.handle_exception(exc)
  File "/usr/local/lib/python3.10/site-packages/rest_framework/views.py", line 469, in handle_exception
    self.raise_uncaught_exception(exc)
  File "/usr/local/lib/python3.10/site-packages/rest_framework/views.py", line 480, in raise_uncaught_exception
    raise exc
  File "/usr/local/lib/python3.10/site-packages/rest_framework/views.py", line 506, in dispatch
    response = handler(request, *args, **kwargs)
  File "/usr/local/lib/python3.10/site-packages/rest_framework/decorators.py", line 50, in handler
    return func(*args, **kwargs)
  File "/app/backend/api/chatbot/replyBot.py", line 55, in predict_job_title
    answer = '推薦職位：' + predicted_job_title.tolist()
TypeError: can only concatenate str (not "list") to str
[01/Jan/2024 16:06:06] ERROR [django.server:212] "POST /api/chatRecommendation/get/ HTTP/1.1" 500 99500
[01/Jan/2024 16:06:06] ERROR [django.server:212] "POST /api/chatRecommendation/get/ HTTP/1.1" 500 99500
