[18/Oct/2023 06:32:29] WARNING [django.request:241] Not Found: /
[18/Oct/2023 06:32:29] WARNING [django.request:241] Not Found: /
[18/Oct/2023 06:32:29] WARNING [django.server:212] "GET / HTTP/1.1" 404 2164
[18/Oct/2023 06:32:29] WARNING [django.server:212] "GET / HTTP/1.1" 404 2164
[18/Oct/2023 06:32:29] WARNING [django.request:241] Not Found: /favicon.ico
[18/Oct/2023 06:32:29] WARNING [django.request:241] Not Found: /favicon.ico
[18/Oct/2023 06:32:29] WARNING [django.server:212] "GET /favicon.ico HTTP/1.1" 404 2215
[18/Oct/2023 06:32:29] WARNING [django.server:212] "GET /favicon.ico HTTP/1.1" 404 2215
[18/Oct/2023 06:33:03] ERROR [django.request:241] Internal Server Error: /api/verify
Traceback (most recent call last):
  File "/usr/local/lib/python3.10/site-packages/django/db/backends/utils.py", line 89, in _execute
    return self.cursor.execute(sql, params)
psycopg2.errors.UndefinedColumn: column api_companyemployee.skills does not exist
LINE 1: ...ePosition_id_id", "api_companyemployee"."salary", "api_compa...
                                                             ^


The above exception was the direct cause of the following exception:

Traceback (most recent call last):
  File "/usr/local/lib/python3.10/site-packages/django/core/handlers/exception.py", line 55, in inner
    response = get_response(request)
  File "/usr/local/lib/python3.10/site-packages/django/core/handlers/base.py", line 197, in _get_response
    response = wrapped_callback(request, *callback_args, **callback_kwargs)
  File "/usr/local/lib/python3.10/site-packages/django/views/decorators/csrf.py", line 56, in wrapper_view
    return view_func(*args, **kwargs)
  File "/usr/local/lib/python3.10/site-packages/django/views/generic/base.py", line 104, in view
    return self.dispatch(request, *args, **kwargs)
  File "/usr/local/lib/python3.10/site-packages/rest_framework/views.py", line 509, in dispatch
    response = self.handle_exception(exc)
  File "/usr/local/lib/python3.10/site-packages/rest_framework/views.py", line 469, in handle_exception
    self.raise_uncaught_exception(exc)
  File "/usr/local/lib/python3.10/site-packages/rest_framework/views.py", line 480, in raise_uncaught_exception
    raise exc
  File "/usr/local/lib/python3.10/site-packages/rest_framework/views.py", line 506, in dispatch
    response = handler(request, *args, **kwargs)
  File "/usr/local/lib/python3.10/site-packages/rest_framework/decorators.py", line 50, in handler
    return func(*args, **kwargs)
  File "/app/backend/api/views.py", line 81, in verify
    'company_employee': company_employee_serializer.data
  File "/usr/local/lib/python3.10/site-packages/rest_framework/serializers.py", line 768, in data
    ret = super().data
  File "/usr/local/lib/python3.10/site-packages/rest_framework/serializers.py", line 253, in data
    self._data = self.to_representation(self.instance)
  File "/usr/local/lib/python3.10/site-packages/rest_framework/serializers.py", line 686, in to_representation
    return [
  File "/usr/local/lib/python3.10/site-packages/django/db/models/query.py", line 398, in __iter__
    self._fetch_all()
  File "/usr/local/lib/python3.10/site-packages/django/db/models/query.py", line 1881, in _fetch_all
    self._result_cache = list(self._iterable_class(self))
  File "/usr/local/lib/python3.10/site-packages/django/db/models/query.py", line 91, in __iter__
    results = compiler.execute_sql(
  File "/usr/local/lib/python3.10/site-packages/django/db/models/sql/compiler.py", line 1560, in execute_sql
    cursor.execute(sql, params)
  File "/usr/local/lib/python3.10/site-packages/django/db/backends/utils.py", line 102, in execute
    return super().execute(sql, params)
  File "/usr/local/lib/python3.10/site-packages/django/db/backends/utils.py", line 67, in execute
    return self._execute_with_wrappers(
  File "/usr/local/lib/python3.10/site-packages/django/db/backends/utils.py", line 80, in _execute_with_wrappers
    return executor(sql, params, many, context)
  File "/usr/local/lib/python3.10/site-packages/django/db/backends/utils.py", line 84, in _execute
    with self.db.wrap_database_errors:
  File "/usr/local/lib/python3.10/site-packages/django/db/utils.py", line 91, in __exit__
    raise dj_exc_value.with_traceback(traceback) from exc_value
  File "/usr/local/lib/python3.10/site-packages/django/db/backends/utils.py", line 89, in _execute
    return self.cursor.execute(sql, params)
django.db.utils.ProgrammingError: column api_companyemployee.skills does not exist
LINE 1: ...ePosition_id_id", "api_companyemployee"."salary", "api_compa...
                                                             ^

[18/Oct/2023 06:33:03] ERROR [django.request:241] Internal Server Error: /api/verify
Traceback (most recent call last):
  File "/usr/local/lib/python3.10/site-packages/django/db/backends/utils.py", line 89, in _execute
    return self.cursor.execute(sql, params)
psycopg2.errors.UndefinedColumn: column api_companyemployee.skills does not exist
LINE 1: ...ePosition_id_id", "api_companyemployee"."salary", "api_compa...
                                                             ^


The above exception was the direct cause of the following exception:

Traceback (most recent call last):
  File "/usr/local/lib/python3.10/site-packages/django/core/handlers/exception.py", line 55, in inner
    response = get_response(request)
  File "/usr/local/lib/python3.10/site-packages/django/core/handlers/base.py", line 197, in _get_response
    response = wrapped_callback(request, *callback_args, **callback_kwargs)
  File "/usr/local/lib/python3.10/site-packages/django/views/decorators/csrf.py", line 56, in wrapper_view
    return view_func(*args, **kwargs)
  File "/usr/local/lib/python3.10/site-packages/django/views/generic/base.py", line 104, in view
    return self.dispatch(request, *args, **kwargs)
  File "/usr/local/lib/python3.10/site-packages/rest_framework/views.py", line 509, in dispatch
    response = self.handle_exception(exc)
  File "/usr/local/lib/python3.10/site-packages/rest_framework/views.py", line 469, in handle_exception
    self.raise_uncaught_exception(exc)
  File "/usr/local/lib/python3.10/site-packages/rest_framework/views.py", line 480, in raise_uncaught_exception
    raise exc
  File "/usr/local/lib/python3.10/site-packages/rest_framework/views.py", line 506, in dispatch
    response = handler(request, *args, **kwargs)
  File "/usr/local/lib/python3.10/site-packages/rest_framework/decorators.py", line 50, in handler
    return func(*args, **kwargs)
  File "/app/backend/api/views.py", line 81, in verify
    'company_employee': company_employee_serializer.data
  File "/usr/local/lib/python3.10/site-packages/rest_framework/serializers.py", line 768, in data
    ret = super().data
  File "/usr/local/lib/python3.10/site-packages/rest_framework/serializers.py", line 253, in data
    self._data = self.to_representation(self.instance)
  File "/usr/local/lib/python3.10/site-packages/rest_framework/serializers.py", line 686, in to_representation
    return [
  File "/usr/local/lib/python3.10/site-packages/django/db/models/query.py", line 398, in __iter__
    self._fetch_all()
  File "/usr/local/lib/python3.10/site-packages/django/db/models/query.py", line 1881, in _fetch_all
    self._result_cache = list(self._iterable_class(self))
  File "/usr/local/lib/python3.10/site-packages/django/db/models/query.py", line 91, in __iter__
    results = compiler.execute_sql(
  File "/usr/local/lib/python3.10/site-packages/django/db/models/sql/compiler.py", line 1560, in execute_sql
    cursor.execute(sql, params)
  File "/usr/local/lib/python3.10/site-packages/django/db/backends/utils.py", line 102, in execute
    return super().execute(sql, params)
  File "/usr/local/lib/python3.10/site-packages/django/db/backends/utils.py", line 67, in execute
    return self._execute_with_wrappers(
  File "/usr/local/lib/python3.10/site-packages/django/db/backends/utils.py", line 80, in _execute_with_wrappers
    return executor(sql, params, many, context)
  File "/usr/local/lib/python3.10/site-packages/django/db/backends/utils.py", line 84, in _execute
    with self.db.wrap_database_errors:
  File "/usr/local/lib/python3.10/site-packages/django/db/utils.py", line 91, in __exit__
    raise dj_exc_value.with_traceback(traceback) from exc_value
  File "/usr/local/lib/python3.10/site-packages/django/db/backends/utils.py", line 89, in _execute
    return self.cursor.execute(sql, params)
django.db.utils.ProgrammingError: column api_companyemployee.skills does not exist
LINE 1: ...ePosition_id_id", "api_companyemployee"."salary", "api_compa...
                                                             ^

[18/Oct/2023 06:33:03] ERROR [django.server:212] "POST /api/verify HTTP/1.1" 500 164840
[18/Oct/2023 06:33:03] ERROR [django.server:212] "POST /api/verify HTTP/1.1" 500 164840
[18/Oct/2023 06:33:12] ERROR [django.request:241] Internal Server Error: /api/verify
Traceback (most recent call last):
  File "/usr/local/lib/python3.10/site-packages/django/db/backends/utils.py", line 89, in _execute
    return self.cursor.execute(sql, params)
psycopg2.errors.UndefinedColumn: column api_companyemployee.skills does not exist
LINE 1: ...ePosition_id_id", "api_companyemployee"."salary", "api_compa...
                                                             ^


The above exception was the direct cause of the following exception:

Traceback (most recent call last):
  File "/usr/local/lib/python3.10/site-packages/django/core/handlers/exception.py", line 55, in inner
    response = get_response(request)
  File "/usr/local/lib/python3.10/site-packages/django/core/handlers/base.py", line 197, in _get_response
    response = wrapped_callback(request, *callback_args, **callback_kwargs)
  File "/usr/local/lib/python3.10/site-packages/django/views/decorators/csrf.py", line 56, in wrapper_view
    return view_func(*args, **kwargs)
  File "/usr/local/lib/python3.10/site-packages/django/views/generic/base.py", line 104, in view
    return self.dispatch(request, *args, **kwargs)
  File "/usr/local/lib/python3.10/site-packages/rest_framework/views.py", line 509, in dispatch
    response = self.handle_exception(exc)
  File "/usr/local/lib/python3.10/site-packages/rest_framework/views.py", line 469, in handle_exception
    self.raise_uncaught_exception(exc)
  File "/usr/local/lib/python3.10/site-packages/rest_framework/views.py", line 480, in raise_uncaught_exception
    raise exc
  File "/usr/local/lib/python3.10/site-packages/rest_framework/views.py", line 506, in dispatch
    response = handler(request, *args, **kwargs)
  File "/usr/local/lib/python3.10/site-packages/rest_framework/decorators.py", line 50, in handler
    return func(*args, **kwargs)
  File "/app/backend/api/views.py", line 81, in verify
    'company_employee': company_employee_serializer.data
  File "/usr/local/lib/python3.10/site-packages/rest_framework/serializers.py", line 768, in data
    ret = super().data
  File "/usr/local/lib/python3.10/site-packages/rest_framework/serializers.py", line 253, in data
    self._data = self.to_representation(self.instance)
  File "/usr/local/lib/python3.10/site-packages/rest_framework/serializers.py", line 686, in to_representation
    return [
  File "/usr/local/lib/python3.10/site-packages/django/db/models/query.py", line 398, in __iter__
    self._fetch_all()
  File "/usr/local/lib/python3.10/site-packages/django/db/models/query.py", line 1881, in _fetch_all
    self._result_cache = list(self._iterable_class(self))
  File "/usr/local/lib/python3.10/site-packages/django/db/models/query.py", line 91, in __iter__
    results = compiler.execute_sql(
  File "/usr/local/lib/python3.10/site-packages/django/db/models/sql/compiler.py", line 1560, in execute_sql
    cursor.execute(sql, params)
  File "/usr/local/lib/python3.10/site-packages/django/db/backends/utils.py", line 102, in execute
    return super().execute(sql, params)
  File "/usr/local/lib/python3.10/site-packages/django/db/backends/utils.py", line 67, in execute
    return self._execute_with_wrappers(
  File "/usr/local/lib/python3.10/site-packages/django/db/backends/utils.py", line 80, in _execute_with_wrappers
    return executor(sql, params, many, context)
  File "/usr/local/lib/python3.10/site-packages/django/db/backends/utils.py", line 84, in _execute
    with self.db.wrap_database_errors:
  File "/usr/local/lib/python3.10/site-packages/django/db/utils.py", line 91, in __exit__
    raise dj_exc_value.with_traceback(traceback) from exc_value
  File "/usr/local/lib/python3.10/site-packages/django/db/backends/utils.py", line 89, in _execute
    return self.cursor.execute(sql, params)
django.db.utils.ProgrammingError: column api_companyemployee.skills does not exist
LINE 1: ...ePosition_id_id", "api_companyemployee"."salary", "api_compa...
                                                             ^

[18/Oct/2023 06:33:12] ERROR [django.request:241] Internal Server Error: /api/verify
Traceback (most recent call last):
  File "/usr/local/lib/python3.10/site-packages/django/db/backends/utils.py", line 89, in _execute
    return self.cursor.execute(sql, params)
psycopg2.errors.UndefinedColumn: column api_companyemployee.skills does not exist
LINE 1: ...ePosition_id_id", "api_companyemployee"."salary", "api_compa...
                                                             ^


The above exception was the direct cause of the following exception:

Traceback (most recent call last):
  File "/usr/local/lib/python3.10/site-packages/django/core/handlers/exception.py", line 55, in inner
    response = get_response(request)
  File "/usr/local/lib/python3.10/site-packages/django/core/handlers/base.py", line 197, in _get_response
    response = wrapped_callback(request, *callback_args, **callback_kwargs)
  File "/usr/local/lib/python3.10/site-packages/django/views/decorators/csrf.py", line 56, in wrapper_view
    return view_func(*args, **kwargs)
  File "/usr/local/lib/python3.10/site-packages/django/views/generic/base.py", line 104, in view
    return self.dispatch(request, *args, **kwargs)
  File "/usr/local/lib/python3.10/site-packages/rest_framework/views.py", line 509, in dispatch
    response = self.handle_exception(exc)
  File "/usr/local/lib/python3.10/site-packages/rest_framework/views.py", line 469, in handle_exception
    self.raise_uncaught_exception(exc)
  File "/usr/local/lib/python3.10/site-packages/rest_framework/views.py", line 480, in raise_uncaught_exception
    raise exc
  File "/usr/local/lib/python3.10/site-packages/rest_framework/views.py", line 506, in dispatch
    response = handler(request, *args, **kwargs)
  File "/usr/local/lib/python3.10/site-packages/rest_framework/decorators.py", line 50, in handler
    return func(*args, **kwargs)
  File "/app/backend/api/views.py", line 81, in verify
    'company_employee': company_employee_serializer.data
  File "/usr/local/lib/python3.10/site-packages/rest_framework/serializers.py", line 768, in data
    ret = super().data
  File "/usr/local/lib/python3.10/site-packages/rest_framework/serializers.py", line 253, in data
    self._data = self.to_representation(self.instance)
  File "/usr/local/lib/python3.10/site-packages/rest_framework/serializers.py", line 686, in to_representation
    return [
  File "/usr/local/lib/python3.10/site-packages/django/db/models/query.py", line 398, in __iter__
    self._fetch_all()
  File "/usr/local/lib/python3.10/site-packages/django/db/models/query.py", line 1881, in _fetch_all
    self._result_cache = list(self._iterable_class(self))
  File "/usr/local/lib/python3.10/site-packages/django/db/models/query.py", line 91, in __iter__
    results = compiler.execute_sql(
  File "/usr/local/lib/python3.10/site-packages/django/db/models/sql/compiler.py", line 1560, in execute_sql
    cursor.execute(sql, params)
  File "/usr/local/lib/python3.10/site-packages/django/db/backends/utils.py", line 102, in execute
    return super().execute(sql, params)
  File "/usr/local/lib/python3.10/site-packages/django/db/backends/utils.py", line 67, in execute
    return self._execute_with_wrappers(
  File "/usr/local/lib/python3.10/site-packages/django/db/backends/utils.py", line 80, in _execute_with_wrappers
    return executor(sql, params, many, context)
  File "/usr/local/lib/python3.10/site-packages/django/db/backends/utils.py", line 84, in _execute
    with self.db.wrap_database_errors:
  File "/usr/local/lib/python3.10/site-packages/django/db/utils.py", line 91, in __exit__
    raise dj_exc_value.with_traceback(traceback) from exc_value
  File "/usr/local/lib/python3.10/site-packages/django/db/backends/utils.py", line 89, in _execute
    return self.cursor.execute(sql, params)
django.db.utils.ProgrammingError: column api_companyemployee.skills does not exist
LINE 1: ...ePosition_id_id", "api_companyemployee"."salary", "api_compa...
                                                             ^

[18/Oct/2023 06:33:12] ERROR [django.server:212] "POST /api/verify HTTP/1.1" 500 164847
[18/Oct/2023 06:33:12] ERROR [django.server:212] "POST /api/verify HTTP/1.1" 500 164847
[18/Oct/2023 06:33:52] ERROR [django.request:241] Internal Server Error: /api/verify
Traceback (most recent call last):
  File "/usr/local/lib/python3.10/site-packages/django/db/backends/utils.py", line 89, in _execute
    return self.cursor.execute(sql, params)
psycopg2.errors.UndefinedColumn: column api_companyemployee.skills does not exist
LINE 1: ...ePosition_id_id", "api_companyemployee"."salary", "api_compa...
                                                             ^


The above exception was the direct cause of the following exception:

Traceback (most recent call last):
  File "/usr/local/lib/python3.10/site-packages/django/core/handlers/exception.py", line 55, in inner
    response = get_response(request)
  File "/usr/local/lib/python3.10/site-packages/django/core/handlers/base.py", line 197, in _get_response
    response = wrapped_callback(request, *callback_args, **callback_kwargs)
  File "/usr/local/lib/python3.10/site-packages/django/views/decorators/csrf.py", line 56, in wrapper_view
    return view_func(*args, **kwargs)
  File "/usr/local/lib/python3.10/site-packages/django/views/generic/base.py", line 104, in view
    return self.dispatch(request, *args, **kwargs)
  File "/usr/local/lib/python3.10/site-packages/rest_framework/views.py", line 509, in dispatch
    response = self.handle_exception(exc)
  File "/usr/local/lib/python3.10/site-packages/rest_framework/views.py", line 469, in handle_exception
    self.raise_uncaught_exception(exc)
  File "/usr/local/lib/python3.10/site-packages/rest_framework/views.py", line 480, in raise_uncaught_exception
    raise exc
  File "/usr/local/lib/python3.10/site-packages/rest_framework/views.py", line 506, in dispatch
    response = handler(request, *args, **kwargs)
  File "/usr/local/lib/python3.10/site-packages/rest_framework/decorators.py", line 50, in handler
    return func(*args, **kwargs)
  File "/app/backend/api/views.py", line 81, in verify
    'company_employee': company_employee_serializer.data
  File "/usr/local/lib/python3.10/site-packages/rest_framework/serializers.py", line 768, in data
    ret = super().data
  File "/usr/local/lib/python3.10/site-packages/rest_framework/serializers.py", line 253, in data
    self._data = self.to_representation(self.instance)
  File "/usr/local/lib/python3.10/site-packages/rest_framework/serializers.py", line 686, in to_representation
    return [
  File "/usr/local/lib/python3.10/site-packages/django/db/models/query.py", line 398, in __iter__
    self._fetch_all()
  File "/usr/local/lib/python3.10/site-packages/django/db/models/query.py", line 1881, in _fetch_all
    self._result_cache = list(self._iterable_class(self))
  File "/usr/local/lib/python3.10/site-packages/django/db/models/query.py", line 91, in __iter__
    results = compiler.execute_sql(
  File "/usr/local/lib/python3.10/site-packages/django/db/models/sql/compiler.py", line 1560, in execute_sql
    cursor.execute(sql, params)
  File "/usr/local/lib/python3.10/site-packages/django/db/backends/utils.py", line 102, in execute
    return super().execute(sql, params)
  File "/usr/local/lib/python3.10/site-packages/django/db/backends/utils.py", line 67, in execute
    return self._execute_with_wrappers(
  File "/usr/local/lib/python3.10/site-packages/django/db/backends/utils.py", line 80, in _execute_with_wrappers
    return executor(sql, params, many, context)
  File "/usr/local/lib/python3.10/site-packages/django/db/backends/utils.py", line 84, in _execute
    with self.db.wrap_database_errors:
  File "/usr/local/lib/python3.10/site-packages/django/db/utils.py", line 91, in __exit__
    raise dj_exc_value.with_traceback(traceback) from exc_value
  File "/usr/local/lib/python3.10/site-packages/django/db/backends/utils.py", line 89, in _execute
    return self.cursor.execute(sql, params)
django.db.utils.ProgrammingError: column api_companyemployee.skills does not exist
LINE 1: ...ePosition_id_id", "api_companyemployee"."salary", "api_compa...
                                                             ^

[18/Oct/2023 06:33:52] ERROR [django.request:241] Internal Server Error: /api/verify
Traceback (most recent call last):
  File "/usr/local/lib/python3.10/site-packages/django/db/backends/utils.py", line 89, in _execute
    return self.cursor.execute(sql, params)
psycopg2.errors.UndefinedColumn: column api_companyemployee.skills does not exist
LINE 1: ...ePosition_id_id", "api_companyemployee"."salary", "api_compa...
                                                             ^


The above exception was the direct cause of the following exception:

Traceback (most recent call last):
  File "/usr/local/lib/python3.10/site-packages/django/core/handlers/exception.py", line 55, in inner
    response = get_response(request)
  File "/usr/local/lib/python3.10/site-packages/django/core/handlers/base.py", line 197, in _get_response
    response = wrapped_callback(request, *callback_args, **callback_kwargs)
  File "/usr/local/lib/python3.10/site-packages/django/views/decorators/csrf.py", line 56, in wrapper_view
    return view_func(*args, **kwargs)
  File "/usr/local/lib/python3.10/site-packages/django/views/generic/base.py", line 104, in view
    return self.dispatch(request, *args, **kwargs)
  File "/usr/local/lib/python3.10/site-packages/rest_framework/views.py", line 509, in dispatch
    response = self.handle_exception(exc)
  File "/usr/local/lib/python3.10/site-packages/rest_framework/views.py", line 469, in handle_exception
    self.raise_uncaught_exception(exc)
  File "/usr/local/lib/python3.10/site-packages/rest_framework/views.py", line 480, in raise_uncaught_exception
    raise exc
  File "/usr/local/lib/python3.10/site-packages/rest_framework/views.py", line 506, in dispatch
    response = handler(request, *args, **kwargs)
  File "/usr/local/lib/python3.10/site-packages/rest_framework/decorators.py", line 50, in handler
    return func(*args, **kwargs)
  File "/app/backend/api/views.py", line 81, in verify
    'company_employee': company_employee_serializer.data
  File "/usr/local/lib/python3.10/site-packages/rest_framework/serializers.py", line 768, in data
    ret = super().data
  File "/usr/local/lib/python3.10/site-packages/rest_framework/serializers.py", line 253, in data
    self._data = self.to_representation(self.instance)
  File "/usr/local/lib/python3.10/site-packages/rest_framework/serializers.py", line 686, in to_representation
    return [
  File "/usr/local/lib/python3.10/site-packages/django/db/models/query.py", line 398, in __iter__
    self._fetch_all()
  File "/usr/local/lib/python3.10/site-packages/django/db/models/query.py", line 1881, in _fetch_all
    self._result_cache = list(self._iterable_class(self))
  File "/usr/local/lib/python3.10/site-packages/django/db/models/query.py", line 91, in __iter__
    results = compiler.execute_sql(
  File "/usr/local/lib/python3.10/site-packages/django/db/models/sql/compiler.py", line 1560, in execute_sql
    cursor.execute(sql, params)
  File "/usr/local/lib/python3.10/site-packages/django/db/backends/utils.py", line 102, in execute
    return super().execute(sql, params)
  File "/usr/local/lib/python3.10/site-packages/django/db/backends/utils.py", line 67, in execute
    return self._execute_with_wrappers(
  File "/usr/local/lib/python3.10/site-packages/django/db/backends/utils.py", line 80, in _execute_with_wrappers
    return executor(sql, params, many, context)
  File "/usr/local/lib/python3.10/site-packages/django/db/backends/utils.py", line 84, in _execute
    with self.db.wrap_database_errors:
  File "/usr/local/lib/python3.10/site-packages/django/db/utils.py", line 91, in __exit__
    raise dj_exc_value.with_traceback(traceback) from exc_value
  File "/usr/local/lib/python3.10/site-packages/django/db/backends/utils.py", line 89, in _execute
    return self.cursor.execute(sql, params)
django.db.utils.ProgrammingError: column api_companyemployee.skills does not exist
LINE 1: ...ePosition_id_id", "api_companyemployee"."salary", "api_compa...
                                                             ^

[18/Oct/2023 06:33:52] ERROR [django.server:212] "POST /api/verify HTTP/1.1" 500 164847
[18/Oct/2023 06:33:52] ERROR [django.server:212] "POST /api/verify HTTP/1.1" 500 164847
[18/Oct/2023 06:36:39] ERROR [django.server:192] You're accessing the development server over HTTPS, but it only supports HTTP.
[18/Oct/2023 06:36:39] ERROR [django.server:192] You're accessing the development server over HTTPS, but it only supports HTTP.
[18/Oct/2023 06:47:21] ERROR [django.request:241] Internal Server Error: /api/getTaskForcesByCompany/get/1
[18/Oct/2023 06:47:21] ERROR [django.request:241] Internal Server Error: /api/getTaskForcesByCompany/get/1
[18/Oct/2023 06:47:21] ERROR [django.server:212] "GET /api/getTaskForcesByCompany/get/1 HTTP/1.1" 500 205
[18/Oct/2023 06:47:21] ERROR [django.server:212] "GET /api/getTaskForcesByCompany/get/1 HTTP/1.1" 500 205
[18/Oct/2023 06:49:20] ERROR [django.request:241] Internal Server Error: /api/getTaskForcesByCompany/get/1
[18/Oct/2023 06:49:20] ERROR [django.request:241] Internal Server Error: /api/getTaskForcesByCompany/get/1
[18/Oct/2023 06:49:20] ERROR [django.server:212] "GET /api/getTaskForcesByCompany/get/1 HTTP/1.1" 500 205
[18/Oct/2023 06:49:20] ERROR [django.server:212] "GET /api/getTaskForcesByCompany/get/1 HTTP/1.1" 500 205
[18/Oct/2023 06:49:20] WARNING [django.request:241] Bad Request: /api/createTaskForces
[18/Oct/2023 06:49:20] WARNING [django.request:241] Bad Request: /api/createTaskForces
[18/Oct/2023 06:49:20] WARNING [django.server:212] "POST /api/createTaskForces HTTP/1.1" 400 155
[18/Oct/2023 06:49:20] WARNING [django.server:212] "POST /api/createTaskForces HTTP/1.1" 400 155
[18/Oct/2023 06:49:34] ERROR [django.request:241] Internal Server Error: /api/getTaskForcesByCompany/get/1
[18/Oct/2023 06:49:34] ERROR [django.request:241] Internal Server Error: /api/getTaskForcesByCompany/get/1
[18/Oct/2023 06:49:34] ERROR [django.server:212] "GET /api/getTaskForcesByCompany/get/1 HTTP/1.1" 500 205
[18/Oct/2023 06:49:34] ERROR [django.server:212] "GET /api/getTaskForcesByCompany/get/1 HTTP/1.1" 500 205
[18/Oct/2023 06:49:34] WARNING [django.request:241] Bad Request: /api/createTaskForces
[18/Oct/2023 06:49:34] WARNING [django.request:241] Bad Request: /api/createTaskForces
[18/Oct/2023 06:49:34] WARNING [django.server:212] "POST /api/createTaskForces HTTP/1.1" 400 155
[18/Oct/2023 06:49:34] WARNING [django.server:212] "POST /api/createTaskForces HTTP/1.1" 400 155
[18/Oct/2023 15:04:05] WARNING [django.request:241] Bad Request: /api/login
[18/Oct/2023 15:04:05] WARNING [django.request:241] Bad Request: /api/login
[18/Oct/2023 15:04:05] WARNING [django.server:212] "POST /api/login HTTP/1.1" 400 46
[18/Oct/2023 15:04:05] WARNING [django.server:212] "POST /api/login HTTP/1.1" 400 46
[18/Oct/2023 15:04:18] ERROR [django.request:241] Internal Server Error: /api/getTaskForcesByCompany/get/1
[18/Oct/2023 15:04:18] ERROR [django.request:241] Internal Server Error: /api/getTaskForcesByCompany/get/1
[18/Oct/2023 15:04:18] ERROR [django.server:212] "GET /api/getTaskForcesByCompany/get/1 HTTP/1.1" 500 205
[18/Oct/2023 15:04:18] ERROR [django.server:212] "GET /api/getTaskForcesByCompany/get/1 HTTP/1.1" 500 205
[18/Oct/2023 15:04:32] ERROR [django.request:241] Internal Server Error: /api/getTaskForcesByCompany/get/1
[18/Oct/2023 15:04:32] ERROR [django.request:241] Internal Server Error: /api/getTaskForcesByCompany/get/1
[18/Oct/2023 15:04:32] ERROR [django.server:212] "GET /api/getTaskForcesByCompany/get/1 HTTP/1.1" 500 205
[18/Oct/2023 15:04:32] ERROR [django.server:212] "GET /api/getTaskForcesByCompany/get/1 HTTP/1.1" 500 205
[18/Oct/2023 15:04:32] WARNING [django.request:241] Bad Request: /api/createTaskForces
[18/Oct/2023 15:04:32] WARNING [django.request:241] Bad Request: /api/createTaskForces
[18/Oct/2023 15:04:32] WARNING [django.server:212] "POST /api/createTaskForces HTTP/1.1" 400 155
[18/Oct/2023 15:04:32] WARNING [django.server:212] "POST /api/createTaskForces HTTP/1.1" 400 155
[18/Oct/2023 15:05:26] ERROR [django.request:241] Internal Server Error: /api/createTaskForces
[18/Oct/2023 15:05:26] ERROR [django.request:241] Internal Server Error: /api/getTaskForcesByCompany/get/1
[18/Oct/2023 15:05:26] ERROR [django.request:241] Internal Server Error: /api/getTaskForcesByCompany/get/1
[18/Oct/2023 15:05:26] ERROR [django.request:241] Internal Server Error: /api/createTaskForces
[18/Oct/2023 15:05:26] ERROR [django.server:212] "POST /api/createTaskForces HTTP/1.1" 500 49
[18/Oct/2023 15:05:26] ERROR [django.server:212] "GET /api/getTaskForcesByCompany/get/1 HTTP/1.1" 500 205
[18/Oct/2023 15:05:26] ERROR [django.server:212] "GET /api/getTaskForcesByCompany/get/1 HTTP/1.1" 500 205
[18/Oct/2023 15:05:26] ERROR [django.server:212] "POST /api/createTaskForces HTTP/1.1" 500 49
[18/Oct/2023 15:08:03] ERROR [django.request:241] Internal Server Error: /api/createTaskForces
[18/Oct/2023 15:08:03] ERROR [django.request:241] Internal Server Error: /api/createTaskForces
[18/Oct/2023 15:08:03] ERROR [django.server:212] "POST /api/createTaskForces HTTP/1.1" 500 49
[18/Oct/2023 15:08:03] ERROR [django.server:212] "POST /api/createTaskForces HTTP/1.1" 500 49
[18/Oct/2023 15:08:39] WARNING [django.request:241] Bad Request: /api/createTaskForces
[18/Oct/2023 15:08:39] WARNING [django.request:241] Bad Request: /api/createTaskForces
[18/Oct/2023 15:08:39] WARNING [django.server:212] "POST /api/createTaskForces HTTP/1.1" 400 155
[18/Oct/2023 15:08:39] WARNING [django.server:212] "POST /api/createTaskForces HTTP/1.1" 400 155
[18/Oct/2023 15:09:49] WARNING [django.request:241] Bad Request: /api/createTaskForces
[18/Oct/2023 15:09:49] WARNING [django.request:241] Bad Request: /api/createTaskForces
[18/Oct/2023 15:09:49] WARNING [django.server:212] "POST /api/createTaskForces HTTP/1.1" 400 155
[18/Oct/2023 15:09:49] WARNING [django.server:212] "POST /api/createTaskForces HTTP/1.1" 400 155
[18/Oct/2023 15:15:56] WARNING [django.request:241] Bad Request: /api/createTaskForces
[18/Oct/2023 15:15:56] WARNING [django.request:241] Bad Request: /api/createTaskForces
[18/Oct/2023 15:15:56] WARNING [django.server:212] "POST /api/createTaskForces HTTP/1.1" 400 63
[18/Oct/2023 15:15:56] WARNING [django.server:212] "POST /api/createTaskForces HTTP/1.1" 400 63
[18/Oct/2023 15:32:01] ERROR [django.request:241] Internal Server Error: /api/createTaskForces
[18/Oct/2023 15:32:01] ERROR [django.request:241] Internal Server Error: /api/createTaskForces
[18/Oct/2023 15:32:01] ERROR [django.server:212] "POST /api/createTaskForces HTTP/1.1" 500 158
[18/Oct/2023 15:32:01] ERROR [django.server:212] "POST /api/createTaskForces HTTP/1.1" 500 158
[18/Oct/2023 15:32:05] ERROR [django.request:241] Internal Server Error: /api/createTaskForces
[18/Oct/2023 15:32:05] ERROR [django.request:241] Internal Server Error: /api/createTaskForces
[18/Oct/2023 15:32:05] ERROR [django.server:212] "POST /api/createTaskForces HTTP/1.1" 500 158
[18/Oct/2023 15:32:05] ERROR [django.server:212] "POST /api/createTaskForces HTTP/1.1" 500 158
[18/Oct/2023 15:35:06] WARNING [django.request:241] Unauthorized: /api/createTaskForces
[18/Oct/2023 15:35:06] WARNING [django.request:241] Unauthorized: /api/createTaskForces
[18/Oct/2023 15:35:06] WARNING [django.server:212] "POST /api/createTaskForces HTTP/1.1" 401 183
[18/Oct/2023 15:35:06] WARNING [django.server:212] "POST /api/createTaskForces HTTP/1.1" 401 183
[18/Oct/2023 15:38:32] ERROR [django.request:241] Internal Server Error: /api/fetchTaskForcesById/get/1
[18/Oct/2023 15:38:32] ERROR [django.request:241] Internal Server Error: /api/fetchTaskForcesById/get/1
[18/Oct/2023 15:38:32] ERROR [django.server:212] "GET /api/fetchTaskForcesById/get/1 HTTP/1.1" 500 48
[18/Oct/2023 15:38:32] ERROR [django.server:212] "GET /api/fetchTaskForcesById/get/1 HTTP/1.1" 500 48
[18/Oct/2023 15:40:01] ERROR [django.request:241] Internal Server Error: /api/fetchTaskForcesById/get/1
[18/Oct/2023 15:40:01] ERROR [django.request:241] Internal Server Error: /api/fetchTaskForcesById/get/1
[18/Oct/2023 15:40:01] ERROR [django.server:212] "GET /api/fetchTaskForcesById/get/1 HTTP/1.1" 500 48
[18/Oct/2023 15:40:01] ERROR [django.server:212] "GET /api/fetchTaskForcesById/get/1 HTTP/1.1" 500 48
[18/Oct/2023 15:40:17] WARNING [django.request:241] Method Not Allowed: /api/deleteTaskForce/1
[18/Oct/2023 15:40:17] WARNING [django.request:241] Method Not Allowed: /api/deleteTaskForce/1
[18/Oct/2023 15:40:17] WARNING [django.server:212] "GET /api/deleteTaskForce/1 HTTP/1.1" 405 40
[18/Oct/2023 15:40:17] WARNING [django.server:212] "GET /api/deleteTaskForce/1 HTTP/1.1" 405 40
[18/Oct/2023 15:40:38] ERROR [django.request:241] Internal Server Error: /api/fetchTaskForcesById/get/1
[18/Oct/2023 15:40:38] ERROR [django.request:241] Internal Server Error: /api/fetchTaskForcesById/get/1
[18/Oct/2023 15:40:38] ERROR [django.server:212] "GET /api/fetchTaskForcesById/get/1 HTTP/1.1" 500 48
[18/Oct/2023 15:40:38] ERROR [django.server:212] "GET /api/fetchTaskForcesById/get/1 HTTP/1.1" 500 48
[18/Oct/2023 15:41:19] ERROR [django.request:241] Internal Server Error: /api/fetchTaskForcesById/get/2
[18/Oct/2023 15:41:19] ERROR [django.request:241] Internal Server Error: /api/fetchTaskForcesById/get/2
[18/Oct/2023 15:41:19] ERROR [django.server:212] "GET /api/fetchTaskForcesById/get/2 HTTP/1.1" 500 48
[18/Oct/2023 15:41:19] ERROR [django.server:212] "GET /api/fetchTaskForcesById/get/2 HTTP/1.1" 500 48
[18/Oct/2023 15:41:27] ERROR [django.request:241] Internal Server Error: /api/fetchTaskForcesById/get/2
[18/Oct/2023 15:41:27] ERROR [django.request:241] Internal Server Error: /api/fetchTaskForcesById/get/2
[18/Oct/2023 15:41:27] ERROR [django.server:212] "GET /api/fetchTaskForcesById/get/2 HTTP/1.1" 500 48
[18/Oct/2023 15:41:27] ERROR [django.server:212] "GET /api/fetchTaskForcesById/get/2 HTTP/1.1" 500 48
[18/Oct/2023 15:41:39] ERROR [django.request:241] Internal Server Error: /api/fetchTaskForcesById/get/2
[18/Oct/2023 15:41:39] ERROR [django.request:241] Internal Server Error: /api/fetchTaskForcesById/get/2
[18/Oct/2023 15:41:39] ERROR [django.server:212] "GET /api/fetchTaskForcesById/get/2 HTTP/1.1" 500 48
[18/Oct/2023 15:41:39] ERROR [django.server:212] "GET /api/fetchTaskForcesById/get/2 HTTP/1.1" 500 48
[18/Oct/2023 15:45:55] WARNING [django.request:241] Not Found: /api/user/update/2
[18/Oct/2023 15:45:55] WARNING [django.request:241] Not Found: /api/user/update/2
[18/Oct/2023 15:45:55] WARNING [django.server:212] "PUT /api/user/update/2 HTTP/1.1" 404 26
[18/Oct/2023 15:45:55] WARNING [django.server:212] "PUT /api/user/update/2 HTTP/1.1" 404 26
[18/Oct/2023 15:46:19] WARNING [django.request:241] Not Found: /api/user/update/2
[18/Oct/2023 15:46:19] WARNING [django.request:241] Not Found: /api/user/update/2
[18/Oct/2023 15:46:19] WARNING [django.server:212] "PUT /api/user/update/2 HTTP/1.1" 404 26
[18/Oct/2023 15:46:19] WARNING [django.server:212] "PUT /api/user/update/2 HTTP/1.1" 404 26
[18/Oct/2023 15:47:20] WARNING [django.request:241] Not Found: /favicon.ico
[18/Oct/2023 15:47:20] WARNING [django.request:241] Not Found: /favicon.ico
[18/Oct/2023 15:47:20] WARNING [django.server:212] "GET /favicon.ico HTTP/1.1" 404 2215
[18/Oct/2023 15:47:20] WARNING [django.server:212] "GET /favicon.ico HTTP/1.1" 404 2215
[18/Oct/2023 15:50:23] WARNING [django.request:241] Not Found: /api/user/update/2
[18/Oct/2023 15:50:23] WARNING [django.request:241] Not Found: /api/user/update/2
[18/Oct/2023 15:50:23] WARNING [django.server:212] "PUT /api/user/update/2 HTTP/1.1" 404 26
[18/Oct/2023 15:50:23] WARNING [django.server:212] "PUT /api/user/update/2 HTTP/1.1" 404 26
[18/Oct/2023 15:51:46] WARNING [django.request:241] Not Found: /api/user/update/2
[18/Oct/2023 15:51:46] WARNING [django.request:241] Not Found: /api/user/update/2
[18/Oct/2023 15:51:46] WARNING [django.server:212] "PUT /api/user/update/2 HTTP/1.1" 404 26
[18/Oct/2023 15:51:46] WARNING [django.server:212] "PUT /api/user/update/2 HTTP/1.1" 404 26
[18/Oct/2023 15:51:53] WARNING [django.request:241] Not Found: /api/user/update/2
[18/Oct/2023 15:51:53] WARNING [django.request:241] Not Found: /api/user/update/2
[18/Oct/2023 15:51:53] WARNING [django.server:212] "PUT /api/user/update/2 HTTP/1.1" 404 26
[18/Oct/2023 15:51:53] WARNING [django.server:212] "PUT /api/user/update/2 HTTP/1.1" 404 26
[18/Oct/2023 15:55:35] WARNING [django.request:241] Not Found: /api/user/update/2
[18/Oct/2023 15:55:35] WARNING [django.request:241] Not Found: /api/user/update/2
[18/Oct/2023 15:55:35] WARNING [django.server:212] "PUT /api/user/update/2 HTTP/1.1" 404 26
[18/Oct/2023 15:55:35] WARNING [django.server:212] "PUT /api/user/update/2 HTTP/1.1" 404 26
[18/Oct/2023 15:56:12] WARNING [django.request:241] Not Found: /api/user/update/2
[18/Oct/2023 15:56:12] WARNING [django.request:241] Not Found: /api/user/update/2
[18/Oct/2023 15:56:12] WARNING [django.server:212] "PUT /api/user/update/2 HTTP/1.1" 404 26
[18/Oct/2023 15:56:12] WARNING [django.server:212] "PUT /api/user/update/2 HTTP/1.1" 404 26
[18/Oct/2023 16:02:18] WARNING [django.request:241] Not Found: /api/user/update/2
[18/Oct/2023 16:02:18] WARNING [django.request:241] Not Found: /api/user/update/2
[18/Oct/2023 16:02:18] WARNING [django.server:212] "PUT /api/user/update/2 HTTP/1.1" 404 26
[18/Oct/2023 16:02:18] WARNING [django.server:212] "PUT /api/user/update/2 HTTP/1.1" 404 26
[18/Oct/2023 16:03:57] WARNING [django.request:241] Not Found: /api/user/update/2
[18/Oct/2023 16:03:57] WARNING [django.request:241] Not Found: /api/user/update/2
[18/Oct/2023 16:03:57] WARNING [django.server:212] "PUT /api/user/update/2 HTTP/1.1" 404 26
[18/Oct/2023 16:03:57] WARNING [django.server:212] "PUT /api/user/update/2 HTTP/1.1" 404 26
[18/Oct/2023 16:04:57] WARNING [django.request:241] Not Found: /api/user/update/2
[18/Oct/2023 16:04:57] WARNING [django.request:241] Not Found: /api/user/update/2
[18/Oct/2023 16:04:57] WARNING [django.server:212] "PUT /api/user/update/2 HTTP/1.1" 404 26
[18/Oct/2023 16:04:57] WARNING [django.server:212] "PUT /api/user/update/2 HTTP/1.1" 404 26
[18/Oct/2023 16:05:24] WARNING [django.request:241] Unauthorized: /api/getTaskForcesByCompany/get/1
[18/Oct/2023 16:05:24] WARNING [django.request:241] Unauthorized: /api/getTaskForcesByCompany/get/1
[18/Oct/2023 16:05:24] WARNING [django.server:212] "GET /api/getTaskForcesByCompany/get/1 HTTP/1.1" 401 183
[18/Oct/2023 16:05:24] WARNING [django.server:212] "GET /api/getTaskForcesByCompany/get/1 HTTP/1.1" 401 183
[18/Oct/2023 16:05:37] WARNING [django.request:241] Unauthorized: /api/getTaskForcesByCompany/get/1
[18/Oct/2023 16:05:37] WARNING [django.request:241] Unauthorized: /api/getTaskForcesByCompany/get/1
[18/Oct/2023 16:05:37] WARNING [django.server:212] "GET /api/getTaskForcesByCompany/get/1 HTTP/1.1" 401 183
[18/Oct/2023 16:05:37] WARNING [django.server:212] "GET /api/getTaskForcesByCompany/get/1 HTTP/1.1" 401 183
[18/Oct/2023 16:05:48] WARNING [django.request:241] Unauthorized: /api/getTaskForcesByCompany/get/1
[18/Oct/2023 16:05:48] WARNING [django.request:241] Unauthorized: /api/getTaskForcesByCompany/get/1
[18/Oct/2023 16:05:48] WARNING [django.server:212] "GET /api/getTaskForcesByCompany/get/1 HTTP/1.1" 401 183
[18/Oct/2023 16:05:48] WARNING [django.server:212] "GET /api/getTaskForcesByCompany/get/1 HTTP/1.1" 401 183
[18/Oct/2023 16:05:48] WARNING [django.request:241] Unauthorized: /api/createTaskForces
[18/Oct/2023 16:05:48] WARNING [django.request:241] Unauthorized: /api/createTaskForces
[18/Oct/2023 16:05:48] WARNING [django.server:212] "POST /api/createTaskForces HTTP/1.1" 401 183
[18/Oct/2023 16:05:48] WARNING [django.server:212] "POST /api/createTaskForces HTTP/1.1" 401 183
[18/Oct/2023 16:05:56] WARNING [django.request:241] Unauthorized: /api/getTaskForcesByCompany/get/1
[18/Oct/2023 16:05:56] WARNING [django.request:241] Unauthorized: /api/getTaskForcesByCompany/get/1
[18/Oct/2023 16:05:56] WARNING [django.server:212] "GET /api/getTaskForcesByCompany/get/1 HTTP/1.1" 401 183
[18/Oct/2023 16:05:56] WARNING [django.server:212] "GET /api/getTaskForcesByCompany/get/1 HTTP/1.1" 401 183
[18/Oct/2023 16:13:42] WARNING [django.request:241] Not Found: /api/user/update/2
[18/Oct/2023 16:13:42] WARNING [django.request:241] Not Found: /api/user/update/2
[18/Oct/2023 16:13:42] WARNING [django.server:212] "PUT /api/user/update/2 HTTP/1.1" 404 26
[18/Oct/2023 16:13:42] WARNING [django.server:212] "PUT /api/user/update/2 HTTP/1.1" 404 26
[18/Oct/2023 16:17:49] WARNING [django.request:241] Not Found: /api/user/update/2
[18/Oct/2023 16:17:49] WARNING [django.request:241] Not Found: /api/user/update/2
[18/Oct/2023 16:17:49] WARNING [django.server:212] "PUT /api/user/update/2 HTTP/1.1" 404 26
[18/Oct/2023 16:17:49] WARNING [django.server:212] "PUT /api/user/update/2 HTTP/1.1" 404 26
[18/Oct/2023 16:22:43] ERROR [django.request:241] Internal Server Error: /api/verify
Traceback (most recent call last):
  File "/usr/local/lib/python3.10/site-packages/django/db/backends/utils.py", line 89, in _execute
    return self.cursor.execute(sql, params)
psycopg2.errors.UndefinedTable: relation "api_useraccount" does not exist
LINE 1: ...t"."is_active", "api_useraccount"."is_staff" FROM "api_usera...
                                                             ^


The above exception was the direct cause of the following exception:

Traceback (most recent call last):
  File "/usr/local/lib/python3.10/site-packages/django/core/handlers/exception.py", line 55, in inner
    response = get_response(request)
  File "/usr/local/lib/python3.10/site-packages/django/core/handlers/base.py", line 197, in _get_response
    response = wrapped_callback(request, *callback_args, **callback_kwargs)
  File "/usr/local/lib/python3.10/site-packages/django/views/decorators/csrf.py", line 56, in wrapper_view
    return view_func(*args, **kwargs)
  File "/usr/local/lib/python3.10/site-packages/django/views/generic/base.py", line 104, in view
    return self.dispatch(request, *args, **kwargs)
  File "/usr/local/lib/python3.10/site-packages/rest_framework/views.py", line 509, in dispatch
    response = self.handle_exception(exc)
  File "/usr/local/lib/python3.10/site-packages/rest_framework/views.py", line 469, in handle_exception
    self.raise_uncaught_exception(exc)
  File "/usr/local/lib/python3.10/site-packages/rest_framework/views.py", line 480, in raise_uncaught_exception
    raise exc
  File "/usr/local/lib/python3.10/site-packages/rest_framework/views.py", line 497, in dispatch
    self.initial(request, *args, **kwargs)
  File "/usr/local/lib/python3.10/site-packages/rest_framework/views.py", line 414, in initial
    self.perform_authentication(request)
  File "/usr/local/lib/python3.10/site-packages/rest_framework/views.py", line 324, in perform_authentication
    request.user
  File "/usr/local/lib/python3.10/site-packages/rest_framework/request.py", line 227, in user
    self._authenticate()
  File "/usr/local/lib/python3.10/site-packages/rest_framework/request.py", line 380, in _authenticate
    user_auth_tuple = authenticator.authenticate(self)
  File "/usr/local/lib/python3.10/site-packages/rest_framework_simplejwt/authentication.py", line 40, in authenticate
    return self.get_user(validated_token), validated_token
  File "/app/backend/api/auth.py", line 18, in get_user
    user_account = UserAccount.objects.get(id=user_id)
  File "/usr/local/lib/python3.10/site-packages/django/db/models/manager.py", line 87, in manager_method
    return getattr(self.get_queryset(), name)(*args, **kwargs)
  File "/usr/local/lib/python3.10/site-packages/django/db/models/query.py", line 633, in get
    num = len(clone)
  File "/usr/local/lib/python3.10/site-packages/django/db/models/query.py", line 380, in __len__
    self._fetch_all()
  File "/usr/local/lib/python3.10/site-packages/django/db/models/query.py", line 1881, in _fetch_all
    self._result_cache = list(self._iterable_class(self))
  File "/usr/local/lib/python3.10/site-packages/django/db/models/query.py", line 91, in __iter__
    results = compiler.execute_sql(
  File "/usr/local/lib/python3.10/site-packages/django/db/models/sql/compiler.py", line 1560, in execute_sql
    cursor.execute(sql, params)
  File "/usr/local/lib/python3.10/site-packages/django/db/backends/utils.py", line 102, in execute
    return super().execute(sql, params)
  File "/usr/local/lib/python3.10/site-packages/django/db/backends/utils.py", line 67, in execute
    return self._execute_with_wrappers(
  File "/usr/local/lib/python3.10/site-packages/django/db/backends/utils.py", line 80, in _execute_with_wrappers
    return executor(sql, params, many, context)
  File "/usr/local/lib/python3.10/site-packages/django/db/backends/utils.py", line 84, in _execute
    with self.db.wrap_database_errors:
  File "/usr/local/lib/python3.10/site-packages/django/db/utils.py", line 91, in __exit__
    raise dj_exc_value.with_traceback(traceback) from exc_value
  File "/usr/local/lib/python3.10/site-packages/django/db/backends/utils.py", line 89, in _execute
    return self.cursor.execute(sql, params)
django.db.utils.ProgrammingError: relation "api_useraccount" does not exist
LINE 1: ...t"."is_active", "api_useraccount"."is_staff" FROM "api_usera...
                                                             ^

[18/Oct/2023 16:22:43] ERROR [django.request:241] Internal Server Error: /api/verify
Traceback (most recent call last):
  File "/usr/local/lib/python3.10/site-packages/django/db/backends/utils.py", line 89, in _execute
    return self.cursor.execute(sql, params)
psycopg2.errors.UndefinedTable: relation "api_useraccount" does not exist
LINE 1: ...t"."is_active", "api_useraccount"."is_staff" FROM "api_usera...
                                                             ^


The above exception was the direct cause of the following exception:

Traceback (most recent call last):
  File "/usr/local/lib/python3.10/site-packages/django/core/handlers/exception.py", line 55, in inner
    response = get_response(request)
  File "/usr/local/lib/python3.10/site-packages/django/core/handlers/base.py", line 197, in _get_response
    response = wrapped_callback(request, *callback_args, **callback_kwargs)
  File "/usr/local/lib/python3.10/site-packages/django/views/decorators/csrf.py", line 56, in wrapper_view
    return view_func(*args, **kwargs)
  File "/usr/local/lib/python3.10/site-packages/django/views/generic/base.py", line 104, in view
    return self.dispatch(request, *args, **kwargs)
  File "/usr/local/lib/python3.10/site-packages/rest_framework/views.py", line 509, in dispatch
    response = self.handle_exception(exc)
  File "/usr/local/lib/python3.10/site-packages/rest_framework/views.py", line 469, in handle_exception
    self.raise_uncaught_exception(exc)
  File "/usr/local/lib/python3.10/site-packages/rest_framework/views.py", line 480, in raise_uncaught_exception
    raise exc
  File "/usr/local/lib/python3.10/site-packages/rest_framework/views.py", line 497, in dispatch
    self.initial(request, *args, **kwargs)
  File "/usr/local/lib/python3.10/site-packages/rest_framework/views.py", line 414, in initial
    self.perform_authentication(request)
  File "/usr/local/lib/python3.10/site-packages/rest_framework/views.py", line 324, in perform_authentication
    request.user
  File "/usr/local/lib/python3.10/site-packages/rest_framework/request.py", line 227, in user
    self._authenticate()
  File "/usr/local/lib/python3.10/site-packages/rest_framework/request.py", line 380, in _authenticate
    user_auth_tuple = authenticator.authenticate(self)
  File "/usr/local/lib/python3.10/site-packages/rest_framework_simplejwt/authentication.py", line 40, in authenticate
    return self.get_user(validated_token), validated_token
  File "/app/backend/api/auth.py", line 18, in get_user
    user_account = UserAccount.objects.get(id=user_id)
  File "/usr/local/lib/python3.10/site-packages/django/db/models/manager.py", line 87, in manager_method
    return getattr(self.get_queryset(), name)(*args, **kwargs)
  File "/usr/local/lib/python3.10/site-packages/django/db/models/query.py", line 633, in get
    num = len(clone)
  File "/usr/local/lib/python3.10/site-packages/django/db/models/query.py", line 380, in __len__
    self._fetch_all()
  File "/usr/local/lib/python3.10/site-packages/django/db/models/query.py", line 1881, in _fetch_all
    self._result_cache = list(self._iterable_class(self))
  File "/usr/local/lib/python3.10/site-packages/django/db/models/query.py", line 91, in __iter__
    results = compiler.execute_sql(
  File "/usr/local/lib/python3.10/site-packages/django/db/models/sql/compiler.py", line 1560, in execute_sql
    cursor.execute(sql, params)
  File "/usr/local/lib/python3.10/site-packages/django/db/backends/utils.py", line 102, in execute
    return super().execute(sql, params)
  File "/usr/local/lib/python3.10/site-packages/django/db/backends/utils.py", line 67, in execute
    return self._execute_with_wrappers(
  File "/usr/local/lib/python3.10/site-packages/django/db/backends/utils.py", line 80, in _execute_with_wrappers
    return executor(sql, params, many, context)
  File "/usr/local/lib/python3.10/site-packages/django/db/backends/utils.py", line 84, in _execute
    with self.db.wrap_database_errors:
  File "/usr/local/lib/python3.10/site-packages/django/db/utils.py", line 91, in __exit__
    raise dj_exc_value.with_traceback(traceback) from exc_value
  File "/usr/local/lib/python3.10/site-packages/django/db/backends/utils.py", line 89, in _execute
    return self.cursor.execute(sql, params)
django.db.utils.ProgrammingError: relation "api_useraccount" does not exist
LINE 1: ...t"."is_active", "api_useraccount"."is_staff" FROM "api_usera...
                                                             ^

[18/Oct/2023 16:22:43] ERROR [django.server:212] "POST /api/verify HTTP/1.1" 500 175279
[18/Oct/2023 16:22:43] ERROR [django.server:212] "POST /api/verify HTTP/1.1" 500 175279
[18/Oct/2023 16:25:30] ERROR [django.security.DisallowedHost:124] Invalid HTTP_HOST header: '61.231.100.225:8000'. You may need to add '61.231.100.225' to ALLOWED_HOSTS.
Traceback (most recent call last):
  File "/usr/local/lib/python3.10/site-packages/django/core/handlers/exception.py", line 55, in inner
    response = get_response(request)
  File "/usr/local/lib/python3.10/site-packages/django/utils/deprecation.py", line 133, in __call__
    response = self.process_request(request)
  File "/usr/local/lib/python3.10/site-packages/django/middleware/common.py", line 48, in process_request
    host = request.get_host()
  File "/usr/local/lib/python3.10/site-packages/django/http/request.py", line 167, in get_host
    raise DisallowedHost(msg)
django.core.exceptions.DisallowedHost: Invalid HTTP_HOST header: '61.231.100.225:8000'. You may need to add '61.231.100.225' to ALLOWED_HOSTS.
[18/Oct/2023 16:25:30] ERROR [django.security.DisallowedHost:124] Invalid HTTP_HOST header: '61.231.100.225:8000'. You may need to add '61.231.100.225' to ALLOWED_HOSTS.
Traceback (most recent call last):
  File "/usr/local/lib/python3.10/site-packages/django/core/handlers/exception.py", line 55, in inner
    response = get_response(request)
  File "/usr/local/lib/python3.10/site-packages/django/utils/deprecation.py", line 133, in __call__
    response = self.process_request(request)
  File "/usr/local/lib/python3.10/site-packages/django/middleware/common.py", line 48, in process_request
    host = request.get_host()
  File "/usr/local/lib/python3.10/site-packages/django/http/request.py", line 167, in get_host
    raise DisallowedHost(msg)
django.core.exceptions.DisallowedHost: Invalid HTTP_HOST header: '61.231.100.225:8000'. You may need to add '61.231.100.225' to ALLOWED_HOSTS.
[18/Oct/2023 16:25:30] WARNING [django.request:241] Bad Request: /
[18/Oct/2023 16:25:30] WARNING [django.request:241] Bad Request: /
[18/Oct/2023 16:25:30] WARNING [django.server:212] "GET / HTTP/1.1" 400 62557
[18/Oct/2023 16:25:30] WARNING [django.server:212] "GET / HTTP/1.1" 400 62557
[18/Oct/2023 16:25:31] ERROR [django.security.DisallowedHost:124] Invalid HTTP_HOST header: '61.231.100.225:8000'. You may need to add '61.231.100.225' to ALLOWED_HOSTS.
Traceback (most recent call last):
  File "/usr/local/lib/python3.10/site-packages/django/core/handlers/exception.py", line 55, in inner
    response = get_response(request)
  File "/usr/local/lib/python3.10/site-packages/django/utils/deprecation.py", line 133, in __call__
    response = self.process_request(request)
  File "/usr/local/lib/python3.10/site-packages/django/middleware/common.py", line 48, in process_request
    host = request.get_host()
  File "/usr/local/lib/python3.10/site-packages/django/http/request.py", line 167, in get_host
    raise DisallowedHost(msg)
django.core.exceptions.DisallowedHost: Invalid HTTP_HOST header: '61.231.100.225:8000'. You may need to add '61.231.100.225' to ALLOWED_HOSTS.
[18/Oct/2023 16:25:31] ERROR [django.security.DisallowedHost:124] Invalid HTTP_HOST header: '61.231.100.225:8000'. You may need to add '61.231.100.225' to ALLOWED_HOSTS.
Traceback (most recent call last):
  File "/usr/local/lib/python3.10/site-packages/django/core/handlers/exception.py", line 55, in inner
    response = get_response(request)
  File "/usr/local/lib/python3.10/site-packages/django/utils/deprecation.py", line 133, in __call__
    response = self.process_request(request)
  File "/usr/local/lib/python3.10/site-packages/django/middleware/common.py", line 48, in process_request
    host = request.get_host()
  File "/usr/local/lib/python3.10/site-packages/django/http/request.py", line 167, in get_host
    raise DisallowedHost(msg)
django.core.exceptions.DisallowedHost: Invalid HTTP_HOST header: '61.231.100.225:8000'. You may need to add '61.231.100.225' to ALLOWED_HOSTS.
[18/Oct/2023 16:25:31] WARNING [django.request:241] Bad Request: /
[18/Oct/2023 16:25:31] WARNING [django.request:241] Bad Request: /
[18/Oct/2023 16:25:31] WARNING [django.server:212] "GET / HTTP/1.1" 400 63088
[18/Oct/2023 16:25:31] WARNING [django.server:212] "GET / HTTP/1.1" 400 63088
[18/Oct/2023 16:25:32] ERROR [django.server:212] "PRI * HTTP/2.0" 505 -
[18/Oct/2023 16:25:32] ERROR [django.server:212] "PRI * HTTP/2.0" 505 -
