[07/Oct/2023 16:36:48] WARNING [django.request:241] Not Found: /favicon.ico
[07/Oct/2023 16:36:48] WARNING [django.request:241] Not Found: /favicon.ico
[07/Oct/2023 16:36:48] WARNING [django.server:212] "GET /favicon.ico HTTP/1.1" 404 2215
[07/Oct/2023 16:36:48] WARNING [django.server:212] "GET /favicon.ico HTTP/1.1" 404 2215
[07/Oct/2023 16:42:47] WARNING [django.request:241] Unauthorized: /api/company/check-in/0
[07/Oct/2023 16:42:47] WARNING [django.request:241] Unauthorized: /api/company/check-in/0
[07/Oct/2023 16:42:47] WARNING [django.server:212] "GET /api/company/check-in/0 HTTP/1.1" 401 58
[07/Oct/2023 16:42:47] WARNING [django.server:212] "GET /api/company/check-in/0 HTTP/1.1" 401 58
[07/Oct/2023 16:43:12] ERROR [django.request:241] Internal Server Error: /api/getTaskForcesByCompany/get/1
[07/Oct/2023 16:43:12] ERROR [django.request:241] Internal Server Error: /api/getTaskForcesByCompany/get/1
[07/Oct/2023 16:43:12] ERROR [django.server:212] "GET /api/getTaskForcesByCompany/get/1 HTTP/1.1" 500 205
[07/Oct/2023 16:43:12] ERROR [django.server:212] "GET /api/getTaskForcesByCompany/get/1 HTTP/1.1" 500 205
[07/Oct/2023 16:44:15] ERROR [django.request:241] Internal Server Error: /api/get_recommendations
Traceback (most recent call last):
  File "/usr/local/lib/python3.10/site-packages/django/core/handlers/exception.py", line 55, in inner
    response = get_response(request)
  File "/usr/local/lib/python3.10/site-packages/django/core/handlers/base.py", line 197, in _get_response
    response = wrapped_callback(request, *callback_args, **callback_kwargs)
  File "/usr/local/lib/python3.10/site-packages/django/views/decorators/csrf.py", line 56, in wrapper_view
    return view_func(*args, **kwargs)
  File "/usr/local/lib/python3.10/site-packages/django/views/generic/base.py", line 104, in view
    return self.dispatch(request, *args, **kwargs)
  File "/usr/local/lib/python3.10/site-packages/rest_framework/views.py", line 509, in dispatch
    response = self.handle_exception(exc)
  File "/usr/local/lib/python3.10/site-packages/rest_framework/views.py", line 469, in handle_exception
    self.raise_uncaught_exception(exc)
  File "/usr/local/lib/python3.10/site-packages/rest_framework/views.py", line 480, in raise_uncaught_exception
    raise exc
  File "/usr/local/lib/python3.10/site-packages/rest_framework/views.py", line 506, in dispatch
    response = handler(request, *args, **kwargs)
  File "/usr/local/lib/python3.10/site-packages/rest_framework/decorators.py", line 50, in handler
    return func(*args, **kwargs)
  File "/app/backend/api/viewsIntelligent.py", line 874, in get_recommendations
    convert_jobs_to_text(candidates, len(candidates)),
  File "/app/backend/api/viewsIntelligent.py", line 784, in convert_jobs_to_text
    requirement = job['requirement']
TypeError: 'UserResume' object is not subscriptable
[07/Oct/2023 16:44:15] ERROR [django.request:241] Internal Server Error: /api/get_recommendations
Traceback (most recent call last):
  File "/usr/local/lib/python3.10/site-packages/django/core/handlers/exception.py", line 55, in inner
    response = get_response(request)
  File "/usr/local/lib/python3.10/site-packages/django/core/handlers/base.py", line 197, in _get_response
    response = wrapped_callback(request, *callback_args, **callback_kwargs)
  File "/usr/local/lib/python3.10/site-packages/django/views/decorators/csrf.py", line 56, in wrapper_view
    return view_func(*args, **kwargs)
  File "/usr/local/lib/python3.10/site-packages/django/views/generic/base.py", line 104, in view
    return self.dispatch(request, *args, **kwargs)
  File "/usr/local/lib/python3.10/site-packages/rest_framework/views.py", line 509, in dispatch
    response = self.handle_exception(exc)
  File "/usr/local/lib/python3.10/site-packages/rest_framework/views.py", line 469, in handle_exception
    self.raise_uncaught_exception(exc)
  File "/usr/local/lib/python3.10/site-packages/rest_framework/views.py", line 480, in raise_uncaught_exception
    raise exc
  File "/usr/local/lib/python3.10/site-packages/rest_framework/views.py", line 506, in dispatch
    response = handler(request, *args, **kwargs)
  File "/usr/local/lib/python3.10/site-packages/rest_framework/decorators.py", line 50, in handler
    return func(*args, **kwargs)
  File "/app/backend/api/viewsIntelligent.py", line 874, in get_recommendations
    convert_jobs_to_text(candidates, len(candidates)),
  File "/app/backend/api/viewsIntelligent.py", line 784, in convert_jobs_to_text
    requirement = job['requirement']
TypeError: 'UserResume' object is not subscriptable
[07/Oct/2023 16:44:15] ERROR [django.server:212] "GET /api/get_recommendations?job_id=1 HTTP/1.1" 500 100334
[07/Oct/2023 16:44:15] ERROR [django.server:212] "GET /api/get_recommendations?job_id=1 HTTP/1.1" 500 100334
[07/Oct/2023 16:44:23] WARNING [django.request:241] Unauthorized: /api/get_recommendations
[07/Oct/2023 16:44:23] WARNING [django.request:241] Unauthorized: /api/get_recommendations
[07/Oct/2023 16:44:23] WARNING [django.server:212] "GET /api/get_recommendations?job_id=1 HTTP/1.1" 401 58
[07/Oct/2023 16:44:23] WARNING [django.server:212] "GET /api/get_recommendations?job_id=1 HTTP/1.1" 401 58
[07/Oct/2023 16:46:54] ERROR [django.request:241] Internal Server Error: /api/get_recommendations
Traceback (most recent call last):
  File "/usr/local/lib/python3.10/site-packages/django/core/handlers/exception.py", line 55, in inner
    response = get_response(request)
  File "/usr/local/lib/python3.10/site-packages/django/core/handlers/base.py", line 197, in _get_response
    response = wrapped_callback(request, *callback_args, **callback_kwargs)
  File "/usr/local/lib/python3.10/site-packages/django/views/decorators/csrf.py", line 56, in wrapper_view
    return view_func(*args, **kwargs)
  File "/usr/local/lib/python3.10/site-packages/django/views/generic/base.py", line 104, in view
    return self.dispatch(request, *args, **kwargs)
  File "/usr/local/lib/python3.10/site-packages/rest_framework/views.py", line 509, in dispatch
    response = self.handle_exception(exc)
  File "/usr/local/lib/python3.10/site-packages/rest_framework/views.py", line 469, in handle_exception
    self.raise_uncaught_exception(exc)
  File "/usr/local/lib/python3.10/site-packages/rest_framework/views.py", line 480, in raise_uncaught_exception
    raise exc
  File "/usr/local/lib/python3.10/site-packages/rest_framework/views.py", line 506, in dispatch
    response = handler(request, *args, **kwargs)
  File "/usr/local/lib/python3.10/site-packages/rest_framework/decorators.py", line 50, in handler
    return func(*args, **kwargs)
  File "/app/backend/api/viewsIntelligent.py", line 867, in get_recommendations
    convert_resumes_to_text(candidates),
  File "/app/backend/api/viewsIntelligent.py", line 798, in convert_resumes_to_text
    resume_text = convert_resume_to_text(resume)
  File "/app/backend/api/viewsIntelligent.py", line 783, in convert_resume_to_text
    title = resume['title']
TypeError: 'UserResume' object is not subscriptable
[07/Oct/2023 16:46:54] ERROR [django.request:241] Internal Server Error: /api/get_recommendations
Traceback (most recent call last):
  File "/usr/local/lib/python3.10/site-packages/django/core/handlers/exception.py", line 55, in inner
    response = get_response(request)
  File "/usr/local/lib/python3.10/site-packages/django/core/handlers/base.py", line 197, in _get_response
    response = wrapped_callback(request, *callback_args, **callback_kwargs)
  File "/usr/local/lib/python3.10/site-packages/django/views/decorators/csrf.py", line 56, in wrapper_view
    return view_func(*args, **kwargs)
  File "/usr/local/lib/python3.10/site-packages/django/views/generic/base.py", line 104, in view
    return self.dispatch(request, *args, **kwargs)
  File "/usr/local/lib/python3.10/site-packages/rest_framework/views.py", line 509, in dispatch
    response = self.handle_exception(exc)
  File "/usr/local/lib/python3.10/site-packages/rest_framework/views.py", line 469, in handle_exception
    self.raise_uncaught_exception(exc)
  File "/usr/local/lib/python3.10/site-packages/rest_framework/views.py", line 480, in raise_uncaught_exception
    raise exc
  File "/usr/local/lib/python3.10/site-packages/rest_framework/views.py", line 506, in dispatch
    response = handler(request, *args, **kwargs)
  File "/usr/local/lib/python3.10/site-packages/rest_framework/decorators.py", line 50, in handler
    return func(*args, **kwargs)
  File "/app/backend/api/viewsIntelligent.py", line 867, in get_recommendations
    convert_resumes_to_text(candidates),
  File "/app/backend/api/viewsIntelligent.py", line 798, in convert_resumes_to_text
    resume_text = convert_resume_to_text(resume)
  File "/app/backend/api/viewsIntelligent.py", line 783, in convert_resume_to_text
    title = resume['title']
TypeError: 'UserResume' object is not subscriptable
[07/Oct/2023 16:46:54] ERROR [django.server:212] "GET /api/get_recommendations?job_id=1 HTTP/1.1" 500 103721
[07/Oct/2023 16:46:54] ERROR [django.server:212] "GET /api/get_recommendations?job_id=1 HTTP/1.1" 500 103721
[07/Oct/2023 16:47:00] ERROR [django.request:241] Internal Server Error: /api/get_recommendations
Traceback (most recent call last):
  File "/usr/local/lib/python3.10/site-packages/django/core/handlers/exception.py", line 55, in inner
    response = get_response(request)
  File "/usr/local/lib/python3.10/site-packages/django/core/handlers/base.py", line 197, in _get_response
    response = wrapped_callback(request, *callback_args, **callback_kwargs)
  File "/usr/local/lib/python3.10/site-packages/django/views/decorators/csrf.py", line 56, in wrapper_view
    return view_func(*args, **kwargs)
  File "/usr/local/lib/python3.10/site-packages/django/views/generic/base.py", line 104, in view
    return self.dispatch(request, *args, **kwargs)
  File "/usr/local/lib/python3.10/site-packages/rest_framework/views.py", line 509, in dispatch
    response = self.handle_exception(exc)
  File "/usr/local/lib/python3.10/site-packages/rest_framework/views.py", line 469, in handle_exception
    self.raise_uncaught_exception(exc)
  File "/usr/local/lib/python3.10/site-packages/rest_framework/views.py", line 480, in raise_uncaught_exception
    raise exc
  File "/usr/local/lib/python3.10/site-packages/rest_framework/views.py", line 506, in dispatch
    response = handler(request, *args, **kwargs)
  File "/usr/local/lib/python3.10/site-packages/rest_framework/decorators.py", line 50, in handler
    return func(*args, **kwargs)
  File "/app/backend/api/viewsIntelligent.py", line 867, in get_recommendations
    convert_resumes_to_text(candidates),
  File "/app/backend/api/viewsIntelligent.py", line 798, in convert_resumes_to_text
    resume_text = convert_resume_to_text(resume)
  File "/app/backend/api/viewsIntelligent.py", line 783, in convert_resume_to_text
    title = resume['title']
TypeError: 'UserResume' object is not subscriptable
[07/Oct/2023 16:47:00] ERROR [django.request:241] Internal Server Error: /api/get_recommendations
Traceback (most recent call last):
  File "/usr/local/lib/python3.10/site-packages/django/core/handlers/exception.py", line 55, in inner
    response = get_response(request)
  File "/usr/local/lib/python3.10/site-packages/django/core/handlers/base.py", line 197, in _get_response
    response = wrapped_callback(request, *callback_args, **callback_kwargs)
  File "/usr/local/lib/python3.10/site-packages/django/views/decorators/csrf.py", line 56, in wrapper_view
    return view_func(*args, **kwargs)
  File "/usr/local/lib/python3.10/site-packages/django/views/generic/base.py", line 104, in view
    return self.dispatch(request, *args, **kwargs)
  File "/usr/local/lib/python3.10/site-packages/rest_framework/views.py", line 509, in dispatch
    response = self.handle_exception(exc)
  File "/usr/local/lib/python3.10/site-packages/rest_framework/views.py", line 469, in handle_exception
    self.raise_uncaught_exception(exc)
  File "/usr/local/lib/python3.10/site-packages/rest_framework/views.py", line 480, in raise_uncaught_exception
    raise exc
  File "/usr/local/lib/python3.10/site-packages/rest_framework/views.py", line 506, in dispatch
    response = handler(request, *args, **kwargs)
  File "/usr/local/lib/python3.10/site-packages/rest_framework/decorators.py", line 50, in handler
    return func(*args, **kwargs)
  File "/app/backend/api/viewsIntelligent.py", line 867, in get_recommendations
    convert_resumes_to_text(candidates),
  File "/app/backend/api/viewsIntelligent.py", line 798, in convert_resumes_to_text
    resume_text = convert_resume_to_text(resume)
  File "/app/backend/api/viewsIntelligent.py", line 783, in convert_resume_to_text
    title = resume['title']
TypeError: 'UserResume' object is not subscriptable
[07/Oct/2023 16:47:00] ERROR [django.server:212] "GET /api/get_recommendations?job_id=1 HTTP/1.1" 500 103721
[07/Oct/2023 16:47:00] ERROR [django.server:212] "GET /api/get_recommendations?job_id=1 HTTP/1.1" 500 103721
[07/Oct/2023 16:52:20] ERROR [django.request:241] Internal Server Error: /api/get_recommendations
Traceback (most recent call last):
  File "/usr/local/lib/python3.10/site-packages/django/core/handlers/exception.py", line 55, in inner
    response = get_response(request)
  File "/usr/local/lib/python3.10/site-packages/django/core/handlers/base.py", line 197, in _get_response
    response = wrapped_callback(request, *callback_args, **callback_kwargs)
  File "/usr/local/lib/python3.10/site-packages/django/views/decorators/csrf.py", line 56, in wrapper_view
    return view_func(*args, **kwargs)
  File "/usr/local/lib/python3.10/site-packages/django/views/generic/base.py", line 104, in view
    return self.dispatch(request, *args, **kwargs)
  File "/usr/local/lib/python3.10/site-packages/rest_framework/views.py", line 509, in dispatch
    response = self.handle_exception(exc)
  File "/usr/local/lib/python3.10/site-packages/rest_framework/views.py", line 469, in handle_exception
    self.raise_uncaught_exception(exc)
  File "/usr/local/lib/python3.10/site-packages/rest_framework/views.py", line 480, in raise_uncaught_exception
    raise exc
  File "/usr/local/lib/python3.10/site-packages/rest_framework/views.py", line 506, in dispatch
    response = handler(request, *args, **kwargs)
  File "/usr/local/lib/python3.10/site-packages/rest_framework/decorators.py", line 50, in handler
    return func(*args, **kwargs)
  File "/app/backend/api/viewsIntelligent.py", line 873, in get_recommendations
    similar_candidates = get_final_recommendations(
  File "/app/backend/api/viewsIntelligent.py", line 809, in get_final_recommendations
    tfidf_matrix_job = tfidf_vectorizer.fit_transform(job_texts)
  File "/usr/local/lib/python3.10/site-packages/sklearn/feature_extraction/text.py", line 2126, in fit_transform
    X = super().fit_transform(raw_documents)
  File "/usr/local/lib/python3.10/site-packages/sklearn/base.py", line 1151, in wrapper
    return fit_method(estimator, *args, **kwargs)
  File "/usr/local/lib/python3.10/site-packages/sklearn/feature_extraction/text.py", line 1361, in fit_transform
    raise ValueError(
ValueError: Iterable over raw text documents expected, string object received.
[07/Oct/2023 16:52:20] ERROR [django.request:241] Internal Server Error: /api/get_recommendations
Traceback (most recent call last):
  File "/usr/local/lib/python3.10/site-packages/django/core/handlers/exception.py", line 55, in inner
    response = get_response(request)
  File "/usr/local/lib/python3.10/site-packages/django/core/handlers/base.py", line 197, in _get_response
    response = wrapped_callback(request, *callback_args, **callback_kwargs)
  File "/usr/local/lib/python3.10/site-packages/django/views/decorators/csrf.py", line 56, in wrapper_view
    return view_func(*args, **kwargs)
  File "/usr/local/lib/python3.10/site-packages/django/views/generic/base.py", line 104, in view
    return self.dispatch(request, *args, **kwargs)
  File "/usr/local/lib/python3.10/site-packages/rest_framework/views.py", line 509, in dispatch
    response = self.handle_exception(exc)
  File "/usr/local/lib/python3.10/site-packages/rest_framework/views.py", line 469, in handle_exception
    self.raise_uncaught_exception(exc)
  File "/usr/local/lib/python3.10/site-packages/rest_framework/views.py", line 480, in raise_uncaught_exception
    raise exc
  File "/usr/local/lib/python3.10/site-packages/rest_framework/views.py", line 506, in dispatch
    response = handler(request, *args, **kwargs)
  File "/usr/local/lib/python3.10/site-packages/rest_framework/decorators.py", line 50, in handler
    return func(*args, **kwargs)
  File "/app/backend/api/viewsIntelligent.py", line 873, in get_recommendations
    similar_candidates = get_final_recommendations(
  File "/app/backend/api/viewsIntelligent.py", line 809, in get_final_recommendations
    tfidf_matrix_job = tfidf_vectorizer.fit_transform(job_texts)
  File "/usr/local/lib/python3.10/site-packages/sklearn/feature_extraction/text.py", line 2126, in fit_transform
    X = super().fit_transform(raw_documents)
  File "/usr/local/lib/python3.10/site-packages/sklearn/base.py", line 1151, in wrapper
    return fit_method(estimator, *args, **kwargs)
  File "/usr/local/lib/python3.10/site-packages/sklearn/feature_extraction/text.py", line 1361, in fit_transform
    raise ValueError(
ValueError: Iterable over raw text documents expected, string object received.
[07/Oct/2023 16:52:20] ERROR [django.server:212] "GET /api/get_recommendations?job_id=1 HTTP/1.1" 500 122955
[07/Oct/2023 16:52:20] ERROR [django.server:212] "GET /api/get_recommendations?job_id=1 HTTP/1.1" 500 122955
[07/Oct/2023 16:54:53] ERROR [django.request:241] Internal Server Error: /api/get_recommendations
Traceback (most recent call last):
  File "/usr/local/lib/python3.10/site-packages/django/core/handlers/exception.py", line 55, in inner
    response = get_response(request)
  File "/usr/local/lib/python3.10/site-packages/django/core/handlers/base.py", line 197, in _get_response
    response = wrapped_callback(request, *callback_args, **callback_kwargs)
  File "/usr/local/lib/python3.10/site-packages/django/views/decorators/csrf.py", line 56, in wrapper_view
    return view_func(*args, **kwargs)
  File "/usr/local/lib/python3.10/site-packages/django/views/generic/base.py", line 104, in view
    return self.dispatch(request, *args, **kwargs)
  File "/usr/local/lib/python3.10/site-packages/rest_framework/views.py", line 509, in dispatch
    response = self.handle_exception(exc)
  File "/usr/local/lib/python3.10/site-packages/rest_framework/views.py", line 469, in handle_exception
    self.raise_uncaught_exception(exc)
  File "/usr/local/lib/python3.10/site-packages/rest_framework/views.py", line 480, in raise_uncaught_exception
    raise exc
  File "/usr/local/lib/python3.10/site-packages/rest_framework/views.py", line 506, in dispatch
    response = handler(request, *args, **kwargs)
  File "/usr/local/lib/python3.10/site-packages/rest_framework/decorators.py", line 50, in handler
    return func(*args, **kwargs)
  File "/app/backend/api/viewsIntelligent.py", line 873, in get_recommendations
    similar_candidates = get_final_recommendations(
  File "/app/backend/api/viewsIntelligent.py", line 809, in get_final_recommendations
    tfidf_matrix_job = tfidf_vectorizer.fit_transform(job_texts)
  File "/usr/local/lib/python3.10/site-packages/sklearn/feature_extraction/text.py", line 2126, in fit_transform
    X = super().fit_transform(raw_documents)
  File "/usr/local/lib/python3.10/site-packages/sklearn/base.py", line 1151, in wrapper
    return fit_method(estimator, *args, **kwargs)
  File "/usr/local/lib/python3.10/site-packages/sklearn/feature_extraction/text.py", line 1361, in fit_transform
    raise ValueError(
ValueError: Iterable over raw text documents expected, string object received.
[07/Oct/2023 16:54:53] ERROR [django.request:241] Internal Server Error: /api/get_recommendations
Traceback (most recent call last):
  File "/usr/local/lib/python3.10/site-packages/django/core/handlers/exception.py", line 55, in inner
    response = get_response(request)
  File "/usr/local/lib/python3.10/site-packages/django/core/handlers/base.py", line 197, in _get_response
    response = wrapped_callback(request, *callback_args, **callback_kwargs)
  File "/usr/local/lib/python3.10/site-packages/django/views/decorators/csrf.py", line 56, in wrapper_view
    return view_func(*args, **kwargs)
  File "/usr/local/lib/python3.10/site-packages/django/views/generic/base.py", line 104, in view
    return self.dispatch(request, *args, **kwargs)
  File "/usr/local/lib/python3.10/site-packages/rest_framework/views.py", line 509, in dispatch
    response = self.handle_exception(exc)
  File "/usr/local/lib/python3.10/site-packages/rest_framework/views.py", line 469, in handle_exception
    self.raise_uncaught_exception(exc)
  File "/usr/local/lib/python3.10/site-packages/rest_framework/views.py", line 480, in raise_uncaught_exception
    raise exc
  File "/usr/local/lib/python3.10/site-packages/rest_framework/views.py", line 506, in dispatch
    response = handler(request, *args, **kwargs)
  File "/usr/local/lib/python3.10/site-packages/rest_framework/decorators.py", line 50, in handler
    return func(*args, **kwargs)
  File "/app/backend/api/viewsIntelligent.py", line 873, in get_recommendations
    similar_candidates = get_final_recommendations(
  File "/app/backend/api/viewsIntelligent.py", line 809, in get_final_recommendations
    tfidf_matrix_job = tfidf_vectorizer.fit_transform(job_texts)
  File "/usr/local/lib/python3.10/site-packages/sklearn/feature_extraction/text.py", line 2126, in fit_transform
    X = super().fit_transform(raw_documents)
  File "/usr/local/lib/python3.10/site-packages/sklearn/base.py", line 1151, in wrapper
    return fit_method(estimator, *args, **kwargs)
  File "/usr/local/lib/python3.10/site-packages/sklearn/feature_extraction/text.py", line 1361, in fit_transform
    raise ValueError(
ValueError: Iterable over raw text documents expected, string object received.
[07/Oct/2023 16:54:53] ERROR [django.server:212] "GET /api/get_recommendations?job_id=1 HTTP/1.1" 500 122955
[07/Oct/2023 16:54:53] ERROR [django.server:212] "GET /api/get_recommendations?job_id=1 HTTP/1.1" 500 122955
[07/Oct/2023 16:54:57] WARNING [django.request:241] Unauthorized: /api/get_recommendations
[07/Oct/2023 16:54:57] WARNING [django.request:241] Unauthorized: /api/get_recommendations
[07/Oct/2023 16:54:57] WARNING [django.server:212] "GET /api/get_recommendations?job_id=1 HTTP/1.1" 401 58
[07/Oct/2023 16:54:57] WARNING [django.server:212] "GET /api/get_recommendations?job_id=1 HTTP/1.1" 401 58
[07/Oct/2023 16:56:22] ERROR [django.request:241] Internal Server Error: /api/getTaskForcesByCompany/get/1
[07/Oct/2023 16:56:22] ERROR [django.request:241] Internal Server Error: /api/getTaskForcesByCompany/get/1
[07/Oct/2023 16:56:22] ERROR [django.server:212] "GET /api/getTaskForcesByCompany/get/1 HTTP/1.1" 500 205
[07/Oct/2023 16:56:22] ERROR [django.server:212] "GET /api/getTaskForcesByCompany/get/1 HTTP/1.1" 500 205
[07/Oct/2023 16:56:25] ERROR [django.request:241] Internal Server Error: /api/getTaskForcesByCompany/get/1
[07/Oct/2023 16:56:25] ERROR [django.request:241] Internal Server Error: /api/getTaskForcesByCompany/get/1
[07/Oct/2023 16:56:25] ERROR [django.server:212] "GET /api/getTaskForcesByCompany/get/1 HTTP/1.1" 500 205
[07/Oct/2023 16:56:25] ERROR [django.server:212] "GET /api/getTaskForcesByCompany/get/1 HTTP/1.1" 500 205
[07/Oct/2023 16:57:06] ERROR [django.request:241] Internal Server Error: /api/getTaskForcesByCompany/get/1
[07/Oct/2023 16:57:06] ERROR [django.request:241] Internal Server Error: /api/getTaskForcesByCompany/get/1
[07/Oct/2023 16:57:06] ERROR [django.server:212] "GET /api/getTaskForcesByCompany/get/1 HTTP/1.1" 500 205
[07/Oct/2023 16:57:06] ERROR [django.server:212] "GET /api/getTaskForcesByCompany/get/1 HTTP/1.1" 500 205
[07/Oct/2023 16:57:09] ERROR [django.request:241] Internal Server Error: /api/getTaskForcesByCompany/get/1
[07/Oct/2023 16:57:09] ERROR [django.request:241] Internal Server Error: /api/getTaskForcesByCompany/get/1
[07/Oct/2023 16:57:09] ERROR [django.server:212] "GET /api/getTaskForcesByCompany/get/1 HTTP/1.1" 500 205
[07/Oct/2023 16:57:09] ERROR [django.server:212] "GET /api/getTaskForcesByCompany/get/1 HTTP/1.1" 500 205
[07/Oct/2023 16:57:34] ERROR [django.request:241] Internal Server Error: /api/getTaskForcesByCompany/get/1
[07/Oct/2023 16:57:34] ERROR [django.request:241] Internal Server Error: /api/getTaskForcesByCompany/get/1
[07/Oct/2023 16:57:34] ERROR [django.server:212] "GET /api/getTaskForcesByCompany/get/1 HTTP/1.1" 500 205
[07/Oct/2023 16:57:34] ERROR [django.server:212] "GET /api/getTaskForcesByCompany/get/1 HTTP/1.1" 500 205
[07/Oct/2023 16:57:46] ERROR [django.request:241] Internal Server Error: /api/getTaskForcesByCompany/get/1
[07/Oct/2023 16:57:46] ERROR [django.request:241] Internal Server Error: /api/getTaskForcesByCompany/get/1
[07/Oct/2023 16:57:46] ERROR [django.server:212] "GET /api/getTaskForcesByCompany/get/1 HTTP/1.1" 500 205
[07/Oct/2023 16:57:46] ERROR [django.server:212] "GET /api/getTaskForcesByCompany/get/1 HTTP/1.1" 500 205
[07/Oct/2023 16:57:48] ERROR [django.request:241] Internal Server Error: /api/getTaskForcesByCompany/get/1
[07/Oct/2023 16:57:48] ERROR [django.request:241] Internal Server Error: /api/getTaskForcesByCompany/get/1
[07/Oct/2023 16:57:48] ERROR [django.server:212] "GET /api/getTaskForcesByCompany/get/1 HTTP/1.1" 500 205
[07/Oct/2023 16:57:48] ERROR [django.server:212] "GET /api/getTaskForcesByCompany/get/1 HTTP/1.1" 500 205
[07/Oct/2023 16:57:54] ERROR [django.request:241] Internal Server Error: /api/getTaskForcesByCompany/get/1
[07/Oct/2023 16:57:54] ERROR [django.request:241] Internal Server Error: /api/getTaskForcesByCompany/get/1
[07/Oct/2023 16:57:54] ERROR [django.server:212] "GET /api/getTaskForcesByCompany/get/1 HTTP/1.1" 500 205
[07/Oct/2023 16:57:54] ERROR [django.server:212] "GET /api/getTaskForcesByCompany/get/1 HTTP/1.1" 500 205
[07/Oct/2023 16:58:21] ERROR [django.request:241] Internal Server Error: /api/get_recommendations
Traceback (most recent call last):
  File "/usr/local/lib/python3.10/site-packages/django/core/handlers/exception.py", line 55, in inner
    response = get_response(request)
  File "/usr/local/lib/python3.10/site-packages/django/core/handlers/base.py", line 197, in _get_response
    response = wrapped_callback(request, *callback_args, **callback_kwargs)
  File "/usr/local/lib/python3.10/site-packages/django/views/decorators/csrf.py", line 56, in wrapper_view
    return view_func(*args, **kwargs)
  File "/usr/local/lib/python3.10/site-packages/django/views/generic/base.py", line 104, in view
    return self.dispatch(request, *args, **kwargs)
  File "/usr/local/lib/python3.10/site-packages/rest_framework/views.py", line 509, in dispatch
    response = self.handle_exception(exc)
  File "/usr/local/lib/python3.10/site-packages/rest_framework/views.py", line 469, in handle_exception
    self.raise_uncaught_exception(exc)
  File "/usr/local/lib/python3.10/site-packages/rest_framework/views.py", line 480, in raise_uncaught_exception
    raise exc
  File "/usr/local/lib/python3.10/site-packages/rest_framework/views.py", line 506, in dispatch
    response = handler(request, *args, **kwargs)
  File "/usr/local/lib/python3.10/site-packages/rest_framework/decorators.py", line 50, in handler
    return func(*args, **kwargs)
  File "/app/backend/api/viewsIntelligent.py", line 873, in get_recommendations
    similar_candidates = get_final_recommendations(
  File "/app/backend/api/viewsIntelligent.py", line 809, in get_final_recommendations
    tfidf_matrix_job = tfidf_vectorizer.fit_transform(job_texts)
  File "/usr/local/lib/python3.10/site-packages/sklearn/feature_extraction/text.py", line 2126, in fit_transform
    X = super().fit_transform(raw_documents)
  File "/usr/local/lib/python3.10/site-packages/sklearn/base.py", line 1151, in wrapper
    return fit_method(estimator, *args, **kwargs)
  File "/usr/local/lib/python3.10/site-packages/sklearn/feature_extraction/text.py", line 1361, in fit_transform
    raise ValueError(
ValueError: Iterable over raw text documents expected, string object received.
[07/Oct/2023 16:58:21] ERROR [django.request:241] Internal Server Error: /api/get_recommendations
Traceback (most recent call last):
  File "/usr/local/lib/python3.10/site-packages/django/core/handlers/exception.py", line 55, in inner
    response = get_response(request)
  File "/usr/local/lib/python3.10/site-packages/django/core/handlers/base.py", line 197, in _get_response
    response = wrapped_callback(request, *callback_args, **callback_kwargs)
  File "/usr/local/lib/python3.10/site-packages/django/views/decorators/csrf.py", line 56, in wrapper_view
    return view_func(*args, **kwargs)
  File "/usr/local/lib/python3.10/site-packages/django/views/generic/base.py", line 104, in view
    return self.dispatch(request, *args, **kwargs)
  File "/usr/local/lib/python3.10/site-packages/rest_framework/views.py", line 509, in dispatch
    response = self.handle_exception(exc)
  File "/usr/local/lib/python3.10/site-packages/rest_framework/views.py", line 469, in handle_exception
    self.raise_uncaught_exception(exc)
  File "/usr/local/lib/python3.10/site-packages/rest_framework/views.py", line 480, in raise_uncaught_exception
    raise exc
  File "/usr/local/lib/python3.10/site-packages/rest_framework/views.py", line 506, in dispatch
    response = handler(request, *args, **kwargs)
  File "/usr/local/lib/python3.10/site-packages/rest_framework/decorators.py", line 50, in handler
    return func(*args, **kwargs)
  File "/app/backend/api/viewsIntelligent.py", line 873, in get_recommendations
    similar_candidates = get_final_recommendations(
  File "/app/backend/api/viewsIntelligent.py", line 809, in get_final_recommendations
    tfidf_matrix_job = tfidf_vectorizer.fit_transform(job_texts)
  File "/usr/local/lib/python3.10/site-packages/sklearn/feature_extraction/text.py", line 2126, in fit_transform
    X = super().fit_transform(raw_documents)
  File "/usr/local/lib/python3.10/site-packages/sklearn/base.py", line 1151, in wrapper
    return fit_method(estimator, *args, **kwargs)
  File "/usr/local/lib/python3.10/site-packages/sklearn/feature_extraction/text.py", line 1361, in fit_transform
    raise ValueError(
ValueError: Iterable over raw text documents expected, string object received.
[07/Oct/2023 16:58:21] ERROR [django.server:212] "GET /api/get_recommendations?job_id=1 HTTP/1.1" 500 122955
[07/Oct/2023 16:58:21] ERROR [django.server:212] "GET /api/get_recommendations?job_id=1 HTTP/1.1" 500 122955
[07/Oct/2023 16:59:03] ERROR [django.request:241] Internal Server Error: /api/get_recommendations
Traceback (most recent call last):
  File "/usr/local/lib/python3.10/site-packages/django/core/handlers/exception.py", line 55, in inner
    response = get_response(request)
  File "/usr/local/lib/python3.10/site-packages/django/core/handlers/base.py", line 197, in _get_response
    response = wrapped_callback(request, *callback_args, **callback_kwargs)
  File "/usr/local/lib/python3.10/site-packages/django/views/decorators/csrf.py", line 56, in wrapper_view
    return view_func(*args, **kwargs)
  File "/usr/local/lib/python3.10/site-packages/django/views/generic/base.py", line 104, in view
    return self.dispatch(request, *args, **kwargs)
  File "/usr/local/lib/python3.10/site-packages/rest_framework/views.py", line 509, in dispatch
    response = self.handle_exception(exc)
  File "/usr/local/lib/python3.10/site-packages/rest_framework/views.py", line 469, in handle_exception
    self.raise_uncaught_exception(exc)
  File "/usr/local/lib/python3.10/site-packages/rest_framework/views.py", line 480, in raise_uncaught_exception
    raise exc
  File "/usr/local/lib/python3.10/site-packages/rest_framework/views.py", line 506, in dispatch
    response = handler(request, *args, **kwargs)
  File "/usr/local/lib/python3.10/site-packages/rest_framework/decorators.py", line 50, in handler
    return func(*args, **kwargs)
  File "/app/backend/api/viewsIntelligent.py", line 873, in get_recommendations
    similar_candidates = get_final_recommendations(
  File "/app/backend/api/viewsIntelligent.py", line 825, in get_final_recommendations
    _, tfidf_indices = knn_tfidf.kneighbors(cosine_similarities_tfidf)
  File "/usr/local/lib/python3.10/site-packages/sklearn/neighbors/_base.py", line 808, in kneighbors
    raise ValueError(
ValueError: Expected n_neighbors <= n_samples,  but n_samples = 1, n_neighbors = 3
[07/Oct/2023 16:59:03] ERROR [django.request:241] Internal Server Error: /api/get_recommendations
Traceback (most recent call last):
  File "/usr/local/lib/python3.10/site-packages/django/core/handlers/exception.py", line 55, in inner
    response = get_response(request)
  File "/usr/local/lib/python3.10/site-packages/django/core/handlers/base.py", line 197, in _get_response
    response = wrapped_callback(request, *callback_args, **callback_kwargs)
  File "/usr/local/lib/python3.10/site-packages/django/views/decorators/csrf.py", line 56, in wrapper_view
    return view_func(*args, **kwargs)
  File "/usr/local/lib/python3.10/site-packages/django/views/generic/base.py", line 104, in view
    return self.dispatch(request, *args, **kwargs)
  File "/usr/local/lib/python3.10/site-packages/rest_framework/views.py", line 509, in dispatch
    response = self.handle_exception(exc)
  File "/usr/local/lib/python3.10/site-packages/rest_framework/views.py", line 469, in handle_exception
    self.raise_uncaught_exception(exc)
  File "/usr/local/lib/python3.10/site-packages/rest_framework/views.py", line 480, in raise_uncaught_exception
    raise exc
  File "/usr/local/lib/python3.10/site-packages/rest_framework/views.py", line 506, in dispatch
    response = handler(request, *args, **kwargs)
  File "/usr/local/lib/python3.10/site-packages/rest_framework/decorators.py", line 50, in handler
    return func(*args, **kwargs)
  File "/app/backend/api/viewsIntelligent.py", line 873, in get_recommendations
    similar_candidates = get_final_recommendations(
  File "/app/backend/api/viewsIntelligent.py", line 825, in get_final_recommendations
    _, tfidf_indices = knn_tfidf.kneighbors(cosine_similarities_tfidf)
  File "/usr/local/lib/python3.10/site-packages/sklearn/neighbors/_base.py", line 808, in kneighbors
    raise ValueError(
ValueError: Expected n_neighbors <= n_samples,  but n_samples = 1, n_neighbors = 3
[07/Oct/2023 16:59:03] ERROR [django.server:212] "GET /api/get_recommendations?job_id=1 HTTP/1.1" 500 117433
[07/Oct/2023 16:59:03] ERROR [django.server:212] "GET /api/get_recommendations?job_id=1 HTTP/1.1" 500 117433
[07/Oct/2023 17:01:39] ERROR [django.request:241] Internal Server Error: /api/get_recommendations
Traceback (most recent call last):
  File "/usr/local/lib/python3.10/site-packages/django/core/handlers/exception.py", line 55, in inner
    response = get_response(request)
  File "/usr/local/lib/python3.10/site-packages/django/core/handlers/base.py", line 197, in _get_response
    response = wrapped_callback(request, *callback_args, **callback_kwargs)
  File "/usr/local/lib/python3.10/site-packages/django/views/decorators/csrf.py", line 56, in wrapper_view
    return view_func(*args, **kwargs)
  File "/usr/local/lib/python3.10/site-packages/django/views/generic/base.py", line 104, in view
    return self.dispatch(request, *args, **kwargs)
  File "/usr/local/lib/python3.10/site-packages/rest_framework/views.py", line 509, in dispatch
    response = self.handle_exception(exc)
  File "/usr/local/lib/python3.10/site-packages/rest_framework/views.py", line 469, in handle_exception
    self.raise_uncaught_exception(exc)
  File "/usr/local/lib/python3.10/site-packages/rest_framework/views.py", line 480, in raise_uncaught_exception
    raise exc
  File "/usr/local/lib/python3.10/site-packages/rest_framework/views.py", line 506, in dispatch
    response = handler(request, *args, **kwargs)
  File "/usr/local/lib/python3.10/site-packages/rest_framework/decorators.py", line 50, in handler
    return func(*args, **kwargs)
  File "/app/backend/api/viewsIntelligent.py", line 873, in get_recommendations
    similar_candidates = get_final_recommendations(
  File "/app/backend/api/viewsIntelligent.py", line 839, in get_final_recommendations
    combined_recommendations.sort(key=lambda idx: cosine_similarities_tfidf[i][idx] + cosine_similarities_count[i][idx])
  File "/app/backend/api/viewsIntelligent.py", line 839, in <lambda>
    combined_recommendations.sort(key=lambda idx: cosine_similarities_tfidf[i][idx] + cosine_similarities_count[i][idx])
IndexError: only integers, slices (`:`), ellipsis (`...`), numpy.newaxis (`None`) and integer or boolean arrays are valid indices
[07/Oct/2023 17:01:39] ERROR [django.request:241] Internal Server Error: /api/get_recommendations
Traceback (most recent call last):
  File "/usr/local/lib/python3.10/site-packages/django/core/handlers/exception.py", line 55, in inner
    response = get_response(request)
  File "/usr/local/lib/python3.10/site-packages/django/core/handlers/base.py", line 197, in _get_response
    response = wrapped_callback(request, *callback_args, **callback_kwargs)
  File "/usr/local/lib/python3.10/site-packages/django/views/decorators/csrf.py", line 56, in wrapper_view
    return view_func(*args, **kwargs)
  File "/usr/local/lib/python3.10/site-packages/django/views/generic/base.py", line 104, in view
    return self.dispatch(request, *args, **kwargs)
  File "/usr/local/lib/python3.10/site-packages/rest_framework/views.py", line 509, in dispatch
    response = self.handle_exception(exc)
  File "/usr/local/lib/python3.10/site-packages/rest_framework/views.py", line 469, in handle_exception
    self.raise_uncaught_exception(exc)
  File "/usr/local/lib/python3.10/site-packages/rest_framework/views.py", line 480, in raise_uncaught_exception
    raise exc
  File "/usr/local/lib/python3.10/site-packages/rest_framework/views.py", line 506, in dispatch
    response = handler(request, *args, **kwargs)
  File "/usr/local/lib/python3.10/site-packages/rest_framework/decorators.py", line 50, in handler
    return func(*args, **kwargs)
  File "/app/backend/api/viewsIntelligent.py", line 873, in get_recommendations
    similar_candidates = get_final_recommendations(
  File "/app/backend/api/viewsIntelligent.py", line 839, in get_final_recommendations
    combined_recommendations.sort(key=lambda idx: cosine_similarities_tfidf[i][idx] + cosine_similarities_count[i][idx])
  File "/app/backend/api/viewsIntelligent.py", line 839, in <lambda>
    combined_recommendations.sort(key=lambda idx: cosine_similarities_tfidf[i][idx] + cosine_similarities_count[i][idx])
IndexError: only integers, slices (`:`), ellipsis (`...`), numpy.newaxis (`None`) and integer or boolean arrays are valid indices
[07/Oct/2023 17:01:39] ERROR [django.server:212] "GET /api/get_recommendations?job_id=1 HTTP/1.1" 500 118975
[07/Oct/2023 17:01:39] ERROR [django.server:212] "GET /api/get_recommendations?job_id=1 HTTP/1.1" 500 118975
[07/Oct/2023 17:01:43] WARNING [django.request:241] Unauthorized: /api/get_recommendations
[07/Oct/2023 17:01:43] WARNING [django.request:241] Unauthorized: /api/get_recommendations
[07/Oct/2023 17:01:43] WARNING [django.server:212] "GET /api/get_recommendations?job_id=1 HTTP/1.1" 401 58
[07/Oct/2023 17:01:43] WARNING [django.server:212] "GET /api/get_recommendations?job_id=1 HTTP/1.1" 401 58
[07/Oct/2023 17:06:43] ERROR [django.request:241] Internal Server Error: /api/get_recommendations
Traceback (most recent call last):
  File "/usr/local/lib/python3.10/site-packages/django/core/handlers/exception.py", line 55, in inner
    response = get_response(request)
  File "/usr/local/lib/python3.10/site-packages/django/core/handlers/base.py", line 197, in _get_response
    response = wrapped_callback(request, *callback_args, **callback_kwargs)
  File "/usr/local/lib/python3.10/site-packages/django/views/decorators/csrf.py", line 56, in wrapper_view
    return view_func(*args, **kwargs)
  File "/usr/local/lib/python3.10/site-packages/django/views/generic/base.py", line 104, in view
    return self.dispatch(request, *args, **kwargs)
  File "/usr/local/lib/python3.10/site-packages/rest_framework/views.py", line 509, in dispatch
    response = self.handle_exception(exc)
  File "/usr/local/lib/python3.10/site-packages/rest_framework/views.py", line 469, in handle_exception
    self.raise_uncaught_exception(exc)
  File "/usr/local/lib/python3.10/site-packages/rest_framework/views.py", line 480, in raise_uncaught_exception
    raise exc
  File "/usr/local/lib/python3.10/site-packages/rest_framework/views.py", line 506, in dispatch
    response = handler(request, *args, **kwargs)
  File "/usr/local/lib/python3.10/site-packages/rest_framework/decorators.py", line 50, in handler
    return func(*args, **kwargs)
  File "/app/backend/api/viewsIntelligent.py", line 869, in get_recommendations
    similar_candidates = get_final_recommendations(
  File "/app/backend/api/viewsIntelligent.py", line 835, in get_final_recommendations
    combined_recommendations.sort(key=lambda idx: cosine_similarities_tfidf[i][idx] + cosine_similarities_count[i][idx])
  File "/app/backend/api/viewsIntelligent.py", line 835, in <lambda>
    combined_recommendations.sort(key=lambda idx: cosine_similarities_tfidf[i][idx] + cosine_similarities_count[i][idx])
IndexError: only integers, slices (`:`), ellipsis (`...`), numpy.newaxis (`None`) and integer or boolean arrays are valid indices
[07/Oct/2023 17:06:43] ERROR [django.request:241] Internal Server Error: /api/get_recommendations
Traceback (most recent call last):
  File "/usr/local/lib/python3.10/site-packages/django/core/handlers/exception.py", line 55, in inner
    response = get_response(request)
  File "/usr/local/lib/python3.10/site-packages/django/core/handlers/base.py", line 197, in _get_response
    response = wrapped_callback(request, *callback_args, **callback_kwargs)
  File "/usr/local/lib/python3.10/site-packages/django/views/decorators/csrf.py", line 56, in wrapper_view
    return view_func(*args, **kwargs)
  File "/usr/local/lib/python3.10/site-packages/django/views/generic/base.py", line 104, in view
    return self.dispatch(request, *args, **kwargs)
  File "/usr/local/lib/python3.10/site-packages/rest_framework/views.py", line 509, in dispatch
    response = self.handle_exception(exc)
  File "/usr/local/lib/python3.10/site-packages/rest_framework/views.py", line 469, in handle_exception
    self.raise_uncaught_exception(exc)
  File "/usr/local/lib/python3.10/site-packages/rest_framework/views.py", line 480, in raise_uncaught_exception
    raise exc
  File "/usr/local/lib/python3.10/site-packages/rest_framework/views.py", line 506, in dispatch
    response = handler(request, *args, **kwargs)
  File "/usr/local/lib/python3.10/site-packages/rest_framework/decorators.py", line 50, in handler
    return func(*args, **kwargs)
  File "/app/backend/api/viewsIntelligent.py", line 869, in get_recommendations
    similar_candidates = get_final_recommendations(
  File "/app/backend/api/viewsIntelligent.py", line 835, in get_final_recommendations
    combined_recommendations.sort(key=lambda idx: cosine_similarities_tfidf[i][idx] + cosine_similarities_count[i][idx])
  File "/app/backend/api/viewsIntelligent.py", line 835, in <lambda>
    combined_recommendations.sort(key=lambda idx: cosine_similarities_tfidf[i][idx] + cosine_similarities_count[i][idx])
IndexError: only integers, slices (`:`), ellipsis (`...`), numpy.newaxis (`None`) and integer or boolean arrays are valid indices
[07/Oct/2023 17:06:43] ERROR [django.server:212] "GET /api/get_recommendations?job_id=1 HTTP/1.1" 500 120088
[07/Oct/2023 17:06:43] ERROR [django.server:212] "GET /api/get_recommendations?job_id=1 HTTP/1.1" 500 120088
[07/Oct/2023 17:06:47] WARNING [django.request:241] Unauthorized: /api/get_recommendations
[07/Oct/2023 17:06:47] WARNING [django.request:241] Unauthorized: /api/get_recommendations
[07/Oct/2023 17:06:47] WARNING [django.server:212] "GET /api/get_recommendations?job_id=1 HTTP/1.1" 401 58
[07/Oct/2023 17:06:47] WARNING [django.server:212] "GET /api/get_recommendations?job_id=1 HTTP/1.1" 401 58
[07/Oct/2023 17:07:23] ERROR [django.request:241] Internal Server Error: /api/get_recommendations
Traceback (most recent call last):
  File "/usr/local/lib/python3.10/site-packages/django/core/handlers/exception.py", line 55, in inner
    response = get_response(request)
  File "/usr/local/lib/python3.10/site-packages/django/core/handlers/base.py", line 197, in _get_response
    response = wrapped_callback(request, *callback_args, **callback_kwargs)
  File "/usr/local/lib/python3.10/site-packages/django/views/decorators/csrf.py", line 56, in wrapper_view
    return view_func(*args, **kwargs)
  File "/usr/local/lib/python3.10/site-packages/django/views/generic/base.py", line 104, in view
    return self.dispatch(request, *args, **kwargs)
  File "/usr/local/lib/python3.10/site-packages/rest_framework/views.py", line 509, in dispatch
    response = self.handle_exception(exc)
  File "/usr/local/lib/python3.10/site-packages/rest_framework/views.py", line 469, in handle_exception
    self.raise_uncaught_exception(exc)
  File "/usr/local/lib/python3.10/site-packages/rest_framework/views.py", line 480, in raise_uncaught_exception
    raise exc
  File "/usr/local/lib/python3.10/site-packages/rest_framework/views.py", line 506, in dispatch
    response = handler(request, *args, **kwargs)
  File "/usr/local/lib/python3.10/site-packages/rest_framework/decorators.py", line 50, in handler
    return func(*args, **kwargs)
  File "/app/backend/api/viewsIntelligent.py", line 870, in get_recommendations
    similar_candidates = get_final_recommendations(
  File "/app/backend/api/viewsIntelligent.py", line 835, in get_final_recommendations
    combined_recommendations.sort(key=lambda idx: cosine_similarities_tfidf[i][idx] + cosine_similarities_count[i][idx])
  File "/app/backend/api/viewsIntelligent.py", line 835, in <lambda>
    combined_recommendations.sort(key=lambda idx: cosine_similarities_tfidf[i][idx] + cosine_similarities_count[i][idx])
IndexError: only integers, slices (`:`), ellipsis (`...`), numpy.newaxis (`None`) and integer or boolean arrays are valid indices
[07/Oct/2023 17:07:23] ERROR [django.request:241] Internal Server Error: /api/get_recommendations
Traceback (most recent call last):
  File "/usr/local/lib/python3.10/site-packages/django/core/handlers/exception.py", line 55, in inner
    response = get_response(request)
  File "/usr/local/lib/python3.10/site-packages/django/core/handlers/base.py", line 197, in _get_response
    response = wrapped_callback(request, *callback_args, **callback_kwargs)
  File "/usr/local/lib/python3.10/site-packages/django/views/decorators/csrf.py", line 56, in wrapper_view
    return view_func(*args, **kwargs)
  File "/usr/local/lib/python3.10/site-packages/django/views/generic/base.py", line 104, in view
    return self.dispatch(request, *args, **kwargs)
  File "/usr/local/lib/python3.10/site-packages/rest_framework/views.py", line 509, in dispatch
    response = self.handle_exception(exc)
  File "/usr/local/lib/python3.10/site-packages/rest_framework/views.py", line 469, in handle_exception
    self.raise_uncaught_exception(exc)
  File "/usr/local/lib/python3.10/site-packages/rest_framework/views.py", line 480, in raise_uncaught_exception
    raise exc
  File "/usr/local/lib/python3.10/site-packages/rest_framework/views.py", line 506, in dispatch
    response = handler(request, *args, **kwargs)
  File "/usr/local/lib/python3.10/site-packages/rest_framework/decorators.py", line 50, in handler
    return func(*args, **kwargs)
  File "/app/backend/api/viewsIntelligent.py", line 870, in get_recommendations
    similar_candidates = get_final_recommendations(
  File "/app/backend/api/viewsIntelligent.py", line 835, in get_final_recommendations
    combined_recommendations.sort(key=lambda idx: cosine_similarities_tfidf[i][idx] + cosine_similarities_count[i][idx])
  File "/app/backend/api/viewsIntelligent.py", line 835, in <lambda>
    combined_recommendations.sort(key=lambda idx: cosine_similarities_tfidf[i][idx] + cosine_similarities_count[i][idx])
IndexError: only integers, slices (`:`), ellipsis (`...`), numpy.newaxis (`None`) and integer or boolean arrays are valid indices
[07/Oct/2023 17:07:23] ERROR [django.server:212] "GET /api/get_recommendations?job_id=1 HTTP/1.1" 500 120032
[07/Oct/2023 17:07:23] ERROR [django.server:212] "GET /api/get_recommendations?job_id=1 HTTP/1.1" 500 120032
[07/Oct/2023 17:09:22] ERROR [django.request:241] Internal Server Error: /api/getTaskForcesByCompany/get/1
[07/Oct/2023 17:09:22] ERROR [django.request:241] Internal Server Error: /api/getTaskForcesByCompany/get/1
[07/Oct/2023 17:09:22] ERROR [django.server:212] "GET /api/getTaskForcesByCompany/get/1 HTTP/1.1" 500 205
[07/Oct/2023 17:09:22] ERROR [django.server:212] "GET /api/getTaskForcesByCompany/get/1 HTTP/1.1" 500 205
[07/Oct/2023 17:12:07] ERROR [django.request:241] Internal Server Error: /api/getTaskForcesByCompany/get/1
[07/Oct/2023 17:12:07] ERROR [django.request:241] Internal Server Error: /api/getTaskForcesByCompany/get/1
[07/Oct/2023 17:12:07] ERROR [django.server:212] "GET /api/getTaskForcesByCompany/get/1 HTTP/1.1" 500 205
[07/Oct/2023 17:12:07] ERROR [django.server:212] "GET /api/getTaskForcesByCompany/get/1 HTTP/1.1" 500 205
[07/Oct/2023 17:12:09] ERROR [django.request:241] Internal Server Error: /api/getTaskForcesByCompany/get/1
[07/Oct/2023 17:12:09] ERROR [django.request:241] Internal Server Error: /api/getTaskForcesByCompany/get/1
[07/Oct/2023 17:12:09] ERROR [django.server:212] "GET /api/getTaskForcesByCompany/get/1 HTTP/1.1" 500 205
[07/Oct/2023 17:12:09] ERROR [django.server:212] "GET /api/getTaskForcesByCompany/get/1 HTTP/1.1" 500 205
[07/Oct/2023 17:12:12] ERROR [django.request:241] Internal Server Error: /api/getTaskForcesByCompany/get/1
[07/Oct/2023 17:12:12] ERROR [django.request:241] Internal Server Error: /api/getTaskForcesByCompany/get/1
[07/Oct/2023 17:12:12] ERROR [django.server:212] "GET /api/getTaskForcesByCompany/get/1 HTTP/1.1" 500 205
[07/Oct/2023 17:12:12] ERROR [django.server:212] "GET /api/getTaskForcesByCompany/get/1 HTTP/1.1" 500 205
[07/Oct/2023 17:12:31] ERROR [django.request:241] Internal Server Error: /api/getTaskForcesByCompany/get/1
[07/Oct/2023 17:12:31] ERROR [django.request:241] Internal Server Error: /api/getTaskForcesByCompany/get/1
[07/Oct/2023 17:12:31] ERROR [django.server:212] "GET /api/getTaskForcesByCompany/get/1 HTTP/1.1" 500 205
[07/Oct/2023 17:12:31] ERROR [django.server:212] "GET /api/getTaskForcesByCompany/get/1 HTTP/1.1" 500 205
[07/Oct/2023 17:12:31] ERROR [django.request:241] Internal Server Error: /api/companyEmployee/create
[07/Oct/2023 17:12:31] ERROR [django.request:241] Internal Server Error: /api/companyEmployee/create
[07/Oct/2023 17:12:31] ERROR [django.server:212] "POST /api/companyEmployee/create HTTP/1.1" 500 55
[07/Oct/2023 17:12:31] ERROR [django.server:212] "POST /api/companyEmployee/create HTTP/1.1" 500 55
[07/Oct/2023 17:12:50] ERROR [django.request:241] Internal Server Error: /api/getTaskForcesByCompany/get/1
[07/Oct/2023 17:12:50] ERROR [django.request:241] Internal Server Error: /api/getTaskForcesByCompany/get/1
[07/Oct/2023 17:12:50] ERROR [django.server:212] "GET /api/getTaskForcesByCompany/get/1 HTTP/1.1" 500 205
[07/Oct/2023 17:12:50] ERROR [django.server:212] "GET /api/getTaskForcesByCompany/get/1 HTTP/1.1" 500 205
[07/Oct/2023 17:12:50] ERROR [django.request:241] Internal Server Error: /api/companyEmployee/create
[07/Oct/2023 17:12:50] ERROR [django.request:241] Internal Server Error: /api/companyEmployee/create
[07/Oct/2023 17:12:50] ERROR [django.server:212] "POST /api/companyEmployee/create HTTP/1.1" 500 55
[07/Oct/2023 17:12:50] ERROR [django.server:212] "POST /api/companyEmployee/create HTTP/1.1" 500 55
[07/Oct/2023 17:13:51] WARNING [django.request:241] Unauthorized: /api/getTaskForcesByCompany/get/1
[07/Oct/2023 17:13:51] WARNING [django.request:241] Unauthorized: /api/getTaskForcesByCompany/get/1
[07/Oct/2023 17:13:51] WARNING [django.server:212] "GET /api/getTaskForcesByCompany/get/1 HTTP/1.1" 401 183
[07/Oct/2023 17:13:51] WARNING [django.server:212] "GET /api/getTaskForcesByCompany/get/1 HTTP/1.1" 401 183
[07/Oct/2023 17:14:04] WARNING [django.request:241] Unauthorized: /api/getTaskForcesByCompany/get/1
[07/Oct/2023 17:14:04] WARNING [django.request:241] Unauthorized: /api/getTaskForcesByCompany/get/1
[07/Oct/2023 17:14:04] WARNING [django.server:212] "GET /api/getTaskForcesByCompany/get/1 HTTP/1.1" 401 183
[07/Oct/2023 17:14:04] WARNING [django.server:212] "GET /api/getTaskForcesByCompany/get/1 HTTP/1.1" 401 183
[07/Oct/2023 17:14:04] WARNING [django.request:241] Unauthorized: /api/createTaskForces
[07/Oct/2023 17:14:04] WARNING [django.request:241] Unauthorized: /api/createTaskForces
[07/Oct/2023 17:14:04] WARNING [django.server:212] "POST /api/createTaskForces HTTP/1.1" 401 183
[07/Oct/2023 17:14:04] WARNING [django.server:212] "POST /api/createTaskForces HTTP/1.1" 401 183
[07/Oct/2023 17:14:35] ERROR [django.request:241] Internal Server Error: /api/getTaskForcesByCompany/get/1
[07/Oct/2023 17:14:35] ERROR [django.request:241] Internal Server Error: /api/getTaskForcesByCompany/get/1
[07/Oct/2023 17:14:35] ERROR [django.server:212] "GET /api/getTaskForcesByCompany/get/1 HTTP/1.1" 500 205
[07/Oct/2023 17:14:35] ERROR [django.server:212] "GET /api/getTaskForcesByCompany/get/1 HTTP/1.1" 500 205
[07/Oct/2023 17:14:45] ERROR [django.request:241] Internal Server Error: /api/getTaskForcesByCompany/get/1
[07/Oct/2023 17:14:45] ERROR [django.request:241] Internal Server Error: /api/getTaskForcesByCompany/get/1
[07/Oct/2023 17:14:45] ERROR [django.server:212] "GET /api/getTaskForcesByCompany/get/1 HTTP/1.1" 500 205
[07/Oct/2023 17:14:45] ERROR [django.server:212] "GET /api/getTaskForcesByCompany/get/1 HTTP/1.1" 500 205
[07/Oct/2023 17:14:45] WARNING [django.request:241] Bad Request: /api/createTaskForces
[07/Oct/2023 17:14:45] WARNING [django.request:241] Bad Request: /api/createTaskForces
[07/Oct/2023 17:14:45] WARNING [django.server:212] "POST /api/createTaskForces HTTP/1.1" 400 155
[07/Oct/2023 17:14:45] WARNING [django.server:212] "POST /api/createTaskForces HTTP/1.1" 400 155
[07/Oct/2023 17:15:57] WARNING [django.request:241] Unauthorized: /api/getTaskForcesByCompany/get/1
[07/Oct/2023 17:15:57] WARNING [django.request:241] Unauthorized: /api/getTaskForcesByCompany/get/1
[07/Oct/2023 17:15:57] WARNING [django.server:212] "GET /api/getTaskForcesByCompany/get/1 HTTP/1.1" 401 58
[07/Oct/2023 17:15:57] WARNING [django.server:212] "GET /api/getTaskForcesByCompany/get/1 HTTP/1.1" 401 58
[07/Oct/2023 17:16:46] ERROR [django.request:241] Internal Server Error: /api/getTaskForcesByCompany/get/1
[07/Oct/2023 17:16:46] ERROR [django.request:241] Internal Server Error: /api/getTaskForcesByCompany/get/1
[07/Oct/2023 17:16:46] ERROR [django.server:212] "GET /api/getTaskForcesByCompany/get/1 HTTP/1.1" 500 205
[07/Oct/2023 17:16:46] ERROR [django.server:212] "GET /api/getTaskForcesByCompany/get/1 HTTP/1.1" 500 205
[07/Oct/2023 17:16:49] ERROR [django.request:241] Internal Server Error: /api/getTaskForcesByCompany/get/1
[07/Oct/2023 17:16:49] ERROR [django.request:241] Internal Server Error: /api/getTaskForcesByCompany/get/1
[07/Oct/2023 17:16:49] ERROR [django.server:212] "GET /api/getTaskForcesByCompany/get/1 HTTP/1.1" 500 205
[07/Oct/2023 17:16:49] ERROR [django.server:212] "GET /api/getTaskForcesByCompany/get/1 HTTP/1.1" 500 205
[07/Oct/2023 17:18:01] WARNING [django.request:241] Bad Request: /api/createTaskForces
[07/Oct/2023 17:18:01] ERROR [django.request:241] Internal Server Error: /api/getTaskForcesByCompany/get/1
[07/Oct/2023 17:18:01] ERROR [django.request:241] Internal Server Error: /api/getTaskForcesByCompany/get/1
[07/Oct/2023 17:18:01] WARNING [django.request:241] Bad Request: /api/createTaskForces
[07/Oct/2023 17:18:01] ERROR [django.server:212] "GET /api/getTaskForcesByCompany/get/1 HTTP/1.1" 500 205
[07/Oct/2023 17:18:01] ERROR [django.server:212] "GET /api/getTaskForcesByCompany/get/1 HTTP/1.1" 500 205
[07/Oct/2023 17:18:01] WARNING [django.server:212] "POST /api/createTaskForces HTTP/1.1" 400 155
[07/Oct/2023 17:18:01] WARNING [django.server:212] "POST /api/createTaskForces HTTP/1.1" 400 155
[07/Oct/2023 17:18:19] ERROR [django.request:241] Internal Server Error: /api/getTaskForcesByCompany/get/1
[07/Oct/2023 17:18:19] ERROR [django.request:241] Internal Server Error: /api/getTaskForcesByCompany/get/1
[07/Oct/2023 17:18:19] ERROR [django.server:212] "GET /api/getTaskForcesByCompany/get/1 HTTP/1.1" 500 205
[07/Oct/2023 17:18:19] ERROR [django.server:212] "GET /api/getTaskForcesByCompany/get/1 HTTP/1.1" 500 205
[07/Oct/2023 17:18:19] WARNING [django.request:241] Bad Request: /api/createTaskForces
[07/Oct/2023 17:18:19] WARNING [django.request:241] Bad Request: /api/createTaskForces
[07/Oct/2023 17:18:19] WARNING [django.server:212] "POST /api/createTaskForces HTTP/1.1" 400 155
[07/Oct/2023 17:18:19] WARNING [django.server:212] "POST /api/createTaskForces HTTP/1.1" 400 155
[07/Oct/2023 17:19:37] ERROR [django.request:241] Internal Server Error: /api/getTaskForcesByCompany/get/1
[07/Oct/2023 17:19:37] ERROR [django.request:241] Internal Server Error: /api/getTaskForcesByCompany/get/1
[07/Oct/2023 17:19:37] ERROR [django.server:212] "GET /api/getTaskForcesByCompany/get/1 HTTP/1.1" 500 205
[07/Oct/2023 17:19:37] ERROR [django.server:212] "GET /api/getTaskForcesByCompany/get/1 HTTP/1.1" 500 205
[07/Oct/2023 17:19:37] WARNING [django.request:241] Bad Request: /api/createTaskForces
[07/Oct/2023 17:19:37] WARNING [django.request:241] Bad Request: /api/createTaskForces
[07/Oct/2023 17:19:37] WARNING [django.server:212] "POST /api/createTaskForces HTTP/1.1" 400 155
[07/Oct/2023 17:19:37] WARNING [django.server:212] "POST /api/createTaskForces HTTP/1.1" 400 155
[07/Oct/2023 17:24:14] ERROR [django.request:241] Internal Server Error: /api/getTaskForcesByCompany/get/1
[07/Oct/2023 17:24:14] ERROR [django.request:241] Internal Server Error: /api/getTaskForcesByCompany/get/1
[07/Oct/2023 17:24:14] ERROR [django.server:212] "GET /api/getTaskForcesByCompany/get/1 HTTP/1.1" 500 205
[07/Oct/2023 17:24:14] ERROR [django.server:212] "GET /api/getTaskForcesByCompany/get/1 HTTP/1.1" 500 205
[07/Oct/2023 17:25:07] ERROR [django.request:241] Internal Server Error: /api/getTaskForcesByCompany/get/1
[07/Oct/2023 17:25:07] ERROR [django.request:241] Internal Server Error: /api/getTaskForcesByCompany/get/1
[07/Oct/2023 17:25:07] ERROR [django.server:212] "GET /api/getTaskForcesByCompany/get/1 HTTP/1.1" 500 205
[07/Oct/2023 17:25:07] ERROR [django.server:212] "GET /api/getTaskForcesByCompany/get/1 HTTP/1.1" 500 205
[07/Oct/2023 17:25:41] ERROR [django.request:241] Internal Server Error: /api/getTaskForcesByCompany/get/1
[07/Oct/2023 17:25:41] ERROR [django.request:241] Internal Server Error: /api/getTaskForcesByCompany/get/1
[07/Oct/2023 17:25:41] ERROR [django.server:212] "GET /api/getTaskForcesByCompany/get/1 HTTP/1.1" 500 205
[07/Oct/2023 17:25:41] ERROR [django.server:212] "GET /api/getTaskForcesByCompany/get/1 HTTP/1.1" 500 205
[07/Oct/2023 17:25:51] ERROR [django.request:241] Internal Server Error: /api/getTaskForcesByCompany/get/1
[07/Oct/2023 17:25:51] ERROR [django.request:241] Internal Server Error: /api/getTaskForcesByCompany/get/1
[07/Oct/2023 17:25:51] ERROR [django.server:212] "GET /api/getTaskForcesByCompany/get/1 HTTP/1.1" 500 205
[07/Oct/2023 17:25:51] ERROR [django.server:212] "GET /api/getTaskForcesByCompany/get/1 HTTP/1.1" 500 205
[07/Oct/2023 17:26:07] ERROR [django.request:241] Internal Server Error: /api/getTaskForcesByCompany/get/1
[07/Oct/2023 17:26:07] ERROR [django.request:241] Internal Server Error: /api/getTaskForcesByCompany/get/1
[07/Oct/2023 17:26:07] ERROR [django.server:212] "GET /api/getTaskForcesByCompany/get/1 HTTP/1.1" 500 205
[07/Oct/2023 17:26:07] ERROR [django.server:212] "GET /api/getTaskForcesByCompany/get/1 HTTP/1.1" 500 205
[07/Oct/2023 17:26:07] WARNING [django.request:241] Bad Request: /api/createTaskForces
[07/Oct/2023 17:26:07] WARNING [django.request:241] Bad Request: /api/createTaskForces
[07/Oct/2023 17:26:07] WARNING [django.server:212] "POST /api/createTaskForces HTTP/1.1" 400 155
[07/Oct/2023 17:26:07] WARNING [django.server:212] "POST /api/createTaskForces HTTP/1.1" 400 155
[07/Oct/2023 17:27:12] ERROR [django.request:241] Internal Server Error: /api/getTaskForcesByCompany/get/1
[07/Oct/2023 17:27:12] ERROR [django.request:241] Internal Server Error: /api/getTaskForcesByCompany/get/1
[07/Oct/2023 17:27:12] ERROR [django.request:241] Internal Server Error: /api/createTaskForces
[07/Oct/2023 17:27:12] ERROR [django.server:212] "GET /api/getTaskForcesByCompany/get/1 HTTP/1.1" 500 205
[07/Oct/2023 17:27:12] ERROR [django.server:212] "GET /api/getTaskForcesByCompany/get/1 HTTP/1.1" 500 205
[07/Oct/2023 17:27:12] ERROR [django.request:241] Internal Server Error: /api/createTaskForces
[07/Oct/2023 17:27:12] ERROR [django.server:212] "POST /api/createTaskForces HTTP/1.1" 500 49
[07/Oct/2023 17:27:12] ERROR [django.server:212] "POST /api/createTaskForces HTTP/1.1" 500 49
[07/Oct/2023 17:27:28] ERROR [django.request:241] Internal Server Error: /api/getTaskForcesByCompany/get/1
[07/Oct/2023 17:27:28] ERROR [django.request:241] Internal Server Error: /api/getTaskForcesByCompany/get/1
[07/Oct/2023 17:27:28] ERROR [django.server:212] "GET /api/getTaskForcesByCompany/get/1 HTTP/1.1" 500 205
[07/Oct/2023 17:27:28] ERROR [django.server:212] "GET /api/getTaskForcesByCompany/get/1 HTTP/1.1" 500 205
[07/Oct/2023 17:27:28] ERROR [django.request:241] Internal Server Error: /api/createTaskForces
[07/Oct/2023 17:27:28] ERROR [django.request:241] Internal Server Error: /api/createTaskForces
[07/Oct/2023 17:27:28] ERROR [django.server:212] "POST /api/createTaskForces HTTP/1.1" 500 49
[07/Oct/2023 17:27:28] ERROR [django.server:212] "POST /api/createTaskForces HTTP/1.1" 500 49
[07/Oct/2023 17:27:53] WARNING [django.request:241] Bad Request: /api/createTaskForces
[07/Oct/2023 17:27:53] WARNING [django.request:241] Bad Request: /api/createTaskForces
[07/Oct/2023 17:27:53] WARNING [django.server:212] "POST /api/createTaskForces HTTP/1.1" 400 155
[07/Oct/2023 17:27:53] WARNING [django.server:212] "POST /api/createTaskForces HTTP/1.1" 400 155
[07/Oct/2023 17:49:16] WARNING [django.request:241] Unauthorized: /api/verify
[07/Oct/2023 17:49:16] WARNING [django.request:241] Unauthorized: /api/verify
[07/Oct/2023 17:49:16] WARNING [django.server:212] "POST /api/verify HTTP/1.1" 401 183
[07/Oct/2023 17:49:16] WARNING [django.server:212] "POST /api/verify HTTP/1.1" 401 183
