[23/May/2023 12:34:37] WARNING [django.request:241] Unauthorized: /api/companyEmployee/get/1
[23/May/2023 12:34:37] WARNING [django.request:241] Unauthorized: /api/companyEmployee/get/1
[23/May/2023 12:34:37] WARNING [django.server:212] "GET /api/companyEmployee/get/1 HTTP/1.1" 401 183
[23/May/2023 12:34:37] WARNING [django.server:212] "GET /api/companyEmployee/get/1 HTTP/1.1" 401 183
[23/May/2023 12:50:57] WARNING [django.request:241] Not Found: /favicon.ico
[23/May/2023 12:50:57] WARNING [django.request:241] Not Found: /favicon.ico
[23/May/2023 12:50:57] WARNING [django.server:212] "GET /favicon.ico HTTP/1.1" 404 2215
[23/May/2023 12:50:57] WARNING [django.server:212] "GET /favicon.ico HTTP/1.1" 404 2215
[23/May/2023 12:54:33] WARNING [django.request:241] Bad Request: /api/announcement/create
[23/May/2023 12:54:33] WARNING [django.request:241] Bad Request: /api/announcement/create
[23/May/2023 12:54:33] WARNING [django.server:212] "POST /api/announcement/create HTTP/1.1" 400 109
[23/May/2023 12:54:33] WARNING [django.server:212] "POST /api/announcement/create HTTP/1.1" 400 109
[23/May/2023 12:54:41] ERROR [django.request:241] Internal Server Error: /api/announcement/create
Traceback (most recent call last):
  File "/usr/local/lib/python3.10/site-packages/django/core/handlers/exception.py", line 55, in inner
    response = get_response(request)
  File "/usr/local/lib/python3.10/site-packages/django/core/handlers/base.py", line 197, in _get_response
    response = wrapped_callback(request, *callback_args, **callback_kwargs)
  File "/usr/local/lib/python3.10/site-packages/django/views/decorators/csrf.py", line 56, in wrapper_view
    return view_func(*args, **kwargs)
  File "/usr/local/lib/python3.10/site-packages/django/views/generic/base.py", line 104, in view
    return self.dispatch(request, *args, **kwargs)
  File "/usr/local/lib/python3.10/site-packages/rest_framework/views.py", line 509, in dispatch
    response = self.handle_exception(exc)
  File "/usr/local/lib/python3.10/site-packages/rest_framework/views.py", line 469, in handle_exception
    self.raise_uncaught_exception(exc)
  File "/usr/local/lib/python3.10/site-packages/rest_framework/views.py", line 480, in raise_uncaught_exception
    raise exc
  File "/usr/local/lib/python3.10/site-packages/rest_framework/views.py", line 506, in dispatch
    response = handler(request, *args, **kwargs)
  File "/usr/local/lib/python3.10/site-packages/rest_framework/decorators.py", line 50, in handler
    return func(*args, **kwargs)
  File "/app/backend/api/views.py", line 207, in postAnnouncement
    groupIds = request.data['group']
KeyError: 'group'
[23/May/2023 12:54:41] ERROR [django.request:241] Internal Server Error: /api/announcement/create
Traceback (most recent call last):
  File "/usr/local/lib/python3.10/site-packages/django/core/handlers/exception.py", line 55, in inner
    response = get_response(request)
  File "/usr/local/lib/python3.10/site-packages/django/core/handlers/base.py", line 197, in _get_response
    response = wrapped_callback(request, *callback_args, **callback_kwargs)
  File "/usr/local/lib/python3.10/site-packages/django/views/decorators/csrf.py", line 56, in wrapper_view
    return view_func(*args, **kwargs)
  File "/usr/local/lib/python3.10/site-packages/django/views/generic/base.py", line 104, in view
    return self.dispatch(request, *args, **kwargs)
  File "/usr/local/lib/python3.10/site-packages/rest_framework/views.py", line 509, in dispatch
    response = self.handle_exception(exc)
  File "/usr/local/lib/python3.10/site-packages/rest_framework/views.py", line 469, in handle_exception
    self.raise_uncaught_exception(exc)
  File "/usr/local/lib/python3.10/site-packages/rest_framework/views.py", line 480, in raise_uncaught_exception
    raise exc
  File "/usr/local/lib/python3.10/site-packages/rest_framework/views.py", line 506, in dispatch
    response = handler(request, *args, **kwargs)
  File "/usr/local/lib/python3.10/site-packages/rest_framework/decorators.py", line 50, in handler
    return func(*args, **kwargs)
  File "/app/backend/api/views.py", line 207, in postAnnouncement
    groupIds = request.data['group']
KeyError: 'group'
[23/May/2023 12:54:41] ERROR [django.server:212] "POST /api/announcement/create HTTP/1.1" 500 90132
[23/May/2023 12:54:41] ERROR [django.server:212] "POST /api/announcement/create HTTP/1.1" 500 90132
[23/May/2023 12:56:39] WARNING [django.request:241] Not Found: /api/announcement/get
[23/May/2023 12:56:39] WARNING [django.request:241] Not Found: /api/announcement/get
[23/May/2023 12:56:39] WARNING [django.server:212] "GET /api/announcement/get HTTP/1.1" 404 5555
[23/May/2023 12:56:39] WARNING [django.server:212] "GET /api/announcement/get HTTP/1.1" 404 5555
[23/May/2023 13:11:33] WARNING [django.request:241] Not Found: /api/announcement/update/1
[23/May/2023 13:11:33] WARNING [django.request:241] Not Found: /api/announcement/update/1
[23/May/2023 13:11:33] WARNING [django.server:212] "PUT /api/announcement/update/1 HTTP/1.1" 404 5570
[23/May/2023 13:11:33] WARNING [django.server:212] "PUT /api/announcement/update/1 HTTP/1.1" 404 5570
[23/May/2023 13:11:57] WARNING [django.request:241] Unauthorized: /api/announcement/update/1
[23/May/2023 13:11:57] WARNING [django.request:241] Unauthorized: /api/announcement/update/1
[23/May/2023 13:11:57] WARNING [django.server:212] "PUT /api/announcement/update/1 HTTP/1.1" 401 183
[23/May/2023 13:11:57] WARNING [django.server:212] "PUT /api/announcement/update/1 HTTP/1.1" 401 183
[23/May/2023 13:12:13] ERROR [django.request:241] Internal Server Error: /api/announcement/update/1
Traceback (most recent call last):
  File "/usr/local/lib/python3.10/site-packages/django/core/handlers/exception.py", line 55, in inner
    response = get_response(request)
  File "/usr/local/lib/python3.10/site-packages/django/core/handlers/base.py", line 197, in _get_response
    response = wrapped_callback(request, *callback_args, **callback_kwargs)
  File "/usr/local/lib/python3.10/site-packages/django/views/decorators/csrf.py", line 56, in wrapper_view
    return view_func(*args, **kwargs)
  File "/usr/local/lib/python3.10/site-packages/django/views/generic/base.py", line 104, in view
    return self.dispatch(request, *args, **kwargs)
  File "/usr/local/lib/python3.10/site-packages/rest_framework/views.py", line 509, in dispatch
    response = self.handle_exception(exc)
  File "/usr/local/lib/python3.10/site-packages/rest_framework/views.py", line 469, in handle_exception
    self.raise_uncaught_exception(exc)
  File "/usr/local/lib/python3.10/site-packages/rest_framework/views.py", line 480, in raise_uncaught_exception
    raise exc
  File "/usr/local/lib/python3.10/site-packages/rest_framework/views.py", line 506, in dispatch
    response = handler(request, *args, **kwargs)
  File "/usr/local/lib/python3.10/site-packages/rest_framework/decorators.py", line 50, in handler
    return func(*args, **kwargs)
  File "/app/backend/api/views.py", line 240, in updateAnnouncement
    for group in updatedAnnouncement['group']:
KeyError: 'group'
[23/May/2023 13:12:13] ERROR [django.request:241] Internal Server Error: /api/announcement/update/1
Traceback (most recent call last):
  File "/usr/local/lib/python3.10/site-packages/django/core/handlers/exception.py", line 55, in inner
    response = get_response(request)
  File "/usr/local/lib/python3.10/site-packages/django/core/handlers/base.py", line 197, in _get_response
    response = wrapped_callback(request, *callback_args, **callback_kwargs)
  File "/usr/local/lib/python3.10/site-packages/django/views/decorators/csrf.py", line 56, in wrapper_view
    return view_func(*args, **kwargs)
  File "/usr/local/lib/python3.10/site-packages/django/views/generic/base.py", line 104, in view
    return self.dispatch(request, *args, **kwargs)
  File "/usr/local/lib/python3.10/site-packages/rest_framework/views.py", line 509, in dispatch
    response = self.handle_exception(exc)
  File "/usr/local/lib/python3.10/site-packages/rest_framework/views.py", line 469, in handle_exception
    self.raise_uncaught_exception(exc)
  File "/usr/local/lib/python3.10/site-packages/rest_framework/views.py", line 480, in raise_uncaught_exception
    raise exc
  File "/usr/local/lib/python3.10/site-packages/rest_framework/views.py", line 506, in dispatch
    response = handler(request, *args, **kwargs)
  File "/usr/local/lib/python3.10/site-packages/rest_framework/decorators.py", line 50, in handler
    return func(*args, **kwargs)
  File "/app/backend/api/views.py", line 240, in updateAnnouncement
    for group in updatedAnnouncement['group']:
KeyError: 'group'
[23/May/2023 13:12:13] ERROR [django.server:212] "PUT /api/announcement/update/1 HTTP/1.1" 500 91042
[23/May/2023 13:12:13] ERROR [django.server:212] "PUT /api/announcement/update/1 HTTP/1.1" 500 91042
[23/May/2023 13:13:18] ERROR [django.request:241] Internal Server Error: /api/announcement/update/1
Traceback (most recent call last):
  File "/usr/local/lib/python3.10/site-packages/django/core/handlers/exception.py", line 55, in inner
    response = get_response(request)
  File "/usr/local/lib/python3.10/site-packages/django/core/handlers/base.py", line 197, in _get_response
    response = wrapped_callback(request, *callback_args, **callback_kwargs)
  File "/usr/local/lib/python3.10/site-packages/django/views/decorators/csrf.py", line 56, in wrapper_view
    return view_func(*args, **kwargs)
  File "/usr/local/lib/python3.10/site-packages/django/views/generic/base.py", line 104, in view
    return self.dispatch(request, *args, **kwargs)
  File "/usr/local/lib/python3.10/site-packages/rest_framework/views.py", line 509, in dispatch
    response = self.handle_exception(exc)
  File "/usr/local/lib/python3.10/site-packages/rest_framework/views.py", line 469, in handle_exception
    self.raise_uncaught_exception(exc)
  File "/usr/local/lib/python3.10/site-packages/rest_framework/views.py", line 480, in raise_uncaught_exception
    raise exc
  File "/usr/local/lib/python3.10/site-packages/rest_framework/views.py", line 506, in dispatch
    response = handler(request, *args, **kwargs)
  File "/usr/local/lib/python3.10/site-packages/rest_framework/decorators.py", line 50, in handler
    return func(*args, **kwargs)
  File "/app/backend/api/views.py", line 241, in updateAnnouncement
    for group in updatedAnnouncement['group']:
KeyError: 'group'
[23/May/2023 13:13:18] ERROR [django.request:241] Internal Server Error: /api/announcement/update/1
Traceback (most recent call last):
  File "/usr/local/lib/python3.10/site-packages/django/core/handlers/exception.py", line 55, in inner
    response = get_response(request)
  File "/usr/local/lib/python3.10/site-packages/django/core/handlers/base.py", line 197, in _get_response
    response = wrapped_callback(request, *callback_args, **callback_kwargs)
  File "/usr/local/lib/python3.10/site-packages/django/views/decorators/csrf.py", line 56, in wrapper_view
    return view_func(*args, **kwargs)
  File "/usr/local/lib/python3.10/site-packages/django/views/generic/base.py", line 104, in view
    return self.dispatch(request, *args, **kwargs)
  File "/usr/local/lib/python3.10/site-packages/rest_framework/views.py", line 509, in dispatch
    response = self.handle_exception(exc)
  File "/usr/local/lib/python3.10/site-packages/rest_framework/views.py", line 469, in handle_exception
    self.raise_uncaught_exception(exc)
  File "/usr/local/lib/python3.10/site-packages/rest_framework/views.py", line 480, in raise_uncaught_exception
    raise exc
  File "/usr/local/lib/python3.10/site-packages/rest_framework/views.py", line 506, in dispatch
    response = handler(request, *args, **kwargs)
  File "/usr/local/lib/python3.10/site-packages/rest_framework/decorators.py", line 50, in handler
    return func(*args, **kwargs)
  File "/app/backend/api/views.py", line 241, in updateAnnouncement
    for group in updatedAnnouncement['group']:
KeyError: 'group'
[23/May/2023 13:13:18] ERROR [django.server:212] "PUT /api/announcement/update/1 HTTP/1.1" 500 91205
[23/May/2023 13:13:18] ERROR [django.server:212] "PUT /api/announcement/update/1 HTTP/1.1" 500 91205
[23/May/2023 13:45:28] WARNING [django.request:241] Unauthorized: /api/announcement/delete/1
[23/May/2023 13:45:28] WARNING [django.request:241] Unauthorized: /api/announcement/delete/1
[23/May/2023 13:45:28] WARNING [django.server:212] "DELETE /api/announcement/delete/1 HTTP/1.1" 401 183
[23/May/2023 13:45:28] WARNING [django.server:212] "DELETE /api/announcement/delete/1 HTTP/1.1" 401 183
[23/May/2023 13:45:50] ERROR [django.request:241] Internal Server Error: /api/announcement/delete/1
Traceback (most recent call last):
  File "/usr/local/lib/python3.10/site-packages/django/core/handlers/exception.py", line 55, in inner
    response = get_response(request)
  File "/usr/local/lib/python3.10/site-packages/django/core/handlers/base.py", line 197, in _get_response
    response = wrapped_callback(request, *callback_args, **callback_kwargs)
  File "/usr/local/lib/python3.10/site-packages/django/views/decorators/csrf.py", line 56, in wrapper_view
    return view_func(*args, **kwargs)
  File "/usr/local/lib/python3.10/site-packages/django/views/generic/base.py", line 104, in view
    return self.dispatch(request, *args, **kwargs)
  File "/usr/local/lib/python3.10/site-packages/rest_framework/views.py", line 511, in dispatch
    self.response = self.finalize_response(request, response, *args, **kwargs)
  File "/usr/local/lib/python3.10/site-packages/rest_framework/views.py", line 423, in finalize_response
    assert isinstance(response, HttpResponseBase), (
AssertionError: Expected a `Response`, `HttpResponse` or `HttpStreamingResponse` to be returned from the view, but received a `<class 'NoneType'>`
[23/May/2023 13:45:50] ERROR [django.request:241] Internal Server Error: /api/announcement/delete/1
Traceback (most recent call last):
  File "/usr/local/lib/python3.10/site-packages/django/core/handlers/exception.py", line 55, in inner
    response = get_response(request)
  File "/usr/local/lib/python3.10/site-packages/django/core/handlers/base.py", line 197, in _get_response
    response = wrapped_callback(request, *callback_args, **callback_kwargs)
  File "/usr/local/lib/python3.10/site-packages/django/views/decorators/csrf.py", line 56, in wrapper_view
    return view_func(*args, **kwargs)
  File "/usr/local/lib/python3.10/site-packages/django/views/generic/base.py", line 104, in view
    return self.dispatch(request, *args, **kwargs)
  File "/usr/local/lib/python3.10/site-packages/rest_framework/views.py", line 511, in dispatch
    self.response = self.finalize_response(request, response, *args, **kwargs)
  File "/usr/local/lib/python3.10/site-packages/rest_framework/views.py", line 423, in finalize_response
    assert isinstance(response, HttpResponseBase), (
AssertionError: Expected a `Response`, `HttpResponse` or `HttpStreamingResponse` to be returned from the view, but received a `<class 'NoneType'>`
[23/May/2023 13:45:50] ERROR [django.server:212] "DELETE /api/announcement/delete/1 HTTP/1.1" 500 73690
[23/May/2023 13:45:50] ERROR [django.server:212] "DELETE /api/announcement/delete/1 HTTP/1.1" 500 73690
[23/May/2023 13:46:31] WARNING [django.request:241] Not Found: /api/announcement/delete/1
[23/May/2023 13:46:31] WARNING [django.request:241] Not Found: /api/announcement/delete/1
[23/May/2023 13:46:31] WARNING [django.server:212] "DELETE /api/announcement/delete/1 HTTP/1.1" 404 29
[23/May/2023 13:46:31] WARNING [django.server:212] "DELETE /api/announcement/delete/1 HTTP/1.1" 404 29
[23/May/2023 13:46:39] ERROR [django.request:241] Internal Server Error: /api/announcement/get/1
Traceback (most recent call last):
  File "/usr/local/lib/python3.10/site-packages/django/core/handlers/exception.py", line 55, in inner
    response = get_response(request)
  File "/usr/local/lib/python3.10/site-packages/django/core/handlers/base.py", line 197, in _get_response
    response = wrapped_callback(request, *callback_args, **callback_kwargs)
  File "/usr/local/lib/python3.10/site-packages/django/views/decorators/csrf.py", line 56, in wrapper_view
    return view_func(*args, **kwargs)
  File "/usr/local/lib/python3.10/site-packages/django/views/generic/base.py", line 104, in view
    return self.dispatch(request, *args, **kwargs)
  File "/usr/local/lib/python3.10/site-packages/rest_framework/views.py", line 509, in dispatch
    response = self.handle_exception(exc)
  File "/usr/local/lib/python3.10/site-packages/rest_framework/views.py", line 469, in handle_exception
    self.raise_uncaught_exception(exc)
  File "/usr/local/lib/python3.10/site-packages/rest_framework/views.py", line 480, in raise_uncaught_exception
    raise exc
  File "/usr/local/lib/python3.10/site-packages/rest_framework/views.py", line 506, in dispatch
    response = handler(request, *args, **kwargs)
  File "/usr/local/lib/python3.10/site-packages/rest_framework/decorators.py", line 50, in handler
    return func(*args, **kwargs)
  File "/app/backend/api/views.py", line 227, in getAnnouncement
    announcementData = models.CompanyAnnouncement.objects.get(id=pk)
  File "/usr/local/lib/python3.10/site-packages/django/db/models/manager.py", line 87, in manager_method
    return getattr(self.get_queryset(), name)(*args, **kwargs)
  File "/usr/local/lib/python3.10/site-packages/django/db/models/query.py", line 637, in get
    raise self.model.DoesNotExist(
api.models.CompanyAnnouncement.DoesNotExist: CompanyAnnouncement matching query does not exist.
[23/May/2023 13:46:39] ERROR [django.request:241] Internal Server Error: /api/announcement/get/1
Traceback (most recent call last):
  File "/usr/local/lib/python3.10/site-packages/django/core/handlers/exception.py", line 55, in inner
    response = get_response(request)
  File "/usr/local/lib/python3.10/site-packages/django/core/handlers/base.py", line 197, in _get_response
    response = wrapped_callback(request, *callback_args, **callback_kwargs)
  File "/usr/local/lib/python3.10/site-packages/django/views/decorators/csrf.py", line 56, in wrapper_view
    return view_func(*args, **kwargs)
  File "/usr/local/lib/python3.10/site-packages/django/views/generic/base.py", line 104, in view
    return self.dispatch(request, *args, **kwargs)
  File "/usr/local/lib/python3.10/site-packages/rest_framework/views.py", line 509, in dispatch
    response = self.handle_exception(exc)
  File "/usr/local/lib/python3.10/site-packages/rest_framework/views.py", line 469, in handle_exception
    self.raise_uncaught_exception(exc)
  File "/usr/local/lib/python3.10/site-packages/rest_framework/views.py", line 480, in raise_uncaught_exception
    raise exc
  File "/usr/local/lib/python3.10/site-packages/rest_framework/views.py", line 506, in dispatch
    response = handler(request, *args, **kwargs)
  File "/usr/local/lib/python3.10/site-packages/rest_framework/decorators.py", line 50, in handler
    return func(*args, **kwargs)
  File "/app/backend/api/views.py", line 227, in getAnnouncement
    announcementData = models.CompanyAnnouncement.objects.get(id=pk)
  File "/usr/local/lib/python3.10/site-packages/django/db/models/manager.py", line 87, in manager_method
    return getattr(self.get_queryset(), name)(*args, **kwargs)
  File "/usr/local/lib/python3.10/site-packages/django/db/models/query.py", line 637, in get
    raise self.model.DoesNotExist(
api.models.CompanyAnnouncement.DoesNotExist: CompanyAnnouncement matching query does not exist.
[23/May/2023 13:46:39] ERROR [django.server:212] "GET /api/announcement/get/1 HTTP/1.1" 500 98923
[23/May/2023 13:46:39] ERROR [django.server:212] "GET /api/announcement/get/1 HTTP/1.1" 500 98923
[23/May/2023 13:46:55] ERROR [django.request:241] Internal Server Error: /api/announcement/update/1
Traceback (most recent call last):
  File "/usr/local/lib/python3.10/site-packages/django/core/handlers/exception.py", line 55, in inner
    response = get_response(request)
  File "/usr/local/lib/python3.10/site-packages/django/core/handlers/base.py", line 197, in _get_response
    response = wrapped_callback(request, *callback_args, **callback_kwargs)
  File "/usr/local/lib/python3.10/site-packages/django/views/decorators/csrf.py", line 56, in wrapper_view
    return view_func(*args, **kwargs)
  File "/usr/local/lib/python3.10/site-packages/django/views/generic/base.py", line 104, in view
    return self.dispatch(request, *args, **kwargs)
  File "/usr/local/lib/python3.10/site-packages/rest_framework/views.py", line 509, in dispatch
    response = self.handle_exception(exc)
  File "/usr/local/lib/python3.10/site-packages/rest_framework/views.py", line 469, in handle_exception
    self.raise_uncaught_exception(exc)
  File "/usr/local/lib/python3.10/site-packages/rest_framework/views.py", line 480, in raise_uncaught_exception
    raise exc
  File "/usr/local/lib/python3.10/site-packages/rest_framework/views.py", line 506, in dispatch
    response = handler(request, *args, **kwargs)
  File "/usr/local/lib/python3.10/site-packages/rest_framework/decorators.py", line 50, in handler
    return func(*args, **kwargs)
  File "/app/backend/api/views.py", line 235, in updateAnnouncement
    originalAnnouncement = models.CompanyAnnouncement.objects.get(id=pk)
  File "/usr/local/lib/python3.10/site-packages/django/db/models/manager.py", line 87, in manager_method
    return getattr(self.get_queryset(), name)(*args, **kwargs)
  File "/usr/local/lib/python3.10/site-packages/django/db/models/query.py", line 637, in get
    raise self.model.DoesNotExist(
api.models.CompanyAnnouncement.DoesNotExist: CompanyAnnouncement matching query does not exist.
[23/May/2023 13:46:55] ERROR [django.request:241] Internal Server Error: /api/announcement/update/1
Traceback (most recent call last):
  File "/usr/local/lib/python3.10/site-packages/django/core/handlers/exception.py", line 55, in inner
    response = get_response(request)
  File "/usr/local/lib/python3.10/site-packages/django/core/handlers/base.py", line 197, in _get_response
    response = wrapped_callback(request, *callback_args, **callback_kwargs)
  File "/usr/local/lib/python3.10/site-packages/django/views/decorators/csrf.py", line 56, in wrapper_view
    return view_func(*args, **kwargs)
  File "/usr/local/lib/python3.10/site-packages/django/views/generic/base.py", line 104, in view
    return self.dispatch(request, *args, **kwargs)
  File "/usr/local/lib/python3.10/site-packages/rest_framework/views.py", line 509, in dispatch
    response = self.handle_exception(exc)
  File "/usr/local/lib/python3.10/site-packages/rest_framework/views.py", line 469, in handle_exception
    self.raise_uncaught_exception(exc)
  File "/usr/local/lib/python3.10/site-packages/rest_framework/views.py", line 480, in raise_uncaught_exception
    raise exc
  File "/usr/local/lib/python3.10/site-packages/rest_framework/views.py", line 506, in dispatch
    response = handler(request, *args, **kwargs)
  File "/usr/local/lib/python3.10/site-packages/rest_framework/decorators.py", line 50, in handler
    return func(*args, **kwargs)
  File "/app/backend/api/views.py", line 235, in updateAnnouncement
    originalAnnouncement = models.CompanyAnnouncement.objects.get(id=pk)
  File "/usr/local/lib/python3.10/site-packages/django/db/models/manager.py", line 87, in manager_method
    return getattr(self.get_queryset(), name)(*args, **kwargs)
  File "/usr/local/lib/python3.10/site-packages/django/db/models/query.py", line 637, in get
    raise self.model.DoesNotExist(
api.models.CompanyAnnouncement.DoesNotExist: CompanyAnnouncement matching query does not exist.
[23/May/2023 13:46:55] ERROR [django.server:212] "PUT /api/announcement/update/1 HTTP/1.1" 500 99448
[23/May/2023 13:46:55] ERROR [django.server:212] "PUT /api/announcement/update/1 HTTP/1.1" 500 99448
[23/May/2023 13:48:35] WARNING [django.request:241] Not Found: /api/announcement/update/1
[23/May/2023 13:48:35] WARNING [django.request:241] Not Found: /api/announcement/update/1
[23/May/2023 13:48:35] WARNING [django.server:212] "PUT /api/announcement/update/1 HTTP/1.1" 404 29
[23/May/2023 13:48:35] WARNING [django.server:212] "PUT /api/announcement/update/1 HTTP/1.1" 404 29
[23/May/2023 13:48:38] WARNING [django.request:241] Not Found: /api/announcement/get/1
[23/May/2023 13:48:38] WARNING [django.request:241] Not Found: /api/announcement/get/1
[23/May/2023 13:48:38] WARNING [django.server:212] "GET /api/announcement/get/1 HTTP/1.1" 404 29
[23/May/2023 13:48:38] WARNING [django.server:212] "GET /api/announcement/get/1 HTTP/1.1" 404 29
[23/May/2023 13:49:00] WARNING [django.request:241] Not Found: /api/announcement/delete/1
[23/May/2023 13:49:00] WARNING [django.request:241] Not Found: /api/announcement/delete/1
[23/May/2023 13:49:00] WARNING [django.server:212] "DELETE /api/announcement/delete/1 HTTP/1.1" 404 29
[23/May/2023 13:49:00] WARNING [django.server:212] "DELETE /api/announcement/delete/1 HTTP/1.1" 404 29
[23/May/2023 13:49:08] ERROR [django.request:241] Internal Server Error: /api/announcement/get/1
Traceback (most recent call last):
  File "/usr/local/lib/python3.10/site-packages/django/core/handlers/exception.py", line 55, in inner
    response = get_response(request)
  File "/usr/local/lib/python3.10/site-packages/django/core/handlers/base.py", line 197, in _get_response
    response = wrapped_callback(request, *callback_args, **callback_kwargs)
  File "/usr/local/lib/python3.10/site-packages/django/views/decorators/csrf.py", line 56, in wrapper_view
    return view_func(*args, **kwargs)
  File "/usr/local/lib/python3.10/site-packages/django/views/generic/base.py", line 104, in view
    return self.dispatch(request, *args, **kwargs)
  File "/usr/local/lib/python3.10/site-packages/rest_framework/views.py", line 509, in dispatch
    response = self.handle_exception(exc)
  File "/usr/local/lib/python3.10/site-packages/rest_framework/views.py", line 469, in handle_exception
    self.raise_uncaught_exception(exc)
  File "/usr/local/lib/python3.10/site-packages/rest_framework/views.py", line 480, in raise_uncaught_exception
    raise exc
  File "/usr/local/lib/python3.10/site-packages/rest_framework/views.py", line 506, in dispatch
    response = handler(request, *args, **kwargs)
  File "/usr/local/lib/python3.10/site-packages/rest_framework/decorators.py", line 50, in handler
    return func(*args, **kwargs)
  File "/app/backend/api/views.py", line 228, in getAnnouncement
    announcementData = models.CompanyAnnouncement.objects.get(id=pk)
  File "/usr/local/lib/python3.10/site-packages/django/db/models/manager.py", line 87, in manager_method
    return getattr(self.get_queryset(), name)(*args, **kwargs)
  File "/usr/local/lib/python3.10/site-packages/django/db/models/query.py", line 637, in get
    raise self.model.DoesNotExist(
api.models.CompanyAnnouncement.DoesNotExist: CompanyAnnouncement matching query does not exist.
[23/May/2023 13:49:08] ERROR [django.request:241] Internal Server Error: /api/announcement/get/1
Traceback (most recent call last):
  File "/usr/local/lib/python3.10/site-packages/django/core/handlers/exception.py", line 55, in inner
    response = get_response(request)
  File "/usr/local/lib/python3.10/site-packages/django/core/handlers/base.py", line 197, in _get_response
    response = wrapped_callback(request, *callback_args, **callback_kwargs)
  File "/usr/local/lib/python3.10/site-packages/django/views/decorators/csrf.py", line 56, in wrapper_view
    return view_func(*args, **kwargs)
  File "/usr/local/lib/python3.10/site-packages/django/views/generic/base.py", line 104, in view
    return self.dispatch(request, *args, **kwargs)
  File "/usr/local/lib/python3.10/site-packages/rest_framework/views.py", line 509, in dispatch
    response = self.handle_exception(exc)
  File "/usr/local/lib/python3.10/site-packages/rest_framework/views.py", line 469, in handle_exception
    self.raise_uncaught_exception(exc)
  File "/usr/local/lib/python3.10/site-packages/rest_framework/views.py", line 480, in raise_uncaught_exception
    raise exc
  File "/usr/local/lib/python3.10/site-packages/rest_framework/views.py", line 506, in dispatch
    response = handler(request, *args, **kwargs)
  File "/usr/local/lib/python3.10/site-packages/rest_framework/decorators.py", line 50, in handler
    return func(*args, **kwargs)
  File "/app/backend/api/views.py", line 228, in getAnnouncement
    announcementData = models.CompanyAnnouncement.objects.get(id=pk)
  File "/usr/local/lib/python3.10/site-packages/django/db/models/manager.py", line 87, in manager_method
    return getattr(self.get_queryset(), name)(*args, **kwargs)
  File "/usr/local/lib/python3.10/site-packages/django/db/models/query.py", line 637, in get
    raise self.model.DoesNotExist(
api.models.CompanyAnnouncement.DoesNotExist: CompanyAnnouncement matching query does not exist.
[23/May/2023 13:49:08] ERROR [django.server:212] "GET /api/announcement/get/1 HTTP/1.1" 500 98887
[23/May/2023 13:49:08] ERROR [django.server:212] "GET /api/announcement/get/1 HTTP/1.1" 500 98887
[23/May/2023 14:34:46] WARNING [django.request:241] Unauthorized: /api/createCompany
[23/May/2023 14:34:46] WARNING [django.request:241] Unauthorized: /api/createCompany
[23/May/2023 14:34:46] WARNING [django.server:212] "POST /api/createCompany HTTP/1.1" 401 183
[23/May/2023 14:34:46] WARNING [django.server:212] "POST /api/createCompany HTTP/1.1" 401 183
[23/May/2023 14:34:55] ERROR [django.request:241] Internal Server Error: /api/createCompany
Traceback (most recent call last):
  File "/usr/local/lib/python3.10/site-packages/django/core/handlers/exception.py", line 55, in inner
    response = get_response(request)
  File "/usr/local/lib/python3.10/site-packages/django/core/handlers/base.py", line 197, in _get_response
    response = wrapped_callback(request, *callback_args, **callback_kwargs)
  File "/usr/local/lib/python3.10/site-packages/django/views/decorators/csrf.py", line 56, in wrapper_view
    return view_func(*args, **kwargs)
  File "/usr/local/lib/python3.10/site-packages/django/views/generic/base.py", line 104, in view
    return self.dispatch(request, *args, **kwargs)
  File "/usr/local/lib/python3.10/site-packages/rest_framework/views.py", line 509, in dispatch
    response = self.handle_exception(exc)
  File "/usr/local/lib/python3.10/site-packages/rest_framework/views.py", line 469, in handle_exception
    self.raise_uncaught_exception(exc)
  File "/usr/local/lib/python3.10/site-packages/rest_framework/views.py", line 480, in raise_uncaught_exception
    raise exc
  File "/usr/local/lib/python3.10/site-packages/rest_framework/views.py", line 506, in dispatch
    response = handler(request, *args, **kwargs)
  File "/usr/local/lib/python3.10/site-packages/rest_framework/decorators.py", line 50, in handler
    return func(*args, **kwargs)
  File "/app/backend/api/views.py", line 96, in createCompany
    createdCompanyEmployeePosition = models.CompanyEmployeePosition.objects.create(
  File "/usr/local/lib/python3.10/site-packages/django/db/models/manager.py", line 87, in manager_method
    return getattr(self.get_queryset(), name)(*args, **kwargs)
  File "/usr/local/lib/python3.10/site-packages/django/db/models/query.py", line 656, in create
    obj = self.model(**kwargs)
  File "/usr/local/lib/python3.10/site-packages/django/db/models/base.py", line 564, in __init__
    _setattr(self, prop, value)
  File "/usr/local/lib/python3.10/site-packages/django/db/models/fields/related_descriptors.py", line 626, in __set__
    raise TypeError(
TypeError: Direct assignment to the forward side of a many-to-many set is prohibited. Use companyPermission_id.set() instead.
[23/May/2023 14:34:55] ERROR [django.request:241] Internal Server Error: /api/createCompany
Traceback (most recent call last):
  File "/usr/local/lib/python3.10/site-packages/django/core/handlers/exception.py", line 55, in inner
    response = get_response(request)
  File "/usr/local/lib/python3.10/site-packages/django/core/handlers/base.py", line 197, in _get_response
    response = wrapped_callback(request, *callback_args, **callback_kwargs)
  File "/usr/local/lib/python3.10/site-packages/django/views/decorators/csrf.py", line 56, in wrapper_view
    return view_func(*args, **kwargs)
  File "/usr/local/lib/python3.10/site-packages/django/views/generic/base.py", line 104, in view
    return self.dispatch(request, *args, **kwargs)
  File "/usr/local/lib/python3.10/site-packages/rest_framework/views.py", line 509, in dispatch
    response = self.handle_exception(exc)
  File "/usr/local/lib/python3.10/site-packages/rest_framework/views.py", line 469, in handle_exception
    self.raise_uncaught_exception(exc)
  File "/usr/local/lib/python3.10/site-packages/rest_framework/views.py", line 480, in raise_uncaught_exception
    raise exc
  File "/usr/local/lib/python3.10/site-packages/rest_framework/views.py", line 506, in dispatch
    response = handler(request, *args, **kwargs)
  File "/usr/local/lib/python3.10/site-packages/rest_framework/decorators.py", line 50, in handler
    return func(*args, **kwargs)
  File "/app/backend/api/views.py", line 96, in createCompany
    createdCompanyEmployeePosition = models.CompanyEmployeePosition.objects.create(
  File "/usr/local/lib/python3.10/site-packages/django/db/models/manager.py", line 87, in manager_method
    return getattr(self.get_queryset(), name)(*args, **kwargs)
  File "/usr/local/lib/python3.10/site-packages/django/db/models/query.py", line 656, in create
    obj = self.model(**kwargs)
  File "/usr/local/lib/python3.10/site-packages/django/db/models/base.py", line 564, in __init__
    _setattr(self, prop, value)
  File "/usr/local/lib/python3.10/site-packages/django/db/models/fields/related_descriptors.py", line 626, in __set__
    raise TypeError(
TypeError: Direct assignment to the forward side of a many-to-many set is prohibited. Use companyPermission_id.set() instead.
[23/May/2023 14:34:55] ERROR [django.server:212] "POST /api/createCompany HTTP/1.1" 500 112174
[23/May/2023 14:34:55] ERROR [django.server:212] "POST /api/createCompany HTTP/1.1" 500 112174
[23/May/2023 14:36:17] ERROR [django.request:241] Internal Server Error: /api/createCompany
Traceback (most recent call last):
  File "/usr/local/lib/python3.10/site-packages/django/core/handlers/exception.py", line 55, in inner
    response = get_response(request)
  File "/usr/local/lib/python3.10/site-packages/django/core/handlers/base.py", line 197, in _get_response
    response = wrapped_callback(request, *callback_args, **callback_kwargs)
  File "/usr/local/lib/python3.10/site-packages/django/views/decorators/csrf.py", line 56, in wrapper_view
    return view_func(*args, **kwargs)
  File "/usr/local/lib/python3.10/site-packages/django/views/generic/base.py", line 104, in view
    return self.dispatch(request, *args, **kwargs)
  File "/usr/local/lib/python3.10/site-packages/rest_framework/views.py", line 509, in dispatch
    response = self.handle_exception(exc)
  File "/usr/local/lib/python3.10/site-packages/rest_framework/views.py", line 469, in handle_exception
    self.raise_uncaught_exception(exc)
  File "/usr/local/lib/python3.10/site-packages/rest_framework/views.py", line 480, in raise_uncaught_exception
    raise exc
  File "/usr/local/lib/python3.10/site-packages/rest_framework/views.py", line 506, in dispatch
    response = handler(request, *args, **kwargs)
  File "/usr/local/lib/python3.10/site-packages/rest_framework/decorators.py", line 50, in handler
    return func(*args, **kwargs)
  File "/app/backend/api/views.py", line 96, in createCompany
    createdCompanyEmployeePosition = models.CompanyEmployeePosition.objects.create(
  File "/usr/local/lib/python3.10/site-packages/django/db/models/manager.py", line 87, in manager_method
    return getattr(self.get_queryset(), name)(*args, **kwargs)
  File "/usr/local/lib/python3.10/site-packages/django/db/models/query.py", line 656, in create
    obj = self.model(**kwargs)
  File "/usr/local/lib/python3.10/site-packages/django/db/models/base.py", line 564, in __init__
    _setattr(self, prop, value)
  File "/usr/local/lib/python3.10/site-packages/django/db/models/fields/related_descriptors.py", line 626, in __set__
    raise TypeError(
TypeError: Direct assignment to the forward side of a many-to-many set is prohibited. Use companyBenefits_id.set() instead.
[23/May/2023 14:36:17] ERROR [django.request:241] Internal Server Error: /api/createCompany
Traceback (most recent call last):
  File "/usr/local/lib/python3.10/site-packages/django/core/handlers/exception.py", line 55, in inner
    response = get_response(request)
  File "/usr/local/lib/python3.10/site-packages/django/core/handlers/base.py", line 197, in _get_response
    response = wrapped_callback(request, *callback_args, **callback_kwargs)
  File "/usr/local/lib/python3.10/site-packages/django/views/decorators/csrf.py", line 56, in wrapper_view
    return view_func(*args, **kwargs)
  File "/usr/local/lib/python3.10/site-packages/django/views/generic/base.py", line 104, in view
    return self.dispatch(request, *args, **kwargs)
  File "/usr/local/lib/python3.10/site-packages/rest_framework/views.py", line 509, in dispatch
    response = self.handle_exception(exc)
  File "/usr/local/lib/python3.10/site-packages/rest_framework/views.py", line 469, in handle_exception
    self.raise_uncaught_exception(exc)
  File "/usr/local/lib/python3.10/site-packages/rest_framework/views.py", line 480, in raise_uncaught_exception
    raise exc
  File "/usr/local/lib/python3.10/site-packages/rest_framework/views.py", line 506, in dispatch
    response = handler(request, *args, **kwargs)
  File "/usr/local/lib/python3.10/site-packages/rest_framework/decorators.py", line 50, in handler
    return func(*args, **kwargs)
  File "/app/backend/api/views.py", line 96, in createCompany
    createdCompanyEmployeePosition = models.CompanyEmployeePosition.objects.create(
  File "/usr/local/lib/python3.10/site-packages/django/db/models/manager.py", line 87, in manager_method
    return getattr(self.get_queryset(), name)(*args, **kwargs)
  File "/usr/local/lib/python3.10/site-packages/django/db/models/query.py", line 656, in create
    obj = self.model(**kwargs)
  File "/usr/local/lib/python3.10/site-packages/django/db/models/base.py", line 564, in __init__
    _setattr(self, prop, value)
  File "/usr/local/lib/python3.10/site-packages/django/db/models/fields/related_descriptors.py", line 626, in __set__
    raise TypeError(
TypeError: Direct assignment to the forward side of a many-to-many set is prohibited. Use companyBenefits_id.set() instead.
[23/May/2023 14:36:17] ERROR [django.server:212] "POST /api/createCompany HTTP/1.1" 500 111990
[23/May/2023 14:36:17] ERROR [django.server:212] "POST /api/createCompany HTTP/1.1" 500 111990
[23/May/2023 14:37:00] ERROR [django.request:241] Internal Server Error: /api/createCompany
Traceback (most recent call last):
  File "/usr/local/lib/python3.10/site-packages/django/core/handlers/exception.py", line 55, in inner
    response = get_response(request)
  File "/usr/local/lib/python3.10/site-packages/django/core/handlers/base.py", line 197, in _get_response
    response = wrapped_callback(request, *callback_args, **callback_kwargs)
  File "/usr/local/lib/python3.10/site-packages/django/views/decorators/csrf.py", line 56, in wrapper_view
    return view_func(*args, **kwargs)
  File "/usr/local/lib/python3.10/site-packages/django/views/generic/base.py", line 104, in view
    return self.dispatch(request, *args, **kwargs)
  File "/usr/local/lib/python3.10/site-packages/rest_framework/views.py", line 509, in dispatch
    response = self.handle_exception(exc)
  File "/usr/local/lib/python3.10/site-packages/rest_framework/views.py", line 469, in handle_exception
    self.raise_uncaught_exception(exc)
  File "/usr/local/lib/python3.10/site-packages/rest_framework/views.py", line 480, in raise_uncaught_exception
    raise exc
  File "/usr/local/lib/python3.10/site-packages/rest_framework/views.py", line 506, in dispatch
    response = handler(request, *args, **kwargs)
  File "/usr/local/lib/python3.10/site-packages/rest_framework/decorators.py", line 50, in handler
    return func(*args, **kwargs)
  File "/app/backend/api/views.py", line 102, in createCompany
    createdCompanyEmployeePosition.companyBenefits_id = createdBenefit
  File "/usr/local/lib/python3.10/site-packages/django/db/models/fields/related_descriptors.py", line 626, in __set__
    raise TypeError(
TypeError: Direct assignment to the forward side of a many-to-many set is prohibited. Use companyBenefits_id.set() instead.
[23/May/2023 14:37:00] ERROR [django.request:241] Internal Server Error: /api/createCompany
Traceback (most recent call last):
  File "/usr/local/lib/python3.10/site-packages/django/core/handlers/exception.py", line 55, in inner
    response = get_response(request)
  File "/usr/local/lib/python3.10/site-packages/django/core/handlers/base.py", line 197, in _get_response
    response = wrapped_callback(request, *callback_args, **callback_kwargs)
  File "/usr/local/lib/python3.10/site-packages/django/views/decorators/csrf.py", line 56, in wrapper_view
    return view_func(*args, **kwargs)
  File "/usr/local/lib/python3.10/site-packages/django/views/generic/base.py", line 104, in view
    return self.dispatch(request, *args, **kwargs)
  File "/usr/local/lib/python3.10/site-packages/rest_framework/views.py", line 509, in dispatch
    response = self.handle_exception(exc)
  File "/usr/local/lib/python3.10/site-packages/rest_framework/views.py", line 469, in handle_exception
    self.raise_uncaught_exception(exc)
  File "/usr/local/lib/python3.10/site-packages/rest_framework/views.py", line 480, in raise_uncaught_exception
    raise exc
  File "/usr/local/lib/python3.10/site-packages/rest_framework/views.py", line 506, in dispatch
    response = handler(request, *args, **kwargs)
  File "/usr/local/lib/python3.10/site-packages/rest_framework/decorators.py", line 50, in handler
    return func(*args, **kwargs)
  File "/app/backend/api/views.py", line 102, in createCompany
    createdCompanyEmployeePosition.companyBenefits_id = createdBenefit
  File "/usr/local/lib/python3.10/site-packages/django/db/models/fields/related_descriptors.py", line 626, in __set__
    raise TypeError(
TypeError: Direct assignment to the forward side of a many-to-many set is prohibited. Use companyBenefits_id.set() instead.
[23/May/2023 14:37:00] ERROR [django.server:212] "POST /api/createCompany HTTP/1.1" 500 97193
[23/May/2023 14:37:00] ERROR [django.server:212] "POST /api/createCompany HTTP/1.1" 500 97193
[23/May/2023 14:38:30] ERROR [django.request:241] Internal Server Error: /api/createCompany
Traceback (most recent call last):
  File "/usr/local/lib/python3.10/site-packages/django/db/models/fields/__init__.py", line 2055, in get_prep_value
    return int(value)
TypeError: int() argument must be a string, a bytes-like object or a real number, not 'UserAccount'

The above exception was the direct cause of the following exception:

Traceback (most recent call last):
  File "/usr/local/lib/python3.10/site-packages/django/core/handlers/exception.py", line 55, in inner
    response = get_response(request)
  File "/usr/local/lib/python3.10/site-packages/django/core/handlers/base.py", line 197, in _get_response
    response = wrapped_callback(request, *callback_args, **callback_kwargs)
  File "/usr/local/lib/python3.10/site-packages/django/views/decorators/csrf.py", line 56, in wrapper_view
    return view_func(*args, **kwargs)
  File "/usr/local/lib/python3.10/site-packages/django/views/generic/base.py", line 104, in view
    return self.dispatch(request, *args, **kwargs)
  File "/usr/local/lib/python3.10/site-packages/rest_framework/views.py", line 509, in dispatch
    response = self.handle_exception(exc)
  File "/usr/local/lib/python3.10/site-packages/rest_framework/views.py", line 469, in handle_exception
    self.raise_uncaught_exception(exc)
  File "/usr/local/lib/python3.10/site-packages/rest_framework/views.py", line 480, in raise_uncaught_exception
    raise exc
  File "/usr/local/lib/python3.10/site-packages/rest_framework/views.py", line 506, in dispatch
    response = handler(request, *args, **kwargs)
  File "/usr/local/lib/python3.10/site-packages/rest_framework/decorators.py", line 50, in handler
    return func(*args, **kwargs)
  File "/app/backend/api/views.py", line 108, in createCompany
    user_id = models.UserAccount.objects.get(id=createdCompany.boss_id),
  File "/usr/local/lib/python3.10/site-packages/django/db/models/manager.py", line 87, in manager_method
    return getattr(self.get_queryset(), name)(*args, **kwargs)
  File "/usr/local/lib/python3.10/site-packages/django/db/models/query.py", line 623, in get
    clone = self._chain() if self.query.combinator else self.filter(*args, **kwargs)
  File "/usr/local/lib/python3.10/site-packages/django/db/models/query.py", line 1436, in filter
    return self._filter_or_exclude(False, args, kwargs)
  File "/usr/local/lib/python3.10/site-packages/django/db/models/query.py", line 1454, in _filter_or_exclude
    clone._filter_or_exclude_inplace(negate, args, kwargs)
  File "/usr/local/lib/python3.10/site-packages/django/db/models/query.py", line 1461, in _filter_or_exclude_inplace
    self._query.add_q(Q(*args, **kwargs))
  File "/usr/local/lib/python3.10/site-packages/django/db/models/sql/query.py", line 1498, in add_q
    clause, _ = self._add_q(q_object, self.used_aliases)
  File "/usr/local/lib/python3.10/site-packages/django/db/models/sql/query.py", line 1529, in _add_q
    child_clause, needed_inner = self.build_filter(
  File "/usr/local/lib/python3.10/site-packages/django/db/models/sql/query.py", line 1444, in build_filter
    condition = self.build_lookup(lookups, col, value)
  File "/usr/local/lib/python3.10/site-packages/django/db/models/sql/query.py", line 1271, in build_lookup
    lookup = lookup_class(lhs, rhs)
  File "/usr/local/lib/python3.10/site-packages/django/db/models/lookups.py", line 27, in __init__
    self.rhs = self.get_prep_lookup()
  File "/usr/local/lib/python3.10/site-packages/django/db/models/lookups.py", line 341, in get_prep_lookup
    return super().get_prep_lookup()
  File "/usr/local/lib/python3.10/site-packages/django/db/models/lookups.py", line 85, in get_prep_lookup
    return self.lhs.output_field.get_prep_value(self.rhs)
  File "/usr/local/lib/python3.10/site-packages/django/db/models/fields/__init__.py", line 2057, in get_prep_value
    raise e.__class__(
TypeError: Field 'id' expected a number but got <UserAccount: helloworld@gmail.com>.
[23/May/2023 14:38:30] ERROR [django.request:241] Internal Server Error: /api/createCompany
Traceback (most recent call last):
  File "/usr/local/lib/python3.10/site-packages/django/db/models/fields/__init__.py", line 2055, in get_prep_value
    return int(value)
TypeError: int() argument must be a string, a bytes-like object or a real number, not 'UserAccount'

The above exception was the direct cause of the following exception:

Traceback (most recent call last):
  File "/usr/local/lib/python3.10/site-packages/django/core/handlers/exception.py", line 55, in inner
    response = get_response(request)
  File "/usr/local/lib/python3.10/site-packages/django/core/handlers/base.py", line 197, in _get_response
    response = wrapped_callback(request, *callback_args, **callback_kwargs)
  File "/usr/local/lib/python3.10/site-packages/django/views/decorators/csrf.py", line 56, in wrapper_view
    return view_func(*args, **kwargs)
  File "/usr/local/lib/python3.10/site-packages/django/views/generic/base.py", line 104, in view
    return self.dispatch(request, *args, **kwargs)
  File "/usr/local/lib/python3.10/site-packages/rest_framework/views.py", line 509, in dispatch
    response = self.handle_exception(exc)
  File "/usr/local/lib/python3.10/site-packages/rest_framework/views.py", line 469, in handle_exception
    self.raise_uncaught_exception(exc)
  File "/usr/local/lib/python3.10/site-packages/rest_framework/views.py", line 480, in raise_uncaught_exception
    raise exc
  File "/usr/local/lib/python3.10/site-packages/rest_framework/views.py", line 506, in dispatch
    response = handler(request, *args, **kwargs)
  File "/usr/local/lib/python3.10/site-packages/rest_framework/decorators.py", line 50, in handler
    return func(*args, **kwargs)
  File "/app/backend/api/views.py", line 108, in createCompany
    user_id = models.UserAccount.objects.get(id=createdCompany.boss_id),
  File "/usr/local/lib/python3.10/site-packages/django/db/models/manager.py", line 87, in manager_method
    return getattr(self.get_queryset(), name)(*args, **kwargs)
  File "/usr/local/lib/python3.10/site-packages/django/db/models/query.py", line 623, in get
    clone = self._chain() if self.query.combinator else self.filter(*args, **kwargs)
  File "/usr/local/lib/python3.10/site-packages/django/db/models/query.py", line 1436, in filter
    return self._filter_or_exclude(False, args, kwargs)
  File "/usr/local/lib/python3.10/site-packages/django/db/models/query.py", line 1454, in _filter_or_exclude
    clone._filter_or_exclude_inplace(negate, args, kwargs)
  File "/usr/local/lib/python3.10/site-packages/django/db/models/query.py", line 1461, in _filter_or_exclude_inplace
    self._query.add_q(Q(*args, **kwargs))
  File "/usr/local/lib/python3.10/site-packages/django/db/models/sql/query.py", line 1498, in add_q
    clause, _ = self._add_q(q_object, self.used_aliases)
  File "/usr/local/lib/python3.10/site-packages/django/db/models/sql/query.py", line 1529, in _add_q
    child_clause, needed_inner = self.build_filter(
  File "/usr/local/lib/python3.10/site-packages/django/db/models/sql/query.py", line 1444, in build_filter
    condition = self.build_lookup(lookups, col, value)
  File "/usr/local/lib/python3.10/site-packages/django/db/models/sql/query.py", line 1271, in build_lookup
    lookup = lookup_class(lhs, rhs)
  File "/usr/local/lib/python3.10/site-packages/django/db/models/lookups.py", line 27, in __init__
    self.rhs = self.get_prep_lookup()
  File "/usr/local/lib/python3.10/site-packages/django/db/models/lookups.py", line 341, in get_prep_lookup
    return super().get_prep_lookup()
  File "/usr/local/lib/python3.10/site-packages/django/db/models/lookups.py", line 85, in get_prep_lookup
    return self.lhs.output_field.get_prep_value(self.rhs)
  File "/usr/local/lib/python3.10/site-packages/django/db/models/fields/__init__.py", line 2057, in get_prep_value
    raise e.__class__(
TypeError: Field 'id' expected a number but got <UserAccount: helloworld@gmail.com>.
[23/May/2023 14:38:30] ERROR [django.server:212] "POST /api/createCompany HTTP/1.1" 500 159170
[23/May/2023 14:38:30] ERROR [django.server:212] "POST /api/createCompany HTTP/1.1" 500 159170
[23/May/2023 14:43:10] ERROR [django.request:241] Internal Server Error: /api/createCompany
Traceback (most recent call last):
  File "/usr/local/lib/python3.10/site-packages/django/core/handlers/exception.py", line 55, in inner
    response = get_response(request)
  File "/usr/local/lib/python3.10/site-packages/django/core/handlers/base.py", line 197, in _get_response
    response = wrapped_callback(request, *callback_args, **callback_kwargs)
  File "/usr/local/lib/python3.10/site-packages/django/views/decorators/csrf.py", line 56, in wrapper_view
    return view_func(*args, **kwargs)
  File "/usr/local/lib/python3.10/site-packages/django/views/generic/base.py", line 104, in view
    return self.dispatch(request, *args, **kwargs)
  File "/usr/local/lib/python3.10/site-packages/rest_framework/views.py", line 509, in dispatch
    response = self.handle_exception(exc)
  File "/usr/local/lib/python3.10/site-packages/rest_framework/views.py", line 469, in handle_exception
    self.raise_uncaught_exception(exc)
  File "/usr/local/lib/python3.10/site-packages/rest_framework/views.py", line 480, in raise_uncaught_exception
    raise exc
  File "/usr/local/lib/python3.10/site-packages/rest_framework/views.py", line 506, in dispatch
    response = handler(request, *args, **kwargs)
  File "/usr/local/lib/python3.10/site-packages/rest_framework/decorators.py", line 50, in handler
    return func(*args, **kwargs)
  File "/app/backend/api/views.py", line 100, in createCompany
    createdCompanyEmployeePosition = models.CompanyEmployeePosition.objects.create(
  File "/usr/local/lib/python3.10/site-packages/django/db/models/manager.py", line 87, in manager_method
    return getattr(self.get_queryset(), name)(*args, **kwargs)
  File "/usr/local/lib/python3.10/site-packages/django/db/models/query.py", line 656, in create
    obj = self.model(**kwargs)
  File "/usr/local/lib/python3.10/site-packages/django/db/models/base.py", line 564, in __init__
    _setattr(self, prop, value)
  File "/usr/local/lib/python3.10/site-packages/django/db/models/fields/related_descriptors.py", line 626, in __set__
    raise TypeError(
TypeError: Direct assignment to the forward side of a many-to-many set is prohibited. Use companyPermission_id.set() instead.
[23/May/2023 14:43:10] ERROR [django.request:241] Internal Server Error: /api/createCompany
Traceback (most recent call last):
  File "/usr/local/lib/python3.10/site-packages/django/core/handlers/exception.py", line 55, in inner
    response = get_response(request)
  File "/usr/local/lib/python3.10/site-packages/django/core/handlers/base.py", line 197, in _get_response
    response = wrapped_callback(request, *callback_args, **callback_kwargs)
  File "/usr/local/lib/python3.10/site-packages/django/views/decorators/csrf.py", line 56, in wrapper_view
    return view_func(*args, **kwargs)
  File "/usr/local/lib/python3.10/site-packages/django/views/generic/base.py", line 104, in view
    return self.dispatch(request, *args, **kwargs)
  File "/usr/local/lib/python3.10/site-packages/rest_framework/views.py", line 509, in dispatch
    response = self.handle_exception(exc)
  File "/usr/local/lib/python3.10/site-packages/rest_framework/views.py", line 469, in handle_exception
    self.raise_uncaught_exception(exc)
  File "/usr/local/lib/python3.10/site-packages/rest_framework/views.py", line 480, in raise_uncaught_exception
    raise exc
  File "/usr/local/lib/python3.10/site-packages/rest_framework/views.py", line 506, in dispatch
    response = handler(request, *args, **kwargs)
  File "/usr/local/lib/python3.10/site-packages/rest_framework/decorators.py", line 50, in handler
    return func(*args, **kwargs)
  File "/app/backend/api/views.py", line 100, in createCompany
    createdCompanyEmployeePosition = models.CompanyEmployeePosition.objects.create(
  File "/usr/local/lib/python3.10/site-packages/django/db/models/manager.py", line 87, in manager_method
    return getattr(self.get_queryset(), name)(*args, **kwargs)
  File "/usr/local/lib/python3.10/site-packages/django/db/models/query.py", line 656, in create
    obj = self.model(**kwargs)
  File "/usr/local/lib/python3.10/site-packages/django/db/models/base.py", line 564, in __init__
    _setattr(self, prop, value)
  File "/usr/local/lib/python3.10/site-packages/django/db/models/fields/related_descriptors.py", line 626, in __set__
    raise TypeError(
TypeError: Direct assignment to the forward side of a many-to-many set is prohibited. Use companyPermission_id.set() instead.
[23/May/2023 14:43:10] ERROR [django.server:212] "POST /api/createCompany HTTP/1.1" 500 112261
[23/May/2023 14:43:10] ERROR [django.server:212] "POST /api/createCompany HTTP/1.1" 500 112261
[23/May/2023 14:44:28] ERROR [django.request:241] Internal Server Error: /api/createCompany
Traceback (most recent call last):
  File "/usr/local/lib/python3.10/site-packages/django/core/handlers/exception.py", line 55, in inner
    response = get_response(request)
  File "/usr/local/lib/python3.10/site-packages/django/core/handlers/base.py", line 197, in _get_response
    response = wrapped_callback(request, *callback_args, **callback_kwargs)
  File "/usr/local/lib/python3.10/site-packages/django/views/decorators/csrf.py", line 56, in wrapper_view
    return view_func(*args, **kwargs)
  File "/usr/local/lib/python3.10/site-packages/django/views/generic/base.py", line 104, in view
    return self.dispatch(request, *args, **kwargs)
  File "/usr/local/lib/python3.10/site-packages/rest_framework/views.py", line 509, in dispatch
    response = self.handle_exception(exc)
  File "/usr/local/lib/python3.10/site-packages/rest_framework/views.py", line 469, in handle_exception
    self.raise_uncaught_exception(exc)
  File "/usr/local/lib/python3.10/site-packages/rest_framework/views.py", line 480, in raise_uncaught_exception
    raise exc
  File "/usr/local/lib/python3.10/site-packages/rest_framework/views.py", line 506, in dispatch
    response = handler(request, *args, **kwargs)
  File "/usr/local/lib/python3.10/site-packages/rest_framework/decorators.py", line 50, in handler
    return func(*args, **kwargs)
  File "/app/backend/api/views.py", line 100, in createCompany
    createdCompanyEmployeePosition = models.CompanyEmployeePosition.objects.create(
  File "/usr/local/lib/python3.10/site-packages/django/db/models/manager.py", line 87, in manager_method
    return getattr(self.get_queryset(), name)(*args, **kwargs)
  File "/usr/local/lib/python3.10/site-packages/django/db/models/query.py", line 656, in create
    obj = self.model(**kwargs)
  File "/usr/local/lib/python3.10/site-packages/django/db/models/base.py", line 564, in __init__
    _setattr(self, prop, value)
  File "/usr/local/lib/python3.10/site-packages/django/db/models/fields/related_descriptors.py", line 626, in __set__
    raise TypeError(
TypeError: Direct assignment to the forward side of a many-to-many set is prohibited. Use companyPermission_id.set() instead.
[23/May/2023 14:44:28] ERROR [django.request:241] Internal Server Error: /api/createCompany
Traceback (most recent call last):
  File "/usr/local/lib/python3.10/site-packages/django/core/handlers/exception.py", line 55, in inner
    response = get_response(request)
  File "/usr/local/lib/python3.10/site-packages/django/core/handlers/base.py", line 197, in _get_response
    response = wrapped_callback(request, *callback_args, **callback_kwargs)
  File "/usr/local/lib/python3.10/site-packages/django/views/decorators/csrf.py", line 56, in wrapper_view
    return view_func(*args, **kwargs)
  File "/usr/local/lib/python3.10/site-packages/django/views/generic/base.py", line 104, in view
    return self.dispatch(request, *args, **kwargs)
  File "/usr/local/lib/python3.10/site-packages/rest_framework/views.py", line 509, in dispatch
    response = self.handle_exception(exc)
  File "/usr/local/lib/python3.10/site-packages/rest_framework/views.py", line 469, in handle_exception
    self.raise_uncaught_exception(exc)
  File "/usr/local/lib/python3.10/site-packages/rest_framework/views.py", line 480, in raise_uncaught_exception
    raise exc
  File "/usr/local/lib/python3.10/site-packages/rest_framework/views.py", line 506, in dispatch
    response = handler(request, *args, **kwargs)
  File "/usr/local/lib/python3.10/site-packages/rest_framework/decorators.py", line 50, in handler
    return func(*args, **kwargs)
  File "/app/backend/api/views.py", line 100, in createCompany
    createdCompanyEmployeePosition = models.CompanyEmployeePosition.objects.create(
  File "/usr/local/lib/python3.10/site-packages/django/db/models/manager.py", line 87, in manager_method
    return getattr(self.get_queryset(), name)(*args, **kwargs)
  File "/usr/local/lib/python3.10/site-packages/django/db/models/query.py", line 656, in create
    obj = self.model(**kwargs)
  File "/usr/local/lib/python3.10/site-packages/django/db/models/base.py", line 564, in __init__
    _setattr(self, prop, value)
  File "/usr/local/lib/python3.10/site-packages/django/db/models/fields/related_descriptors.py", line 626, in __set__
    raise TypeError(
TypeError: Direct assignment to the forward side of a many-to-many set is prohibited. Use companyPermission_id.set() instead.
[23/May/2023 14:44:28] ERROR [django.server:212] "POST /api/createCompany HTTP/1.1" 500 112267
[23/May/2023 14:44:28] ERROR [django.server:212] "POST /api/createCompany HTTP/1.1" 500 112267
[24/May/2023 01:17:08] WARNING [django.request:241] Unauthorized: /api/createCompany
[24/May/2023 01:17:08] WARNING [django.request:241] Unauthorized: /api/createCompany
[24/May/2023 01:17:08] WARNING [django.server:212] "POST /api/createCompany HTTP/1.1" 401 183
[24/May/2023 01:17:08] WARNING [django.server:212] "POST /api/createCompany HTTP/1.1" 401 183
[24/May/2023 01:18:03] ERROR [django.request:241] Internal Server Error: /api/createCompany
Traceback (most recent call last):
  File "/app/backend/api/views.py", line 57, in createCompany
    with transaction:
AttributeError: __enter__

During handling of the above exception, another exception occurred:

Traceback (most recent call last):
  File "/usr/local/lib/python3.10/site-packages/django/core/handlers/exception.py", line 55, in inner
    response = get_response(request)
  File "/usr/local/lib/python3.10/site-packages/django/core/handlers/base.py", line 197, in _get_response
    response = wrapped_callback(request, *callback_args, **callback_kwargs)
  File "/usr/local/lib/python3.10/site-packages/django/views/decorators/csrf.py", line 56, in wrapper_view
    return view_func(*args, **kwargs)
  File "/usr/local/lib/python3.10/site-packages/django/views/generic/base.py", line 104, in view
    return self.dispatch(request, *args, **kwargs)
  File "/usr/local/lib/python3.10/site-packages/rest_framework/views.py", line 509, in dispatch
    response = self.handle_exception(exc)
  File "/usr/local/lib/python3.10/site-packages/rest_framework/views.py", line 469, in handle_exception
    self.raise_uncaught_exception(exc)
  File "/usr/local/lib/python3.10/site-packages/rest_framework/views.py", line 480, in raise_uncaught_exception
    raise exc
  File "/usr/local/lib/python3.10/site-packages/rest_framework/views.py", line 506, in dispatch
    response = handler(request, *args, **kwargs)
  File "/usr/local/lib/python3.10/site-packages/rest_framework/decorators.py", line 50, in handler
    return func(*args, **kwargs)
  File "/app/backend/api/views.py", line 159, in createCompany
    transaction.set_rollback(True)
  File "/usr/local/lib/python3.10/site-packages/django/db/transaction.py", line 97, in set_rollback
    return get_connection(using).set_rollback(rollback)
  File "/usr/local/lib/python3.10/site-packages/django/db/backends/base/base.py", line 517, in set_rollback
    raise TransactionManagementError(
django.db.transaction.TransactionManagementError: The rollback flag doesn't work outside of an 'atomic' block.
[24/May/2023 01:18:03] ERROR [django.request:241] Internal Server Error: /api/createCompany
Traceback (most recent call last):
  File "/app/backend/api/views.py", line 57, in createCompany
    with transaction:
AttributeError: __enter__

During handling of the above exception, another exception occurred:

Traceback (most recent call last):
  File "/usr/local/lib/python3.10/site-packages/django/core/handlers/exception.py", line 55, in inner
    response = get_response(request)
  File "/usr/local/lib/python3.10/site-packages/django/core/handlers/base.py", line 197, in _get_response
    response = wrapped_callback(request, *callback_args, **callback_kwargs)
  File "/usr/local/lib/python3.10/site-packages/django/views/decorators/csrf.py", line 56, in wrapper_view
    return view_func(*args, **kwargs)
  File "/usr/local/lib/python3.10/site-packages/django/views/generic/base.py", line 104, in view
    return self.dispatch(request, *args, **kwargs)
  File "/usr/local/lib/python3.10/site-packages/rest_framework/views.py", line 509, in dispatch
    response = self.handle_exception(exc)
  File "/usr/local/lib/python3.10/site-packages/rest_framework/views.py", line 469, in handle_exception
    self.raise_uncaught_exception(exc)
  File "/usr/local/lib/python3.10/site-packages/rest_framework/views.py", line 480, in raise_uncaught_exception
    raise exc
  File "/usr/local/lib/python3.10/site-packages/rest_framework/views.py", line 506, in dispatch
    response = handler(request, *args, **kwargs)
  File "/usr/local/lib/python3.10/site-packages/rest_framework/decorators.py", line 50, in handler
    return func(*args, **kwargs)
  File "/app/backend/api/views.py", line 159, in createCompany
    transaction.set_rollback(True)
  File "/usr/local/lib/python3.10/site-packages/django/db/transaction.py", line 97, in set_rollback
    return get_connection(using).set_rollback(rollback)
  File "/usr/local/lib/python3.10/site-packages/django/db/backends/base/base.py", line 517, in set_rollback
    raise TransactionManagementError(
django.db.transaction.TransactionManagementError: The rollback flag doesn't work outside of an 'atomic' block.
[24/May/2023 01:18:03] ERROR [django.server:212] "POST /api/createCompany HTTP/1.1" 500 101832
[24/May/2023 01:18:03] ERROR [django.server:212] "POST /api/createCompany HTTP/1.1" 500 101832
[24/May/2023 01:19:23] ERROR [django.request:241] Internal Server Error: /api/createCompany
Traceback (most recent call last):
  File "/app/backend/api/views.py", line 141, in createCompany
    createdCompanyEmployeePosition = models.CompanyEmployeePosition.objects.create(
  File "/usr/local/lib/python3.10/site-packages/django/db/models/manager.py", line 87, in manager_method
    return getattr(self.get_queryset(), name)(*args, **kwargs)
  File "/usr/local/lib/python3.10/site-packages/django/db/models/query.py", line 656, in create
    obj = self.model(**kwargs)
  File "/usr/local/lib/python3.10/site-packages/django/db/models/base.py", line 564, in __init__
    _setattr(self, prop, value)
  File "/usr/local/lib/python3.10/site-packages/django/db/models/fields/related_descriptors.py", line 626, in __set__
    raise TypeError(
TypeError: Direct assignment to the forward side of a many-to-many set is prohibited. Use companyPermission_id.set() instead.

During handling of the above exception, another exception occurred:

Traceback (most recent call last):
  File "/usr/local/lib/python3.10/site-packages/django/core/handlers/exception.py", line 55, in inner
    response = get_response(request)
  File "/usr/local/lib/python3.10/site-packages/django/core/handlers/base.py", line 197, in _get_response
    response = wrapped_callback(request, *callback_args, **callback_kwargs)
  File "/usr/local/lib/python3.10/site-packages/django/views/decorators/csrf.py", line 56, in wrapper_view
    return view_func(*args, **kwargs)
  File "/usr/local/lib/python3.10/site-packages/django/views/generic/base.py", line 104, in view
    return self.dispatch(request, *args, **kwargs)
  File "/usr/local/lib/python3.10/site-packages/rest_framework/views.py", line 509, in dispatch
    response = self.handle_exception(exc)
  File "/usr/local/lib/python3.10/site-packages/rest_framework/views.py", line 469, in handle_exception
    self.raise_uncaught_exception(exc)
  File "/usr/local/lib/python3.10/site-packages/rest_framework/views.py", line 480, in raise_uncaught_exception
    raise exc
  File "/usr/local/lib/python3.10/site-packages/rest_framework/views.py", line 506, in dispatch
    response = handler(request, *args, **kwargs)
  File "/usr/local/lib/python3.10/site-packages/rest_framework/decorators.py", line 50, in handler
    return func(*args, **kwargs)
  File "/app/backend/api/views.py", line 159, in createCompany
    transaction.set_rollback(True)
  File "/usr/local/lib/python3.10/site-packages/django/db/transaction.py", line 97, in set_rollback
    return get_connection(using).set_rollback(rollback)
  File "/usr/local/lib/python3.10/site-packages/django/db/backends/base/base.py", line 517, in set_rollback
    raise TransactionManagementError(
django.db.transaction.TransactionManagementError: The rollback flag doesn't work outside of an 'atomic' block.
[24/May/2023 01:19:23] ERROR [django.request:241] Internal Server Error: /api/createCompany
Traceback (most recent call last):
  File "/app/backend/api/views.py", line 141, in createCompany
    createdCompanyEmployeePosition = models.CompanyEmployeePosition.objects.create(
  File "/usr/local/lib/python3.10/site-packages/django/db/models/manager.py", line 87, in manager_method
    return getattr(self.get_queryset(), name)(*args, **kwargs)
  File "/usr/local/lib/python3.10/site-packages/django/db/models/query.py", line 656, in create
    obj = self.model(**kwargs)
  File "/usr/local/lib/python3.10/site-packages/django/db/models/base.py", line 564, in __init__
    _setattr(self, prop, value)
  File "/usr/local/lib/python3.10/site-packages/django/db/models/fields/related_descriptors.py", line 626, in __set__
    raise TypeError(
TypeError: Direct assignment to the forward side of a many-to-many set is prohibited. Use companyPermission_id.set() instead.

During handling of the above exception, another exception occurred:

Traceback (most recent call last):
  File "/usr/local/lib/python3.10/site-packages/django/core/handlers/exception.py", line 55, in inner
    response = get_response(request)
  File "/usr/local/lib/python3.10/site-packages/django/core/handlers/base.py", line 197, in _get_response
    response = wrapped_callback(request, *callback_args, **callback_kwargs)
  File "/usr/local/lib/python3.10/site-packages/django/views/decorators/csrf.py", line 56, in wrapper_view
    return view_func(*args, **kwargs)
  File "/usr/local/lib/python3.10/site-packages/django/views/generic/base.py", line 104, in view
    return self.dispatch(request, *args, **kwargs)
  File "/usr/local/lib/python3.10/site-packages/rest_framework/views.py", line 509, in dispatch
    response = self.handle_exception(exc)
  File "/usr/local/lib/python3.10/site-packages/rest_framework/views.py", line 469, in handle_exception
    self.raise_uncaught_exception(exc)
  File "/usr/local/lib/python3.10/site-packages/rest_framework/views.py", line 480, in raise_uncaught_exception
    raise exc
  File "/usr/local/lib/python3.10/site-packages/rest_framework/views.py", line 506, in dispatch
    response = handler(request, *args, **kwargs)
  File "/usr/local/lib/python3.10/site-packages/rest_framework/decorators.py", line 50, in handler
    return func(*args, **kwargs)
  File "/app/backend/api/views.py", line 159, in createCompany
    transaction.set_rollback(True)
  File "/usr/local/lib/python3.10/site-packages/django/db/transaction.py", line 97, in set_rollback
    return get_connection(using).set_rollback(rollback)
  File "/usr/local/lib/python3.10/site-packages/django/db/backends/base/base.py", line 517, in set_rollback
    raise TransactionManagementError(
django.db.transaction.TransactionManagementError: The rollback flag doesn't work outside of an 'atomic' block.
[24/May/2023 01:19:23] ERROR [django.server:212] "POST /api/createCompany HTTP/1.1" 500 126529
[24/May/2023 01:19:23] ERROR [django.server:212] "POST /api/createCompany HTTP/1.1" 500 126529
[24/May/2023 09:14:02] WARNING [django.request:241] Unauthorized: /api/companyEmployee/create
[24/May/2023 09:14:02] WARNING [django.request:241] Unauthorized: /api/companyEmployee/create
[24/May/2023 09:14:02] WARNING [django.server:212] "POST /api/companyEmployee/create HTTP/1.1" 401 183
[24/May/2023 09:14:02] WARNING [django.server:212] "POST /api/companyEmployee/create HTTP/1.1" 401 183
[24/May/2023 09:44:18] WARNING [django.request:241] Unauthorized: /api/companyEmployee/update/5
[24/May/2023 09:44:18] WARNING [django.request:241] Unauthorized: /api/companyEmployee/update/5
[24/May/2023 09:44:18] WARNING [django.server:212] "PUT /api/companyEmployee/update/5 HTTP/1.1" 401 183
[24/May/2023 09:44:18] WARNING [django.server:212] "PUT /api/companyEmployee/update/5 HTTP/1.1" 401 183
[24/May/2023 09:59:23] WARNING [django.request:241] Not Found: /api/companyEmployee/delete/5
[24/May/2023 09:59:23] WARNING [django.request:241] Not Found: /api/companyEmployee/delete/5
[24/May/2023 09:59:23] WARNING [django.server:212] "DELETE /api/companyEmployee/delete/5 HTTP/1.1" 404 53
[24/May/2023 09:59:23] WARNING [django.server:212] "DELETE /api/companyEmployee/delete/5 HTTP/1.1" 404 53
[24/May/2023 13:25:12] ERROR [django.security.DisallowedHost:124] Invalid HTTP_HOST header: '220.141.67.139:8000'. You may need to add '220.141.67.139' to ALLOWED_HOSTS.
Traceback (most recent call last):
  File "/usr/local/lib/python3.10/site-packages/django/core/handlers/exception.py", line 55, in inner
    response = get_response(request)
  File "/usr/local/lib/python3.10/site-packages/django/utils/deprecation.py", line 133, in __call__
    response = self.process_request(request)
  File "/usr/local/lib/python3.10/site-packages/django/middleware/common.py", line 48, in process_request
    host = request.get_host()
  File "/usr/local/lib/python3.10/site-packages/django/http/request.py", line 167, in get_host
    raise DisallowedHost(msg)
django.core.exceptions.DisallowedHost: Invalid HTTP_HOST header: '220.141.67.139:8000'. You may need to add '220.141.67.139' to ALLOWED_HOSTS.
[24/May/2023 13:25:12] ERROR [django.security.DisallowedHost:124] Invalid HTTP_HOST header: '220.141.67.139:8000'. You may need to add '220.141.67.139' to ALLOWED_HOSTS.
Traceback (most recent call last):
  File "/usr/local/lib/python3.10/site-packages/django/core/handlers/exception.py", line 55, in inner
    response = get_response(request)
  File "/usr/local/lib/python3.10/site-packages/django/utils/deprecation.py", line 133, in __call__
    response = self.process_request(request)
  File "/usr/local/lib/python3.10/site-packages/django/middleware/common.py", line 48, in process_request
    host = request.get_host()
  File "/usr/local/lib/python3.10/site-packages/django/http/request.py", line 167, in get_host
    raise DisallowedHost(msg)
django.core.exceptions.DisallowedHost: Invalid HTTP_HOST header: '220.141.67.139:8000'. You may need to add '220.141.67.139' to ALLOWED_HOSTS.
[24/May/2023 13:25:12] WARNING [django.request:241] Bad Request: /
[24/May/2023 13:25:12] WARNING [django.request:241] Bad Request: /
[24/May/2023 13:25:12] WARNING [django.server:212] "GET / HTTP/1.1" 400 63190
[24/May/2023 13:25:12] WARNING [django.server:212] "GET / HTTP/1.1" 400 63190
[24/May/2023 13:25:13] ERROR [django.server:192] You're accessing the development server over HTTPS, but it only supports HTTP.
[24/May/2023 13:25:13] ERROR [django.server:192] You're accessing the development server over HTTPS, but it only supports HTTP.
[24/May/2023 13:37:53] ERROR [django.security.DisallowedHost:124] Invalid HTTP_HOST header: '220.141.67.139:8000'. You may need to add '220.141.67.139' to ALLOWED_HOSTS.
Traceback (most recent call last):
  File "/usr/local/lib/python3.10/site-packages/django/core/handlers/exception.py", line 55, in inner
    response = get_response(request)
  File "/usr/local/lib/python3.10/site-packages/django/utils/deprecation.py", line 133, in __call__
    response = self.process_request(request)
  File "/usr/local/lib/python3.10/site-packages/django/middleware/common.py", line 48, in process_request
    host = request.get_host()
  File "/usr/local/lib/python3.10/site-packages/django/http/request.py", line 167, in get_host
    raise DisallowedHost(msg)
django.core.exceptions.DisallowedHost: Invalid HTTP_HOST header: '220.141.67.139:8000'. You may need to add '220.141.67.139' to ALLOWED_HOSTS.
[24/May/2023 13:37:53] ERROR [django.security.DisallowedHost:124] Invalid HTTP_HOST header: '220.141.67.139:8000'. You may need to add '220.141.67.139' to ALLOWED_HOSTS.
Traceback (most recent call last):
  File "/usr/local/lib/python3.10/site-packages/django/core/handlers/exception.py", line 55, in inner
    response = get_response(request)
  File "/usr/local/lib/python3.10/site-packages/django/utils/deprecation.py", line 133, in __call__
    response = self.process_request(request)
  File "/usr/local/lib/python3.10/site-packages/django/middleware/common.py", line 48, in process_request
    host = request.get_host()
  File "/usr/local/lib/python3.10/site-packages/django/http/request.py", line 167, in get_host
    raise DisallowedHost(msg)
django.core.exceptions.DisallowedHost: Invalid HTTP_HOST header: '220.141.67.139:8000'. You may need to add '220.141.67.139' to ALLOWED_HOSTS.
[24/May/2023 13:37:53] WARNING [django.request:241] Bad Request: /
[24/May/2023 13:37:53] WARNING [django.request:241] Bad Request: /
[24/May/2023 13:37:53] WARNING [django.server:212] "GET / HTTP/1.1" 400 62543
[24/May/2023 13:37:53] WARNING [django.server:212] "GET / HTTP/1.1" 400 62543
[24/May/2023 13:37:54] ERROR [django.security.DisallowedHost:124] Invalid HTTP_HOST header: '220.141.67.139:8000'. You may need to add '220.141.67.139' to ALLOWED_HOSTS.
Traceback (most recent call last):
  File "/usr/local/lib/python3.10/site-packages/django/core/handlers/exception.py", line 55, in inner
    response = get_response(request)
  File "/usr/local/lib/python3.10/site-packages/django/utils/deprecation.py", line 133, in __call__
    response = self.process_request(request)
  File "/usr/local/lib/python3.10/site-packages/django/middleware/common.py", line 48, in process_request
    host = request.get_host()
  File "/usr/local/lib/python3.10/site-packages/django/http/request.py", line 167, in get_host
    raise DisallowedHost(msg)
django.core.exceptions.DisallowedHost: Invalid HTTP_HOST header: '220.141.67.139:8000'. You may need to add '220.141.67.139' to ALLOWED_HOSTS.
[24/May/2023 13:37:54] ERROR [django.security.DisallowedHost:124] Invalid HTTP_HOST header: '220.141.67.139:8000'. You may need to add '220.141.67.139' to ALLOWED_HOSTS.
Traceback (most recent call last):
  File "/usr/local/lib/python3.10/site-packages/django/core/handlers/exception.py", line 55, in inner
    response = get_response(request)
  File "/usr/local/lib/python3.10/site-packages/django/utils/deprecation.py", line 133, in __call__
    response = self.process_request(request)
  File "/usr/local/lib/python3.10/site-packages/django/middleware/common.py", line 48, in process_request
    host = request.get_host()
  File "/usr/local/lib/python3.10/site-packages/django/http/request.py", line 167, in get_host
    raise DisallowedHost(msg)
django.core.exceptions.DisallowedHost: Invalid HTTP_HOST header: '220.141.67.139:8000'. You may need to add '220.141.67.139' to ALLOWED_HOSTS.
[24/May/2023 13:37:54] WARNING [django.request:241] Bad Request: /
[24/May/2023 13:37:54] WARNING [django.request:241] Bad Request: /
[24/May/2023 13:37:54] WARNING [django.server:212] "GET / HTTP/1.1" 400 63074
[24/May/2023 13:37:54] WARNING [django.server:212] "GET / HTTP/1.1" 400 63074
[24/May/2023 13:37:55] ERROR [django.server:212] "PRI * HTTP/2.0" 505 -
[24/May/2023 13:37:55] ERROR [django.server:212] "PRI * HTTP/2.0" 505 -
[24/May/2023 13:44:57] WARNING [django.server:212] "Z¥     " 400 -
[24/May/2023 13:44:57] WARNING [django.server:212] "Z¥     " 400 -
[25/May/2023 11:24:21] WARNING [django.request:241] Not Found: /favicon.ico
[25/May/2023 11:24:21] WARNING [django.request:241] Not Found: /favicon.ico
[25/May/2023 11:24:21] WARNING [django.server:212] "GET /favicon.ico HTTP/1.1" 404 2215
[25/May/2023 11:24:21] WARNING [django.server:212] "GET /favicon.ico HTTP/1.1" 404 2215
[25/May/2023 11:28:34] ERROR [django.server:192] You're accessing the development server over HTTPS, but it only supports HTTP.
[25/May/2023 11:28:34] ERROR [django.server:192] You're accessing the development server over HTTPS, but it only supports HTTP.
[25/May/2023 11:28:57] ERROR [django.request:241] Internal Server Error: /api/resume/create
Traceback (most recent call last):
  File "/usr/local/lib/python3.10/site-packages/django/core/handlers/exception.py", line 55, in inner
    response = get_response(request)
  File "/usr/local/lib/python3.10/site-packages/django/core/handlers/base.py", line 197, in _get_response
    response = wrapped_callback(request, *callback_args, **callback_kwargs)
  File "/usr/local/lib/python3.10/site-packages/django/views/decorators/csrf.py", line 56, in wrapper_view
    return view_func(*args, **kwargs)
  File "/usr/local/lib/python3.10/site-packages/django/views/generic/base.py", line 104, in view
    return self.dispatch(request, *args, **kwargs)
  File "/usr/local/lib/python3.10/site-packages/rest_framework/views.py", line 509, in dispatch
    response = self.handle_exception(exc)
  File "/usr/local/lib/python3.10/site-packages/rest_framework/views.py", line 469, in handle_exception
    self.raise_uncaught_exception(exc)
  File "/usr/local/lib/python3.10/site-packages/rest_framework/views.py", line 480, in raise_uncaught_exception
    raise exc
  File "/usr/local/lib/python3.10/site-packages/rest_framework/views.py", line 506, in dispatch
    response = handler(request, *args, **kwargs)
  File "/usr/local/lib/python3.10/site-packages/rest_framework/decorators.py", line 50, in handler
    return func(*args, **kwargs)
TypeError: createResume() missing 1 required positional argument: 'pk'
[25/May/2023 11:28:57] ERROR [django.request:241] Internal Server Error: /api/resume/create
Traceback (most recent call last):
  File "/usr/local/lib/python3.10/site-packages/django/core/handlers/exception.py", line 55, in inner
    response = get_response(request)
  File "/usr/local/lib/python3.10/site-packages/django/core/handlers/base.py", line 197, in _get_response
    response = wrapped_callback(request, *callback_args, **callback_kwargs)
  File "/usr/local/lib/python3.10/site-packages/django/views/decorators/csrf.py", line 56, in wrapper_view
    return view_func(*args, **kwargs)
  File "/usr/local/lib/python3.10/site-packages/django/views/generic/base.py", line 104, in view
    return self.dispatch(request, *args, **kwargs)
  File "/usr/local/lib/python3.10/site-packages/rest_framework/views.py", line 509, in dispatch
    response = self.handle_exception(exc)
  File "/usr/local/lib/python3.10/site-packages/rest_framework/views.py", line 469, in handle_exception
    self.raise_uncaught_exception(exc)
  File "/usr/local/lib/python3.10/site-packages/rest_framework/views.py", line 480, in raise_uncaught_exception
    raise exc
  File "/usr/local/lib/python3.10/site-packages/rest_framework/views.py", line 506, in dispatch
    response = handler(request, *args, **kwargs)
  File "/usr/local/lib/python3.10/site-packages/rest_framework/decorators.py", line 50, in handler
    return func(*args, **kwargs)
TypeError: createResume() missing 1 required positional argument: 'pk'
[25/May/2023 11:28:57] ERROR [django.server:212] "POST /api/resume/create HTTP/1.1" 500 86471
[25/May/2023 11:28:57] ERROR [django.server:212] "POST /api/resume/create HTTP/1.1" 500 86471
[25/May/2023 11:29:53] ERROR [django.request:241] Internal Server Error: /api/resume/create
Traceback (most recent call last):
  File "/app/backend/api/views.py", line 163, in createResume
    user = models.UserAccount.objects.get(id=createdResume['user']),
UnboundLocalError: local variable 'createdResume' referenced before assignment

During handling of the above exception, another exception occurred:

Traceback (most recent call last):
  File "/usr/local/lib/python3.10/site-packages/django/http/response.py", line 134, in __init__
    self.status_code = int(status)
TypeError: int() argument must be a string, a bytes-like object or a real number, not 'UnboundLocalError'

During handling of the above exception, another exception occurred:

Traceback (most recent call last):
  File "/usr/local/lib/python3.10/site-packages/django/core/handlers/exception.py", line 55, in inner
    response = get_response(request)
  File "/usr/local/lib/python3.10/site-packages/django/core/handlers/base.py", line 197, in _get_response
    response = wrapped_callback(request, *callback_args, **callback_kwargs)
  File "/usr/local/lib/python3.10/site-packages/django/views/decorators/csrf.py", line 56, in wrapper_view
    return view_func(*args, **kwargs)
  File "/usr/local/lib/python3.10/site-packages/django/views/generic/base.py", line 104, in view
    return self.dispatch(request, *args, **kwargs)
  File "/usr/local/lib/python3.10/site-packages/rest_framework/views.py", line 509, in dispatch
    response = self.handle_exception(exc)
  File "/usr/local/lib/python3.10/site-packages/rest_framework/views.py", line 469, in handle_exception
    self.raise_uncaught_exception(exc)
  File "/usr/local/lib/python3.10/site-packages/rest_framework/views.py", line 480, in raise_uncaught_exception
    raise exc
  File "/usr/local/lib/python3.10/site-packages/rest_framework/views.py", line 506, in dispatch
    response = handler(request, *args, **kwargs)
  File "/usr/local/lib/python3.10/site-packages/rest_framework/decorators.py", line 50, in handler
    return func(*args, **kwargs)
  File "/app/backend/api/views.py", line 177, in createResume
    return Response({'message':'履歷建立失敗 , 請稍後再嘗試'}, e)
  File "/usr/local/lib/python3.10/site-packages/rest_framework/response.py", line 30, in __init__
    super().__init__(None, status=status)
  File "/usr/local/lib/python3.10/site-packages/django/template/response.py", line 46, in __init__
    super().__init__("", content_type, status, charset=charset, headers=headers)
  File "/usr/local/lib/python3.10/site-packages/django/http/response.py", line 384, in __init__
    super().__init__(*args, **kwargs)
  File "/usr/local/lib/python3.10/site-packages/django/http/response.py", line 136, in __init__
    raise TypeError("HTTP status code must be an integer.")
TypeError: HTTP status code must be an integer.
[25/May/2023 11:29:53] ERROR [django.request:241] Internal Server Error: /api/resume/create
Traceback (most recent call last):
  File "/app/backend/api/views.py", line 163, in createResume
    user = models.UserAccount.objects.get(id=createdResume['user']),
UnboundLocalError: local variable 'createdResume' referenced before assignment

During handling of the above exception, another exception occurred:

Traceback (most recent call last):
  File "/usr/local/lib/python3.10/site-packages/django/http/response.py", line 134, in __init__
    self.status_code = int(status)
TypeError: int() argument must be a string, a bytes-like object or a real number, not 'UnboundLocalError'

During handling of the above exception, another exception occurred:

Traceback (most recent call last):
  File "/usr/local/lib/python3.10/site-packages/django/core/handlers/exception.py", line 55, in inner
    response = get_response(request)
  File "/usr/local/lib/python3.10/site-packages/django/core/handlers/base.py", line 197, in _get_response
    response = wrapped_callback(request, *callback_args, **callback_kwargs)
  File "/usr/local/lib/python3.10/site-packages/django/views/decorators/csrf.py", line 56, in wrapper_view
    return view_func(*args, **kwargs)
  File "/usr/local/lib/python3.10/site-packages/django/views/generic/base.py", line 104, in view
    return self.dispatch(request, *args, **kwargs)
  File "/usr/local/lib/python3.10/site-packages/rest_framework/views.py", line 509, in dispatch
    response = self.handle_exception(exc)
  File "/usr/local/lib/python3.10/site-packages/rest_framework/views.py", line 469, in handle_exception
    self.raise_uncaught_exception(exc)
  File "/usr/local/lib/python3.10/site-packages/rest_framework/views.py", line 480, in raise_uncaught_exception
    raise exc
  File "/usr/local/lib/python3.10/site-packages/rest_framework/views.py", line 506, in dispatch
    response = handler(request, *args, **kwargs)
  File "/usr/local/lib/python3.10/site-packages/rest_framework/decorators.py", line 50, in handler
    return func(*args, **kwargs)
  File "/app/backend/api/views.py", line 177, in createResume
    return Response({'message':'履歷建立失敗 , 請稍後再嘗試'}, e)
  File "/usr/local/lib/python3.10/site-packages/rest_framework/response.py", line 30, in __init__
    super().__init__(None, status=status)
  File "/usr/local/lib/python3.10/site-packages/django/template/response.py", line 46, in __init__
    super().__init__("", content_type, status, charset=charset, headers=headers)
  File "/usr/local/lib/python3.10/site-packages/django/http/response.py", line 384, in __init__
    super().__init__(*args, **kwargs)
  File "/usr/local/lib/python3.10/site-packages/django/http/response.py", line 136, in __init__
    raise TypeError("HTTP status code must be an integer.")
TypeError: HTTP status code must be an integer.
[25/May/2023 11:29:53] ERROR [django.server:212] "POST /api/resume/create HTTP/1.1" 500 120002
[25/May/2023 11:29:53] ERROR [django.server:212] "POST /api/resume/create HTTP/1.1" 500 120002
[25/May/2023 11:31:15] ERROR [django.request:241] Internal Server Error: /api/resume/create
Traceback (most recent call last):
  File "/usr/local/lib/python3.10/site-packages/django/core/handlers/exception.py", line 55, in inner
    response = get_response(request)
  File "/usr/local/lib/python3.10/site-packages/django/core/handlers/base.py", line 220, in _get_response
    response = response.render()
  File "/usr/local/lib/python3.10/site-packages/django/template/response.py", line 111, in render
    self.content = self.rendered_content
  File "/usr/local/lib/python3.10/site-packages/rest_framework/response.py", line 70, in rendered_content
    ret = renderer.render(self.data, accepted_media_type, context)
  File "/usr/local/lib/python3.10/site-packages/rest_framework/renderers.py", line 99, in render
    ret = json.dumps(
  File "/usr/local/lib/python3.10/site-packages/rest_framework/utils/json.py", line 25, in dumps
    return json.dumps(*args, **kwargs)
  File "/usr/local/lib/python3.10/json/__init__.py", line 238, in dumps
    **kw).encode(obj)
  File "/usr/local/lib/python3.10/json/encoder.py", line 199, in encode
    chunks = self.iterencode(o, _one_shot=True)
  File "/usr/local/lib/python3.10/json/encoder.py", line 257, in iterencode
    return _iterencode(o, 0)
  File "/usr/local/lib/python3.10/site-packages/rest_framework/utils/encoders.py", line 67, in default
    return super().default(obj)
  File "/usr/local/lib/python3.10/json/encoder.py", line 179, in default
    raise TypeError(f'Object of type {o.__class__.__name__} '
TypeError: Object of type UnboundLocalError is not JSON serializable
[25/May/2023 11:31:15] ERROR [django.request:241] Internal Server Error: /api/resume/create
Traceback (most recent call last):
  File "/usr/local/lib/python3.10/site-packages/django/core/handlers/exception.py", line 55, in inner
    response = get_response(request)
  File "/usr/local/lib/python3.10/site-packages/django/core/handlers/base.py", line 220, in _get_response
    response = response.render()
  File "/usr/local/lib/python3.10/site-packages/django/template/response.py", line 111, in render
    self.content = self.rendered_content
  File "/usr/local/lib/python3.10/site-packages/rest_framework/response.py", line 70, in rendered_content
    ret = renderer.render(self.data, accepted_media_type, context)
  File "/usr/local/lib/python3.10/site-packages/rest_framework/renderers.py", line 99, in render
    ret = json.dumps(
  File "/usr/local/lib/python3.10/site-packages/rest_framework/utils/json.py", line 25, in dumps
    return json.dumps(*args, **kwargs)
  File "/usr/local/lib/python3.10/json/__init__.py", line 238, in dumps
    **kw).encode(obj)
  File "/usr/local/lib/python3.10/json/encoder.py", line 199, in encode
    chunks = self.iterencode(o, _one_shot=True)
  File "/usr/local/lib/python3.10/json/encoder.py", line 257, in iterencode
    return _iterencode(o, 0)
  File "/usr/local/lib/python3.10/site-packages/rest_framework/utils/encoders.py", line 67, in default
    return super().default(obj)
  File "/usr/local/lib/python3.10/json/encoder.py", line 179, in default
    raise TypeError(f'Object of type {o.__class__.__name__} '
TypeError: Object of type UnboundLocalError is not JSON serializable
[25/May/2023 11:31:15] ERROR [django.server:212] "POST /api/resume/create HTTP/1.1" 500 95409
[25/May/2023 11:31:15] ERROR [django.server:212] "POST /api/resume/create HTTP/1.1" 500 95409
[25/May/2023 11:36:41] WARNING [django.request:241] Method Not Allowed: /api/resume/update/5
[25/May/2023 11:36:41] WARNING [django.request:241] Method Not Allowed: /api/resume/update/5
[25/May/2023 11:36:41] WARNING [django.server:212] "POST /api/resume/update/5 HTTP/1.1" 405 41
[25/May/2023 11:36:41] WARNING [django.server:212] "POST /api/resume/update/5 HTTP/1.1" 405 41
[25/May/2023 11:38:02] WARNING [django.request:241] Method Not Allowed: /api/resume/get/5
[25/May/2023 11:38:02] WARNING [django.request:241] Method Not Allowed: /api/resume/get/5
[25/May/2023 11:38:02] WARNING [django.server:212] "DELETE /api/resume/get/5 HTTP/1.1" 405 43
[25/May/2023 11:38:02] WARNING [django.server:212] "DELETE /api/resume/get/5 HTTP/1.1" 405 43
[25/May/2023 11:38:11] WARNING [django.request:241] Not Found: /api/resume/delete/5
[25/May/2023 11:38:11] WARNING [django.request:241] Not Found: /api/resume/delete/5
[25/May/2023 11:38:11] WARNING [django.server:212] "DELETE /api/resume/delete/5 HTTP/1.1" 404 7804
[25/May/2023 11:38:11] WARNING [django.server:212] "DELETE /api/resume/delete/5 HTTP/1.1" 404 7804
[25/May/2023 13:40:35] WARNING [django.request:241] Unauthorized: /api/companyEmployee/create/multiple
[25/May/2023 13:40:35] WARNING [django.request:241] Unauthorized: /api/companyEmployee/create/multiple
[25/May/2023 13:40:35] WARNING [django.server:212] "POST /api/companyEmployee/create/multiple HTTP/1.1" 401 183
[25/May/2023 13:40:35] WARNING [django.server:212] "POST /api/companyEmployee/create/multiple HTTP/1.1" 401 183
[25/May/2023 13:42:26] ERROR [django.request:241] Internal Server Error: /api/companyEmployee/create/multiple
Traceback (most recent call last):
  File "/usr/local/lib/python3.10/site-packages/django/core/handlers/exception.py", line 55, in inner
    response = get_response(request)
  File "/usr/local/lib/python3.10/site-packages/django/core/handlers/base.py", line 220, in _get_response
    response = response.render()
  File "/usr/local/lib/python3.10/site-packages/django/template/response.py", line 111, in render
    self.content = self.rendered_content
  File "/usr/local/lib/python3.10/site-packages/rest_framework/response.py", line 70, in rendered_content
    ret = renderer.render(self.data, accepted_media_type, context)
  File "/usr/local/lib/python3.10/site-packages/rest_framework/renderers.py", line 99, in render
    ret = json.dumps(
  File "/usr/local/lib/python3.10/site-packages/rest_framework/utils/json.py", line 25, in dumps
    return json.dumps(*args, **kwargs)
  File "/usr/local/lib/python3.10/json/__init__.py", line 238, in dumps
    **kw).encode(obj)
  File "/usr/local/lib/python3.10/json/encoder.py", line 199, in encode
    chunks = self.iterencode(o, _one_shot=True)
  File "/usr/local/lib/python3.10/json/encoder.py", line 257, in iterencode
    return _iterencode(o, 0)
  File "/usr/local/lib/python3.10/site-packages/rest_framework/utils/encoders.py", line 67, in default
    return super().default(obj)
  File "/usr/local/lib/python3.10/json/encoder.py", line 179, in default
    raise TypeError(f'Object of type {o.__class__.__name__} '
TypeError: Object of type CompanyEmployee is not JSON serializable
[25/May/2023 13:42:26] ERROR [django.request:241] Internal Server Error: /api/companyEmployee/create/multiple
Traceback (most recent call last):
  File "/usr/local/lib/python3.10/site-packages/django/core/handlers/exception.py", line 55, in inner
    response = get_response(request)
  File "/usr/local/lib/python3.10/site-packages/django/core/handlers/base.py", line 220, in _get_response
    response = response.render()
  File "/usr/local/lib/python3.10/site-packages/django/template/response.py", line 111, in render
    self.content = self.rendered_content
  File "/usr/local/lib/python3.10/site-packages/rest_framework/response.py", line 70, in rendered_content
    ret = renderer.render(self.data, accepted_media_type, context)
  File "/usr/local/lib/python3.10/site-packages/rest_framework/renderers.py", line 99, in render
    ret = json.dumps(
  File "/usr/local/lib/python3.10/site-packages/rest_framework/utils/json.py", line 25, in dumps
    return json.dumps(*args, **kwargs)
  File "/usr/local/lib/python3.10/json/__init__.py", line 238, in dumps
    **kw).encode(obj)
  File "/usr/local/lib/python3.10/json/encoder.py", line 199, in encode
    chunks = self.iterencode(o, _one_shot=True)
  File "/usr/local/lib/python3.10/json/encoder.py", line 257, in iterencode
    return _iterencode(o, 0)
  File "/usr/local/lib/python3.10/site-packages/rest_framework/utils/encoders.py", line 67, in default
    return super().default(obj)
  File "/usr/local/lib/python3.10/json/encoder.py", line 179, in default
    raise TypeError(f'Object of type {o.__class__.__name__} '
TypeError: Object of type CompanyEmployee is not JSON serializable
[25/May/2023 13:42:26] ERROR [django.server:212] "POST /api/companyEmployee/create/multiple HTTP/1.1" 500 95918
[25/May/2023 13:42:26] ERROR [django.server:212] "POST /api/companyEmployee/create/multiple HTTP/1.1" 500 95918
[25/May/2023 13:43:21] ERROR [django.request:241] Internal Server Error: /api/companyEmployee/create/multiple
Traceback (most recent call last):
  File "/usr/local/lib/python3.10/site-packages/django/core/handlers/exception.py", line 55, in inner
    response = get_response(request)
  File "/usr/local/lib/python3.10/site-packages/django/core/handlers/base.py", line 220, in _get_response
    response = response.render()
  File "/usr/local/lib/python3.10/site-packages/django/template/response.py", line 111, in render
    self.content = self.rendered_content
  File "/usr/local/lib/python3.10/site-packages/rest_framework/response.py", line 70, in rendered_content
    ret = renderer.render(self.data, accepted_media_type, context)
  File "/usr/local/lib/python3.10/site-packages/rest_framework/renderers.py", line 99, in render
    ret = json.dumps(
  File "/usr/local/lib/python3.10/site-packages/rest_framework/utils/json.py", line 25, in dumps
    return json.dumps(*args, **kwargs)
  File "/usr/local/lib/python3.10/json/__init__.py", line 238, in dumps
    **kw).encode(obj)
  File "/usr/local/lib/python3.10/json/encoder.py", line 199, in encode
    chunks = self.iterencode(o, _one_shot=True)
  File "/usr/local/lib/python3.10/json/encoder.py", line 257, in iterencode
    return _iterencode(o, 0)
  File "/usr/local/lib/python3.10/site-packages/rest_framework/utils/encoders.py", line 67, in default
    return super().default(obj)
  File "/usr/local/lib/python3.10/json/encoder.py", line 179, in default
    raise TypeError(f'Object of type {o.__class__.__name__} '
TypeError: Object of type CompanyEmployeeSerializer is not JSON serializable
[25/May/2023 13:43:21] ERROR [django.request:241] Internal Server Error: /api/companyEmployee/create/multiple
Traceback (most recent call last):
  File "/usr/local/lib/python3.10/site-packages/django/core/handlers/exception.py", line 55, in inner
    response = get_response(request)
  File "/usr/local/lib/python3.10/site-packages/django/core/handlers/base.py", line 220, in _get_response
    response = response.render()
  File "/usr/local/lib/python3.10/site-packages/django/template/response.py", line 111, in render
    self.content = self.rendered_content
  File "/usr/local/lib/python3.10/site-packages/rest_framework/response.py", line 70, in rendered_content
    ret = renderer.render(self.data, accepted_media_type, context)
  File "/usr/local/lib/python3.10/site-packages/rest_framework/renderers.py", line 99, in render
    ret = json.dumps(
  File "/usr/local/lib/python3.10/site-packages/rest_framework/utils/json.py", line 25, in dumps
    return json.dumps(*args, **kwargs)
  File "/usr/local/lib/python3.10/json/__init__.py", line 238, in dumps
    **kw).encode(obj)
  File "/usr/local/lib/python3.10/json/encoder.py", line 199, in encode
    chunks = self.iterencode(o, _one_shot=True)
  File "/usr/local/lib/python3.10/json/encoder.py", line 257, in iterencode
    return _iterencode(o, 0)
  File "/usr/local/lib/python3.10/site-packages/rest_framework/utils/encoders.py", line 67, in default
    return super().default(obj)
  File "/usr/local/lib/python3.10/json/encoder.py", line 179, in default
    raise TypeError(f'Object of type {o.__class__.__name__} '
TypeError: Object of type CompanyEmployeeSerializer is not JSON serializable
[25/May/2023 13:43:21] ERROR [django.server:212] "POST /api/companyEmployee/create/multiple HTTP/1.1" 500 123412
[25/May/2023 13:43:21] ERROR [django.server:212] "POST /api/companyEmployee/create/multiple HTTP/1.1" 500 123412
[25/May/2023 14:18:09] WARNING [django.request:241] Unauthorized: /api/companyEmployee/fire/18
[25/May/2023 14:18:09] WARNING [django.request:241] Unauthorized: /api/companyEmployee/fire/18
[25/May/2023 14:18:09] WARNING [django.server:212] "PUT /api/companyEmployee/fire/18 HTTP/1.1" 401 183
[25/May/2023 14:18:09] WARNING [django.server:212] "PUT /api/companyEmployee/fire/18 HTTP/1.1" 401 183
[25/May/2023 14:51:00] WARNING [django.request:241] Unauthorized: /api/companyDepartment/get
[25/May/2023 14:51:00] WARNING [django.request:241] Unauthorized: /api/companyDepartment/get
[25/May/2023 14:51:00] WARNING [django.server:212] "GET /api/companyDepartment/get HTTP/1.1" 401 183
[25/May/2023 14:51:00] WARNING [django.server:212] "GET /api/companyDepartment/get HTTP/1.1" 401 183
[25/May/2023 14:51:14] ERROR [django.request:241] Internal Server Error: /api/companyDepartment/get
Traceback (most recent call last):
  File "/usr/local/lib/python3.10/site-packages/django/core/handlers/exception.py", line 55, in inner
    response = get_response(request)
  File "/usr/local/lib/python3.10/site-packages/django/core/handlers/base.py", line 197, in _get_response
    response = wrapped_callback(request, *callback_args, **callback_kwargs)
  File "/usr/local/lib/python3.10/site-packages/django/views/decorators/csrf.py", line 56, in wrapper_view
    return view_func(*args, **kwargs)
  File "/usr/local/lib/python3.10/site-packages/django/views/generic/base.py", line 104, in view
    return self.dispatch(request, *args, **kwargs)
  File "/usr/local/lib/python3.10/site-packages/rest_framework/views.py", line 509, in dispatch
    response = self.handle_exception(exc)
  File "/usr/local/lib/python3.10/site-packages/rest_framework/views.py", line 469, in handle_exception
    self.raise_uncaught_exception(exc)
  File "/usr/local/lib/python3.10/site-packages/rest_framework/views.py", line 480, in raise_uncaught_exception
    raise exc
  File "/usr/local/lib/python3.10/site-packages/rest_framework/views.py", line 506, in dispatch
    response = handler(request, *args, **kwargs)
  File "/usr/local/lib/python3.10/site-packages/rest_framework/decorators.py", line 50, in handler
    return func(*args, **kwargs)
TypeError: getDepartment() missing 1 required positional argument: 'pk'
[25/May/2023 14:51:14] ERROR [django.request:241] Internal Server Error: /api/companyDepartment/get
Traceback (most recent call last):
  File "/usr/local/lib/python3.10/site-packages/django/core/handlers/exception.py", line 55, in inner
    response = get_response(request)
  File "/usr/local/lib/python3.10/site-packages/django/core/handlers/base.py", line 197, in _get_response
    response = wrapped_callback(request, *callback_args, **callback_kwargs)
  File "/usr/local/lib/python3.10/site-packages/django/views/decorators/csrf.py", line 56, in wrapper_view
    return view_func(*args, **kwargs)
  File "/usr/local/lib/python3.10/site-packages/django/views/generic/base.py", line 104, in view
    return self.dispatch(request, *args, **kwargs)
  File "/usr/local/lib/python3.10/site-packages/rest_framework/views.py", line 509, in dispatch
    response = self.handle_exception(exc)
  File "/usr/local/lib/python3.10/site-packages/rest_framework/views.py", line 469, in handle_exception
    self.raise_uncaught_exception(exc)
  File "/usr/local/lib/python3.10/site-packages/rest_framework/views.py", line 480, in raise_uncaught_exception
    raise exc
  File "/usr/local/lib/python3.10/site-packages/rest_framework/views.py", line 506, in dispatch
    response = handler(request, *args, **kwargs)
  File "/usr/local/lib/python3.10/site-packages/rest_framework/decorators.py", line 50, in handler
    return func(*args, **kwargs)
TypeError: getDepartment() missing 1 required positional argument: 'pk'
[25/May/2023 14:51:14] ERROR [django.server:212] "GET /api/companyDepartment/get HTTP/1.1" 500 86586
[25/May/2023 14:51:14] ERROR [django.server:212] "GET /api/companyDepartment/get HTTP/1.1" 500 86586
[26/May/2023 03:09:25] WARNING [django.server:212] "Z¥     " 400 -
[26/May/2023 03:09:25] WARNING [django.server:212] "Z¥     " 400 -
[26/May/2023 03:57:55] WARNING [django.server:212] "   TZ         .    I¨À )z» zÚf Ò~Uñi»©                ÃÐ¢|¦v½óOÑËÜ®Ëd" 400 -
[26/May/2023 03:57:55] WARNING [django.server:212] "   TZ         .    I¨À )z» zÚf Ò~Uñi»©                ÃÐ¢|¦v½óOÑËÜ®Ëd" 400 -
[26/May/2023 06:24:10] ERROR [django.security.DisallowedHost:124] Invalid HTTP_HOST header: '220.141.68.251:8000'. You may need to add '220.141.68.251' to ALLOWED_HOSTS.
Traceback (most recent call last):
  File "/usr/local/lib/python3.10/site-packages/django/core/handlers/exception.py", line 55, in inner
    response = get_response(request)
  File "/usr/local/lib/python3.10/site-packages/django/utils/deprecation.py", line 133, in __call__
    response = self.process_request(request)
  File "/usr/local/lib/python3.10/site-packages/django/middleware/common.py", line 48, in process_request
    host = request.get_host()
  File "/usr/local/lib/python3.10/site-packages/django/http/request.py", line 167, in get_host
    raise DisallowedHost(msg)
django.core.exceptions.DisallowedHost: Invalid HTTP_HOST header: '220.141.68.251:8000'. You may need to add '220.141.68.251' to ALLOWED_HOSTS.
[26/May/2023 06:24:10] ERROR [django.security.DisallowedHost:124] Invalid HTTP_HOST header: '220.141.68.251:8000'. You may need to add '220.141.68.251' to ALLOWED_HOSTS.
Traceback (most recent call last):
  File "/usr/local/lib/python3.10/site-packages/django/core/handlers/exception.py", line 55, in inner
    response = get_response(request)
  File "/usr/local/lib/python3.10/site-packages/django/utils/deprecation.py", line 133, in __call__
    response = self.process_request(request)
  File "/usr/local/lib/python3.10/site-packages/django/middleware/common.py", line 48, in process_request
    host = request.get_host()
  File "/usr/local/lib/python3.10/site-packages/django/http/request.py", line 167, in get_host
    raise DisallowedHost(msg)
django.core.exceptions.DisallowedHost: Invalid HTTP_HOST header: '220.141.68.251:8000'. You may need to add '220.141.68.251' to ALLOWED_HOSTS.
[26/May/2023 06:24:11] WARNING [django.request:241] Bad Request: /
[26/May/2023 06:24:11] WARNING [django.request:241] Bad Request: /
[26/May/2023 06:24:11] WARNING [django.server:212] "GET / HTTP/1.1" 400 62543
[26/May/2023 06:24:11] WARNING [django.server:212] "GET / HTTP/1.1" 400 62543
[26/May/2023 06:24:11] ERROR [django.security.DisallowedHost:124] Invalid HTTP_HOST header: '220.141.68.251:8000'. You may need to add '220.141.68.251' to ALLOWED_HOSTS.
Traceback (most recent call last):
  File "/usr/local/lib/python3.10/site-packages/django/core/handlers/exception.py", line 55, in inner
    response = get_response(request)
  File "/usr/local/lib/python3.10/site-packages/django/utils/deprecation.py", line 133, in __call__
    response = self.process_request(request)
  File "/usr/local/lib/python3.10/site-packages/django/middleware/common.py", line 48, in process_request
    host = request.get_host()
  File "/usr/local/lib/python3.10/site-packages/django/http/request.py", line 167, in get_host
    raise DisallowedHost(msg)
django.core.exceptions.DisallowedHost: Invalid HTTP_HOST header: '220.141.68.251:8000'. You may need to add '220.141.68.251' to ALLOWED_HOSTS.
[26/May/2023 06:24:11] ERROR [django.security.DisallowedHost:124] Invalid HTTP_HOST header: '220.141.68.251:8000'. You may need to add '220.141.68.251' to ALLOWED_HOSTS.
Traceback (most recent call last):
  File "/usr/local/lib/python3.10/site-packages/django/core/handlers/exception.py", line 55, in inner
    response = get_response(request)
  File "/usr/local/lib/python3.10/site-packages/django/utils/deprecation.py", line 133, in __call__
    response = self.process_request(request)
  File "/usr/local/lib/python3.10/site-packages/django/middleware/common.py", line 48, in process_request
    host = request.get_host()
  File "/usr/local/lib/python3.10/site-packages/django/http/request.py", line 167, in get_host
    raise DisallowedHost(msg)
django.core.exceptions.DisallowedHost: Invalid HTTP_HOST header: '220.141.68.251:8000'. You may need to add '220.141.68.251' to ALLOWED_HOSTS.
[26/May/2023 06:24:12] WARNING [django.request:241] Bad Request: /
[26/May/2023 06:24:12] WARNING [django.request:241] Bad Request: /
[26/May/2023 06:24:12] WARNING [django.server:212] "GET / HTTP/1.1" 400 63074
[26/May/2023 06:24:12] WARNING [django.server:212] "GET / HTTP/1.1" 400 63074
[26/May/2023 06:24:12] ERROR [django.server:212] "PRI * HTTP/2.0" 505 -
[26/May/2023 06:24:12] ERROR [django.server:212] "PRI * HTTP/2.0" 505 -
[26/May/2023 06:58:39] ERROR [django.server:192] You're accessing the development server over HTTPS, but it only supports HTTP.
[26/May/2023 06:58:39] ERROR [django.server:192] You're accessing the development server over HTTPS, but it only supports HTTP.
[26/May/2023 07:24:59] WARNING [django.server:212] "  à          " 400 -
[26/May/2023 07:24:59] WARNING [django.server:212] "  à          " 400 -
[26/May/2023 07:26:53] ERROR [django.security.DisallowedHost:124] Invalid HTTP_HOST header: '220.141.68.251:8000'. You may need to add '220.141.68.251' to ALLOWED_HOSTS.
Traceback (most recent call last):
  File "/usr/local/lib/python3.10/site-packages/django/core/handlers/exception.py", line 55, in inner
    response = get_response(request)
  File "/usr/local/lib/python3.10/site-packages/django/utils/deprecation.py", line 133, in __call__
    response = self.process_request(request)
  File "/usr/local/lib/python3.10/site-packages/django/middleware/common.py", line 48, in process_request
    host = request.get_host()
  File "/usr/local/lib/python3.10/site-packages/django/http/request.py", line 167, in get_host
    raise DisallowedHost(msg)
django.core.exceptions.DisallowedHost: Invalid HTTP_HOST header: '220.141.68.251:8000'. You may need to add '220.141.68.251' to ALLOWED_HOSTS.
[26/May/2023 07:26:53] ERROR [django.security.DisallowedHost:124] Invalid HTTP_HOST header: '220.141.68.251:8000'. You may need to add '220.141.68.251' to ALLOWED_HOSTS.
Traceback (most recent call last):
  File "/usr/local/lib/python3.10/site-packages/django/core/handlers/exception.py", line 55, in inner
    response = get_response(request)
  File "/usr/local/lib/python3.10/site-packages/django/utils/deprecation.py", line 133, in __call__
    response = self.process_request(request)
  File "/usr/local/lib/python3.10/site-packages/django/middleware/common.py", line 48, in process_request
    host = request.get_host()
  File "/usr/local/lib/python3.10/site-packages/django/http/request.py", line 167, in get_host
    raise DisallowedHost(msg)
django.core.exceptions.DisallowedHost: Invalid HTTP_HOST header: '220.141.68.251:8000'. You may need to add '220.141.68.251' to ALLOWED_HOSTS.
[26/May/2023 07:26:54] WARNING [django.request:241] Bad Request: /
[26/May/2023 07:26:54] WARNING [django.request:241] Bad Request: /
[26/May/2023 07:26:54] WARNING [django.server:212] "GET / HTTP/1.1" 400 63310
[26/May/2023 07:26:54] WARNING [django.server:212] "GET / HTTP/1.1" 400 63310
[26/May/2023 08:13:09] WARNING [django.server:212] "SSH-2.0-OpenSSH" 400 -
[26/May/2023 08:13:09] WARNING [django.server:212] "SSH-2.0-OpenSSH" 400 -
[26/May/2023 13:44:52] ERROR [django.server:192] You're accessing the development server over HTTPS, but it only supports HTTP.
[26/May/2023 13:44:52] ERROR [django.server:192] You're accessing the development server over HTTPS, but it only supports HTTP.
[26/May/2023 13:44:52] ERROR [django.server:192] You're accessing the development server over HTTPS, but it only supports HTTP.
[26/May/2023 13:44:52] ERROR [django.server:192] You're accessing the development server over HTTPS, but it only supports HTTP.
[26/May/2023 13:44:52] ERROR [django.security.DisallowedHost:124] Invalid HTTP_HOST header: '220.141.72.96:8000'. You may need to add '220.141.72.96' to ALLOWED_HOSTS.
Traceback (most recent call last):
  File "/usr/local/lib/python3.10/site-packages/django/core/handlers/exception.py", line 55, in inner
    response = get_response(request)
  File "/usr/local/lib/python3.10/site-packages/django/utils/deprecation.py", line 133, in __call__
    response = self.process_request(request)
  File "/usr/local/lib/python3.10/site-packages/django/middleware/common.py", line 48, in process_request
    host = request.get_host()
  File "/usr/local/lib/python3.10/site-packages/django/http/request.py", line 167, in get_host
    raise DisallowedHost(msg)
django.core.exceptions.DisallowedHost: Invalid HTTP_HOST header: '220.141.72.96:8000'. You may need to add '220.141.72.96' to ALLOWED_HOSTS.
[26/May/2023 13:44:52] ERROR [django.security.DisallowedHost:124] Invalid HTTP_HOST header: '220.141.72.96:8000'. You may need to add '220.141.72.96' to ALLOWED_HOSTS.
Traceback (most recent call last):
  File "/usr/local/lib/python3.10/site-packages/django/core/handlers/exception.py", line 55, in inner
    response = get_response(request)
  File "/usr/local/lib/python3.10/site-packages/django/utils/deprecation.py", line 133, in __call__
    response = self.process_request(request)
  File "/usr/local/lib/python3.10/site-packages/django/middleware/common.py", line 48, in process_request
    host = request.get_host()
  File "/usr/local/lib/python3.10/site-packages/django/http/request.py", line 167, in get_host
    raise DisallowedHost(msg)
django.core.exceptions.DisallowedHost: Invalid HTTP_HOST header: '220.141.72.96:8000'. You may need to add '220.141.72.96' to ALLOWED_HOSTS.
[26/May/2023 13:44:52] WARNING [django.request:241] Bad Request: /
[26/May/2023 13:44:52] WARNING [django.request:241] Bad Request: /
[26/May/2023 13:44:52] WARNING [django.server:212] "GET / HTTP/1.1" 400 63173
[26/May/2023 13:44:52] WARNING [django.server:212] "GET / HTTP/1.1" 400 63173
[26/May/2023 13:44:52] ERROR [django.server:192] You're accessing the development server over HTTPS, but it only supports HTTP.
[26/May/2023 13:44:52] ERROR [django.server:192] You're accessing the development server over HTTPS, but it only supports HTTP.
[26/May/2023 13:44:52] ERROR [django.security.DisallowedHost:124] Invalid HTTP_HOST header: '220.141.72.96:8000'. You may need to add '220.141.72.96' to ALLOWED_HOSTS.
Traceback (most recent call last):
  File "/usr/local/lib/python3.10/site-packages/django/core/handlers/exception.py", line 55, in inner
    response = get_response(request)
  File "/usr/local/lib/python3.10/site-packages/django/utils/deprecation.py", line 133, in __call__
    response = self.process_request(request)
  File "/usr/local/lib/python3.10/site-packages/django/middleware/common.py", line 48, in process_request
    host = request.get_host()
  File "/usr/local/lib/python3.10/site-packages/django/http/request.py", line 167, in get_host
    raise DisallowedHost(msg)
django.core.exceptions.DisallowedHost: Invalid HTTP_HOST header: '220.141.72.96:8000'. You may need to add '220.141.72.96' to ALLOWED_HOSTS.
[26/May/2023 13:44:52] ERROR [django.security.DisallowedHost:124] Invalid HTTP_HOST header: '220.141.72.96:8000'. You may need to add '220.141.72.96' to ALLOWED_HOSTS.
Traceback (most recent call last):
  File "/usr/local/lib/python3.10/site-packages/django/core/handlers/exception.py", line 55, in inner
    response = get_response(request)
  File "/usr/local/lib/python3.10/site-packages/django/utils/deprecation.py", line 133, in __call__
    response = self.process_request(request)
  File "/usr/local/lib/python3.10/site-packages/django/middleware/common.py", line 48, in process_request
    host = request.get_host()
  File "/usr/local/lib/python3.10/site-packages/django/http/request.py", line 167, in get_host
    raise DisallowedHost(msg)
django.core.exceptions.DisallowedHost: Invalid HTTP_HOST header: '220.141.72.96:8000'. You may need to add '220.141.72.96' to ALLOWED_HOSTS.
[26/May/2023 13:44:52] WARNING [django.request:241] Bad Request: /api/islogged
[26/May/2023 13:44:52] WARNING [django.request:241] Bad Request: /api/islogged
[26/May/2023 13:44:52] WARNING [django.server:212] "GET /api/islogged HTTP/1.1" 400 63305
[26/May/2023 13:44:52] WARNING [django.server:212] "GET /api/islogged HTTP/1.1" 400 63305
[26/May/2023 14:06:54] ERROR [django.security.DisallowedHost:124] Invalid HTTP_HOST header: '220.141.72.96:8000'. You may need to add '220.141.72.96' to ALLOWED_HOSTS.
Traceback (most recent call last):
  File "/usr/local/lib/python3.10/site-packages/django/core/handlers/exception.py", line 55, in inner
    response = get_response(request)
  File "/usr/local/lib/python3.10/site-packages/django/utils/deprecation.py", line 133, in __call__
    response = self.process_request(request)
  File "/usr/local/lib/python3.10/site-packages/django/middleware/common.py", line 48, in process_request
    host = request.get_host()
  File "/usr/local/lib/python3.10/site-packages/django/http/request.py", line 167, in get_host
    raise DisallowedHost(msg)
django.core.exceptions.DisallowedHost: Invalid HTTP_HOST header: '220.141.72.96:8000'. You may need to add '220.141.72.96' to ALLOWED_HOSTS.
[26/May/2023 14:06:54] ERROR [django.security.DisallowedHost:124] Invalid HTTP_HOST header: '220.141.72.96:8000'. You may need to add '220.141.72.96' to ALLOWED_HOSTS.
Traceback (most recent call last):
  File "/usr/local/lib/python3.10/site-packages/django/core/handlers/exception.py", line 55, in inner
    response = get_response(request)
  File "/usr/local/lib/python3.10/site-packages/django/utils/deprecation.py", line 133, in __call__
    response = self.process_request(request)
  File "/usr/local/lib/python3.10/site-packages/django/middleware/common.py", line 48, in process_request
    host = request.get_host()
  File "/usr/local/lib/python3.10/site-packages/django/http/request.py", line 167, in get_host
    raise DisallowedHost(msg)
django.core.exceptions.DisallowedHost: Invalid HTTP_HOST header: '220.141.72.96:8000'. You may need to add '220.141.72.96' to ALLOWED_HOSTS.
[26/May/2023 14:06:54] WARNING [django.request:241] Bad Request: /
[26/May/2023 14:06:54] WARNING [django.request:241] Bad Request: /
[26/May/2023 14:06:54] WARNING [django.server:212] "GET / HTTP/1.1" 400 63199
[26/May/2023 14:06:54] WARNING [django.server:212] "GET / HTTP/1.1" 400 63199
[26/May/2023 14:25:01] WARNING [django.request:241] Unauthorized: /api/companyDepartment/get/16
[26/May/2023 14:25:01] WARNING [django.request:241] Unauthorized: /api/companyDepartment/get/16
[26/May/2023 14:25:01] WARNING [django.server:212] "GET /api/companyDepartment/get/16 HTTP/1.1" 401 183
[26/May/2023 14:25:01] WARNING [django.server:212] "GET /api/companyDepartment/get/16 HTTP/1.1" 401 183
[26/May/2023 14:25:09] ERROR [django.request:241] Internal Server Error: /api/companyDepartment/get/16
[26/May/2023 14:25:09] ERROR [django.request:241] Internal Server Error: /api/companyDepartment/get/16
[26/May/2023 14:25:09] ERROR [django.server:212] "GET /api/companyDepartment/get/16 HTTP/1.1" 500 234
[26/May/2023 14:25:09] ERROR [django.server:212] "GET /api/companyDepartment/get/16 HTTP/1.1" 500 234
[26/May/2023 14:26:32] ERROR [django.request:241] Internal Server Error: /api/companyDepartment/create
[26/May/2023 14:26:32] ERROR [django.request:241] Internal Server Error: /api/companyDepartment/create
[26/May/2023 14:26:32] ERROR [django.server:212] "POST /api/companyDepartment/create HTTP/1.1" 500 79
[26/May/2023 14:26:32] ERROR [django.server:212] "POST /api/companyDepartment/create HTTP/1.1" 500 79
[26/May/2023 14:31:03] ERROR [django.request:241] Internal Server Error: /api/companyDepartment/delete/17
Traceback (most recent call last):
  File "/usr/local/lib/python3.10/site-packages/django/core/handlers/exception.py", line 55, in inner
    response = get_response(request)
  File "/usr/local/lib/python3.10/site-packages/django/core/handlers/base.py", line 197, in _get_response
    response = wrapped_callback(request, *callback_args, **callback_kwargs)
  File "/usr/local/lib/python3.10/site-packages/django/views/decorators/csrf.py", line 56, in wrapper_view
    return view_func(*args, **kwargs)
  File "/usr/local/lib/python3.10/site-packages/django/views/generic/base.py", line 104, in view
    return self.dispatch(request, *args, **kwargs)
  File "/usr/local/lib/python3.10/site-packages/rest_framework/views.py", line 511, in dispatch
    self.response = self.finalize_response(request, response, *args, **kwargs)
  File "/usr/local/lib/python3.10/site-packages/rest_framework/views.py", line 423, in finalize_response
    assert isinstance(response, HttpResponseBase), (
AssertionError: Expected a `Response`, `HttpResponse` or `HttpStreamingResponse` to be returned from the view, but received a `<class 'NoneType'>`
[26/May/2023 14:31:03] ERROR [django.request:241] Internal Server Error: /api/companyDepartment/delete/17
Traceback (most recent call last):
  File "/usr/local/lib/python3.10/site-packages/django/core/handlers/exception.py", line 55, in inner
    response = get_response(request)
  File "/usr/local/lib/python3.10/site-packages/django/core/handlers/base.py", line 197, in _get_response
    response = wrapped_callback(request, *callback_args, **callback_kwargs)
  File "/usr/local/lib/python3.10/site-packages/django/views/decorators/csrf.py", line 56, in wrapper_view
    return view_func(*args, **kwargs)
  File "/usr/local/lib/python3.10/site-packages/django/views/generic/base.py", line 104, in view
    return self.dispatch(request, *args, **kwargs)
  File "/usr/local/lib/python3.10/site-packages/rest_framework/views.py", line 511, in dispatch
    self.response = self.finalize_response(request, response, *args, **kwargs)
  File "/usr/local/lib/python3.10/site-packages/rest_framework/views.py", line 423, in finalize_response
    assert isinstance(response, HttpResponseBase), (
AssertionError: Expected a `Response`, `HttpResponse` or `HttpStreamingResponse` to be returned from the view, but received a `<class 'NoneType'>`
[26/May/2023 14:31:03] ERROR [django.server:212] "DELETE /api/companyDepartment/delete/17 HTTP/1.1" 500 73763
[26/May/2023 14:31:03] ERROR [django.server:212] "DELETE /api/companyDepartment/delete/17 HTTP/1.1" 500 73763
[26/May/2023 14:35:05] WARNING [django.request:241] Not Found: /api/companyDepartment/delete/17
[26/May/2023 14:35:05] WARNING [django.request:241] Not Found: /api/companyDepartment/delete/17
[26/May/2023 14:35:05] WARNING [django.server:212] "DELETE /api/companyDepartment/delete/17 HTTP/1.1" 404 29
[26/May/2023 14:35:05] WARNING [django.server:212] "DELETE /api/companyDepartment/delete/17 HTTP/1.1" 404 29
[26/May/2023 14:35:12] WARNING [django.request:241] Not Found: /api/companyDepartment/get/17
[26/May/2023 14:35:12] WARNING [django.request:241] Not Found: /api/companyDepartment/get/17
[26/May/2023 14:35:12] WARNING [django.server:212] "GET /api/companyDepartment/get/17 HTTP/1.1" 404 29
[26/May/2023 14:35:12] WARNING [django.server:212] "GET /api/companyDepartment/get/17 HTTP/1.1" 404 29
[26/May/2023 14:37:55] WARNING [django.request:241] Not Found: /api/companyDepartment/get/company/all/38
[26/May/2023 14:37:55] WARNING [django.request:241] Not Found: /api/companyDepartment/get/company/all/38
[26/May/2023 14:37:55] WARNING [django.server:212] "GET /api/companyDepartment/get/company/all/38 HTTP/1.1" 404 9801
[26/May/2023 14:37:55] WARNING [django.server:212] "GET /api/companyDepartment/get/company/all/38 HTTP/1.1" 404 9801
[26/May/2023 14:39:23] WARNING [django.request:241] Not Found: /api/companyDepartment/get/16
[26/May/2023 14:39:23] WARNING [django.request:241] Not Found: /api/companyDepartment/get/16
[26/May/2023 14:39:23] WARNING [django.server:212] "GET /api/companyDepartment/get/16 HTTP/1.1" 404 29
[26/May/2023 14:39:23] WARNING [django.server:212] "GET /api/companyDepartment/get/16 HTTP/1.1" 404 29
[26/May/2023 14:39:26] WARNING [django.request:241] Not Found: /api/companyDepartment/get/16
[26/May/2023 14:39:26] WARNING [django.request:241] Not Found: /api/companyDepartment/get/16
[26/May/2023 14:39:26] WARNING [django.server:212] "GET /api/companyDepartment/get/16 HTTP/1.1" 404 29
[26/May/2023 14:39:26] WARNING [django.server:212] "GET /api/companyDepartment/get/16 HTTP/1.1" 404 29
[27/May/2023 03:32:10] WARNING [django.request:241] Not Found: /favicon.ico
[27/May/2023 03:32:10] WARNING [django.request:241] Not Found: /favicon.ico
[27/May/2023 03:32:10] WARNING [django.server:212] "GET /favicon.ico HTTP/1.1" 404 2215
[27/May/2023 03:32:10] WARNING [django.server:212] "GET /favicon.ico HTTP/1.1" 404 2215
[27/May/2023 03:32:15] ERROR [django.request:241] Internal Server Error: /admin/api/companybenefits/
Traceback (most recent call last):
  File "/usr/local/lib/python3.10/site-packages/django/db/backends/utils.py", line 89, in _execute
    return self.cursor.execute(sql, params)
psycopg2.errors.UndefinedColumn: column api_companybenefits.benefit_name does not exist
LINE 1: ...its"."id", "api_companybenefits"."company_id_id", "api_compa...
                                                             ^


The above exception was the direct cause of the following exception:

Traceback (most recent call last):
  File "/usr/local/lib/python3.10/site-packages/django/core/handlers/exception.py", line 55, in inner
    response = get_response(request)
  File "/usr/local/lib/python3.10/site-packages/django/core/handlers/base.py", line 197, in _get_response
    response = wrapped_callback(request, *callback_args, **callback_kwargs)
  File "/usr/local/lib/python3.10/site-packages/django/contrib/admin/options.py", line 688, in wrapper
    return self.admin_site.admin_view(view)(*args, **kwargs)
  File "/usr/local/lib/python3.10/site-packages/django/utils/decorators.py", line 134, in _wrapper_view
    response = view_func(request, *args, **kwargs)
  File "/usr/local/lib/python3.10/site-packages/django/views/decorators/cache.py", line 62, in _wrapper_view_func
    response = view_func(request, *args, **kwargs)
  File "/usr/local/lib/python3.10/site-packages/django/contrib/admin/sites.py", line 242, in inner
    return view(request, *args, **kwargs)
  File "/usr/local/lib/python3.10/site-packages/django/utils/decorators.py", line 46, in _wrapper
    return bound_method(*args, **kwargs)
  File "/usr/local/lib/python3.10/site-packages/django/utils/decorators.py", line 134, in _wrapper_view
    response = view_func(request, *args, **kwargs)
  File "/usr/local/lib/python3.10/site-packages/django/contrib/admin/options.py", line 2065, in changelist_view
    "selection_note": _("0 of %(cnt)s selected") % {"cnt": len(cl.result_list)},
  File "/usr/local/lib/python3.10/site-packages/django/db/models/query.py", line 380, in __len__
    self._fetch_all()
  File "/usr/local/lib/python3.10/site-packages/django/db/models/query.py", line 1881, in _fetch_all
    self._result_cache = list(self._iterable_class(self))
  File "/usr/local/lib/python3.10/site-packages/django/db/models/query.py", line 91, in __iter__
    results = compiler.execute_sql(
  File "/usr/local/lib/python3.10/site-packages/django/db/models/sql/compiler.py", line 1560, in execute_sql
    cursor.execute(sql, params)
  File "/usr/local/lib/python3.10/site-packages/django/db/backends/utils.py", line 102, in execute
    return super().execute(sql, params)
  File "/usr/local/lib/python3.10/site-packages/django/db/backends/utils.py", line 67, in execute
    return self._execute_with_wrappers(
  File "/usr/local/lib/python3.10/site-packages/django/db/backends/utils.py", line 80, in _execute_with_wrappers
    return executor(sql, params, many, context)
  File "/usr/local/lib/python3.10/site-packages/django/db/backends/utils.py", line 84, in _execute
    with self.db.wrap_database_errors:
  File "/usr/local/lib/python3.10/site-packages/django/db/utils.py", line 91, in __exit__
    raise dj_exc_value.with_traceback(traceback) from exc_value
  File "/usr/local/lib/python3.10/site-packages/django/db/backends/utils.py", line 89, in _execute
    return self.cursor.execute(sql, params)
django.db.utils.ProgrammingError: column api_companybenefits.benefit_name does not exist
LINE 1: ...its"."id", "api_companybenefits"."company_id_id", "api_compa...
                                                             ^

[27/May/2023 03:32:15] ERROR [django.request:241] Internal Server Error: /admin/api/companybenefits/
Traceback (most recent call last):
  File "/usr/local/lib/python3.10/site-packages/django/db/backends/utils.py", line 89, in _execute
    return self.cursor.execute(sql, params)
psycopg2.errors.UndefinedColumn: column api_companybenefits.benefit_name does not exist
LINE 1: ...its"."id", "api_companybenefits"."company_id_id", "api_compa...
                                                             ^


The above exception was the direct cause of the following exception:

Traceback (most recent call last):
  File "/usr/local/lib/python3.10/site-packages/django/core/handlers/exception.py", line 55, in inner
    response = get_response(request)
  File "/usr/local/lib/python3.10/site-packages/django/core/handlers/base.py", line 197, in _get_response
    response = wrapped_callback(request, *callback_args, **callback_kwargs)
  File "/usr/local/lib/python3.10/site-packages/django/contrib/admin/options.py", line 688, in wrapper
    return self.admin_site.admin_view(view)(*args, **kwargs)
  File "/usr/local/lib/python3.10/site-packages/django/utils/decorators.py", line 134, in _wrapper_view
    response = view_func(request, *args, **kwargs)
  File "/usr/local/lib/python3.10/site-packages/django/views/decorators/cache.py", line 62, in _wrapper_view_func
    response = view_func(request, *args, **kwargs)
  File "/usr/local/lib/python3.10/site-packages/django/contrib/admin/sites.py", line 242, in inner
    return view(request, *args, **kwargs)
  File "/usr/local/lib/python3.10/site-packages/django/utils/decorators.py", line 46, in _wrapper
    return bound_method(*args, **kwargs)
  File "/usr/local/lib/python3.10/site-packages/django/utils/decorators.py", line 134, in _wrapper_view
    response = view_func(request, *args, **kwargs)
  File "/usr/local/lib/python3.10/site-packages/django/contrib/admin/options.py", line 2065, in changelist_view
    "selection_note": _("0 of %(cnt)s selected") % {"cnt": len(cl.result_list)},
  File "/usr/local/lib/python3.10/site-packages/django/db/models/query.py", line 380, in __len__
    self._fetch_all()
  File "/usr/local/lib/python3.10/site-packages/django/db/models/query.py", line 1881, in _fetch_all
    self._result_cache = list(self._iterable_class(self))
  File "/usr/local/lib/python3.10/site-packages/django/db/models/query.py", line 91, in __iter__
    results = compiler.execute_sql(
  File "/usr/local/lib/python3.10/site-packages/django/db/models/sql/compiler.py", line 1560, in execute_sql
    cursor.execute(sql, params)
  File "/usr/local/lib/python3.10/site-packages/django/db/backends/utils.py", line 102, in execute
    return super().execute(sql, params)
  File "/usr/local/lib/python3.10/site-packages/django/db/backends/utils.py", line 67, in execute
    return self._execute_with_wrappers(
  File "/usr/local/lib/python3.10/site-packages/django/db/backends/utils.py", line 80, in _execute_with_wrappers
    return executor(sql, params, many, context)
  File "/usr/local/lib/python3.10/site-packages/django/db/backends/utils.py", line 84, in _execute
    with self.db.wrap_database_errors:
  File "/usr/local/lib/python3.10/site-packages/django/db/utils.py", line 91, in __exit__
    raise dj_exc_value.with_traceback(traceback) from exc_value
  File "/usr/local/lib/python3.10/site-packages/django/db/backends/utils.py", line 89, in _execute
    return self.cursor.execute(sql, params)
django.db.utils.ProgrammingError: column api_companybenefits.benefit_name does not exist
LINE 1: ...its"."id", "api_companybenefits"."company_id_id", "api_compa...
                                                             ^

[27/May/2023 03:32:15] ERROR [django.server:212] "GET /admin/api/companybenefits/ HTTP/1.1" 500 158041
[27/May/2023 03:32:15] ERROR [django.server:212] "GET /admin/api/companybenefits/ HTTP/1.1" 500 158041
[27/May/2023 03:46:32] WARNING [django.request:241] Unauthorized: /api/companyBenefit/get/1
[27/May/2023 03:46:32] WARNING [django.request:241] Unauthorized: /api/companyBenefit/get/1
[27/May/2023 03:46:32] WARNING [django.server:212] "GET /api/companyBenefit/get/1 HTTP/1.1" 401 183
[27/May/2023 03:46:32] WARNING [django.server:212] "GET /api/companyBenefit/get/1 HTTP/1.1" 401 183
[27/May/2023 03:47:32] WARNING [django.request:241] Method Not Allowed: /api/companyBenefit/create
[27/May/2023 03:47:32] WARNING [django.request:241] Method Not Allowed: /api/companyBenefit/create
[27/May/2023 03:47:32] WARNING [django.server:212] "GET /api/companyBenefit/create HTTP/1.1" 405 40
[27/May/2023 03:47:32] WARNING [django.server:212] "GET /api/companyBenefit/create HTTP/1.1" 405 40
[27/May/2023 03:47:39] ERROR [django.request:241] Internal Server Error: /api/companyBenefit/create
[27/May/2023 03:47:39] ERROR [django.request:241] Internal Server Error: /api/companyBenefit/create
[27/May/2023 03:47:39] ERROR [django.server:212] "POST /api/companyBenefit/create HTTP/1.1" 500 32
[27/May/2023 03:47:39] ERROR [django.server:212] "POST /api/companyBenefit/create HTTP/1.1" 500 32
[27/May/2023 03:48:44] ERROR [django.request:241] Internal Server Error: /api/companyBenefit/create
[27/May/2023 03:48:44] ERROR [django.request:241] Internal Server Error: /api/companyBenefit/create
[27/May/2023 03:48:44] ERROR [django.server:212] "POST /api/companyBenefit/create HTTP/1.1" 500 80
[27/May/2023 03:48:44] ERROR [django.server:212] "POST /api/companyBenefit/create HTTP/1.1" 500 80
[27/May/2023 03:49:02] ERROR [django.request:241] Internal Server Error: /api/companyBenefit/create
[27/May/2023 03:49:02] ERROR [django.request:241] Internal Server Error: /api/companyBenefit/create
[27/May/2023 03:49:02] ERROR [django.server:212] "POST /api/companyBenefit/create HTTP/1.1" 500 80
[27/May/2023 03:49:02] ERROR [django.server:212] "POST /api/companyBenefit/create HTTP/1.1" 500 80
[27/May/2023 03:51:31] WARNING [django.request:241] Not Found: /api/companyBenefit/get/25
[27/May/2023 03:51:31] WARNING [django.request:241] Not Found: /api/companyBenefit/get/25
[27/May/2023 03:51:31] WARNING [django.server:212] "GET /api/companyBenefit/get/25 HTTP/1.1" 404 29
[27/May/2023 03:51:31] WARNING [django.server:212] "GET /api/companyBenefit/get/25 HTTP/1.1" 404 29
[27/May/2023 03:51:45] WARNING [django.request:241] Not Found: /api/companyBenefit/get/company/all25
[27/May/2023 03:51:45] WARNING [django.request:241] Not Found: /api/companyBenefit/get/company/all25
[27/May/2023 03:51:45] WARNING [django.server:212] "GET /api/companyBenefit/get/company/all25 HTTP/1.1" 404 10830
[27/May/2023 03:51:45] WARNING [django.server:212] "GET /api/companyBenefit/get/company/all25 HTTP/1.1" 404 10830
[27/May/2023 03:52:44] ERROR [django.request:241] Internal Server Error: /api/companyBenefit/update/25
Traceback (most recent call last):
  File "/app/backend/api/views.py", line 485, in updateBenefit
    benefit = models.CompanyBenefits.objects.get(id=pk)
  File "/usr/local/lib/python3.10/site-packages/django/db/models/manager.py", line 87, in manager_method
    return getattr(self.get_queryset(), name)(*args, **kwargs)
  File "/usr/local/lib/python3.10/site-packages/django/db/models/query.py", line 637, in get
    raise self.model.DoesNotExist(
api.models.CompanyBenefits.DoesNotExist: CompanyBenefits matching query does not exist.

During handling of the above exception, another exception occurred:

Traceback (most recent call last):
  File "/usr/local/lib/python3.10/site-packages/django/core/handlers/exception.py", line 55, in inner
    response = get_response(request)
  File "/usr/local/lib/python3.10/site-packages/django/core/handlers/base.py", line 197, in _get_response
    response = wrapped_callback(request, *callback_args, **callback_kwargs)
  File "/usr/local/lib/python3.10/site-packages/django/views/decorators/csrf.py", line 56, in wrapper_view
    return view_func(*args, **kwargs)
  File "/usr/local/lib/python3.10/site-packages/django/views/generic/base.py", line 104, in view
    return self.dispatch(request, *args, **kwargs)
  File "/usr/local/lib/python3.10/site-packages/rest_framework/views.py", line 509, in dispatch
    response = self.handle_exception(exc)
  File "/usr/local/lib/python3.10/site-packages/rest_framework/views.py", line 469, in handle_exception
    self.raise_uncaught_exception(exc)
  File "/usr/local/lib/python3.10/site-packages/rest_framework/views.py", line 480, in raise_uncaught_exception
    raise exc
  File "/usr/local/lib/python3.10/site-packages/rest_framework/views.py", line 506, in dispatch
    response = handler(request, *args, **kwargs)
  File "/usr/local/lib/python3.10/site-packages/rest_framework/decorators.py", line 50, in handler
    return func(*args, **kwargs)
  File "/app/backend/api/views.py", line 492, in updateBenefit
    return Exception({'message':'權限更新不存在'}, status=status.HTTP_404_NOT_FOUND)
TypeError: Exception() takes no keyword arguments
[27/May/2023 03:52:44] ERROR [django.request:241] Internal Server Error: /api/companyBenefit/update/25
Traceback (most recent call last):
  File "/app/backend/api/views.py", line 485, in updateBenefit
    benefit = models.CompanyBenefits.objects.get(id=pk)
  File "/usr/local/lib/python3.10/site-packages/django/db/models/manager.py", line 87, in manager_method
    return getattr(self.get_queryset(), name)(*args, **kwargs)
  File "/usr/local/lib/python3.10/site-packages/django/db/models/query.py", line 637, in get
    raise self.model.DoesNotExist(
api.models.CompanyBenefits.DoesNotExist: CompanyBenefits matching query does not exist.

During handling of the above exception, another exception occurred:

Traceback (most recent call last):
  File "/usr/local/lib/python3.10/site-packages/django/core/handlers/exception.py", line 55, in inner
    response = get_response(request)
  File "/usr/local/lib/python3.10/site-packages/django/core/handlers/base.py", line 197, in _get_response
    response = wrapped_callback(request, *callback_args, **callback_kwargs)
  File "/usr/local/lib/python3.10/site-packages/django/views/decorators/csrf.py", line 56, in wrapper_view
    return view_func(*args, **kwargs)
  File "/usr/local/lib/python3.10/site-packages/django/views/generic/base.py", line 104, in view
    return self.dispatch(request, *args, **kwargs)
  File "/usr/local/lib/python3.10/site-packages/rest_framework/views.py", line 509, in dispatch
    response = self.handle_exception(exc)
  File "/usr/local/lib/python3.10/site-packages/rest_framework/views.py", line 469, in handle_exception
    self.raise_uncaught_exception(exc)
  File "/usr/local/lib/python3.10/site-packages/rest_framework/views.py", line 480, in raise_uncaught_exception
    raise exc
  File "/usr/local/lib/python3.10/site-packages/rest_framework/views.py", line 506, in dispatch
    response = handler(request, *args, **kwargs)
  File "/usr/local/lib/python3.10/site-packages/rest_framework/decorators.py", line 50, in handler
    return func(*args, **kwargs)
  File "/app/backend/api/views.py", line 492, in updateBenefit
    return Exception({'message':'權限更新不存在'}, status=status.HTTP_404_NOT_FOUND)
TypeError: Exception() takes no keyword arguments
[27/May/2023 03:52:45] ERROR [django.server:212] "PUT /api/companyBenefit/update/25 HTTP/1.1" 500 104426
[27/May/2023 03:52:45] ERROR [django.server:212] "PUT /api/companyBenefit/update/25 HTTP/1.1" 500 104426
[27/May/2023 03:53:48] WARNING [django.request:241] Not Found: /api/companyBenefit/update/25
[27/May/2023 03:53:48] WARNING [django.request:241] Not Found: /api/companyBenefit/update/25
[27/May/2023 03:53:48] WARNING [django.server:212] "PUT /api/companyBenefit/update/25 HTTP/1.1" 404 35
[27/May/2023 03:53:48] WARNING [django.server:212] "PUT /api/companyBenefit/update/25 HTTP/1.1" 404 35
[27/May/2023 03:54:40] ERROR [django.request:241] Internal Server Error: /api/companyBenefit/delete/15
[27/May/2023 03:54:40] ERROR [django.request:241] Internal Server Error: /api/companyBenefit/delete/15
[27/May/2023 03:54:40] ERROR [django.server:212] "DELETE /api/companyBenefit/delete/15 HTTP/1.1" 500 95
[27/May/2023 03:54:40] ERROR [django.server:212] "DELETE /api/companyBenefit/delete/15 HTTP/1.1" 500 95
[27/May/2023 03:55:21] WARNING [django.request:241] Not Found: /api/companyBenefit/delete/15
[27/May/2023 03:55:21] WARNING [django.request:241] Not Found: /api/companyBenefit/delete/15
[27/May/2023 03:55:21] WARNING [django.server:212] "DELETE /api/companyBenefit/delete/15 HTTP/1.1" 404 29
[27/May/2023 03:55:21] WARNING [django.server:212] "DELETE /api/companyBenefit/delete/15 HTTP/1.1" 404 29
[27/May/2023 03:55:26] WARNING [django.request:241] Not Found: /api/companyBenefit/update/15
[27/May/2023 03:55:26] WARNING [django.request:241] Not Found: /api/companyBenefit/update/15
[27/May/2023 03:55:26] WARNING [django.server:212] "PUT /api/companyBenefit/update/15 HTTP/1.1" 404 35
[27/May/2023 03:55:26] WARNING [django.server:212] "PUT /api/companyBenefit/update/15 HTTP/1.1" 404 35
[27/May/2023 14:49:51] WARNING [django.request:241] Unauthorized: /api/companyPosition/create
[27/May/2023 14:49:51] WARNING [django.request:241] Unauthorized: /api/companyPosition/create
[27/May/2023 14:49:51] WARNING [django.server:212] "POST /api/companyPosition/create HTTP/1.1" 401 183
[27/May/2023 14:49:51] WARNING [django.server:212] "POST /api/companyPosition/create HTTP/1.1" 401 183
[27/May/2023 14:49:59] ERROR [django.request:241] Internal Server Error: /api/companyPosition/create
[27/May/2023 14:49:59] ERROR [django.request:241] Internal Server Error: /api/companyPosition/create
[27/May/2023 14:49:59] ERROR [django.server:212] "POST /api/companyPosition/create HTTP/1.1" 500 60
[27/May/2023 14:49:59] ERROR [django.server:212] "POST /api/companyPosition/create HTTP/1.1" 500 60
[27/May/2023 14:50:38] ERROR [django.request:241] Internal Server Error: /api/companyPosition/create
[27/May/2023 14:50:38] ERROR [django.request:241] Internal Server Error: /api/companyPosition/create
[27/May/2023 14:50:38] ERROR [django.server:212] "POST /api/companyPosition/create HTTP/1.1" 500 157
[27/May/2023 14:50:38] ERROR [django.server:212] "POST /api/companyPosition/create HTTP/1.1" 500 157
[27/May/2023 14:51:07] ERROR [django.request:241] Internal Server Error: /api/companyPosition/create
Traceback (most recent call last):
  File "/usr/local/lib/python3.10/site-packages/django/core/handlers/exception.py", line 55, in inner
    response = get_response(request)
  File "/usr/local/lib/python3.10/site-packages/django/core/handlers/base.py", line 197, in _get_response
    response = wrapped_callback(request, *callback_args, **callback_kwargs)
  File "/usr/local/lib/python3.10/site-packages/django/views/decorators/csrf.py", line 56, in wrapper_view
    return view_func(*args, **kwargs)
  File "/usr/local/lib/python3.10/site-packages/django/views/generic/base.py", line 104, in view
    return self.dispatch(request, *args, **kwargs)
  File "/usr/local/lib/python3.10/site-packages/rest_framework/views.py", line 511, in dispatch
    self.response = self.finalize_response(request, response, *args, **kwargs)
  File "/usr/local/lib/python3.10/site-packages/rest_framework/views.py", line 423, in finalize_response
    assert isinstance(response, HttpResponseBase), (
AssertionError: Expected a `Response`, `HttpResponse` or `HttpStreamingResponse` to be returned from the view, but received a `<class 'NoneType'>`
[27/May/2023 14:51:07] ERROR [django.request:241] Internal Server Error: /api/companyPosition/create
Traceback (most recent call last):
  File "/usr/local/lib/python3.10/site-packages/django/core/handlers/exception.py", line 55, in inner
    response = get_response(request)
  File "/usr/local/lib/python3.10/site-packages/django/core/handlers/base.py", line 197, in _get_response
    response = wrapped_callback(request, *callback_args, **callback_kwargs)
  File "/usr/local/lib/python3.10/site-packages/django/views/decorators/csrf.py", line 56, in wrapper_view
    return view_func(*args, **kwargs)
  File "/usr/local/lib/python3.10/site-packages/django/views/generic/base.py", line 104, in view
    return self.dispatch(request, *args, **kwargs)
  File "/usr/local/lib/python3.10/site-packages/rest_framework/views.py", line 511, in dispatch
    self.response = self.finalize_response(request, response, *args, **kwargs)
  File "/usr/local/lib/python3.10/site-packages/rest_framework/views.py", line 423, in finalize_response
    assert isinstance(response, HttpResponseBase), (
AssertionError: Expected a `Response`, `HttpResponse` or `HttpStreamingResponse` to be returned from the view, but received a `<class 'NoneType'>`
[27/May/2023 14:51:07] ERROR [django.server:212] "POST /api/companyPosition/create HTTP/1.1" 500 73597
[27/May/2023 14:51:07] ERROR [django.server:212] "POST /api/companyPosition/create HTTP/1.1" 500 73597
[28/May/2023 05:59:36] WARNING [django.request:241] Unauthorized: /api/companyPosition/get/38
[28/May/2023 05:59:36] WARNING [django.request:241] Unauthorized: /api/companyPosition/get/38
[28/May/2023 05:59:36] WARNING [django.server:212] "GET /api/companyPosition/get/38 HTTP/1.1" 401 183
[28/May/2023 05:59:36] WARNING [django.server:212] "GET /api/companyPosition/get/38 HTTP/1.1" 401 183
[28/May/2023 05:59:55] WARNING [django.request:241] Not Found: /api/companyPosition/get/38
[28/May/2023 05:59:55] WARNING [django.request:241] Not Found: /api/companyPosition/get/38
[28/May/2023 05:59:55] WARNING [django.server:212] "GET /api/companyPosition/get/38 HTTP/1.1" 404 29
[28/May/2023 05:59:55] WARNING [django.server:212] "GET /api/companyPosition/get/38 HTTP/1.1" 404 29
[28/May/2023 06:07:43] ERROR [django.request:241] Internal Server Error: /api/companyPosition/create
[28/May/2023 06:07:43] ERROR [django.request:241] Internal Server Error: /api/companyPosition/create
[28/May/2023 06:07:43] ERROR [django.server:212] "POST /api/companyPosition/create HTTP/1.1" 500 85
[28/May/2023 06:07:43] ERROR [django.server:212] "POST /api/companyPosition/create HTTP/1.1" 500 85
[28/May/2023 06:14:09] ERROR [django.request:241] Internal Server Error: /api/companyPosition/get/company/all/38
[28/May/2023 06:14:09] ERROR [django.request:241] Internal Server Error: /api/companyPosition/get/company/all/38
[28/May/2023 06:14:09] ERROR [django.server:212] "GET /api/companyPosition/get/company/all/38 HTTP/1.1" 500 134
[28/May/2023 06:14:09] ERROR [django.server:212] "GET /api/companyPosition/get/company/all/38 HTTP/1.1" 500 134
[28/May/2023 06:16:17] ERROR [django.server:192] You're accessing the development server over HTTPS, but it only supports HTTP.
[28/May/2023 06:16:17] ERROR [django.server:192] You're accessing the development server over HTTPS, but it only supports HTTP.
[28/May/2023 06:42:03] WARNING [django.request:241] Unauthorized: /api/companyPosition/update/7
[28/May/2023 06:42:03] WARNING [django.request:241] Unauthorized: /api/companyPosition/update/7
[28/May/2023 06:42:03] WARNING [django.server:212] "POST /api/companyPosition/update/7 HTTP/1.1" 401 183
[28/May/2023 06:42:03] WARNING [django.server:212] "POST /api/companyPosition/update/7 HTTP/1.1" 401 183
[28/May/2023 06:42:11] WARNING [django.request:241] Method Not Allowed: /api/companyPosition/update/7
[28/May/2023 06:42:11] WARNING [django.request:241] Method Not Allowed: /api/companyPosition/update/7
[28/May/2023 06:42:11] WARNING [django.server:212] "POST /api/companyPosition/update/7 HTTP/1.1" 405 41
[28/May/2023 06:42:11] WARNING [django.server:212] "POST /api/companyPosition/update/7 HTTP/1.1" 405 41
[28/May/2023 06:42:28] ERROR [django.request:241] Internal Server Error: /api/companyPosition/update/7
[28/May/2023 06:42:28] ERROR [django.request:241] Internal Server Error: /api/companyPosition/update/7
[28/May/2023 06:42:28] ERROR [django.server:212] "PUT /api/companyPosition/update/7 HTTP/1.1" 500 93
[28/May/2023 06:42:28] ERROR [django.server:212] "PUT /api/companyPosition/update/7 HTTP/1.1" 500 93
[28/May/2023 06:43:24] WARNING [django.request:241] Not Found: /api/companyPosition/get/115
[28/May/2023 06:43:24] WARNING [django.request:241] Not Found: /api/companyPosition/get/115
[28/May/2023 06:43:24] WARNING [django.server:212] "GET /api/companyPosition/get/115 HTTP/1.1" 404 29
[28/May/2023 06:43:24] WARNING [django.server:212] "GET /api/companyPosition/get/115 HTTP/1.1" 404 29
[28/May/2023 06:43:27] WARNING [django.request:241] Not Found: /api/companyPosition/get/15
[28/May/2023 06:43:27] WARNING [django.request:241] Not Found: /api/companyPosition/get/15
[28/May/2023 06:43:27] WARNING [django.server:212] "GET /api/companyPosition/get/15 HTTP/1.1" 404 29
[28/May/2023 06:43:27] WARNING [django.server:212] "GET /api/companyPosition/get/15 HTTP/1.1" 404 29
[28/May/2023 06:43:54] ERROR [django.request:241] Internal Server Error: /api/companyPosition/update/14
[28/May/2023 06:43:54] ERROR [django.request:241] Internal Server Error: /api/companyPosition/update/14
[28/May/2023 06:43:54] ERROR [django.server:212] "PUT /api/companyPosition/update/14 HTTP/1.1" 500 93
[28/May/2023 06:43:54] ERROR [django.server:212] "PUT /api/companyPosition/update/14 HTTP/1.1" 500 93
[28/May/2023 06:44:10] ERROR [django.request:241] Internal Server Error: /api/companyPosition/update/14
[28/May/2023 06:44:10] ERROR [django.request:241] Internal Server Error: /api/companyPosition/update/14
[28/May/2023 06:44:10] ERROR [django.server:212] "PUT /api/companyPosition/update/14 HTTP/1.1" 500 93
[28/May/2023 06:44:10] ERROR [django.server:212] "PUT /api/companyPosition/update/14 HTTP/1.1" 500 93
[28/May/2023 06:45:25] ERROR [django.request:241] Internal Server Error: /api/companyPosition/update/14
[28/May/2023 06:45:25] ERROR [django.request:241] Internal Server Error: /api/companyPosition/update/14
[28/May/2023 06:45:25] ERROR [django.server:212] "PUT /api/companyPosition/update/14 HTTP/1.1" 500 93
[28/May/2023 06:45:25] ERROR [django.server:212] "PUT /api/companyPosition/update/14 HTTP/1.1" 500 93
[28/May/2023 06:48:06] WARNING [django.server:212] "   qjn0k¡¢" 400 -
[28/May/2023 06:48:06] WARNING [django.server:212] "   qjn0k¡¢" 400 -
[28/May/2023 06:48:13] WARNING [django.server:212] "  " 400 -
[28/May/2023 06:48:13] WARNING [django.server:212] "  " 400 -
[28/May/2023 06:48:16] ERROR [django.request:241] Internal Server Error: /api/companyPosition/update/14
[28/May/2023 06:48:16] ERROR [django.request:241] Internal Server Error: /api/companyPosition/update/14
[28/May/2023 06:48:16] ERROR [django.server:212] "PUT /api/companyPosition/update/14 HTTP/1.1" 500 93
[28/May/2023 06:48:16] ERROR [django.server:212] "PUT /api/companyPosition/update/14 HTTP/1.1" 500 93
[28/May/2023 06:48:20] ERROR [django.request:241] Internal Server Error: /api/companyPosition/update/14
[28/May/2023 06:48:20] ERROR [django.request:241] Internal Server Error: /api/companyPosition/update/14
[28/May/2023 06:48:20] ERROR [django.server:212] "PUT /api/companyPosition/update/14 HTTP/1.1" 500 93
[28/May/2023 06:48:20] ERROR [django.server:212] "PUT /api/companyPosition/update/14 HTTP/1.1" 500 93
[28/May/2023 06:48:23] WARNING [django.server:212] "   root " 400 -
[28/May/2023 06:48:23] WARNING [django.server:212] "   root " 400 -
[28/May/2023 06:48:25] ERROR [django.server:192] You're accessing the development server over HTTPS, but it only supports HTTP.
[28/May/2023 06:48:25] ERROR [django.server:192] You're accessing the development server over HTTPS, but it only supports HTTP.
[28/May/2023 06:48:28] ERROR [django.security.DisallowedHost:124] Invalid HTTP_HOST header: '3e1daac8e3ea:8000'. You may need to add '3e1daac8e3ea' to ALLOWED_HOSTS.
Traceback (most recent call last):
  File "/usr/local/lib/python3.10/site-packages/django/core/handlers/exception.py", line 55, in inner
    response = get_response(request)
  File "/usr/local/lib/python3.10/site-packages/django/utils/deprecation.py", line 133, in __call__
    response = self.process_request(request)
  File "/usr/local/lib/python3.10/site-packages/django/middleware/common.py", line 48, in process_request
    host = request.get_host()
  File "/usr/local/lib/python3.10/site-packages/django/http/request.py", line 167, in get_host
    raise DisallowedHost(msg)
django.core.exceptions.DisallowedHost: Invalid HTTP_HOST header: '3e1daac8e3ea:8000'. You may need to add '3e1daac8e3ea' to ALLOWED_HOSTS.
[28/May/2023 06:48:28] ERROR [django.security.DisallowedHost:124] Invalid HTTP_HOST header: '3e1daac8e3ea:8000'. You may need to add '3e1daac8e3ea' to ALLOWED_HOSTS.
Traceback (most recent call last):
  File "/usr/local/lib/python3.10/site-packages/django/core/handlers/exception.py", line 55, in inner
    response = get_response(request)
  File "/usr/local/lib/python3.10/site-packages/django/utils/deprecation.py", line 133, in __call__
    response = self.process_request(request)
  File "/usr/local/lib/python3.10/site-packages/django/middleware/common.py", line 48, in process_request
    host = request.get_host()
  File "/usr/local/lib/python3.10/site-packages/django/http/request.py", line 167, in get_host
    raise DisallowedHost(msg)
django.core.exceptions.DisallowedHost: Invalid HTTP_HOST header: '3e1daac8e3ea:8000'. You may need to add '3e1daac8e3ea' to ALLOWED_HOSTS.
[28/May/2023 06:48:28] WARNING [django.request:241] Bad Request: /
[28/May/2023 06:48:28] WARNING [django.request:241] Bad Request: /
[28/May/2023 06:48:28] WARNING [django.server:212] "OPTIONS / HTTP/1.0" 400 62405
[28/May/2023 06:48:28] WARNING [django.server:212] "OPTIONS / HTTP/1.0" 400 62405
[28/May/2023 06:48:28] ERROR [django.server:192] You're accessing the development server over HTTPS, but it only supports HTTP.
[28/May/2023 06:48:28] ERROR [django.server:192] You're accessing the development server over HTTPS, but it only supports HTTP.
[28/May/2023 06:50:07] ERROR [django.request:241] Internal Server Error: /api/companyPosition/update/14
[28/May/2023 06:50:07] ERROR [django.request:241] Internal Server Error: /api/companyPosition/update/14
[28/May/2023 06:50:07] ERROR [django.server:212] "PUT /api/companyPosition/update/14 HTTP/1.1" 500 93
[28/May/2023 06:50:07] ERROR [django.server:212] "PUT /api/companyPosition/update/14 HTTP/1.1" 500 93
[28/May/2023 06:51:14] ERROR [django.request:241] Internal Server Error: /api/companyPosition/update/14
[28/May/2023 06:51:14] ERROR [django.request:241] Internal Server Error: /api/companyPosition/update/14
[28/May/2023 06:51:14] ERROR [django.server:212] "PUT /api/companyPosition/update/14 HTTP/1.1" 500 93
[28/May/2023 06:51:14] ERROR [django.server:212] "PUT /api/companyPosition/update/14 HTTP/1.1" 500 93
[28/May/2023 06:56:35] ERROR [django.security.DisallowedHost:124] Invalid HTTP_HOST header: '220.141.73.103:8000'. You may need to add '220.141.73.103' to ALLOWED_HOSTS.
Traceback (most recent call last):
  File "/usr/local/lib/python3.10/site-packages/django/core/handlers/exception.py", line 55, in inner
    response = get_response(request)
  File "/usr/local/lib/python3.10/site-packages/django/utils/deprecation.py", line 133, in __call__
    response = self.process_request(request)
  File "/usr/local/lib/python3.10/site-packages/django/middleware/common.py", line 48, in process_request
    host = request.get_host()
  File "/usr/local/lib/python3.10/site-packages/django/http/request.py", line 167, in get_host
    raise DisallowedHost(msg)
django.core.exceptions.DisallowedHost: Invalid HTTP_HOST header: '220.141.73.103:8000'. You may need to add '220.141.73.103' to ALLOWED_HOSTS.
[28/May/2023 06:56:35] ERROR [django.security.DisallowedHost:124] Invalid HTTP_HOST header: '220.141.73.103:8000'. You may need to add '220.141.73.103' to ALLOWED_HOSTS.
Traceback (most recent call last):
  File "/usr/local/lib/python3.10/site-packages/django/core/handlers/exception.py", line 55, in inner
    response = get_response(request)
  File "/usr/local/lib/python3.10/site-packages/django/utils/deprecation.py", line 133, in __call__
    response = self.process_request(request)
  File "/usr/local/lib/python3.10/site-packages/django/middleware/common.py", line 48, in process_request
    host = request.get_host()
  File "/usr/local/lib/python3.10/site-packages/django/http/request.py", line 167, in get_host
    raise DisallowedHost(msg)
django.core.exceptions.DisallowedHost: Invalid HTTP_HOST header: '220.141.73.103:8000'. You may need to add '220.141.73.103' to ALLOWED_HOSTS.
[28/May/2023 06:56:35] WARNING [django.request:241] Bad Request: /
[28/May/2023 06:56:35] WARNING [django.request:241] Bad Request: /
[28/May/2023 06:56:35] WARNING [django.server:212] "GET / HTTP/1.1" 400 63583
[28/May/2023 06:56:35] WARNING [django.server:212] "GET / HTTP/1.1" 400 63583
[28/May/2023 06:56:36] ERROR [django.security.DisallowedHost:124] Invalid HTTP_HOST header: '220.141.73.103:8000'. You may need to add '220.141.73.103' to ALLOWED_HOSTS.
Traceback (most recent call last):
  File "/usr/local/lib/python3.10/site-packages/django/core/handlers/exception.py", line 55, in inner
    response = get_response(request)
  File "/usr/local/lib/python3.10/site-packages/django/utils/deprecation.py", line 133, in __call__
    response = self.process_request(request)
  File "/usr/local/lib/python3.10/site-packages/django/middleware/common.py", line 48, in process_request
    host = request.get_host()
  File "/usr/local/lib/python3.10/site-packages/django/http/request.py", line 167, in get_host
    raise DisallowedHost(msg)
django.core.exceptions.DisallowedHost: Invalid HTTP_HOST header: '220.141.73.103:8000'. You may need to add '220.141.73.103' to ALLOWED_HOSTS.
[28/May/2023 06:56:36] ERROR [django.security.DisallowedHost:124] Invalid HTTP_HOST header: '220.141.73.103:8000'. You may need to add '220.141.73.103' to ALLOWED_HOSTS.
Traceback (most recent call last):
  File "/usr/local/lib/python3.10/site-packages/django/core/handlers/exception.py", line 55, in inner
    response = get_response(request)
  File "/usr/local/lib/python3.10/site-packages/django/utils/deprecation.py", line 133, in __call__
    response = self.process_request(request)
  File "/usr/local/lib/python3.10/site-packages/django/middleware/common.py", line 48, in process_request
    host = request.get_host()
  File "/usr/local/lib/python3.10/site-packages/django/http/request.py", line 167, in get_host
    raise DisallowedHost(msg)
django.core.exceptions.DisallowedHost: Invalid HTTP_HOST header: '220.141.73.103:8000'. You may need to add '220.141.73.103' to ALLOWED_HOSTS.
[28/May/2023 06:56:36] WARNING [django.request:241] Bad Request: /favicon.ico
[28/May/2023 06:56:36] WARNING [django.request:241] Bad Request: /favicon.ico
[28/May/2023 06:56:36] WARNING [django.server:212] "GET /favicon.ico HTTP/1.1" 400 63706
[28/May/2023 06:56:36] WARNING [django.server:212] "GET /favicon.ico HTTP/1.1" 400 63706
[28/May/2023 06:56:36] ERROR [django.security.DisallowedHost:124] Invalid HTTP_HOST header: '220.141.73.103:8000'. You may need to add '220.141.73.103' to ALLOWED_HOSTS.
Traceback (most recent call last):
  File "/usr/local/lib/python3.10/site-packages/django/core/handlers/exception.py", line 55, in inner
    response = get_response(request)
  File "/usr/local/lib/python3.10/site-packages/django/utils/deprecation.py", line 133, in __call__
    response = self.process_request(request)
  File "/usr/local/lib/python3.10/site-packages/django/middleware/common.py", line 48, in process_request
    host = request.get_host()
  File "/usr/local/lib/python3.10/site-packages/django/http/request.py", line 167, in get_host
    raise DisallowedHost(msg)
django.core.exceptions.DisallowedHost: Invalid HTTP_HOST header: '220.141.73.103:8000'. You may need to add '220.141.73.103' to ALLOWED_HOSTS.
[28/May/2023 06:56:36] ERROR [django.security.DisallowedHost:124] Invalid HTTP_HOST header: '220.141.73.103:8000'. You may need to add '220.141.73.103' to ALLOWED_HOSTS.
Traceback (most recent call last):
  File "/usr/local/lib/python3.10/site-packages/django/core/handlers/exception.py", line 55, in inner
    response = get_response(request)
  File "/usr/local/lib/python3.10/site-packages/django/utils/deprecation.py", line 133, in __call__
    response = self.process_request(request)
  File "/usr/local/lib/python3.10/site-packages/django/middleware/common.py", line 48, in process_request
    host = request.get_host()
  File "/usr/local/lib/python3.10/site-packages/django/http/request.py", line 167, in get_host
    raise DisallowedHost(msg)
django.core.exceptions.DisallowedHost: Invalid HTTP_HOST header: '220.141.73.103:8000'. You may need to add '220.141.73.103' to ALLOWED_HOSTS.
[28/May/2023 06:56:36] ERROR [django.security.DisallowedHost:124] Invalid HTTP_HOST header: '220.141.73.103:8000'. You may need to add '220.141.73.103' to ALLOWED_HOSTS.
Traceback (most recent call last):
  File "/usr/local/lib/python3.10/site-packages/django/core/handlers/exception.py", line 55, in inner
    response = get_response(request)
  File "/usr/local/lib/python3.10/site-packages/django/utils/deprecation.py", line 133, in __call__
    response = self.process_request(request)
  File "/usr/local/lib/python3.10/site-packages/django/middleware/common.py", line 48, in process_request
    host = request.get_host()
  File "/usr/local/lib/python3.10/site-packages/django/http/request.py", line 167, in get_host
    raise DisallowedHost(msg)
django.core.exceptions.DisallowedHost: Invalid HTTP_HOST header: '220.141.73.103:8000'. You may need to add '220.141.73.103' to ALLOWED_HOSTS.
[28/May/2023 06:56:36] ERROR [django.security.DisallowedHost:124] Invalid HTTP_HOST header: '220.141.73.103:8000'. You may need to add '220.141.73.103' to ALLOWED_HOSTS.
Traceback (most recent call last):
  File "/usr/local/lib/python3.10/site-packages/django/core/handlers/exception.py", line 55, in inner
    response = get_response(request)
  File "/usr/local/lib/python3.10/site-packages/django/utils/deprecation.py", line 133, in __call__
    response = self.process_request(request)
  File "/usr/local/lib/python3.10/site-packages/django/middleware/common.py", line 48, in process_request
    host = request.get_host()
  File "/usr/local/lib/python3.10/site-packages/django/http/request.py", line 167, in get_host
    raise DisallowedHost(msg)
django.core.exceptions.DisallowedHost: Invalid HTTP_HOST header: '220.141.73.103:8000'. You may need to add '220.141.73.103' to ALLOWED_HOSTS.
[28/May/2023 06:56:36] WARNING [django.request:241] Bad Request: /robots.txt
[28/May/2023 06:56:36] WARNING [django.request:241] Bad Request: /robots.txt
[28/May/2023 06:56:36] WARNING [django.server:212] "GET /robots.txt HTTP/1.1" 400 63671
[28/May/2023 06:56:36] WARNING [django.server:212] "GET /robots.txt HTTP/1.1" 400 63671
[28/May/2023 06:56:36] WARNING [django.request:241] Bad Request: /sitemap.xml
[28/May/2023 06:56:36] WARNING [django.request:241] Bad Request: /sitemap.xml
[28/May/2023 06:56:36] WARNING [django.server:212] "GET /sitemap.xml HTTP/1.1" 400 63702
[28/May/2023 06:56:36] WARNING [django.server:212] "GET /sitemap.xml HTTP/1.1" 400 63702
[28/May/2023 06:57:03] ERROR [django.request:241] Internal Server Error: /api/companyPosition/update/14
[28/May/2023 06:57:03] ERROR [django.request:241] Internal Server Error: /api/companyPosition/update/14
[28/May/2023 06:57:03] ERROR [django.server:212] "PUT /api/companyPosition/update/14 HTTP/1.1" 500 107
[28/May/2023 06:57:03] ERROR [django.server:212] "PUT /api/companyPosition/update/14 HTTP/1.1" 500 107
[28/May/2023 06:59:09] WARNING [django.request:241] Not Found: /api/companyPosition/update/14
[28/May/2023 06:59:09] WARNING [django.request:241] Not Found: /api/companyPosition/update/14
[28/May/2023 06:59:09] WARNING [django.server:212] "PUT /api/companyPosition/update/14 HTTP/1.1" 404 29
[28/May/2023 06:59:09] WARNING [django.server:212] "PUT /api/companyPosition/update/14 HTTP/1.1" 404 29
[28/May/2023 06:59:33] WARNING [django.request:241] Not Found: /api/companyPosition/update/14
[28/May/2023 06:59:33] WARNING [django.request:241] Not Found: /api/companyPosition/update/14
[28/May/2023 06:59:33] WARNING [django.server:212] "PUT /api/companyPosition/update/14 HTTP/1.1" 404 29
[28/May/2023 06:59:33] WARNING [django.server:212] "PUT /api/companyPosition/update/14 HTTP/1.1" 404 29
[28/May/2023 07:00:55] WARNING [django.request:241] Not Found: /api/companyPosition/update/14
[28/May/2023 07:00:55] WARNING [django.request:241] Not Found: /api/companyPosition/update/14
[28/May/2023 07:00:55] WARNING [django.server:212] "PUT /api/companyPosition/update/14 HTTP/1.1" 404 29
[28/May/2023 07:00:55] WARNING [django.server:212] "PUT /api/companyPosition/update/14 HTTP/1.1" 404 29
[28/May/2023 07:01:27] WARNING [django.request:241] Not Found: /api/companyPosition/update/14
[28/May/2023 07:01:27] WARNING [django.request:241] Not Found: /api/companyPosition/update/14
[28/May/2023 07:01:27] WARNING [django.server:212] "PUT /api/companyPosition/update/14 HTTP/1.1" 404 86
[28/May/2023 07:01:27] WARNING [django.server:212] "PUT /api/companyPosition/update/14 HTTP/1.1" 404 86
[28/May/2023 07:01:52] WARNING [django.request:241] Not Found: /api/companyBenefit/get/12
[28/May/2023 07:01:52] WARNING [django.request:241] Not Found: /api/companyBenefit/get/12
[28/May/2023 07:01:52] WARNING [django.server:212] "GET /api/companyBenefit/get/12 HTTP/1.1" 404 29
[28/May/2023 07:01:52] WARNING [django.server:212] "GET /api/companyBenefit/get/12 HTTP/1.1" 404 29
[28/May/2023 07:02:03] WARNING [django.request:241] Not Found: /api/companyBenefit/get/14
[28/May/2023 07:02:03] WARNING [django.request:241] Not Found: /api/companyBenefit/get/14
[28/May/2023 07:02:03] WARNING [django.server:212] "GET /api/companyBenefit/get/14 HTTP/1.1" 404 29
[28/May/2023 07:02:03] WARNING [django.server:212] "GET /api/companyBenefit/get/14 HTTP/1.1" 404 29
[28/May/2023 07:02:33] ERROR [django.request:241] Internal Server Error: /api/companyPosition/update/14
[28/May/2023 07:02:33] ERROR [django.request:241] Internal Server Error: /api/companyPosition/update/14
[28/May/2023 07:02:33] ERROR [django.server:212] "PUT /api/companyPosition/update/14 HTTP/1.1" 500 87
[28/May/2023 07:02:33] ERROR [django.server:212] "PUT /api/companyPosition/update/14 HTTP/1.1" 500 87
[28/May/2023 07:04:25] ERROR [django.request:241] Internal Server Error: /api/companyPosition/update/14
[28/May/2023 07:04:25] ERROR [django.request:241] Internal Server Error: /api/companyPosition/update/14
[28/May/2023 07:04:26] ERROR [django.server:212] "PUT /api/companyPosition/update/14 HTTP/1.1" 500 87
[28/May/2023 07:04:26] ERROR [django.server:212] "PUT /api/companyPosition/update/14 HTTP/1.1" 500 87
[28/May/2023 07:16:55] WARNING [django.request:241] Unauthorized: /api/companyPosition/update/14
[28/May/2023 07:16:55] WARNING [django.request:241] Unauthorized: /api/companyPosition/update/14
[28/May/2023 07:16:55] WARNING [django.server:212] "PUT /api/companyPosition/update/14 HTTP/1.1" 401 183
[28/May/2023 07:16:55] WARNING [django.server:212] "PUT /api/companyPosition/update/14 HTTP/1.1" 401 183
[28/May/2023 07:17:03] ERROR [django.request:241] Internal Server Error: /api/companyPosition/update/14
[28/May/2023 07:17:03] ERROR [django.request:241] Internal Server Error: /api/companyPosition/update/14
[28/May/2023 07:17:03] ERROR [django.server:212] "PUT /api/companyPosition/update/14 HTTP/1.1" 500 120
[28/May/2023 07:17:03] ERROR [django.server:212] "PUT /api/companyPosition/update/14 HTTP/1.1" 500 120
[28/May/2023 07:17:48] ERROR [django.request:241] Internal Server Error: /api/companyPosition/update/14
[28/May/2023 07:17:48] ERROR [django.request:241] Internal Server Error: /api/companyPosition/update/14
[28/May/2023 07:17:48] ERROR [django.server:212] "PUT /api/companyPosition/update/14 HTTP/1.1" 500 120
[28/May/2023 07:17:48] ERROR [django.server:212] "PUT /api/companyPosition/update/14 HTTP/1.1" 500 120
[28/May/2023 07:18:05] ERROR [django.request:241] Internal Server Error: /api/companyPosition/update/14
[28/May/2023 07:18:05] ERROR [django.request:241] Internal Server Error: /api/companyPosition/update/14
[28/May/2023 07:18:05] ERROR [django.server:212] "PUT /api/companyPosition/update/14 HTTP/1.1" 500 120
[28/May/2023 07:18:05] ERROR [django.server:212] "PUT /api/companyPosition/update/14 HTTP/1.1" 500 120
[28/May/2023 07:19:20] ERROR [django.request:241] Internal Server Error: /api/companyPosition/update/14
[28/May/2023 07:19:20] ERROR [django.request:241] Internal Server Error: /api/companyPosition/update/14
[28/May/2023 07:19:20] ERROR [django.server:212] "PUT /api/companyPosition/update/14 HTTP/1.1" 500 120
[28/May/2023 07:19:20] ERROR [django.server:212] "PUT /api/companyPosition/update/14 HTTP/1.1" 500 120
[28/May/2023 07:20:27] ERROR [django.request:241] Internal Server Error: /api/companyPosition/update/14
[28/May/2023 07:20:27] ERROR [django.request:241] Internal Server Error: /api/companyPosition/update/14
[28/May/2023 07:20:27] ERROR [django.server:212] "PUT /api/companyPosition/update/14 HTTP/1.1" 500 107
[28/May/2023 07:20:27] ERROR [django.server:212] "PUT /api/companyPosition/update/14 HTTP/1.1" 500 107
[28/May/2023 07:22:20] ERROR [django.request:241] Internal Server Error: /api/companyPosition/update/14
[28/May/2023 07:22:20] ERROR [django.request:241] Internal Server Error: /api/companyPosition/update/14
[28/May/2023 07:22:20] ERROR [django.server:212] "PUT /api/companyPosition/update/14 HTTP/1.1" 500 112
[28/May/2023 07:22:20] ERROR [django.server:212] "PUT /api/companyPosition/update/14 HTTP/1.1" 500 112
[28/May/2023 09:14:37] WARNING [django.request:241] Unauthorized: /api/companyPosition/delete/14
[28/May/2023 09:14:37] WARNING [django.request:241] Unauthorized: /api/companyPosition/delete/14
[28/May/2023 09:14:37] WARNING [django.server:212] "PUT /api/companyPosition/delete/14 HTTP/1.1" 401 183
[28/May/2023 09:14:37] WARNING [django.server:212] "PUT /api/companyPosition/delete/14 HTTP/1.1" 401 183
[28/May/2023 09:14:45] WARNING [django.request:241] Method Not Allowed: /api/companyPosition/delete/14
[28/May/2023 09:14:45] WARNING [django.request:241] Method Not Allowed: /api/companyPosition/delete/14
[28/May/2023 09:14:45] WARNING [django.server:212] "PUT /api/companyPosition/delete/14 HTTP/1.1" 405 40
[28/May/2023 09:14:45] WARNING [django.server:212] "PUT /api/companyPosition/delete/14 HTTP/1.1" 405 40
[28/May/2023 09:18:56] ERROR [django.request:241] Internal Server Error: /api/companyPermission/create
[28/May/2023 09:18:56] ERROR [django.request:241] Internal Server Error: /api/companyPermission/create
[28/May/2023 09:18:56] ERROR [django.server:212] "POST /api/companyPermission/create HTTP/1.1" 500 32
[28/May/2023 09:18:56] ERROR [django.server:212] "POST /api/companyPermission/create HTTP/1.1" 500 32
[28/May/2023 09:19:27] ERROR [django.request:241] Internal Server Error: /api/companyPermission/create
[28/May/2023 09:19:27] ERROR [django.request:241] Internal Server Error: /api/companyPermission/create
[28/May/2023 09:19:27] ERROR [django.server:212] "POST /api/companyPermission/create HTTP/1.1" 500 86
[28/May/2023 09:19:27] ERROR [django.server:212] "POST /api/companyPermission/create HTTP/1.1" 500 86
[28/May/2023 09:32:04] WARNING [django.request:241] Not Found: /api/companyPermission/delete/17
[28/May/2023 09:32:04] WARNING [django.request:241] Not Found: /api/companyPermission/delete/17
[28/May/2023 09:32:04] WARNING [django.server:212] "DELETE /api/companyPermission/delete/17 HTTP/1.1" 404 29
[28/May/2023 09:32:04] WARNING [django.server:212] "DELETE /api/companyPermission/delete/17 HTTP/1.1" 404 29
