[20/Oct/2023 16:25:27] ERROR [django.request:241] Internal Server Error: /api/login
Traceback (most recent call last):
  File "/usr/local/lib/python3.10/site-packages/django/db/backends/utils.py", line 89, in _execute
    return self.cursor.execute(sql, params)
psycopg2.errors.UndefinedColumn: column api_useraccount.type does not exist
LINE 1: ..."."last_login", "api_useraccount"."is_superuser", "api_usera...
                                                             ^


The above exception was the direct cause of the following exception:

Traceback (most recent call last):
  File "/usr/local/lib/python3.10/site-packages/django/core/handlers/exception.py", line 55, in inner
    response = get_response(request)
  File "/usr/local/lib/python3.10/site-packages/django/core/handlers/base.py", line 197, in _get_response
    response = wrapped_callback(request, *callback_args, **callback_kwargs)
  File "/usr/local/lib/python3.10/site-packages/django/views/decorators/csrf.py", line 56, in wrapper_view
    return view_func(*args, **kwargs)
  File "/usr/local/lib/python3.10/site-packages/django/views/generic/base.py", line 104, in view
    return self.dispatch(request, *args, **kwargs)
  File "/usr/local/lib/python3.10/site-packages/rest_framework/views.py", line 509, in dispatch
    response = self.handle_exception(exc)
  File "/usr/local/lib/python3.10/site-packages/rest_framework/views.py", line 469, in handle_exception
    self.raise_uncaught_exception(exc)
  File "/usr/local/lib/python3.10/site-packages/rest_framework/views.py", line 480, in raise_uncaught_exception
    raise exc
  File "/usr/local/lib/python3.10/site-packages/rest_framework/views.py", line 506, in dispatch
    response = handler(request, *args, **kwargs)
  File "/usr/local/lib/python3.10/site-packages/rest_framework_simplejwt/views.py", line 43, in post
    serializer.is_valid(raise_exception=True)
  File "/usr/local/lib/python3.10/site-packages/rest_framework/serializers.py", line 227, in is_valid
    self._validated_data = self.run_validation(self.initial_data)
  File "/usr/local/lib/python3.10/site-packages/rest_framework/serializers.py", line 429, in run_validation
    value = self.validate(value)
  File "/app/backend/api/customToken.py", line 114, in validate
    user = UserAccount.objects.filter(email=attrs.get('email')).first()
  File "/usr/local/lib/python3.10/site-packages/django/db/models/query.py", line 1057, in first
    for obj in queryset[:1]:
  File "/usr/local/lib/python3.10/site-packages/django/db/models/query.py", line 398, in __iter__
    self._fetch_all()
  File "/usr/local/lib/python3.10/site-packages/django/db/models/query.py", line 1881, in _fetch_all
    self._result_cache = list(self._iterable_class(self))
  File "/usr/local/lib/python3.10/site-packages/django/db/models/query.py", line 91, in __iter__
    results = compiler.execute_sql(
  File "/usr/local/lib/python3.10/site-packages/django/db/models/sql/compiler.py", line 1560, in execute_sql
    cursor.execute(sql, params)
  File "/usr/local/lib/python3.10/site-packages/django/db/backends/utils.py", line 102, in execute
    return super().execute(sql, params)
  File "/usr/local/lib/python3.10/site-packages/django/db/backends/utils.py", line 67, in execute
    return self._execute_with_wrappers(
  File "/usr/local/lib/python3.10/site-packages/django/db/backends/utils.py", line 80, in _execute_with_wrappers
    return executor(sql, params, many, context)
  File "/usr/local/lib/python3.10/site-packages/django/db/backends/utils.py", line 84, in _execute
    with self.db.wrap_database_errors:
  File "/usr/local/lib/python3.10/site-packages/django/db/utils.py", line 91, in __exit__
    raise dj_exc_value.with_traceback(traceback) from exc_value
  File "/usr/local/lib/python3.10/site-packages/django/db/backends/utils.py", line 89, in _execute
    return self.cursor.execute(sql, params)
django.db.utils.ProgrammingError: column api_useraccount.type does not exist
LINE 1: ..."."last_login", "api_useraccount"."is_superuser", "api_usera...
                                                             ^

[20/Oct/2023 16:25:27] ERROR [django.request:241] Internal Server Error: /api/login
Traceback (most recent call last):
  File "/usr/local/lib/python3.10/site-packages/django/db/backends/utils.py", line 89, in _execute
    return self.cursor.execute(sql, params)
psycopg2.errors.UndefinedColumn: column api_useraccount.type does not exist
LINE 1: ..."."last_login", "api_useraccount"."is_superuser", "api_usera...
                                                             ^


The above exception was the direct cause of the following exception:

Traceback (most recent call last):
  File "/usr/local/lib/python3.10/site-packages/django/core/handlers/exception.py", line 55, in inner
    response = get_response(request)
  File "/usr/local/lib/python3.10/site-packages/django/core/handlers/base.py", line 197, in _get_response
    response = wrapped_callback(request, *callback_args, **callback_kwargs)
  File "/usr/local/lib/python3.10/site-packages/django/views/decorators/csrf.py", line 56, in wrapper_view
    return view_func(*args, **kwargs)
  File "/usr/local/lib/python3.10/site-packages/django/views/generic/base.py", line 104, in view
    return self.dispatch(request, *args, **kwargs)
  File "/usr/local/lib/python3.10/site-packages/rest_framework/views.py", line 509, in dispatch
    response = self.handle_exception(exc)
  File "/usr/local/lib/python3.10/site-packages/rest_framework/views.py", line 469, in handle_exception
    self.raise_uncaught_exception(exc)
  File "/usr/local/lib/python3.10/site-packages/rest_framework/views.py", line 480, in raise_uncaught_exception
    raise exc
  File "/usr/local/lib/python3.10/site-packages/rest_framework/views.py", line 506, in dispatch
    response = handler(request, *args, **kwargs)
  File "/usr/local/lib/python3.10/site-packages/rest_framework_simplejwt/views.py", line 43, in post
    serializer.is_valid(raise_exception=True)
  File "/usr/local/lib/python3.10/site-packages/rest_framework/serializers.py", line 227, in is_valid
    self._validated_data = self.run_validation(self.initial_data)
  File "/usr/local/lib/python3.10/site-packages/rest_framework/serializers.py", line 429, in run_validation
    value = self.validate(value)
  File "/app/backend/api/customToken.py", line 114, in validate
    user = UserAccount.objects.filter(email=attrs.get('email')).first()
  File "/usr/local/lib/python3.10/site-packages/django/db/models/query.py", line 1057, in first
    for obj in queryset[:1]:
  File "/usr/local/lib/python3.10/site-packages/django/db/models/query.py", line 398, in __iter__
    self._fetch_all()
  File "/usr/local/lib/python3.10/site-packages/django/db/models/query.py", line 1881, in _fetch_all
    self._result_cache = list(self._iterable_class(self))
  File "/usr/local/lib/python3.10/site-packages/django/db/models/query.py", line 91, in __iter__
    results = compiler.execute_sql(
  File "/usr/local/lib/python3.10/site-packages/django/db/models/sql/compiler.py", line 1560, in execute_sql
    cursor.execute(sql, params)
  File "/usr/local/lib/python3.10/site-packages/django/db/backends/utils.py", line 102, in execute
    return super().execute(sql, params)
  File "/usr/local/lib/python3.10/site-packages/django/db/backends/utils.py", line 67, in execute
    return self._execute_with_wrappers(
  File "/usr/local/lib/python3.10/site-packages/django/db/backends/utils.py", line 80, in _execute_with_wrappers
    return executor(sql, params, many, context)
  File "/usr/local/lib/python3.10/site-packages/django/db/backends/utils.py", line 84, in _execute
    with self.db.wrap_database_errors:
  File "/usr/local/lib/python3.10/site-packages/django/db/utils.py", line 91, in __exit__
    raise dj_exc_value.with_traceback(traceback) from exc_value
  File "/usr/local/lib/python3.10/site-packages/django/db/backends/utils.py", line 89, in _execute
    return self.cursor.execute(sql, params)
django.db.utils.ProgrammingError: column api_useraccount.type does not exist
LINE 1: ..."."last_login", "api_useraccount"."is_superuser", "api_usera...
                                                             ^

[20/Oct/2023 16:25:27] ERROR [django.server:212] "POST /api/login HTTP/1.1" 500 163434
[20/Oct/2023 16:25:27] ERROR [django.server:212] "POST /api/login HTTP/1.1" 500 163434
[20/Oct/2023 16:43:17] WARNING [django.request:241] Not Found: /api/company/check-in/0
[20/Oct/2023 16:43:17] WARNING [django.request:241] Not Found: /api/company/check-in/0
[20/Oct/2023 16:43:17] WARNING [django.server:212] "GET /api/company/check-in/0 HTTP/1.1" 404 23
[20/Oct/2023 16:43:17] WARNING [django.server:212] "GET /api/company/check-in/0 HTTP/1.1" 404 23
[20/Oct/2023 16:43:17] WARNING [django.request:241] Not Found: /api/company/check-in/0
[20/Oct/2023 16:43:17] WARNING [django.request:241] Not Found: /api/company/check-in/0
[20/Oct/2023 16:43:17] WARNING [django.server:212] "GET /api/company/check-in/0 HTTP/1.1" 404 23
[20/Oct/2023 16:43:17] WARNING [django.server:212] "GET /api/company/check-in/0 HTTP/1.1" 404 23
[20/Oct/2023 16:43:17] WARNING [django.request:241] Not Found: /api/company/check-in/0
[20/Oct/2023 16:43:17] WARNING [django.request:241] Not Found: /api/company/check-in/0
[20/Oct/2023 16:43:17] WARNING [django.server:212] "GET /api/company/check-in/0 HTTP/1.1" 404 23
[20/Oct/2023 16:43:17] WARNING [django.server:212] "GET /api/company/check-in/0 HTTP/1.1" 404 23
[20/Oct/2023 16:43:50] WARNING [django.request:241] Bad Request: /api/user/update/1
[20/Oct/2023 16:43:50] WARNING [django.request:241] Bad Request: /api/user/update/1
[20/Oct/2023 16:43:50] WARNING [django.server:212] "PUT /api/user/update/1 HTTP/1.1" 400 184
[20/Oct/2023 16:43:50] WARNING [django.server:212] "PUT /api/user/update/1 HTTP/1.1" 400 184
[20/Oct/2023 16:44:09] ERROR [django.request:241] Internal Server Error: /api/companyEmployee/create
[20/Oct/2023 16:44:09] ERROR [django.request:241] Internal Server Error: /api/companyEmployee/create
[20/Oct/2023 16:44:09] ERROR [django.server:212] "POST /api/companyEmployee/create HTTP/1.1" 500 55
[20/Oct/2023 16:44:09] ERROR [django.server:212] "POST /api/companyEmployee/create HTTP/1.1" 500 55
[20/Oct/2023 16:50:49] WARNING [django.request:241] Not Found: /api/getTasksByTfId/get/NaN
[20/Oct/2023 16:50:49] WARNING [django.request:241] Not Found: /api/getTasksByTfId/get/NaN
[20/Oct/2023 16:50:49] WARNING [django.server:212] "GET /api/getTasksByTfId/get/NaN HTTP/1.1" 404 35646
[20/Oct/2023 16:50:49] WARNING [django.server:212] "GET /api/getTasksByTfId/get/NaN HTTP/1.1" 404 35646
[20/Oct/2023 16:51:58] ERROR [django.request:241] Internal Server Error: /api/companyEmployee/create
[20/Oct/2023 16:51:58] ERROR [django.request:241] Internal Server Error: /api/companyEmployee/create
[20/Oct/2023 16:51:58] ERROR [django.server:212] "POST /api/companyEmployee/create HTTP/1.1" 500 55
[20/Oct/2023 16:51:58] ERROR [django.server:212] "POST /api/companyEmployee/create HTTP/1.1" 500 55
[20/Oct/2023 16:52:23] WARNING [django.request:241] Bad Request: /api/createTasks
[20/Oct/2023 16:52:23] WARNING [django.request:241] Bad Request: /api/createTasks
[20/Oct/2023 16:52:23] WARNING [django.server:212] "POST /api/createTasks HTTP/1.1" 400 155
[20/Oct/2023 16:52:23] WARNING [django.server:212] "POST /api/createTasks HTTP/1.1" 400 155
[20/Oct/2023 16:52:29] WARNING [django.request:241] Bad Request: /api/createTasks
[20/Oct/2023 16:52:29] WARNING [django.request:241] Bad Request: /api/createTasks
[20/Oct/2023 16:52:29] WARNING [django.server:212] "POST /api/createTasks HTTP/1.1" 400 155
[20/Oct/2023 16:52:29] WARNING [django.server:212] "POST /api/createTasks HTTP/1.1" 400 155
[20/Oct/2023 16:53:49] WARNING [django.request:241] Bad Request: /api/createTasks
[20/Oct/2023 16:53:49] WARNING [django.request:241] Bad Request: /api/createTasks
[20/Oct/2023 16:53:49] WARNING [django.server:212] "POST /api/createTasks HTTP/1.1" 400 155
[20/Oct/2023 16:53:49] WARNING [django.server:212] "POST /api/createTasks HTTP/1.1" 400 155
[20/Oct/2023 16:54:18] WARNING [django.request:241] Bad Request: /api/user/update/1
[20/Oct/2023 16:54:18] WARNING [django.request:241] Bad Request: /api/user/update/1
[20/Oct/2023 16:54:18] WARNING [django.server:212] "PUT /api/user/update/1 HTTP/1.1" 400 184
[20/Oct/2023 16:54:18] WARNING [django.server:212] "PUT /api/user/update/1 HTTP/1.1" 400 184
[20/Oct/2023 16:56:23] WARNING [django.request:241] Not Found: /api/user/update/2
[20/Oct/2023 16:56:23] WARNING [django.request:241] Not Found: /api/user/update/2
[20/Oct/2023 16:56:23] WARNING [django.server:212] "PUT /api/user/update/2 HTTP/1.1" 404 26
[20/Oct/2023 16:56:23] WARNING [django.server:212] "PUT /api/user/update/2 HTTP/1.1" 404 26
[20/Oct/2023 16:58:49] WARNING [django.request:241] Bad Request: /api/user/update/1
[20/Oct/2023 16:58:49] WARNING [django.request:241] Bad Request: /api/user/update/1
[20/Oct/2023 16:58:49] WARNING [django.server:212] "PUT /api/user/update/1 HTTP/1.1" 400 184
[20/Oct/2023 16:58:49] WARNING [django.server:212] "PUT /api/user/update/1 HTTP/1.1" 400 184
[20/Oct/2023 17:00:07] WARNING [django.request:241] Bad Request: /api/user/update/1
[20/Oct/2023 17:00:07] WARNING [django.request:241] Bad Request: /api/user/update/1
[20/Oct/2023 17:00:07] WARNING [django.server:212] "PUT /api/user/update/1 HTTP/1.1" 400 184
[20/Oct/2023 17:00:07] WARNING [django.server:212] "PUT /api/user/update/1 HTTP/1.1" 400 184
[20/Oct/2023 17:03:16] WARNING [django.request:241] Bad Request: /api/createTasks
[20/Oct/2023 17:03:16] WARNING [django.request:241] Bad Request: /api/createTasks
[20/Oct/2023 17:03:16] WARNING [django.server:212] "POST /api/createTasks HTTP/1.1" 400 42
[20/Oct/2023 17:03:16] WARNING [django.server:212] "POST /api/createTasks HTTP/1.1" 400 42
[20/Oct/2023 17:03:55] WARNING [django.request:241] Bad Request: /api/createTasks
[20/Oct/2023 17:03:55] WARNING [django.request:241] Bad Request: /api/createTasks
[20/Oct/2023 17:03:55] WARNING [django.server:212] "POST /api/createTasks HTTP/1.1" 400 68
[20/Oct/2023 17:03:55] WARNING [django.server:212] "POST /api/createTasks HTTP/1.1" 400 68
[20/Oct/2023 17:04:30] WARNING [django.request:241] Bad Request: /api/createTasks
[20/Oct/2023 17:04:30] WARNING [django.request:241] Bad Request: /api/createTasks
[20/Oct/2023 17:04:30] WARNING [django.server:212] "POST /api/createTasks HTTP/1.1" 400 46
[20/Oct/2023 17:04:30] WARNING [django.server:212] "POST /api/createTasks HTTP/1.1" 400 46
[20/Oct/2023 17:08:48] ERROR [django.security.DisallowedHost:124] Invalid HTTP_HOST header: '61.231.64.27:8000'. You may need to add '61.231.64.27' to ALLOWED_HOSTS.
Traceback (most recent call last):
  File "/usr/local/lib/python3.10/site-packages/django/core/handlers/exception.py", line 55, in inner
    response = get_response(request)
  File "/usr/local/lib/python3.10/site-packages/django/utils/deprecation.py", line 133, in __call__
    response = self.process_request(request)
  File "/usr/local/lib/python3.10/site-packages/django/middleware/common.py", line 48, in process_request
    host = request.get_host()
  File "/usr/local/lib/python3.10/site-packages/django/http/request.py", line 167, in get_host
    raise DisallowedHost(msg)
django.core.exceptions.DisallowedHost: Invalid HTTP_HOST header: '61.231.64.27:8000'. You may need to add '61.231.64.27' to ALLOWED_HOSTS.
[20/Oct/2023 17:08:48] ERROR [django.security.DisallowedHost:124] Invalid HTTP_HOST header: '61.231.64.27:8000'. You may need to add '61.231.64.27' to ALLOWED_HOSTS.
Traceback (most recent call last):
  File "/usr/local/lib/python3.10/site-packages/django/core/handlers/exception.py", line 55, in inner
    response = get_response(request)
  File "/usr/local/lib/python3.10/site-packages/django/utils/deprecation.py", line 133, in __call__
    response = self.process_request(request)
  File "/usr/local/lib/python3.10/site-packages/django/middleware/common.py", line 48, in process_request
    host = request.get_host()
  File "/usr/local/lib/python3.10/site-packages/django/http/request.py", line 167, in get_host
    raise DisallowedHost(msg)
django.core.exceptions.DisallowedHost: Invalid HTTP_HOST header: '61.231.64.27:8000'. You may need to add '61.231.64.27' to ALLOWED_HOSTS.
[20/Oct/2023 17:08:48] WARNING [django.request:241] Bad Request: /
[20/Oct/2023 17:08:48] WARNING [django.request:241] Bad Request: /
[20/Oct/2023 17:08:48] WARNING [django.server:212] "GET / HTTP/1.1" 400 63180
[20/Oct/2023 17:08:48] WARNING [django.server:212] "GET / HTTP/1.1" 400 63180
[20/Oct/2023 17:09:25] ERROR [django.security.DisallowedHost:124] Invalid HTTP_HOST header: '61.231.64.27:8000'. You may need to add '61.231.64.27' to ALLOWED_HOSTS.
Traceback (most recent call last):
  File "/usr/local/lib/python3.10/site-packages/django/core/handlers/exception.py", line 55, in inner
    response = get_response(request)
  File "/usr/local/lib/python3.10/site-packages/django/utils/deprecation.py", line 133, in __call__
    response = self.process_request(request)
  File "/usr/local/lib/python3.10/site-packages/django/middleware/common.py", line 48, in process_request
    host = request.get_host()
  File "/usr/local/lib/python3.10/site-packages/django/http/request.py", line 167, in get_host
    raise DisallowedHost(msg)
django.core.exceptions.DisallowedHost: Invalid HTTP_HOST header: '61.231.64.27:8000'. You may need to add '61.231.64.27' to ALLOWED_HOSTS.
[20/Oct/2023 17:09:25] ERROR [django.security.DisallowedHost:124] Invalid HTTP_HOST header: '61.231.64.27:8000'. You may need to add '61.231.64.27' to ALLOWED_HOSTS.
Traceback (most recent call last):
  File "/usr/local/lib/python3.10/site-packages/django/core/handlers/exception.py", line 55, in inner
    response = get_response(request)
  File "/usr/local/lib/python3.10/site-packages/django/utils/deprecation.py", line 133, in __call__
    response = self.process_request(request)
  File "/usr/local/lib/python3.10/site-packages/django/middleware/common.py", line 48, in process_request
    host = request.get_host()
  File "/usr/local/lib/python3.10/site-packages/django/http/request.py", line 167, in get_host
    raise DisallowedHost(msg)
django.core.exceptions.DisallowedHost: Invalid HTTP_HOST header: '61.231.64.27:8000'. You may need to add '61.231.64.27' to ALLOWED_HOSTS.
[20/Oct/2023 17:09:25] WARNING [django.request:241] Bad Request: /admin/
[20/Oct/2023 17:09:25] WARNING [django.request:241] Bad Request: /admin/
[20/Oct/2023 17:09:25] WARNING [django.server:212] "GET /admin/ HTTP/1.1" 400 63344
[20/Oct/2023 17:09:25] WARNING [django.server:212] "GET /admin/ HTTP/1.1" 400 63344
[20/Oct/2023 17:09:26] ERROR [django.security.DisallowedHost:124] Invalid HTTP_HOST header: '61.231.64.27:8000'. You may need to add '61.231.64.27' to ALLOWED_HOSTS.
Traceback (most recent call last):
  File "/usr/local/lib/python3.10/site-packages/django/core/handlers/exception.py", line 55, in inner
    response = get_response(request)
  File "/usr/local/lib/python3.10/site-packages/django/utils/deprecation.py", line 133, in __call__
    response = self.process_request(request)
  File "/usr/local/lib/python3.10/site-packages/django/middleware/common.py", line 48, in process_request
    host = request.get_host()
  File "/usr/local/lib/python3.10/site-packages/django/http/request.py", line 167, in get_host
    raise DisallowedHost(msg)
django.core.exceptions.DisallowedHost: Invalid HTTP_HOST header: '61.231.64.27:8000'. You may need to add '61.231.64.27' to ALLOWED_HOSTS.
[20/Oct/2023 17:09:26] ERROR [django.security.DisallowedHost:124] Invalid HTTP_HOST header: '61.231.64.27:8000'. You may need to add '61.231.64.27' to ALLOWED_HOSTS.
Traceback (most recent call last):
  File "/usr/local/lib/python3.10/site-packages/django/core/handlers/exception.py", line 55, in inner
    response = get_response(request)
  File "/usr/local/lib/python3.10/site-packages/django/utils/deprecation.py", line 133, in __call__
    response = self.process_request(request)
  File "/usr/local/lib/python3.10/site-packages/django/middleware/common.py", line 48, in process_request
    host = request.get_host()
  File "/usr/local/lib/python3.10/site-packages/django/http/request.py", line 167, in get_host
    raise DisallowedHost(msg)
django.core.exceptions.DisallowedHost: Invalid HTTP_HOST header: '61.231.64.27:8000'. You may need to add '61.231.64.27' to ALLOWED_HOSTS.
[20/Oct/2023 17:09:26] WARNING [django.request:241] Bad Request: /
[20/Oct/2023 17:09:26] WARNING [django.request:241] Bad Request: /
[20/Oct/2023 17:09:26] WARNING [django.server:212] "GET / HTTP/1.1" 400 63180
[20/Oct/2023 17:09:26] WARNING [django.server:212] "GET / HTTP/1.1" 400 63180
[20/Oct/2023 17:09:27] ERROR [django.security.DisallowedHost:124] Invalid HTTP_HOST header: '61.231.64.27:8000'. You may need to add '61.231.64.27' to ALLOWED_HOSTS.
Traceback (most recent call last):
  File "/usr/local/lib/python3.10/site-packages/django/core/handlers/exception.py", line 55, in inner
    response = get_response(request)
  File "/usr/local/lib/python3.10/site-packages/django/utils/deprecation.py", line 133, in __call__
    response = self.process_request(request)
  File "/usr/local/lib/python3.10/site-packages/django/middleware/common.py", line 48, in process_request
    host = request.get_host()
  File "/usr/local/lib/python3.10/site-packages/django/http/request.py", line 167, in get_host
    raise DisallowedHost(msg)
django.core.exceptions.DisallowedHost: Invalid HTTP_HOST header: '61.231.64.27:8000'. You may need to add '61.231.64.27' to ALLOWED_HOSTS.
[20/Oct/2023 17:09:27] ERROR [django.security.DisallowedHost:124] Invalid HTTP_HOST header: '61.231.64.27:8000'. You may need to add '61.231.64.27' to ALLOWED_HOSTS.
Traceback (most recent call last):
  File "/usr/local/lib/python3.10/site-packages/django/core/handlers/exception.py", line 55, in inner
    response = get_response(request)
  File "/usr/local/lib/python3.10/site-packages/django/utils/deprecation.py", line 133, in __call__
    response = self.process_request(request)
  File "/usr/local/lib/python3.10/site-packages/django/middleware/common.py", line 48, in process_request
    host = request.get_host()
  File "/usr/local/lib/python3.10/site-packages/django/http/request.py", line 167, in get_host
    raise DisallowedHost(msg)
django.core.exceptions.DisallowedHost: Invalid HTTP_HOST header: '61.231.64.27:8000'. You may need to add '61.231.64.27' to ALLOWED_HOSTS.
[20/Oct/2023 17:09:27] WARNING [django.request:241] Bad Request: /api/session/properties
[20/Oct/2023 17:09:27] WARNING [django.request:241] Bad Request: /api/session/properties
[20/Oct/2023 17:09:27] WARNING [django.server:212] "GET /api/session/properties HTTP/1.1" 400 63422
[20/Oct/2023 17:09:27] WARNING [django.server:212] "GET /api/session/properties HTTP/1.1" 400 63422
[20/Oct/2023 17:09:29] ERROR [django.request:241] Internal Server Error: /api/getTasksByTfId/get/2
[20/Oct/2023 17:09:29] ERROR [django.request:241] Internal Server Error: /api/getTasksByTfId/get/2
[20/Oct/2023 17:09:29] ERROR [django.server:212] "GET /api/getTasksByTfId/get/2 HTTP/1.1" 500 188
[20/Oct/2023 17:09:29] ERROR [django.server:212] "GET /api/getTasksByTfId/get/2 HTTP/1.1" 500 188
[20/Oct/2023 17:09:37] ERROR [django.request:241] Internal Server Error: /api/getTasksByTfId/get/2
[20/Oct/2023 17:09:37] ERROR [django.request:241] Internal Server Error: /api/getTasksByTfId/get/2
[20/Oct/2023 17:09:37] ERROR [django.server:212] "GET /api/getTasksByTfId/get/2 HTTP/1.1" 500 188
[20/Oct/2023 17:09:37] ERROR [django.server:212] "GET /api/getTasksByTfId/get/2 HTTP/1.1" 500 188
[20/Oct/2023 17:12:37] WARNING [django.request:241] Not Found: /api/company/check-in/0
[20/Oct/2023 17:12:37] WARNING [django.request:241] Not Found: /api/company/check-in/0
[20/Oct/2023 17:12:37] WARNING [django.server:212] "GET /api/company/check-in/0 HTTP/1.1" 404 23
[20/Oct/2023 17:12:37] WARNING [django.server:212] "GET /api/company/check-in/0 HTTP/1.1" 404 23
[20/Oct/2023 17:12:37] WARNING [django.request:241] Not Found: /api/company/check-in/0
[20/Oct/2023 17:12:37] WARNING [django.request:241] Not Found: /api/company/check-in/0
[20/Oct/2023 17:12:37] WARNING [django.server:212] "GET /api/company/check-in/0 HTTP/1.1" 404 23
[20/Oct/2023 17:12:37] WARNING [django.server:212] "GET /api/company/check-in/0 HTTP/1.1" 404 23
[20/Oct/2023 17:12:37] WARNING [django.request:241] Not Found: /api/company/check-in/0
[20/Oct/2023 17:12:37] WARNING [django.request:241] Not Found: /api/company/check-in/0
[20/Oct/2023 17:12:37] WARNING [django.server:212] "GET /api/company/check-in/0 HTTP/1.1" 404 23
[20/Oct/2023 17:12:37] WARNING [django.server:212] "GET /api/company/check-in/0 HTTP/1.1" 404 23
[20/Oct/2023 17:12:37] WARNING [django.request:241] Not Found: /api/company/check-in/0
[20/Oct/2023 17:12:37] WARNING [django.request:241] Not Found: /api/company/check-in/0
[20/Oct/2023 17:12:37] WARNING [django.server:212] "GET /api/company/check-in/0 HTTP/1.1" 404 23
[20/Oct/2023 17:12:37] WARNING [django.server:212] "GET /api/company/check-in/0 HTTP/1.1" 404 23
[20/Oct/2023 17:12:48] WARNING [django.request:241] Not Found: /api/companyEmployeeLeave/get/employee/all/null
[20/Oct/2023 17:12:48] WARNING [django.request:241] Not Found: /api/companyEmployeeLeave/get/employee/all/null
[20/Oct/2023 17:12:48] WARNING [django.server:212] "GET /api/companyEmployeeLeave/get/employee/all/null HTTP/1.1" 404 35706
[20/Oct/2023 17:12:48] WARNING [django.server:212] "GET /api/companyEmployeeLeave/get/employee/all/null HTTP/1.1" 404 35706
[20/Oct/2023 17:12:50] WARNING [django.request:241] Not Found: /api/company/check-in/0
[20/Oct/2023 17:12:50] WARNING [django.request:241] Not Found: /api/company/check-in/0
[20/Oct/2023 17:12:50] WARNING [django.server:212] "GET /api/company/check-in/0 HTTP/1.1" 404 23
[20/Oct/2023 17:12:50] WARNING [django.server:212] "GET /api/company/check-in/0 HTTP/1.1" 404 23
[20/Oct/2023 17:12:50] WARNING [django.request:241] Not Found: /api/company/check-in/0
[20/Oct/2023 17:12:50] WARNING [django.request:241] Not Found: /api/company/check-in/0
[20/Oct/2023 17:12:50] WARNING [django.server:212] "GET /api/company/check-in/0 HTTP/1.1" 404 23
[20/Oct/2023 17:12:50] WARNING [django.server:212] "GET /api/company/check-in/0 HTTP/1.1" 404 23
[20/Oct/2023 17:12:50] WARNING [django.request:241] Not Found: /api/company/check-in/0
[20/Oct/2023 17:12:50] WARNING [django.request:241] Not Found: /api/company/check-in/0
[20/Oct/2023 17:12:50] WARNING [django.server:212] "GET /api/company/check-in/0 HTTP/1.1" 404 23
[20/Oct/2023 17:12:50] WARNING [django.server:212] "GET /api/company/check-in/0 HTTP/1.1" 404 23
[20/Oct/2023 17:15:57] WARNING [django.request:241] Unauthorized: /api/getTaskForcesByCompany/get/1
[20/Oct/2023 17:15:57] WARNING [django.request:241] Unauthorized: /api/getTaskForcesByCompany/get/1
[20/Oct/2023 17:15:57] WARNING [django.server:212] "GET /api/getTaskForcesByCompany/get/1 HTTP/1.1" 401 183
[20/Oct/2023 17:15:57] WARNING [django.server:212] "GET /api/getTaskForcesByCompany/get/1 HTTP/1.1" 401 183
[20/Oct/2023 17:16:18] WARNING [django.request:241] Bad Request: /api/updateTaskForces/1
[20/Oct/2023 17:16:18] WARNING [django.request:241] Bad Request: /api/updateTaskForces/1
[20/Oct/2023 17:16:18] WARNING [django.server:212] "PUT /api/updateTaskForces/1 HTTP/1.1" 400 155
[20/Oct/2023 17:16:18] WARNING [django.server:212] "PUT /api/updateTaskForces/1 HTTP/1.1" 400 155
[20/Oct/2023 17:19:44] ERROR [django.request:241] Internal Server Error: /api/verify
Traceback (most recent call last):
  File "/usr/local/lib/python3.10/site-packages/rest_framework_simplejwt/backends.py", line 137, in decode
    return jwt.decode(
  File "/usr/local/lib/python3.10/site-packages/jwt/api_jwt.py", line 210, in decode
    decoded = self.decode_complete(
  File "/usr/local/lib/python3.10/site-packages/jwt/api_jwt.py", line 162, in decode_complete
    self._validate_claims(
  File "/usr/local/lib/python3.10/site-packages/jwt/api_jwt.py", line 248, in _validate_claims
    self._validate_exp(payload, now, leeway)
  File "/usr/local/lib/python3.10/site-packages/jwt/api_jwt.py", line 304, in _validate_exp
    raise ExpiredSignatureError("Signature has expired")
jwt.exceptions.ExpiredSignatureError: Signature has expired

The above exception was the direct cause of the following exception:

Traceback (most recent call last):
  File "/usr/local/lib/python3.10/site-packages/rest_framework_simplejwt/tokens.py", line 42, in __init__
    self.payload = token_backend.decode(token, verify=verify)
  File "/usr/local/lib/python3.10/site-packages/rest_framework_simplejwt/backends.py", line 152, in decode
    raise TokenBackendError(_("Token is invalid or expired")) from ex
rest_framework_simplejwt.exceptions.TokenBackendError: Token is invalid or expired

During handling of the above exception, another exception occurred:

Traceback (most recent call last):
  File "/usr/local/lib/python3.10/site-packages/django/core/handlers/exception.py", line 55, in inner
    response = get_response(request)
  File "/usr/local/lib/python3.10/site-packages/django/core/handlers/base.py", line 197, in _get_response
    response = wrapped_callback(request, *callback_args, **callback_kwargs)
  File "/usr/local/lib/python3.10/site-packages/django/views/decorators/csrf.py", line 56, in wrapper_view
    return view_func(*args, **kwargs)
  File "/usr/local/lib/python3.10/site-packages/django/views/generic/base.py", line 104, in view
    return self.dispatch(request, *args, **kwargs)
  File "/usr/local/lib/python3.10/site-packages/rest_framework/views.py", line 509, in dispatch
    response = self.handle_exception(exc)
  File "/usr/local/lib/python3.10/site-packages/rest_framework/views.py", line 469, in handle_exception
    self.raise_uncaught_exception(exc)
  File "/usr/local/lib/python3.10/site-packages/rest_framework/views.py", line 480, in raise_uncaught_exception
    raise exc
  File "/usr/local/lib/python3.10/site-packages/rest_framework/views.py", line 506, in dispatch
    response = handler(request, *args, **kwargs)
  File "/usr/local/lib/python3.10/site-packages/rest_framework/decorators.py", line 50, in handler
    return func(*args, **kwargs)
  File "/app/backend/api/views.py", line 64, in verify
    token = AccessToken(access_token)
  File "/usr/local/lib/python3.10/site-packages/rest_framework_simplejwt/tokens.py", line 44, in __init__
    raise TokenError(_("Token is invalid or expired"))
rest_framework_simplejwt.exceptions.TokenError: Token is invalid or expired
[20/Oct/2023 17:19:44] ERROR [django.request:241] Internal Server Error: /api/verify
Traceback (most recent call last):
  File "/usr/local/lib/python3.10/site-packages/rest_framework_simplejwt/backends.py", line 137, in decode
    return jwt.decode(
  File "/usr/local/lib/python3.10/site-packages/jwt/api_jwt.py", line 210, in decode
    decoded = self.decode_complete(
  File "/usr/local/lib/python3.10/site-packages/jwt/api_jwt.py", line 162, in decode_complete
    self._validate_claims(
  File "/usr/local/lib/python3.10/site-packages/jwt/api_jwt.py", line 248, in _validate_claims
    self._validate_exp(payload, now, leeway)
  File "/usr/local/lib/python3.10/site-packages/jwt/api_jwt.py", line 304, in _validate_exp
    raise ExpiredSignatureError("Signature has expired")
jwt.exceptions.ExpiredSignatureError: Signature has expired

The above exception was the direct cause of the following exception:

Traceback (most recent call last):
  File "/usr/local/lib/python3.10/site-packages/rest_framework_simplejwt/tokens.py", line 42, in __init__
    self.payload = token_backend.decode(token, verify=verify)
  File "/usr/local/lib/python3.10/site-packages/rest_framework_simplejwt/backends.py", line 152, in decode
    raise TokenBackendError(_("Token is invalid or expired")) from ex
rest_framework_simplejwt.exceptions.TokenBackendError: Token is invalid or expired

During handling of the above exception, another exception occurred:

Traceback (most recent call last):
  File "/usr/local/lib/python3.10/site-packages/django/core/handlers/exception.py", line 55, in inner
    response = get_response(request)
  File "/usr/local/lib/python3.10/site-packages/django/core/handlers/base.py", line 197, in _get_response
    response = wrapped_callback(request, *callback_args, **callback_kwargs)
  File "/usr/local/lib/python3.10/site-packages/django/views/decorators/csrf.py", line 56, in wrapper_view
    return view_func(*args, **kwargs)
  File "/usr/local/lib/python3.10/site-packages/django/views/generic/base.py", line 104, in view
    return self.dispatch(request, *args, **kwargs)
  File "/usr/local/lib/python3.10/site-packages/rest_framework/views.py", line 509, in dispatch
    response = self.handle_exception(exc)
  File "/usr/local/lib/python3.10/site-packages/rest_framework/views.py", line 469, in handle_exception
    self.raise_uncaught_exception(exc)
  File "/usr/local/lib/python3.10/site-packages/rest_framework/views.py", line 480, in raise_uncaught_exception
    raise exc
  File "/usr/local/lib/python3.10/site-packages/rest_framework/views.py", line 506, in dispatch
    response = handler(request, *args, **kwargs)
  File "/usr/local/lib/python3.10/site-packages/rest_framework/decorators.py", line 50, in handler
    return func(*args, **kwargs)
  File "/app/backend/api/views.py", line 64, in verify
    token = AccessToken(access_token)
  File "/usr/local/lib/python3.10/site-packages/rest_framework_simplejwt/tokens.py", line 44, in __init__
    raise TokenError(_("Token is invalid or expired"))
rest_framework_simplejwt.exceptions.TokenError: Token is invalid or expired
[20/Oct/2023 17:19:44] ERROR [django.request:241] Internal Server Error: /api/verify
Traceback (most recent call last):
  File "/usr/local/lib/python3.10/site-packages/rest_framework_simplejwt/backends.py", line 137, in decode
    return jwt.decode(
  File "/usr/local/lib/python3.10/site-packages/jwt/api_jwt.py", line 210, in decode
    decoded = self.decode_complete(
  File "/usr/local/lib/python3.10/site-packages/jwt/api_jwt.py", line 162, in decode_complete
    self._validate_claims(
  File "/usr/local/lib/python3.10/site-packages/jwt/api_jwt.py", line 248, in _validate_claims
    self._validate_exp(payload, now, leeway)
  File "/usr/local/lib/python3.10/site-packages/jwt/api_jwt.py", line 304, in _validate_exp
    raise ExpiredSignatureError("Signature has expired")
jwt.exceptions.ExpiredSignatureError: Signature has expired

The above exception was the direct cause of the following exception:

Traceback (most recent call last):
  File "/usr/local/lib/python3.10/site-packages/rest_framework_simplejwt/tokens.py", line 42, in __init__
    self.payload = token_backend.decode(token, verify=verify)
  File "/usr/local/lib/python3.10/site-packages/rest_framework_simplejwt/backends.py", line 152, in decode
    raise TokenBackendError(_("Token is invalid or expired")) from ex
rest_framework_simplejwt.exceptions.TokenBackendError: Token is invalid or expired

During handling of the above exception, another exception occurred:

Traceback (most recent call last):
  File "/usr/local/lib/python3.10/site-packages/django/core/handlers/exception.py", line 55, in inner
    response = get_response(request)
  File "/usr/local/lib/python3.10/site-packages/django/core/handlers/base.py", line 197, in _get_response
    response = wrapped_callback(request, *callback_args, **callback_kwargs)
  File "/usr/local/lib/python3.10/site-packages/django/views/decorators/csrf.py", line 56, in wrapper_view
    return view_func(*args, **kwargs)
  File "/usr/local/lib/python3.10/site-packages/django/views/generic/base.py", line 104, in view
    return self.dispatch(request, *args, **kwargs)
  File "/usr/local/lib/python3.10/site-packages/rest_framework/views.py", line 509, in dispatch
    response = self.handle_exception(exc)
  File "/usr/local/lib/python3.10/site-packages/rest_framework/views.py", line 469, in handle_exception
    self.raise_uncaught_exception(exc)
  File "/usr/local/lib/python3.10/site-packages/rest_framework/views.py", line 480, in raise_uncaught_exception
    raise exc
  File "/usr/local/lib/python3.10/site-packages/rest_framework/views.py", line 506, in dispatch
    response = handler(request, *args, **kwargs)
  File "/usr/local/lib/python3.10/site-packages/rest_framework/decorators.py", line 50, in handler
    return func(*args, **kwargs)
  File "/app/backend/api/views.py", line 64, in verify
    token = AccessToken(access_token)
  File "/usr/local/lib/python3.10/site-packages/rest_framework_simplejwt/tokens.py", line 44, in __init__
    raise TokenError(_("Token is invalid or expired"))
rest_framework_simplejwt.exceptions.TokenError: Token is invalid or expired
[20/Oct/2023 17:19:44] ERROR [django.request:241] Internal Server Error: /api/verify
Traceback (most recent call last):
  File "/usr/local/lib/python3.10/site-packages/rest_framework_simplejwt/backends.py", line 137, in decode
    return jwt.decode(
  File "/usr/local/lib/python3.10/site-packages/jwt/api_jwt.py", line 210, in decode
    decoded = self.decode_complete(
  File "/usr/local/lib/python3.10/site-packages/jwt/api_jwt.py", line 162, in decode_complete
    self._validate_claims(
  File "/usr/local/lib/python3.10/site-packages/jwt/api_jwt.py", line 248, in _validate_claims
    self._validate_exp(payload, now, leeway)
  File "/usr/local/lib/python3.10/site-packages/jwt/api_jwt.py", line 304, in _validate_exp
    raise ExpiredSignatureError("Signature has expired")
jwt.exceptions.ExpiredSignatureError: Signature has expired

The above exception was the direct cause of the following exception:

Traceback (most recent call last):
  File "/usr/local/lib/python3.10/site-packages/rest_framework_simplejwt/tokens.py", line 42, in __init__
    self.payload = token_backend.decode(token, verify=verify)
  File "/usr/local/lib/python3.10/site-packages/rest_framework_simplejwt/backends.py", line 152, in decode
    raise TokenBackendError(_("Token is invalid or expired")) from ex
rest_framework_simplejwt.exceptions.TokenBackendError: Token is invalid or expired

During handling of the above exception, another exception occurred:

Traceback (most recent call last):
  File "/usr/local/lib/python3.10/site-packages/django/core/handlers/exception.py", line 55, in inner
    response = get_response(request)
  File "/usr/local/lib/python3.10/site-packages/django/core/handlers/base.py", line 197, in _get_response
    response = wrapped_callback(request, *callback_args, **callback_kwargs)
  File "/usr/local/lib/python3.10/site-packages/django/views/decorators/csrf.py", line 56, in wrapper_view
    return view_func(*args, **kwargs)
  File "/usr/local/lib/python3.10/site-packages/django/views/generic/base.py", line 104, in view
    return self.dispatch(request, *args, **kwargs)
  File "/usr/local/lib/python3.10/site-packages/rest_framework/views.py", line 509, in dispatch
    response = self.handle_exception(exc)
  File "/usr/local/lib/python3.10/site-packages/rest_framework/views.py", line 469, in handle_exception
    self.raise_uncaught_exception(exc)
  File "/usr/local/lib/python3.10/site-packages/rest_framework/views.py", line 480, in raise_uncaught_exception
    raise exc
  File "/usr/local/lib/python3.10/site-packages/rest_framework/views.py", line 506, in dispatch
    response = handler(request, *args, **kwargs)
  File "/usr/local/lib/python3.10/site-packages/rest_framework/decorators.py", line 50, in handler
    return func(*args, **kwargs)
  File "/app/backend/api/views.py", line 64, in verify
    token = AccessToken(access_token)
  File "/usr/local/lib/python3.10/site-packages/rest_framework_simplejwt/tokens.py", line 44, in __init__
    raise TokenError(_("Token is invalid or expired"))
rest_framework_simplejwt.exceptions.TokenError: Token is invalid or expired
[20/Oct/2023 17:19:44] ERROR [django.server:212] "POST /api/verify HTTP/1.1" 500 131459
[20/Oct/2023 17:19:44] ERROR [django.server:212] "POST /api/verify HTTP/1.1" 500 131459
[20/Oct/2023 17:19:44] ERROR [django.server:212] "POST /api/verify HTTP/1.1" 500 131459
[20/Oct/2023 17:19:44] ERROR [django.server:212] "POST /api/verify HTTP/1.1" 500 131459
[20/Oct/2023 17:19:44] WARNING [django.request:241] Unauthorized: /api/company/check-in/0
[20/Oct/2023 17:19:44] WARNING [django.request:241] Unauthorized: /api/company/check-in/0
[20/Oct/2023 17:19:44] WARNING [django.server:212] "GET /api/company/check-in/0 HTTP/1.1" 401 58
[20/Oct/2023 17:19:44] WARNING [django.server:212] "GET /api/company/check-in/0 HTTP/1.1" 401 58
[20/Oct/2023 17:21:03] WARNING [django.request:241] Bad Request: /api/updateTaskForces/1
[20/Oct/2023 17:21:03] WARNING [django.request:241] Bad Request: /api/updateTaskForces/1
[20/Oct/2023 17:21:03] WARNING [django.server:212] "PUT /api/updateTaskForces/1 HTTP/1.1" 400 155
[20/Oct/2023 17:21:03] WARNING [django.server:212] "PUT /api/updateTaskForces/1 HTTP/1.1" 400 155
[20/Oct/2023 17:51:41] WARNING [django.request:241] Unauthorized: /api/fetchTasksByEmployeeId/get/0
[20/Oct/2023 17:51:41] WARNING [django.request:241] Unauthorized: /api/fetchTasksByEmployeeId/get/0
[20/Oct/2023 17:51:42] WARNING [django.server:212] "GET /api/fetchTasksByEmployeeId/get/0 HTTP/1.1" 401 183
[20/Oct/2023 17:51:42] WARNING [django.server:212] "GET /api/fetchTasksByEmployeeId/get/0 HTTP/1.1" 401 183
[20/Oct/2023 17:51:57] WARNING [django.request:241] Not Found: /api/fetchTasksByEmployeeId/get/0
[20/Oct/2023 17:51:57] WARNING [django.request:241] Not Found: /api/fetchTasksByEmployeeId/get/0
[20/Oct/2023 17:51:57] WARNING [django.server:212] "GET /api/fetchTasksByEmployeeId/get/0 HTTP/1.1" 404 49
[20/Oct/2023 17:51:57] WARNING [django.server:212] "GET /api/fetchTasksByEmployeeId/get/0 HTTP/1.1" 404 49
[20/Oct/2023 17:52:28] WARNING [django.request:241] Not Found: /api/fetchTasksByEmployeeId/get/0
[20/Oct/2023 17:52:28] WARNING [django.request:241] Not Found: /api/fetchTasksByEmployeeId/get/0
[20/Oct/2023 17:52:28] WARNING [django.server:212] "GET /api/fetchTasksByEmployeeId/get/0 HTTP/1.1" 404 49
[20/Oct/2023 17:52:28] WARNING [django.server:212] "GET /api/fetchTasksByEmployeeId/get/0 HTTP/1.1" 404 49
[20/Oct/2023 17:52:30] WARNING [django.request:241] Not Found: /api/fetchTasksByEmployeeId/get/0
[20/Oct/2023 17:52:30] WARNING [django.request:241] Not Found: /api/fetchTasksByEmployeeId/get/0
[20/Oct/2023 17:52:30] WARNING [django.server:212] "GET /api/fetchTasksByEmployeeId/get/0 HTTP/1.1" 404 49
[20/Oct/2023 17:52:30] WARNING [django.server:212] "GET /api/fetchTasksByEmployeeId/get/0 HTTP/1.1" 404 49
[20/Oct/2023 17:53:57] WARNING [django.request:241] Not Found: /api/fetchTasksByEmployeeId/get/0
[20/Oct/2023 17:53:57] WARNING [django.request:241] Not Found: /api/fetchTasksByEmployeeId/get/0
[20/Oct/2023 17:53:57] WARNING [django.server:212] "GET /api/fetchTasksByEmployeeId/get/0 HTTP/1.1" 404 49
[20/Oct/2023 17:53:57] WARNING [django.server:212] "GET /api/fetchTasksByEmployeeId/get/0 HTTP/1.1" 404 49
[20/Oct/2023 17:55:21] WARNING [django.request:241] Bad Request: /api/register
[20/Oct/2023 17:55:21] WARNING [django.request:241] Bad Request: /api/register
[20/Oct/2023 17:55:21] WARNING [django.server:212] "POST /api/register HTTP/1.1" 400 42
[20/Oct/2023 17:55:21] WARNING [django.server:212] "POST /api/register HTTP/1.1" 400 42
[20/Oct/2023 17:55:28] WARNING [django.request:241] Bad Request: /api/register
[20/Oct/2023 17:55:28] WARNING [django.request:241] Bad Request: /api/register
[20/Oct/2023 17:55:28] WARNING [django.server:212] "POST /api/register HTTP/1.1" 400 42
[20/Oct/2023 17:55:28] WARNING [django.server:212] "POST /api/register HTTP/1.1" 400 42
[20/Oct/2023 17:55:35] WARNING [django.request:241] Bad Request: /api/register
[20/Oct/2023 17:55:35] WARNING [django.request:241] Bad Request: /api/register
[20/Oct/2023 17:55:35] WARNING [django.server:212] "POST /api/register HTTP/1.1" 400 42
[20/Oct/2023 17:55:35] WARNING [django.server:212] "POST /api/register HTTP/1.1" 400 42
[20/Oct/2023 17:56:13] ERROR [django.request:241] Internal Server Error: /api/companyEmployee/create
[20/Oct/2023 17:56:13] ERROR [django.request:241] Internal Server Error: /api/companyEmployee/create
[20/Oct/2023 17:56:13] ERROR [django.server:212] "POST /api/companyEmployee/create HTTP/1.1" 500 51
[20/Oct/2023 17:56:13] ERROR [django.server:212] "POST /api/companyEmployee/create HTTP/1.1" 500 51
[20/Oct/2023 17:58:35] WARNING [django.request:241] Not Found: /api/fetchTasksByEmployeeId/get/0
[20/Oct/2023 17:58:35] WARNING [django.request:241] Not Found: /api/fetchTasksByEmployeeId/get/0
[20/Oct/2023 17:58:35] WARNING [django.server:212] "GET /api/fetchTasksByEmployeeId/get/0 HTTP/1.1" 404 49
[20/Oct/2023 17:58:35] WARNING [django.server:212] "GET /api/fetchTasksByEmployeeId/get/0 HTTP/1.1" 404 49
[20/Oct/2023 17:58:45] WARNING [django.request:241] Not Found: /api/fetchTasksByEmployeeId/get/0
[20/Oct/2023 17:58:45] WARNING [django.request:241] Not Found: /api/fetchTasksByEmployeeId/get/0
[20/Oct/2023 17:58:45] WARNING [django.server:212] "GET /api/fetchTasksByEmployeeId/get/0 HTTP/1.1" 404 49
[20/Oct/2023 17:58:45] WARNING [django.server:212] "GET /api/fetchTasksByEmployeeId/get/0 HTTP/1.1" 404 49
[20/Oct/2023 18:00:21] WARNING [django.request:241] Not Found: /api/fetchTasksByEmployeeId/get/0
[20/Oct/2023 18:00:21] WARNING [django.request:241] Not Found: /api/fetchTasksByEmployeeId/get/0
[20/Oct/2023 18:00:21] WARNING [django.server:212] "GET /api/fetchTasksByEmployeeId/get/0 HTTP/1.1" 404 49
[20/Oct/2023 18:00:21] WARNING [django.server:212] "GET /api/fetchTasksByEmployeeId/get/0 HTTP/1.1" 404 49
[20/Oct/2023 18:00:24] WARNING [django.request:241] Not Found: /api/fetchTasksByEmployeeId/get/0
[20/Oct/2023 18:00:24] WARNING [django.request:241] Not Found: /api/fetchTasksByEmployeeId/get/0
[20/Oct/2023 18:00:24] WARNING [django.server:212] "GET /api/fetchTasksByEmployeeId/get/0 HTTP/1.1" 404 49
[20/Oct/2023 18:00:24] WARNING [django.server:212] "GET /api/fetchTasksByEmployeeId/get/0 HTTP/1.1" 404 49
[20/Oct/2023 18:02:42] WARNING [django.request:241] Not Found: /api/fetchTasksByEmployeeId/get/0
[20/Oct/2023 18:02:42] WARNING [django.request:241] Not Found: /api/fetchTasksByEmployeeId/get/0
[20/Oct/2023 18:02:42] WARNING [django.server:212] "GET /api/fetchTasksByEmployeeId/get/0 HTTP/1.1" 404 49
[20/Oct/2023 18:02:42] WARNING [django.server:212] "GET /api/fetchTasksByEmployeeId/get/0 HTTP/1.1" 404 49
[20/Oct/2023 18:34:09] WARNING [django.request:241] Unauthorized: /api/getTasksByTfId/get/1
[20/Oct/2023 18:34:09] WARNING [django.request:241] Unauthorized: /api/getTasksByTfId/get/1
[20/Oct/2023 18:34:09] WARNING [django.server:212] "GET /api/getTasksByTfId/get/1 HTTP/1.1" 401 183
[20/Oct/2023 18:34:09] WARNING [django.server:212] "GET /api/getTasksByTfId/get/1 HTTP/1.1" 401 183
[20/Oct/2023 18:37:24] WARNING [django.request:241] Bad Request: /api/updateTasks/2
[20/Oct/2023 18:37:24] WARNING [django.request:241] Bad Request: /api/updateTasks/2
[20/Oct/2023 18:37:24] WARNING [django.server:212] "PUT /api/updateTasks/2 HTTP/1.1" 400 42
[20/Oct/2023 18:37:24] WARNING [django.server:212] "PUT /api/updateTasks/2 HTTP/1.1" 400 42
[20/Oct/2023 19:08:34] WARNING [django.request:241] Unauthorized: /api/verify
[20/Oct/2023 19:08:34] WARNING [django.request:241] Unauthorized: /api/verify
[20/Oct/2023 19:08:34] WARNING [django.server:212] "POST /api/verify HTTP/1.1" 401 183
[20/Oct/2023 19:08:34] WARNING [django.server:212] "POST /api/verify HTTP/1.1" 401 183
[20/Oct/2023 19:11:16] WARNING [django.request:241] Unauthorized: /api/getTasksByTfId/get/2
[20/Oct/2023 19:11:16] WARNING [django.request:241] Unauthorized: /api/getTasksByTfId/get/2
[20/Oct/2023 19:11:16] WARNING [django.server:212] "GET /api/getTasksByTfId/get/2 HTTP/1.1" 401 58
[20/Oct/2023 19:11:16] WARNING [django.server:212] "GET /api/getTasksByTfId/get/2 HTTP/1.1" 401 58
[20/Oct/2023 19:11:20] WARNING [django.request:241] Unauthorized: /api/getTasksByTfId/get/2
[20/Oct/2023 19:11:20] WARNING [django.request:241] Unauthorized: /api/getTasksByTfId/get/2
[20/Oct/2023 19:11:20] WARNING [django.server:212] "GET /api/getTasksByTfId/get/2 HTTP/1.1" 401 58
[20/Oct/2023 19:11:20] WARNING [django.server:212] "GET /api/getTasksByTfId/get/2 HTTP/1.1" 401 58
[20/Oct/2023 19:12:33] WARNING [django.request:241] Bad Request: /api/updateTasks/1
[20/Oct/2023 19:12:33] WARNING [django.request:241] Bad Request: /api/updateTasks/1
[20/Oct/2023 19:12:33] WARNING [django.server:212] "PUT /api/updateTasks/1 HTTP/1.1" 400 58
[20/Oct/2023 19:12:33] WARNING [django.server:212] "PUT /api/updateTasks/1 HTTP/1.1" 400 58
[20/Oct/2023 19:42:59] WARNING [django.request:241] Unauthorized: /api/verify
[20/Oct/2023 19:42:59] WARNING [django.request:241] Unauthorized: /api/verify
[20/Oct/2023 19:42:59] WARNING [django.server:212] "POST /api/verify HTTP/1.1" 401 183
[20/Oct/2023 19:42:59] WARNING [django.server:212] "POST /api/verify HTTP/1.1" 401 183
[20/Oct/2023 19:48:58] WARNING [django.request:241] Unauthorized: /api/getTasksByTfId/get/1
[20/Oct/2023 19:48:58] WARNING [django.request:241] Unauthorized: /api/getTasksByTfId/get/1
[20/Oct/2023 19:48:58] WARNING [django.server:212] "GET /api/getTasksByTfId/get/1 HTTP/1.1" 401 58
[20/Oct/2023 19:48:58] WARNING [django.server:212] "GET /api/getTasksByTfId/get/1 HTTP/1.1" 401 58
[20/Oct/2023 19:49:04] WARNING [django.request:241] Unauthorized: /api/getTasksByTfId/get/1
[20/Oct/2023 19:49:04] WARNING [django.request:241] Unauthorized: /api/getTasksByTfId/get/1
[20/Oct/2023 19:49:04] WARNING [django.server:212] "GET /api/getTasksByTfId/get/1 HTTP/1.1" 401 58
[20/Oct/2023 19:49:04] WARNING [django.server:212] "GET /api/getTasksByTfId/get/1 HTTP/1.1" 401 58
[20/Oct/2023 19:49:26] ERROR [django.security.DisallowedHost:124] Invalid HTTP_HOST header: '61.231.64.27:8000'. You may need to add '61.231.64.27' to ALLOWED_HOSTS.
Traceback (most recent call last):
  File "/usr/local/lib/python3.10/site-packages/django/core/handlers/exception.py", line 55, in inner
    response = get_response(request)
  File "/usr/local/lib/python3.10/site-packages/django/utils/deprecation.py", line 133, in __call__
    response = self.process_request(request)
  File "/usr/local/lib/python3.10/site-packages/django/middleware/common.py", line 48, in process_request
    host = request.get_host()
  File "/usr/local/lib/python3.10/site-packages/django/http/request.py", line 167, in get_host
    raise DisallowedHost(msg)
django.core.exceptions.DisallowedHost: Invalid HTTP_HOST header: '61.231.64.27:8000'. You may need to add '61.231.64.27' to ALLOWED_HOSTS.
[20/Oct/2023 19:49:26] ERROR [django.security.DisallowedHost:124] Invalid HTTP_HOST header: '61.231.64.27:8000'. You may need to add '61.231.64.27' to ALLOWED_HOSTS.
Traceback (most recent call last):
  File "/usr/local/lib/python3.10/site-packages/django/core/handlers/exception.py", line 55, in inner
    response = get_response(request)
  File "/usr/local/lib/python3.10/site-packages/django/utils/deprecation.py", line 133, in __call__
    response = self.process_request(request)
  File "/usr/local/lib/python3.10/site-packages/django/middleware/common.py", line 48, in process_request
    host = request.get_host()
  File "/usr/local/lib/python3.10/site-packages/django/http/request.py", line 167, in get_host
    raise DisallowedHost(msg)
django.core.exceptions.DisallowedHost: Invalid HTTP_HOST header: '61.231.64.27:8000'. You may need to add '61.231.64.27' to ALLOWED_HOSTS.
[20/Oct/2023 19:49:26] WARNING [django.request:241] Bad Request: /
[20/Oct/2023 19:49:26] WARNING [django.request:241] Bad Request: /
[20/Oct/2023 19:49:26] WARNING [django.server:212] "GET / HTTP/1.1" 400 63180
[20/Oct/2023 19:49:26] WARNING [django.server:212] "GET / HTTP/1.1" 400 63180
[20/Oct/2023 20:11:04] WARNING [django.request:241] Not Found: /api/updateTasks/undefined
[20/Oct/2023 20:11:04] WARNING [django.request:241] Not Found: /api/updateTasks/undefined
[20/Oct/2023 20:11:04] WARNING [django.server:212] "PUT /api/updateTasks/undefined HTTP/1.1" 404 35866
[20/Oct/2023 20:11:04] WARNING [django.server:212] "PUT /api/updateTasks/undefined HTTP/1.1" 404 35866
[21/Oct/2023 06:16:27] WARNING [django.request:241] Bad Request: /api/updateTasks/3
[21/Oct/2023 06:16:27] WARNING [django.request:241] Bad Request: /api/updateTasks/3
[21/Oct/2023 06:16:27] WARNING [django.server:212] "PUT /api/updateTasks/3 HTTP/1.1" 400 60
[21/Oct/2023 06:16:27] WARNING [django.server:212] "PUT /api/updateTasks/3 HTTP/1.1" 400 60
[21/Oct/2023 06:17:33] WARNING [django.request:241] Bad Request: /api/updateTasks/3
[21/Oct/2023 06:17:33] WARNING [django.request:241] Bad Request: /api/updateTasks/3
[21/Oct/2023 06:17:33] WARNING [django.server:212] "PUT /api/updateTasks/3 HTTP/1.1" 400 42
[21/Oct/2023 06:17:33] WARNING [django.server:212] "PUT /api/updateTasks/3 HTTP/1.1" 400 42
[06/Nov/2023 08:21:58] ERROR [django.request:241] Internal Server Error: /api/companyRecruitment/get/company/all
[06/Nov/2023 08:21:58] ERROR [django.request:241] Internal Server Error: /api/companyRecruitment/get/company/all
[06/Nov/2023 08:21:58] ERROR [django.server:212] "GET /api/companyRecruitment/get/company/all HTTP/1.1" 500 241
[06/Nov/2023 08:21:58] ERROR [django.server:212] "GET /api/companyRecruitment/get/company/all HTTP/1.1" 500 241
[06/Nov/2023 08:22:14] ERROR [django.request:241] Internal Server Error: /api/companyRecruitment/get/company/all
[06/Nov/2023 08:22:14] ERROR [django.request:241] Internal Server Error: /api/companyRecruitment/get/company/all
[06/Nov/2023 08:22:14] ERROR [django.server:212] "GET /api/companyRecruitment/get/company/all HTTP/1.1" 500 241
[06/Nov/2023 08:22:14] ERROR [django.server:212] "GET /api/companyRecruitment/get/company/all HTTP/1.1" 500 241
[06/Nov/2023 08:22:20] ERROR [django.request:241] Internal Server Error: /api/companyRecruitment/get/company/all
[06/Nov/2023 08:22:20] ERROR [django.request:241] Internal Server Error: /api/companyRecruitment/get/company/all
[06/Nov/2023 08:22:20] ERROR [django.server:212] "GET /api/companyRecruitment/get/company/all HTTP/1.1" 500 241
[06/Nov/2023 08:22:20] ERROR [django.server:212] "GET /api/companyRecruitment/get/company/all HTTP/1.1" 500 241
[06/Nov/2023 08:24:15] ERROR [django.request:241] Internal Server Error: /api/companyRecruitment/get/company/all
[06/Nov/2023 08:24:15] ERROR [django.request:241] Internal Server Error: /api/companyRecruitment/get/company/all
[06/Nov/2023 08:24:15] ERROR [django.server:212] "GET /api/companyRecruitment/get/company/all HTTP/1.1" 500 241
[06/Nov/2023 08:24:15] ERROR [django.server:212] "GET /api/companyRecruitment/get/company/all HTTP/1.1" 500 241
[06/Nov/2023 08:24:23] ERROR [django.request:241] Internal Server Error: /api/companyRecruitment/get/company/all
[06/Nov/2023 08:24:23] ERROR [django.request:241] Internal Server Error: /api/companyRecruitment/get/company/all
[06/Nov/2023 08:24:23] ERROR [django.server:212] "GET /api/companyRecruitment/get/company/all HTTP/1.1" 500 241
[06/Nov/2023 08:24:23] ERROR [django.server:212] "GET /api/companyRecruitment/get/company/all HTTP/1.1" 500 241
[06/Nov/2023 08:25:47] ERROR [django.request:241] Internal Server Error: /api/companyRecruitment/get/company/all
[06/Nov/2023 08:25:47] ERROR [django.request:241] Internal Server Error: /api/companyRecruitment/get/company/all
[06/Nov/2023 08:25:47] ERROR [django.server:212] "GET /api/companyRecruitment/get/company/all HTTP/1.1" 500 241
[06/Nov/2023 08:25:47] ERROR [django.server:212] "GET /api/companyRecruitment/get/company/all HTTP/1.1" 500 241
[06/Nov/2023 08:25:49] ERROR [django.request:241] Internal Server Error: /api/companyRecruitment/get/company/all
[06/Nov/2023 08:25:49] ERROR [django.request:241] Internal Server Error: /api/companyRecruitment/get/company/all
[06/Nov/2023 08:25:49] ERROR [django.server:212] "GET /api/companyRecruitment/get/company/all HTTP/1.1" 500 241
[06/Nov/2023 08:25:49] ERROR [django.server:212] "GET /api/companyRecruitment/get/company/all HTTP/1.1" 500 241
[06/Nov/2023 08:25:52] ERROR [django.request:241] Internal Server Error: /api/companyRecruitment/get/company/all
[06/Nov/2023 08:25:52] ERROR [django.request:241] Internal Server Error: /api/companyRecruitment/get/company/all
[06/Nov/2023 08:25:52] ERROR [django.server:212] "GET /api/companyRecruitment/get/company/all HTTP/1.1" 500 241
[06/Nov/2023 08:25:52] ERROR [django.server:212] "GET /api/companyRecruitment/get/company/all HTTP/1.1" 500 241
[06/Nov/2023 08:25:58] ERROR [django.request:241] Internal Server Error: /api/companyRecruitment/get/company/all
[06/Nov/2023 08:25:58] ERROR [django.request:241] Internal Server Error: /api/companyRecruitment/get/company/all
[06/Nov/2023 08:25:58] ERROR [django.server:212] "GET /api/companyRecruitment/get/company/all HTTP/1.1" 500 241
[06/Nov/2023 08:25:58] ERROR [django.server:212] "GET /api/companyRecruitment/get/company/all HTTP/1.1" 500 241
[06/Nov/2023 08:27:06] ERROR [django.request:241] Internal Server Error: /api/companyRecruitment/get/company/all
[06/Nov/2023 08:27:06] ERROR [django.request:241] Internal Server Error: /api/companyRecruitment/get/company/all
[06/Nov/2023 08:27:06] ERROR [django.server:212] "GET /api/companyRecruitment/get/company/all HTTP/1.1" 500 241
[06/Nov/2023 08:27:06] ERROR [django.server:212] "GET /api/companyRecruitment/get/company/all HTTP/1.1" 500 241
[06/Nov/2023 08:27:55] ERROR [django.request:241] Internal Server Error: /api/companyRecruitment/get/company/all
[06/Nov/2023 08:27:55] ERROR [django.request:241] Internal Server Error: /api/companyRecruitment/get/company/all
[06/Nov/2023 08:27:55] ERROR [django.server:212] "GET /api/companyRecruitment/get/company/all HTTP/1.1" 500 241
[06/Nov/2023 08:27:55] ERROR [django.server:212] "GET /api/companyRecruitment/get/company/all HTTP/1.1" 500 241
[06/Nov/2023 08:28:05] ERROR [django.request:241] Internal Server Error: /api/companyRecruitment/get/company/all
[06/Nov/2023 08:28:05] ERROR [django.request:241] Internal Server Error: /api/companyRecruitment/get/company/all
[06/Nov/2023 08:28:05] ERROR [django.server:212] "GET /api/companyRecruitment/get/company/all HTTP/1.1" 500 241
[06/Nov/2023 08:28:05] ERROR [django.server:212] "GET /api/companyRecruitment/get/company/all HTTP/1.1" 500 241
[06/Nov/2023 08:29:04] ERROR [django.request:241] Internal Server Error: /api/companyRecruitment/get/company/all
[06/Nov/2023 08:29:04] ERROR [django.request:241] Internal Server Error: /api/companyRecruitment/get/company/all
[06/Nov/2023 08:29:04] ERROR [django.server:212] "GET /api/companyRecruitment/get/company/all HTTP/1.1" 500 241
[06/Nov/2023 08:29:04] ERROR [django.server:212] "GET /api/companyRecruitment/get/company/all HTTP/1.1" 500 241
[06/Nov/2023 08:29:09] ERROR [django.request:241] Internal Server Error: /api/companyRecruitment/get/company/all
[06/Nov/2023 08:29:09] ERROR [django.request:241] Internal Server Error: /api/companyRecruitment/get/company/all
[06/Nov/2023 08:29:09] ERROR [django.server:212] "GET /api/companyRecruitment/get/company/all HTTP/1.1" 500 241
[06/Nov/2023 08:29:09] ERROR [django.server:212] "GET /api/companyRecruitment/get/company/all HTTP/1.1" 500 241
[06/Nov/2023 08:29:42] ERROR [django.request:241] Internal Server Error: /api/companyRecruitment/get/company/all
[06/Nov/2023 08:29:42] ERROR [django.request:241] Internal Server Error: /api/companyRecruitment/get/company/all
[06/Nov/2023 08:29:42] ERROR [django.server:212] "GET /api/companyRecruitment/get/company/all HTTP/1.1" 500 241
[06/Nov/2023 08:29:42] ERROR [django.server:212] "GET /api/companyRecruitment/get/company/all HTTP/1.1" 500 241
[06/Nov/2023 08:29:44] ERROR [django.request:241] Internal Server Error: /api/companyRecruitment/get/company/all
[06/Nov/2023 08:29:44] ERROR [django.request:241] Internal Server Error: /api/companyRecruitment/get/company/all
[06/Nov/2023 08:29:44] ERROR [django.server:212] "GET /api/companyRecruitment/get/company/all HTTP/1.1" 500 241
[06/Nov/2023 08:29:44] ERROR [django.server:212] "GET /api/companyRecruitment/get/company/all HTTP/1.1" 500 241
[06/Nov/2023 08:29:45] ERROR [django.request:241] Internal Server Error: /api/companyRecruitment/get/company/all
[06/Nov/2023 08:29:45] ERROR [django.request:241] Internal Server Error: /api/companyRecruitment/get/company/all
[06/Nov/2023 08:29:45] ERROR [django.server:212] "GET /api/companyRecruitment/get/company/all HTTP/1.1" 500 241
[06/Nov/2023 08:29:45] ERROR [django.server:212] "GET /api/companyRecruitment/get/company/all HTTP/1.1" 500 241
[06/Nov/2023 08:30:01] ERROR [django.request:241] Internal Server Error: /api/companyRecruitment/get/company/all
[06/Nov/2023 08:30:01] ERROR [django.request:241] Internal Server Error: /api/companyRecruitment/get/company/all
[06/Nov/2023 08:30:01] ERROR [django.server:212] "GET /api/companyRecruitment/get/company/all HTTP/1.1" 500 241
[06/Nov/2023 08:30:01] ERROR [django.server:212] "GET /api/companyRecruitment/get/company/all HTTP/1.1" 500 241
[06/Nov/2023 08:30:04] ERROR [django.request:241] Internal Server Error: /api/companyRecruitment/get/company/all
[06/Nov/2023 08:30:04] ERROR [django.request:241] Internal Server Error: /api/companyRecruitment/get/company/all
[06/Nov/2023 08:30:04] ERROR [django.server:212] "GET /api/companyRecruitment/get/company/all HTTP/1.1" 500 241
[06/Nov/2023 08:30:04] ERROR [django.server:212] "GET /api/companyRecruitment/get/company/all HTTP/1.1" 500 241
[06/Nov/2023 08:30:10] ERROR [django.request:241] Internal Server Error: /api/companyRecruitment/get/company/all
[06/Nov/2023 08:30:10] ERROR [django.request:241] Internal Server Error: /api/companyRecruitment/get/company/all
[06/Nov/2023 08:30:10] ERROR [django.server:212] "GET /api/companyRecruitment/get/company/all HTTP/1.1" 500 241
[06/Nov/2023 08:30:10] ERROR [django.server:212] "GET /api/companyRecruitment/get/company/all HTTP/1.1" 500 241
[06/Nov/2023 08:30:42] ERROR [django.request:241] Internal Server Error: /api/companyRecruitment/get/company/all
[06/Nov/2023 08:30:42] ERROR [django.request:241] Internal Server Error: /api/companyRecruitment/get/company/all
[06/Nov/2023 08:30:42] ERROR [django.server:212] "GET /api/companyRecruitment/get/company/all HTTP/1.1" 500 241
[06/Nov/2023 08:30:42] ERROR [django.server:212] "GET /api/companyRecruitment/get/company/all HTTP/1.1" 500 241
